Workbook

Sheet Template Loading Instruction
C1: CCC PIGS BULK FEED LOADING AND RECEIVING FORM | G1: CCC PIGS BULK FEED LOADING AND RECEIVING FORM | K1: CCC PIGS BULK FEED LOADING AND RECEIVING FORM | O1: CCC PIGS BULK FEED LOADING AND RECEIVING FORM | S1: CCC PIGS BULK FEED LOADING AND RECEIVING FORM | W1: CCC PIGS BULK FEED LOADING AND RECEIVING FORM | AA1: CCC PIGS BULK FEED LOADING AND RECEIVING FORM
C2: Farm/Site Name: | E2: Driver name: | G2: Farm/Site Name: | I2: Driver name: | K2: Farm/Site Name: | M2: Driver name: | O2: Farm/Site Name: | Q2: Driver name: | S2: Farm/Site Name: | U2: Driver name: | W2: Farm/Site Name: | Y2: Driver name: | AA2: Farm/Site Name: | AC2: Driver name:
C3: Week No: | E3: Truck reg: | G3: Week No: | I3: Truck reg: | K3: Week No: | M3: Truck reg: | O3: Week No: | Q3: Truck reg: | S3: Week No: | U3: Truck reg: | W3: Week No: | Y3: Truck reg: | AA3: Week No: | AC3: Truck reg:
C4: Date: | E4: Trailer reg: | G4: Date: | I4: Trailer reg: | K4: Date: | M4: Trailer reg: | O4: Date: | Q4: Trailer reg: | S4: Date: | U4: Trailer reg: | W4: Date: | Y4: Trailer reg: | AA4: Date: | AC4: Trailer reg:
C5: Weighbridge Ticket No: | E5: System Shipment No: | G5: Weighbridge Ticket No: | I5: System Shipment No: | K5: Weighbridge Ticket No: | M5: System Shipment No: | O5: Weighbridge Ticket No: | Q5: System Shipment No: | S5: Weighbridge Ticket No: | U5: System Shipment No: | W5: Weighbridge Ticket No: | Y5: System Shipment No: | AA5: Weighbridge Ticket No: | AC5: System Shipment No:
C6: Load start time: | E6: Load end time: | G6: Load start time: | I6: Load end time: | K6: Load start time: | M6: Load end time: | O6: Load start time: | Q6: Load end time: | S6: Load start time: | U6: Load end time: | W6: Load start time: | Y6: Load end time: | AA6: Load start time: | AC6: Load end time:
C7: Offload start time: | E7: Offload end time: | G7: Offload start time: | I7: Offload end time: | K7: Offload start time: | M7: Offload end time: | O7: Offload start time: | Q7: Offload end time: | S7: Offload start time: | U7: Offload end time: | W7: Offload start time: | Y7: Offload end time: | AA7: Offload start time: | AC7: Offload end time:
A9: House # | C9: Monday | G9: Tuesday | K9: Wednesday | O9: Thursday | S9: Friday | W9: Saturday | AA9: Sunday | AE9: Totals
C10: Diet | D10: Kgs Ordered | E10: kgs Loaded | F10: Compartment No. | G10: Diet | H10: Kgs Ordered | I10: kgs Loaded | J10: Compartment No. | K10: Diet | L10: Kgs Ordered | M10: kgs Loaded | N10: Compartment No. | O10: Diet | P10: Kgs Ordered | Q10: kgs Loaded | R10: Compartment No. | S10: Diet | T10: Kgs Ordered | U10: kgs Loaded | V10: Compartment No. | W10: Diet | X10: Kgs Ordered | Y10: kgs Loaded | Z10: Compartment No. | AA10: Diet | AB10: Kgs Ordered | AC10: kgs Loaded | AD10: Compartment No. | AE10: Kgs Ordered | AF10: Kg delivered
A11: W6 | C11: ='Template Feed Order'!D72 -> Creep 2 | AE11: =SUM(D11,H11,L11,P11,T11,X11,AB11) -> 0 | AF11: =SUM(E11,I11,M11,Q11,U11,Y11,AC11) -> 0
A12: W5 | AE12: =SUM(D12,H12,L12,P12,T12,X12,AB12) -> 0 | AF12: =SUM(E12,I12,M12,Q12,U12,Y12,AC12) -> 0
A13: W4 | AE13: =SUM(D13,H13,L13,P13,T13,X13,AB13) -> 0 | AF13: =SUM(E13,I13,M13,Q13,U13,Y13,AC13) -> 0
A14: W2 | AE14: =SUM(D14,H14,L14,P14,T14,X14,AB14) -> 0 | AF14: =SUM(E14,I14,M14,Q14,U14,Y14,AC14) -> 0
A15: W1 | AE15: =SUM(D15,H15,L15,P15,T15,X15,AB15) -> 0 | AF15: =SUM(E15,I15,M15,Q15,U15,Y15,AC15) -> 0
A16: DST4 | AE16: =SUM(D16,H16,L16,P16,T16,X16,AB16) -> 0 | AF16: =SUM(E16,I16,M16,Q16,U16,Y16,AC16) -> 0
A17: DST 3 | AE17: =SUM(D17,H17,L17,P17,T17,X17,AB17) -> 0 | AF17: =SUM(E17,I17,M17,Q17,U17,Y17,AC17) -> 0
A18: DST 2 | AE18: =SUM(D18,H18,L18,P18,T18,X18,AB18) -> 0 | AF18: =SUM(E18,I18,M18,Q18,U18,Y18,AC18) -> 0
A19: DST1 | AE19: =SUM(D19,H19,L19,P19,T19,X19,AB19) -> 0 | AF19: =SUM(E19,I19,M19,Q19,U19,Y19,AC19) -> 0
A20: GR4 | AE20: =SUM(D20,H20,L20,P20,T20,X20,AB20) -> 0 | AF20: =SUM(E20,I20,M20,Q20,U20,Y20,AC20) -> 0
A21: GR3 | AE21: =SUM(D21,H21,L21,P21,T21,X21,AB21) -> 0 | AF21: =SUM(E21,I21,M21,Q21,U21,Y21,AC21) -> 0
A22: GR2 | AE22: =SUM(D22,H22,L22,P22,T22,X22,AB22) -> 0 | AF22: =SUM(E22,I22,M22,Q22,U22,Y22,AC22) -> 0
A23: Gr1 | AE23: =SUM(D23,H23,L23,P23,T23,X23,AB23) -> 0 | AF23: =SUM(E23,I23,M23,Q23,U23,Y23,AC23) -> 0
... A40: DS3 | AE40: =SUM(D40,H40,L40,P40,T40,X40,AB40) -> 0 | AF40: =SUM(E40,I40,M40,Q40,U40,Y40,AC40) -> 0
A41: Total | D41: =SUM(D11:D40) -> 0 | H41: =SUM(H11:H40) -> 0 | L41: =SUM(L11:L40) -> 0 | P41: =SUM(P11:P40) -> 0 | T41: =SUM(T11:T40) -> 0 | X41: =SUM(X11:X40) -> 0 | AB41: =SUM(AB11:AB40) -> 0 | AE41: =SUM(AE11:AE40) -> 0 | AF41: =SUM(AF11:AF40) -> 0
C43: Loaded by | E43: Received by | G43: Loaded by | I43: Received by | K43: Loaded by | M43: Received by | O43: Loaded by | Q43: Received by | S43: Loaded by | U43: Received by | W43: Loaded by | Y43: Received by | AA43: Loaded by | AC43: Received by
C44: Checked by | E44: Checked by | G44: Checked by | I44: Checked by | K44: Checked by | M44: Checked by | O44: Checked by | Q44: Checked by | S44: Checked by | U44: Checked by | W44: Checked by | Y44: Checked by | AA44: Checked by | AC44: Checked by
C45: Authorized by | E45: Authorized by | G45: Authorized by | I45: Authorized by | K45: Authorized by | M45: Authorized by | O45: Authorized by | Q45: Authorized by | S45: Authorized by | U45: Authorized by | W45: Authorized by | Y45: Authorized by | AA45: Authorized by | AC45: Authorized by

Sheet Template Feed Order
A4: WEANER BULK FEED ORDER REQUIRED | K4: MAINSITE BULK FEED ORDER REQUIRED
A5: DIET | B5: Mon | C5: Tue | D5: Wed | E5: Thu | F5: Fri | G5: Sat | H5: Sun | K5: DIET | L5: Mon | M5: Tue | N5: Wed | O5: Thu | P5: Fri | Q5: Sat | R5: Sun
A6: Creep 1 | B6: =SUM(T72:T77) -> 0 | C6: =SUM(Y72:Y77) -> 0 | D6: =SUM(AD72:AD77) -> 0 | E6: =SUM(AI72:AI77) -> 0 | F6: =SUM(AN72:AN77) -> 0 | G6: =SUM(AX72:AX77) -> 0 | H6: 0 | K6: Dry Sow | L6: =SUM(T28:T40) -> 0 | M6: =SUM(Y28:Y40) -> 0 | N6: =SUM(AD28:AD40) -> 0 | O6: =SUM(AI28:AI40) -> 0 | P6: =SUM(AN28:AN40) -> 0 | Q6: =SUM(AS28:AS40) -> 0 | R6: =SUM(AX28:AX40) -> 0
A7: Creep 2 | B7: =SUM(U72:U77) -> 0 | C7: =SUM(Z72:Z77) -> 0 | D7: =SUM(AE72:AE77) -> 0 | E7: =SUM(AJ72:AJ77) -> 0 | F7: =SUM(AO72:AO77) -> 0 | G7: 0 | H7: =AY72+AY73+AY74+AY75+AY76+AY77 -> 0 | K7: Supa flush | L7: =V34 -> 0 | M7: =AA34 -> 0 | N7: =AF34 -> 0 | O7: =AK34 -> 0 | P7: =AP34 -> 0 | Q7: =AU34 -> 0 | R7: =AZ34 -> 0
A8: CREEP 3 | B8: =SUM(V72:V77) -> 0 | C8: =SUM(AA72:AA77) -> 0 | D8: =SUM(AF72:AF77) -> 0 | E8: =SUM(AK72:AK77) -> 0 | F8: =SUM(AP72:AP77) -> 0 | G8: =SUM(AU72:AU77) -> 0 | H8: =AZ72+AZ73+AZ74+AZ75+AZ76+AZ77 -> 0 | K8: Dry gilt | L8: =SUM(U28:U40) -> 0 | M8: =SUM(Z28:Z40) -> 0 | N8: =SUM(AE28:AE40) -> 0 | O8: =SUM(AJ28:AJ40) -> 0 | P8: =SUM(AO28:AO40) -> 0 | Q8: =SUM(AT28:AT40) -> 0 | R8: =SUM(AY28:AY40) -> 0
A9: WEAN 1 | B9: =SUM(W72:W77) -> 0 | C9: =SUM(AB72:AB77) -> 0 | D9: =SUM(AG72:AG77) -> 0 | E9: =SUM(AL72:AL77) -> 0 | F9: =SUM(AQ72:AQ77) -> 0 | G9: =SUM(AV72:AV77) -> 0 | H9: =SUM(BA72:BA77) -> 0 | K9: Lact Sow | L9: =SUM(T49:T63) -> 0 | M9: =SUM(Y49:Y63) -> 0 | N9: =SUM(AD49:AD63) -> 0 | O9: =SUM(AI49:AI63) -> 0 | P9: =SUM(AN49:AN63) -> 0 | Q9: =SUM(AS49:AS63) -> 0 | R9: =SUM(AX49:AX63) -> 0
A10: TOTAL | B10: =SUM(B6:B9) -> 0 | C10: =SUM(C6:C9) -> 0 | D10: =SUM(D6:D9) -> 0 | E10: =SUM(E6:E9) -> 0 | F10: =SUM(F6:F9) -> 0 | G10: =SUM(G6:G9) -> 0 | H10: =SUM(H6:H9) -> 0 | K10: Transition | L10: =SUM(V49:V63) -> 0 | M10: =SUM(AA49:AA63) -> 0 | N10: =SUM(AF49:AF63) -> 0 | O10: =SUM(AK49:AK63) -> 0 | P10: =SUM(AP49:AP63) -> 0 | Q10: =SUM(AU49:AU63) -> 0 | R10: =SUM(AZ49:AZ63) -> 0
K11: Lact gilt | L11: =SUM(U49:U63) -> 0 | M11: =SUM(Z49:Z63) -> 0 | N11: =SUM(AE49:AE63) -> 0 | O11: =SUM(AJ49:AJ63) -> 0 | P11: =SUM(AO49:AO63) -> 0 | Q11: =SUM(AT49:AT63) -> 0 | R11: =SUM(AY49:AY63) -> 0
A12: GROWER BULK FEED ORDER REQUIRED
A13: DIET | B13: Mon | C13: Tue | D13: Wed | E13: Thu | F13: Fri | G13: Sat | H13: Sun
A14: W1 | B14: =SUM(T81:T123) -> 0 | C14: =SUM(Y81:Y123) -> 0 | D14: =SUM(AD81:AD123) -> 0 | E14: =SUM(AI81:AI123) -> 0 | F14: =SUM(AN81:AN123) -> 0 | G14: =SUM(AS81:AS86) -> 0 | H14: =SUM(AX81:AX123) -> 0
A15: GR 1 | B15: =SUM(U81:U123) -> 0 | C15: =SUM(Z81:Z123) -> 0 | D15: =SUM(AE81:AE123) -> 0 | E15: =SUM(AJ81:AJ123) -> 0 | F15: =SUM(AO81:AO123) -> 0 | G15: =SUM(AT81:AT123) -> 0 | H15: =SUM(AY81:AY123) -> 0 | K15: TOTAL | L15: =SUM(L6:L11) -> 0 | M15: =SUM(M6:M14) -> 0 | N15: =SUM(N6:N14) -> 0 | O15: =SUM(O6:O14) -> 0 | P15: =SUM(P6:P14) -> 0 | Q15: =SUM(Q6:Q14) -> 0 | R15: =SUM(R6:R14) -> 0
A16: GR 2 | B16: =SUM(V81:V123) -> 0 | C16: =SUM(AA81:AA123) -> 0 | D16: =SUM(AF81:AF123) -> 0 | E16: =SUM(AK81:AK123) -> 0 | F16: =SUM(AP81:AP123) -> 0 | G16: =SUM(AU93:AU98) -> 0 | H16: =SUM(AZ81:AZ123) -> 0
A17: GR 3 | B17: =SUM(W81:W123) -> 0 | C17: =SUM(AB81:AB123) -> 0 | D17: =SUM(AG81:AG123) -> 0 | E17: =SUM(AL81:AL123) -> 0 | F17: =SUM(AQ81:AQ123) -> 0 | G17: =SUM(AV99:AV108) -> 0 | H17: =SUM(BA81:BA123) -> 0
A18: Fin | B18: =SUM(X81:X123) -> 0 | C18: =SUM(AC81:AC123) -> 0 | D18: =SUM(AH81:AH123) -> 0 | E18: =SUM(AM81:AM123) -> 0 | F18: =SUM(AR81:AR123) -> 0 | G18: =SUM(AW105:AW123) -> 0 | H18: =SUM(BB81:BB123) -> 0
A19: TOTAL | B19: =SUM(B14:B18) -> 0 | C19: =SUM(C14:C18) -> 0 | D19: =SUM(D14:D18) -> 0 | E19: =SUM(E14:E18) -> 0 | F19: =SUM(F14:F18) -> 0 | G19: =SUM(G14:G18) -> 0 | H19: =SUM(H14:H18) -> 0
I20: TOTAL BULK ORDER
A21: Comb total | B21: =B10+B19+L15 -> 0 | C21: =C10+C19+M15 -> 0 | D21: =D10+D19+N15 -> 0 | E21: =E10+E19+O15 -> 0 | F21: =F10+F19+P15 -> 0 | G21: =G10+G19+Q15 -> 0 | H21: =H10+H19+R15 -> 0 | I21: =SUM(B21:H21) -> 0
A26: MAINSITE BULK FEED ORDER
A27: Batch # | B27: House # | C27: AGE | D27: DIET | E27: INTAKE | F27: Actual intake | G27: NOP | H27: Batch intake | I27: BFT max | J27: BFT level | K27: Monday | L27: Tuesday | M27: Wednesday | N27: Thursday | O27: Friday | P27: Saturday | Q27: Sunday | R27: Monday | S27: Tuesday | T27: Mon-Dry Sow | U27: Mon-Dry Gilt | V27: Mon-Supaflash | W27: Mon | X27: Mon | Y27: Tues-Dry Sow | Z27: Tues-Dry Gilt | AA27: Tues-Supaflsh | AB27: Tues | AC27: Tues | AD27: Wed-Dry Sow | AE27: Wed-Dry Gilt | AF27: Wed-Supaflash | AG27: Wed | AH27: Wed | AI27: Thur-Dry Sow | AJ27: Thur-Dry Gilt | AK27: Thur-Supaflash | AL27: Thur | AM27: Thur | AN27: Fri-Dry Sow | AO27: Fri-Dry Gilt | AP27: Fri-Supaflash | AQ27: Fri | AR27: Fri | AS27: Sat-Dry Sow | AT27: Sat-Dry Gilt | AU27: Sat-Supaflash | AV27: Sat | AW27: Sat | AX27: Sun-Dry Sow | AY27: Sun-Dry Gilt | AZ27: Sun-Supaflash | BA27: Sun | BB27: Sun | BC27: total delivered | BD27: bft closing | BE27: actual consumed
B28: DS1 | C28: 5wks, 10wks, 9wks, 8wks | D28: Dry Sow | E28: 2.5 | F28: =(BE28/G28)/4 -> #DIV/0! | H28: =G28*E28 -> 0 | K28: =J28-$H28 -> 0 | L28: =K28-$H28 -> 0 | M28: =L28-$H28 -> 0 | N28: =M28-$H28 -> 0 | O28: =N28-$H28 -> 0 | P28: =O28-$H28 -> 0 | Q28: =P28-$H28 -> 0 | R28: =Q28-$H28 -> 0 | S28: =R28-$H28 -> 0
B29: DS2 | C29: 1wk, 2wk, 3wk, 14wk | D29: Dry Sow | E29: 3 | F29: =(BE29/G29)/7 -> #DIV/0! | H29: =G29*E29 -> 0 | K29: =J29-$H29 -> 0 | L29: =K29-$H29 -> 0 | M29: =L29-$H29 -> 0 | N29: =M29-$H29 -> 0 | O29: =N29-$H29 -> 0 | P29: =O29-$H29 -> 0 | Q29: =P29-$H29 -> 0 | R29: =Q29-$H29 -> 0 | S29: =R29-$H29 -> 0
B30: DS4 | C30: 11wk, 12wk, 13wks, 6wks | D30: Dry Sow | E30: 2.8 | F30: =(BE30/G30)/7 -> #DIV/0! | H30: =G30*E30 -> 0 | K30: =J30-$H30 -> 0 | L30: =K30-$H30 -> 0 | M30: =L30-$H30 -> 0 | N30: =M30-$H30 -> 0 | O30: =N30-$H30 -> 0 | P30: =O30-$H30 -> 0 | Q30: =P30-$H30 -> 0 | R30: =Q30-$H30 -> 0 | S30: =R30-$H30 -> 0
D31: Dry Sow | E31: 2.5 | F31: =(BE31/G31)/7 -> #DIV/0! | H31: =G31*E31 -> 0 | K31: =J31-$H31 -> 0 | L31: =(K31-$H31)+AS31 -> 0 | M31: =(L31-$H31)+AX31 -> 0 | N31: =(M31-$H31)+T31 -> 0 | O31: =(N31-$H31)+Y31 -> 0 | P31: =(O31-$H31)+AD31 -> 0 | Q31: =(P31-$H31)+AE31 -> 0 | R31: =(Q31-$H31)+AF31 -> 0 | S31: =(R31-$H31)+AG31 -> 0
D32: Dry Sow | E32: 3 | F32: =(BE32/G32)/7 -> #DIV/0! | H32: =G32*E32 -> 0 | K32: =J32-$H32 -> 0 | L32: =(K32-$H32)+AS32 -> 0 | M32: =(L32-$H32)+AX32 -> 0 | N32: =(M32-$H32)+T32 -> 0 | O32: =(N32-$H32)+Y32 -> 0 | P32: =(O32-$H32)+AD32 -> 0 | Q32: =(P32-$H32)+AI32 -> 0 | R32: =(Q32-$H32) -> 0 | S32: =(R32-$H32) -> 0
D33: Dry Sow | E33: 3 | F33: =(BE33/G33)/7 -> #DIV/0! | H33: =G33*E33 -> 0 | K33: =J33-$H33 -> 0 | L33: =(K33-$H33)+AS33 -> 0 | M33: =(L33-$H33)+AX33 -> 0 | N33: =(M33-$H33)+T33 -> 0 | O33: =(N33-$H33)+Y33 -> 0 | P33: =(O33-$H33)+AD33 -> 0 | Q33: =(P33-$H33)+AI33 -> 0 | R33: =(Q33-$H33) -> 0 | S33: =(R33-$H33) -> 0
B34: SL | D34: Supa Flush | E34: 6 | F34: =(BE34/G34)/7 -> #DIV/0! | H34: =G34*E34 -> 0 | K34: =J34-$H34 -> 0 | L34: =K34-$H34 -> 0 | M34: =L34-$H34 -> 0 | N34: =M34-$H34 -> 0 | O34: =N34-$H34 -> 0 | P34: =O34-$H34 -> 0 | Q34: =P34-$H34 -> 0 | R34: =Q34-$H34 -> 0 | S34: =R34-$H34 -> 0
B35: DS3 | C35: all preg gilts | D35: Dry Gilt | E35: 2.5 | F35: =(BE35/G35)/7 -> #DIV/0! | H35: =G35*E35 -> 0 | K35: =J35-$H35 -> 0 | L35: =K35-$H35 -> 0 | M35: =L35-$H35 -> 0 | N35: =M35-$H35 -> 0 | O35: =N35-$H35 -> 0 | P35: =O35-$H35 -> 0 | Q35: =P35-$H35 -> 0 | R35: =Q35-$H35 -> 0 | S35: =R35-$H35 -> 0
D36: Dry Gilt | E36: 2.5 | F36: =(BE36/G36)/7 -> #DIV/0! | H36: =G36*E36 -> 0 | K36: =(J36-$H36)+AO36 -> 0 | L36: =(K36-$H36)+AT36 -> 0 | M36: =(L36-$H36)+AY36 -> 0 | N36: =(M36-$H36)+U36 -> 0 | O36: =(N36-$H36)+Z36 -> 0 | P36: =(O36-$H36)+AE36 -> 0 | Q36: =(P36-$H36)+AJ36 -> 0 | R36: =Q36-$H36 -> 0 | S36: =R36-$H36 -> 0
D37: Dry Gilt | E37: 2.5 | F37: =(BE37/G37)/7 -> #DIV/0! | H37: =G37*E37 -> 0 | K37: =(J37-$H37)+AO37 -> 0 | L37: =(K37-$H37)+AT37 -> 0 | M37: =(L37-$H37)+AY37 -> 0 | N37: =(M37-$H37)+U37 -> 0 | O37: =(N37-$H37)+Z37 -> 0 | P37: =(O37-$H37)+AE37 -> 0 | Q37: =(P37-$H37)+AJ37 -> 0 | R37: =Q37-$H37 -> 0 | S37: =R37-$H37 -> 0
D38: Dry Gilt | E38: 2.5 | F38: =(BE38/G38)/7 -> #DIV/0! | H38: =G38*E38 -> 0 | K38: =(J38-$H38)+AO38 -> 0 | L38: =(K38-$H38)+AT38 -> 0 | M38: =(L38-$H38)+AY38 -> 0 | N38: =(M38-$H38)+U38 -> 0 | O38: =(N38-$H38)+Z38 -> 0 | P38: =(O38-$H38)+AE38 -> 0 | Q38: =(P38-$H38)+AJ38 -> 0 | R38: =Q38-$H38 -> 0 | S38: =R38-$H38 -> 0
D39: Dry Gilt | E39: 3 | F39: =(BE39/G39)/7 -> #DIV/0! | H39: =G39*E39 -> 0 | K39: =(J39-$H39)+AO39 -> 0 | L39: =(K39-$H39)+AT39 -> 0 | M39: =(L39-$H39)+AY39 -> 0 | N39: =(M39-$H39)+U39 -> 0 | O39: =(N39-$H39)+Z39 -> 0 | P39: =(O39-$H39)+AE39 -> 0 | Q39: =(P39-$H39)+AJ39 -> 0 | R39: =Q39-$H39 -> 0 | S39: =R39-$H39 -> 0
D40: Dry Gilt | E40: 3 | F40: =(BE40/G40)/7 -> #DIV/0! | H40: =G40*E40 -> 0 | K40: =(J40-$H40)+AO40 -> 0 | L40: =(K40-$H40)+AT40 -> 0 | M40: =(L40-$H40)+AY40 -> 0 | N40: =(M40-$H40)+U40 -> 0 | O40: =(N40-$H40)+Z40 -> 0 | P40: =(O40-$H40)+AE40 -> 0 | Q40: =(P40-$H40)+AJ40 -> 0 | R40: =Q40-$H40 -> 0 | S40: =R40-$H40 -> 0
A47: MAINSITE BULK FEED ORDER
A48: Batch # | B48: House # | C48: AGE | D48: DIET | E48: INTAKE | F48: Actual intake | G48: NOP | H48: Batch intake | I48: BFT max | J48: BFT level | K48: Monday | L48: Tuesday | M48: Wednesday | N48: Thursday | O48: Friday | P48: Saturday | Q48: Sunday | R48: Monday | S48: Tuesday | T48: Mon-L Sow | U48: Mon- L Gilt | V48: Mon-Trans | W48: Mon | X48: Mon | Y48: Tue-L Sow | Z48: Tue- L Gilt | AA48: Tue-Trans | AB48: Tues | AC48: Tues | AD48: Wed-L Sow | AE48: Wed- L Gilt | AF48: Wed-Trans | AG48: Wed | AH48: Wed | AI48: Thur-L Sow | AJ48: Thur- L Gilt | AK48: Thur-Trans | AL48: Thur | AM48: Thur | AN48: Fri-L Sow | AO48: Fri- L Gilt | AP48: Fri-Trans | AQ48: Fri | AR48: Fri | AS48: Sat-L Sow | AT48: Sat- L Gilt | AU48: Sat-Trans | AV48: Sat | AW48: Sat | AX48: Sun-L Sow | AY48: Sun- L Gilt | AZ48: Sun-Trans | BA48: Sun | BB48: Sun | BC48: total delivered | BD48: bft closing | BE48: actual consumed
C49: post active and 2 weeks | D49: LACTATE SOW | F49: =(BE49/G49)/7 -> #DIV/0! | H49: =G49*E49 -> 0 | K49: =J49-H49 -> 0 | L49: =K49-$H49 -> 0 | M49: =L49-$H49 -> 0 | N49: =M49-$H49 -> 0 | O49: =N49-$H49 -> 0 | P49: =O49-$H49 -> 0 | Q49: =P49-$H49 -> 0 | R49: =Q49-$H49 -> 0 | S49: =R49-$H49 -> 0
B50: FH 1 and 2 lact | C50: FH 1 and FH2 | D50: LACTATE GILT | E50: 6 | F50: =(BE50/G50)/7 -> #DIV/0! | H50: =G50*E50 -> 0 | K50: =J50-$H50 -> 0 | L50: =K50-$H50 -> 0 | M50: =L50-$H50 -> 0 | N50: =M50-$H50 -> 0 | O50: =N50-$H50 -> 0 | P50: =O50-$H50 -> 0 | Q50: =P50-$H50 -> 0 | R50: =Q50-$H50 -> 0 | S50: =R50-$H50 -> 0
B51: FH 1 and 2 Trans | D51: TRANSITION | E51: 2.5 | F51: =(BE51/G51)/7 -> #DIV/0! | H51: =G51*E51 -> 0 | K51: =J51-$H51 -> 0 | L51: =K51-$H51 -> 0 | M51: =L51-$H51 -> 0 | N51: =M51-$H51 -> 0 | O51: =N51-$H51 -> 0 | P51: =O51-$H51 -> 0 | Q51: =P51-$H51 -> 0 | R51: =Q51-$H51 -> 0 | S51: =R51-$H51 -> 0
C52: active and 4 weeks | D52: LACTATE SOW | F52: =(BE52/G52)/7 -> #DIV/0! | H52: =G52*E52 -> 0 | K52: =(J52-$H52)+T52 -> 0 | L52: =K52-$H52 -> 0 | M52: =L52-$H52 -> 0 | N52: =M52-$H52 -> 0 | O52: =N52-$H52 -> 0 | P52: =O52-$H52 -> 0 | Q52: =P52-$H52 -> 0 | R52: =Q52-$H52 -> 0 | S52: =R52-$H52 -> 0
B53: FH 3 and 4 lact | C53: Fh3 and Fh4 | D53: LACTATE GILT | E53: 11 | F53: =(BE53/G53)/7 -> #DIV/0! | H53: =G53*E53 -> 0 | K53: =J53-$H53 -> 0 | L53: =K53-$H53 -> 0 | M53: =L53-$H53 -> 0 | N53: =M53-$H53 -> 0 | O53: =N53-$H53 -> 0 | P53: =O53-$H53 -> 0 | Q53: =P53-$H53 -> 0 | R53: =Q53-$H53 -> 0 | S53: =R53-$H53 -> 0
...

Sheet Daily Dispatch Tracking
B2: Monday 07:00 | D2: Bulk | E2: Week 34
B4: Overal order | C4: Grower | E4: Grower | G4: Grower
B6: Farm | C6: Sunday | D6: Monday | E6: Tuesday | F6: Wednesday | G6: Thursday | H6: Friday | I6: Saturday
B7: Porta | D7: 30000 | E7: 27000 | F7: 30000 | G7: 30000 | H7: 30000 | I7: 60000 | J7: =+C7+D7+E7+F7+G7+H7+I7 -> 207000
B8: Lionshead | C8: 60000 | F8: 30000 | G8: 30000 | J8: =+C8+D8+E8+F8+G8+H8+I8 -> 120000
B9: Grasmere | C9: 85000 | D9: 71000 | E9: 33000 | F9: 61000 | G9: 61000 | H9: 12000 | J9: =+C9+D9+E9+F9+G9+H9+I9 -> 323000
B10: Multiplier | C10: 13000 | D10: 13000 | E10: 16000 | F10: 13000 | G10: 10000 | I10: 11000 | J10: =+C10+D10+E10+F10+G10+H10+I10 -> 76000
B11: Learig | D11: 30000 | E11: 30000 | F11: 30000 | J11: =+C11+D11+E11+F11+G11+H11+I11 -> 90000
B12: Richlands | C12: 30000 | D12: 30000 | E12: 30000 | F12: 30000 | G12: 30000 | J12: =+C12+D12+E12+F12+G12+H12+I12 -> 150000
B13: Totals | C13: =SUM(C7:C12) -> 188000 | D13: =SUM(D7:D12) -> 174000 | E13: =SUM(E7:E12) -> 136000 | F13: =SUM(F7:F12) -> 194000 | G13: =SUM(G7:G12) -> 161000 | H13: =SUM(H7:H12) -> 42000 | I13: =SUM(I7:I12) -> 71000 | J13: =C13+D13+E13+F13+G13+H13+I13 -> 966000
B14: Daily Limit | C14: 180000 | D14: 180000 | E14: 180000 | F14: 180000 | G14: 180000 | H14: 40000 | I14: 40000 | J14: 980000
B17: Balance to Dispatch | C17: Sunday | D17: Monday | E17: Tuesday | F17: Wednesday | G17: Thursday | H17: Friday | I17: Saturday
B18: Farm
B19: Porta | D19: 30000 | E19: 27000 | F19: 30000 | G19: 30000 | H19: 30000 | I19: 60000 | J19: =C19+D19+E19+F19+G19+H19+I19 -> 207000
B20: Lionshead | C20: 60000 | F20: 30000 | G20: 30000 | J20: =C20+D20+E20+F20+G20+H20+I20 -> 120000
B21: Grasmere | C21: 85000 | D21: 71000 | E21: 33000 | F21: 61000 | G21: 61000 | H21: 12000 | J21: =C21+D21+E21+F21+G21+H21+I21 -> 323000
B22: Multiplier | C22: 13000 | D22: 13000 | E22: 16000 | F22: 13000 | G22: 10000 | I22: 11000 | J22: =C22+D22+E22+F22+G22+H22+I22 -> 76000
B23: Learig | D23: 30000 | E23: 30000 | F23: 30000 | J23: =C23+D23+E23+F23+G23+H23+I23 -> 90000
B24: Richlands | C24: 30000 | D24: 30000 | E24: 30000 | F24: 30000 | G24: 30000 | J24: =C24+D24+E24+F24+G24+H24+I24 -> 150000
B25: Totals | C25: =+C19+C20+C21+C22+C23+C24 -> 188000 | D25: =+D19+D20+D21+D22+D23+D24 -> 174000 | E25: =+E19+E20+E21+E22+E23+E24 -> 136000 | F25: =+F19+F20+F21+F22+F23+F24 -> 194000 | G25: =+G19+G20+G21+G22+G23+G24 -> 161000 | H25: =+H19+H20+H21+H22+H23+H24 -> 42000 | I25: =+I19+I20+I21+I22+I23+I24 -> 71000 | J25: =+J19+J20+J21+J22+J24+J23 -> 966000
D28: Bags
B29: Overal order
F30: .
B31: Farm | C31: Sunday | D31: Monday | E31: Tuesday | F31: Wednesday | G31: Thursday | H31: Friday | I31: Saturday
B32: Porta | G32: 6000 | J32: =+C32+D32+E32+F32+G32+H32+I32 -> 6000
B33: lionhead Ext | D33: 30000 | F33: 18000 | J33: =+C33+D33+E33+F33+G33+H33+I33 -> 48000
B34: villa | E34: 30000 | G34: 41000 | J34: =+C34+D34+E34+F34+G34+H34+I34 -> 71000
B35: Lionshead | C35: 30000 | E35: 14000 | J35: =+C35+D35+E35+F35+G35+H35+I35 -> 44000
B36: Grasmere | G36: 8000 | J36: =+C36+D36+E36+F36+G36+H36+I36 -> 8000
B37: Multiplier | E37: 3000 | J37: =+C37+D37+E37+F37+G37+H37+I37 -> 3000
B38: Selous | G38: 17000 | J38: =+C38+D38+E38+F38+G38+H38+I38 -> 17000
B39: Learig | F39: 12000 | J39: =+C39+D39+E39+F39+G39+H39+I39 -> 12000
B40: Richlands | C40: 30000 | F40: 15000 | J40: =+C40+D40+E40+F40+G40+H40+I40 -> 45000
B41: Totals | C41: =SUM(C32:C40) -> 60000 | D41: =SUM(D32:D40) -> 30000 | E41: =SUM(E32:E40) -> 47000 | F41: =SUM(F32:F40) -> 45000 | G41: =SUM(G32:G40) -> 72000 | H41: =SUM(H32:H40) -> 0 | I41: =SUM(I32:I40) -> 0 | J41: =+C41+D41+E41+F41+G41+H41+I41 -> 254000
B44: Balance to Dispatch
B46: Farm | C46: Sunday | D46: Monday | E46: Tuesday | F46: Wednesday | G46: Thursday | H46: Friday | I46: Saturday
B47: Porta | G47: 6000 | J47: 6000
B48: lionhead Ext | D48: 30000 | F48: 18000 | J48: 48000
B49: villa | E49: 30000 | G49: 41000 | J49: 71000
B50: Lionshead | C50: 30000 | E50: 14000 | J50: 44000
...

Sheet Logistics Plan
B2: DISPATCH WEEK 34
B3: SITE | C3: Ordered Bags | D3: Ordered Bulk | E3: Monday Plan | G3: Tuesday Plan | I3: Wednesday Plan | K3: Thursday Plan | M3: Friday Plan | O3: Saturday Plan | Q3: Sunday Plan
E4: Bags | F4: Bulk | G4: Bags | H4: Bulk | I4: Bags | J4: Bulk | K4: Bags | L4: Bulk | M4: Bags | N4: Bulk | O4: Bags | P4: Bulk | Q4: Bags | R4: Bulk | S4: Total
B5: Villa Franca | C5: 71 | D5: =[1]Summary!H69 -> 0 | F5: 0 | H5: 0 | I5: 30 | J5: 0 | K5: 41 | L5: 0 | N5: 0 | S5: =SUM(E5:R5) -> 71
B6: Richlands | C6: 45 | D6: 150 | E6: 30 | F6: 30 | G6: 15 | H6: 30 | J6: 30 | K6: =C6-E6-G6-I6 -> 0 | L6: 60 | N6: 0 | S6: =SUM(E6:R6) -> 195
B7: Lionhead | C7: 44 | D7: 150 | E7: 30 | G7: 14 | H7: 60 | J7: 30 | N7: 60 | O7: 0 | P7: 0 | Q7: 0 | R7: 0 | S7: =SUM(E7:R7) -> 194
B8: Porta | C8: 6 | D8: 210 | E8: 0 | F8: 30 | G8: 0 | H8: 30 | I8: 0 | J8: 30 | K8: 0 | L8: 30 | M8: 6 | N8: 30 | O8: 0 | P8: 30 | R8: 30 | S8: =SUM(E8:R8) -> 216
B9: Learig | C9: =[1]Summary!AH69 -> 6 | D9: 114 | F9: 0 | G9: 0 | H9: 30 | J9: 40 | L9: 30 | N9: 0 | S9: =SUM(E9:R9) -> 100
B10: Lionhead Extension | C10: 48 | D10: 0 | F10: 0 | G10: 30 | H10: 0 | I10: 18 | J10: =+[1]Summary!E33 -> 0 | L10: 0 | N10: 0 | S10: =SUM(E10:R10) -> 48
B11: Grasmere Mainsite | C11: 5 | D11: 70 | F11: 0 | H11: 20 | J11: 25 | L11: 25 | M11: 5 | N11: 0 | S11: =SUM(E11:R11) -> 75
B12: Grasmere Grower | C12: =+[1]Summary!Q33 -> 0 | D12: =+[1]Summary!R33 -> 250 | F12: 60 | H12: 60 | J12: 0 | L12: 60 | N12: 70 | S12: =SUM(E12:R12) -> 250
B13: Grasmere Weaner | C13: =+[1]Summary!Z33 -> 0 | D13: =+[1]Summary!AA33 -> 35 | F13: 0 | H13: =+[1]Summary!AB33 -> 0 | J13: 35 | L13: =C13-H13 -> 0 | N13: 0 | S13: =SUM(E13:R13) -> 35
B14: Grasmere AI | C14: 1 | D14: =+[1]Summary!AI33 -> 0 | E14: 1 | H14: =+[1]Summary!AJ33 -> 0 | J14: =+[1]Summary!AK33 -> 0 | L14: =C14-H14 -> 1 | N14: 0 | S14: =SUM(E14:R14) -> 2
B15: Multiplier | C15: 3 | D15: 70 | F15: 10 | G15: 0 | H15: 8 | I15: 3 | J15: 12 | L15: 10 | N15: 10 | P15: 10 | R15: 10 | S15: =SUM(E15:R15) -> 73
B16: Quarantine | C16: 0 | D16: 0 | F16: =SUM(C16:D16) -> 0 | H16: 0 | J16: 0 | L16: =C16-H16 -> 0 | N16: 0 | S16: =SUM(D16:R16) -> 0
B17: Selous | C17: =+[1]Summary!AP69 -> 0 | D17: =+[1]Summary!AQ69 -> 0 | F17: =SUM(C17:D17) -> 0 | H17: =+[1]Summary!AR69 -> 0 | J17: =+[1]Summary!AS69 -> 0 | L17: =C17-H17 -> 0 | N17: 0 | S17: =SUM(D17:R17) -> 0
B18: TOTAL | C18: =SUM(C5:C17) -> 229 | D18: =SUM(D5:D17) -> 1049 | E18: =SUM(E5:E17) -> 61 | F18: =SUM(F5:F17) -> 130 | G18: =SUM(G5:G17) -> 59 | H18: =SUM(H5:H17) -> 238 | I18: =SUM(I5:I17) -> 51 | J18: =SUM(J5:J17) -> 202 | ... R18: =SUM(R5:R17) -> 40
D20: Total order
D21: =C18+D18 -> 1278
A23: Trucks Distribution | I23: Priority list
B24: Sites | C24: bulk tankers | D24: bags trucks | E24: wagons | F24: Trailers | I24: Bulk
H25: Monday | I25: Tuesday | J25: Wednesday | K25: Thursday | L25: Friday | M25: Saturday | N25: Sunday
B26: Villa Franca | C26: 0 | D26: 3 | G26: 1 | H26: Porta | I26: Porta | J26: Porta | K26: Porta | L26: Porta | M26: Porta | N26: Porta
B27: Richlands | C27: 5 | D27: 2 | G27: 2 | H27: Grower | I27: Lionhead | J27: Lionhead | K27: Grower | L27: Lionshead
B28: Lionhead | C28: 5 | D28: 3 | G28: 3 | H28: Richlands | I28: Lionhead | J28: Weaner | K28: Learig | L28: Lionshead
B29: Porta | C29: 7 | D29: 1 | G29: 4 | H29: Richlands | I29: Grower | J29: Learig | K29: Richlands | L29: Grower
B30: Learig | C30: 4 | D30: 1 | G30: 5 | H30: Grower | I30: Learig | J30: Richlands | K30: Mainsite | L30: Grower
B31: Lionhead Extension | D31: 3 | G31: 6 | H31: Mainsite | I31: Grower | J31: Mainsite | K31: Richlands | L31: Grower
B32: Grasmere Mainsite | C32: 3 | D32: 0 | F32: 1
B33: Grasmere Grower | C33: 8 | D33: 0 | I33: Bags
B34: Grasmere Weaner | C34: 1 | D34: 0 | H34: Monday | I34: Tuesday | J34: Wednesday | K34: Thursday | L34: Friday
B35: Grasmere AI | C35: 0 | D35: 0 | F35: 1 | G35: 1 | H35: Lionhead | I35: Lionhead | J35: Villa | K35: Villa | L35: Porta
B36: Multiplier | C36: 0 | D36: 0 | E36: 2 | F36: 1 | G36: 2 | H36: Richlands | I36: Lionhead EX | J36: Richlands | K36: Grasmere | L36: Grasmere
B37: Quarantine | C37: 0 | D37: 0 | G37: 3 | H37: Lionhead EX | I37: Grasmere | K37: Learig
B38: Selous | C38: 0 | D38: 0
B39: TOTAL | C39: =SUM(C26:C38) -> 33 | D39: =SUM(D26:D38) -> 13 | E39: =SUM(E26:E38) -> 2 | F39: =SUM(F26:F38) -> 3

Sheet Daily Production Plan
A1: DATE: | B1: DAILY PRODUCTION PLAN WEEK NO: 34 | E1: DAY: SUNDAY and MONDAY
J2: PRIORITY LISTING
B3: DIET | C3: GRASMERE | D3: RICHLANDS | E3: LIONHEAD | F3: PORTA | G3: LEARIG | H3: MULTIPLER | I3: TOTAL TONNES | J3: Total ton prio | K3: TOTAL FREQ | L3: Total truck prio | M3: Final priority | N3: ACTUAL PROD | O3: BALANCE | P3: Prod Order # | Q3: BIN NUMBER 1ST | R3: BIN NUMBER 2ND
B4: GROWER 3 | C4: =15+9 -> 24 | D4: 9 | E4: 6 | F4: 6 | G4: 3 | H4: 6 | I4: =SUM(C4:H4) -> 54 | J4: 3 | K4: =COUNT(C4:H4) -> 6 | L4: 1 | M4: =AVERAGE(J4,L4) -> 2 | N4: 54 | O4: =I4-N4 -> 0 | Q4: 24
B5: GROWER 2 -OTC | C5: 15 | D5: 9 | E5: 12 | F5: 9 | I5: =SUM(C5:H5) -> 45 | J5: 4 | K5: =COUNT(C5:H5) -> 4 | L5: 2 | M5: =AVERAGE(J5,L5) -> 3 | N5: 45 | O5: =I5-N5 -> 0 | Q5: 23
B6: WEANER - CARA | D6: 6 | E6: 6 | G6: 3 | H6: 4 | I6: =SUM(C6:H6) -> 19 | J6: 7 | K6: =COUNT(C6:H6) -> 4 | L6: 2 | M6: =AVERAGE(J6,L6) -> 4.5 | N6: 19 | O6: =I6-N6 -> 0 | Q6: 17
B7: FINISHER | D7: 27 | E7: 15 | G7: 24 | I7: =SUM(C7:H7) -> 66 | J7: 1 | K7: =COUNT(C7:H7) -> 3 | L7: 3 | M7: =AVERAGE(J7,L7) -> 2 | N7: 66 | O7: =I7-N7 -> 0 | Q7: 21
B8: FINISHER - Promote | C8: 36 | F8: 9 | H8: 11 | I8: =SUM(C8:H8) -> 56 | J8: 2 | K8: =COUNT(C8:H8) -> 3 | L8: 3 | M8: =AVERAGE(J8,L8) -> 2.5 | N8: 56 | O8: =I8-N8 -> 0 | Q8: 22
B9: GROWER 1 | C9: 21 | E9: 12 | F9: 12 | I9: =SUM(C9:H9) -> 45 | J9: 4 | K9: =COUNT(C9:H9) -> 3 | L9: 3 | M9: =AVERAGE(J9,L9) -> 3.5 | N9: 45 | O9: =I9-N9 -> 0 | Q9: 19
B10: WEANER- OTC grower | C10: 15 | E10: 9 | F10: 6 | I10: =SUM(C10:H10) -> 30 | J10: 5 | K10: =COUNT(C10:H10) -> 3 | L10: 3 | M10: =AVERAGE(J10,L10) -> 4 | N10: 30 | O10: =I10-N10 -> 0 | Q10: 16
B11: CREEP 3 | D11: 6 | F11: 3 | H11: 4 | I11: =SUM(C11:H11) -> 13 | J11: 8 | K11: =COUNT(C11:H11) -> 3 | L11: 3 | M11: =AVERAGE(J11,L11) -> 5.5 | N11: 13 | O11: =I11-N11 -> 0 | Q11: 18
B12: DRY SOW | C12: =14+7 -> 21 | F12: 3 | I12: =SUM(C12:H12) -> 24 | J12: 6 | K12: =COUNT(C12:H12) -> 2 | L12: 4 | M12: =AVERAGE(J12,L12) -> 5 | N12: 24 | O12: =I12-N12 -> 0 | Q12: 15
B13: LACTATING GILT | C13: 2 | D13: 3 | I13: =SUM(C13:H13) -> 5 | J13: 11 | K13: =COUNT(C13:H13) -> 2 | L13: 4 | M13: =AVERAGE(J13,L13) -> 7.5 | N13: 5 | O13: =I13-N13 -> 0 | R13: 18
B14: SUPER FLUSH | C14: 2 | F14: 3 | I14: =SUM(C14:H14) -> 5 | J14: 11 | K14: =COUNT(C14:H14) -> 2 | L14: 4 | M14: =AVERAGE(J14,L14) -> 7.5 | N14: 5 | O14: =I14-N14 -> 0 | R14: 18
B15: DRY GILT | F15: 3 | H15: 1 | I15: =SUM(C15:H15) -> 4 | J15: 12 | K15: =COUNT(C15:H15) -> 2 | L15: 4 | M15: =AVERAGE(J15,L15) -> 8 | N15: 4 | O15: =I15-N15 -> 0 | Q15: 20
B16: LACTATE SOW | C16: 12 | I16: =SUM(C16:H16) -> 12 | J16: 9 | K16: =COUNT(C16:H16) -> 1 | L16: 5 | M16: =AVERAGE(J16,L16) -> 7 | N16: 12 | O16: =I16-N16 -> 0 | R16: 20
B17: 90 PLUS | C17: 8 | I17: =SUM(C17:H17) -> 8 | J17: 10 | K17: =COUNT(C17:H17) -> 1 | L17: 5 | M17: =AVERAGE(J17,L17) -> 7.5 | N17: 8 | O17: =I17-N17 -> 0 | R17: 18
B18: TRANSITION | F18: 3 | I18: =SUM(C18:H18) -> 3 | J18: 13 | K18: =COUNT(C18:H18) -> 1 | L18: 5 | M18: =AVERAGE(J18,L18) -> 9 | N18: 3 | O18: =I18-N18 -> 0 | R18: 20
B19: GILT 4.1 | I19: =SUM(C19:H19) -> 0 | K19: =COUNT(C19:H19) -> 0 | M19: =AVERAGE(J19,L19) -> #DIV/0! | O19: =I19-N19 -> 0
B20: LACTATE SOW Z LINE | I20: =SUM(C20:H20) -> 0 | K20: =COUNT(C20:H20) -> 0 | M20: =AVERAGE(J20,L20) -> #DIV/0! | O20: =I20-N20 -> 0
B21: GILT 1-NO OTC | I21: =SUM(C21:H21) -> 0 | K21: =COUNT(C21:H21) -> 0 | M21: =AVERAGE(J21,L21) -> #DIV/0! | O21: =I21-N21 -> 0
B22: LACTATION TRIAL | I22: =SUM(C22:H22) -> 0 | K22: =COUNT(C22:H22) -> 0 | M22: =AVERAGE(J22,L22) -> #DIV/0! | O22: =I22-N22 -> 0
B23: CREEP 2 -(ZnO) | I23: =SUM(C23:H23) -> 0 | K23: =COUNT(C23:H23) -> 0 | M23: =AVERAGE(J23,L23) -> #DIV/0! | O23: =I23-N23 -> 0
B24: GROWER 2 -CTC | I24: =SUM(C24:H24) -> 0 | K24: =COUNT(C24:H24) -> 0 | M24: =AVERAGE(J24,L24) -> #DIV/0! | O24: =I24-N24 -> 0
B25: WEANER- CTC grower | I25: =SUM(C25:H25) -> 0 | K25: =COUNT(C25:H25) -> 0 | M25: =AVERAGE(J25,L25) -> #DIV/0! | O25: =I25-N25 -> 0
B26: CREEP 3 BACTOFOS | I26: =SUM(C26:H26) -> 0 | K26: =COUNT(C26:H26) -> 0 | M26: =AVERAGE(J26,L26) -> #DIV/0! | O26: =I26-N26 -> 0
B27: GILT 2 | I27: =SUM(C27:H27) -> 0 | K27: =COUNT(C27:H27) -> 0 | M27: =AVERAGE(J27,L27) -> #DIV/0! | O27: =I27-N27 -> 0
B28: GILT 3 | I28: =SUM(C28:H28) -> 0 | K28: =COUNT(C28:H28) -> 0 | M28: =AVERAGE(J28,L28) -> #DIV/0! | O28: =I28-N28 -> 0
B29: GILT 5 | I29: =SUM(C29:H29) -> 0 | K29: =COUNT(C29:H29) -> 0 | M29: =AVERAGE(J29,L29) -> #DIV/0! | O29: =I29-N29 -> 0
B30: 90 PLUS | I30: =SUM(C30:H30) -> 0 | K30: =COUNT(C30:H30) -> 0 | M30: =AVERAGE(J30,L30) -> #DIV/0! | O30: =I30-N30 -> 0
... B32: WEANER - CARA CTC | I32: =SUM(C32:H32) -> 0 | K32: =COUNT(C32:H32) -> 0 | M32: =AVERAGE(J32,L32) -> #DIV/0! | O32: =I32-N32 -> 0
I33: =SUM(C33:H33) -> 0 | M33: =AVERAGE(J33,L33) -> #DIV/0! | O33: =I33-N33 -> 0
B34: TOTAL TONNES | C34: =SUM(C4:C33) -> 156 | D34: =SUM(D4:D33) -> 60 | E34: =SUM(E4:E33) -> 60 | F34: =SUM(F4:F33) -> 57 | G34: =SUM(G4:G33) -> 30 | H34: =SUM(H4:H33) -> 26 | I34: =SUM(I4:I33) -> 389 | O34: =SUM(O4:O33) -> 0
H36: TUE AND WED
B37: DIET | C37: GRASMERE | D37: RICHLANDS | E37: LIONHEAD | F37: PORTA | G37: LEARIG | H37: MULTIPLER | I37: TOTAL TONNES | J37: =J3 -> Total ton prio | K37: =K3 -> TOTAL FREQ | L37: =L3 -> Total truck prio | M37: Final priority | N37: ACTUAL PROD | O37: BALANCE | P37: Prod Order # | Q37: BIN NUMBER 1ST | R37: BIN NUMBER 2ND
B38: GROWER 3 | C38: 9 | D38: 3 | E38: 9 | F38: 18 | G38: 21 | I38: =SUM(C38:H38) -> 60 | J38: 1 | K38: =COUNT(C38:H38) -> 5 | L38: 2 | M38: =AVERAGE(J38,L38) -> 1.5 | N38: 60 | O38: =I38-N38 -> 0 | Q38: 24
B39: GROWER 2 -OTC | C39: 9 | D39: 12 | E39: 6 | F39: 6 | G39: 9 | H39: 7 | I39: =SUM(C39:H39) -> 49 | J39: 3 | K39: =COUNT(C39:H39) -> 6 | L39: 1 | M39: =AVERAGE(J39,L39) -> 2 | N39: 49 | O39: =I39-N39 -> 0 | Q39: 23
B40: GROWER 1 | C40: 9 | D40: 9 | E40: 6 | F40: 6 | G40: 12 | H40: 4 | I40: =SUM(C40:H40) -> 46 | J40: 4 | K40: =COUNT(C40:H40) -> 6 | L40: 1 | M40: =AVERAGE(J40,L40) -> 2.5 | N40: 46 | O40: =I40-N40 -> 0 | Q40: 20
B41: FINISHER | D41: 30 | E41: 15 | G41: 6 | I41: =SUM(C41:H41) -> 51 | J41: 2 | K41: =COUNT(C41:H41) -> 3 | L41: 4 | M41: =AVERAGE(J41,L41) -> 3 | N41: 51 | O41: =I41-N41 -> 0 | Q41: 21
B42: WEANER- OTC grower | C42: 3 | D42: 9 | E42: 6 | F42: 3 | G42: 6 | H42: 4 | I42: =SUM(C42:H42) -> 31 | J42: 6 | K42: =COUNT(C42:H42) -> 6 | L42: 1 | M42: =AVERAGE(J42,L42) -> 3.5 | N42: 31 | O42: =I42-N42 -> 0 | Q42: 19
...

Sheet Feed Order Summary 
B2: Overal order | D2: Grower | F2: Grower | H2: Grower
B4: Farm | C4: Sunday | D4: Monday | E4: Tuesday | F4: Wednesday | G4: Thursday | H4: Friday | I4: Saturday | J4: Sunday
B5: Porta | C5: 0 | D5: ='Porta Wk 34 '!B18 -> 30000 | E5: ='Porta Wk 34 '!C18 -> 27000 | F5: ='Porta Wk 34 '!D18 -> 30000 | G5: ='Porta Wk 34 '!E18 -> 30000 | H5: ='Porta Wk 34 '!F18 -> 30000 | I5: ='Porta Wk 34 '!G18 -> 30000 | J5: ='Porta Wk 34 '!H18 -> 30000 | K5: =SUM(C5:J5) -> 207000
B6: Lionshead | C6: 0 | D6: ='Lionshead Wk 34'!D18 -> 60000 | E6: ='Lionshead Wk 34'!E18 -> 0 | F6: ='Lionshead Wk 34'!F18 -> 60000 | G6: ='Lionshead Wk 34'!G18 -> 0 | H6: ='Lionshead Wk 34'!H18 -> 0 | I6: 0 | J6: 0 | K6: =SUM(C6:J6) -> 120000
B7: Grasmere | C7: ='Grasmere Wk 34'!B18 -> 85000 | D7: ='Grasmere Wk 34'!C18 -> 71000 | E7: ='Grasmere Wk 34'!D18 -> 35000 | F7: ='Grasmere Wk 34'!E18 -> 55000 | G7: ='Grasmere Wk 34'!F18 -> 61000 | H7: ='Grasmere Wk 34'!G18 -> 4000 | I7: ='Grasmere Wk 34'!H18 -> 0 | J7: ='Grasmere Wk 34'!I18 -> 0 | K7: =SUM(C7:J7) -> 311000
B8: Multiplier | C8: ='Multiplier Wk 34'!B18 -> 13000 | D8: ='Multiplier Wk 34'!C18 -> 13000 | E8: ='Multiplier Wk 34'!D18 -> 16000 | F8: ='Multiplier Wk 34'!E18 -> 13000 | G8: ='Multiplier Wk 34'!F18 -> 10000 | H8: ='Multiplier Wk 34'!G18 -> 0 | I8: ='Multiplier Wk 34'!H18 -> 11000 | J8: ='Multiplier Wk 34'!I18 -> 0 | K8: =SUM(C8:J8) -> 76000
B9: Learig | C9: ='Learig Wk 34'!B18 -> 0 | D9: ='Learig Wk 34'!C18 -> 30000 | E9: ='Learig Wk 34'!D18 -> 30000 | F9: ='Learig Wk 34'!E18 -> 30000 | G9: ='Learig Wk 34'!F18 -> 0 | H9: ='Learig Wk 34'!G18 -> 0 | I9: ='Learig Wk 34'!H18 -> 0 | J9: ='Learig Wk 34'!I18 -> 0 | K9: =SUM(C9:J9) -> 90000
B10: Richlands | C10: ='Richlands Wk 34'!B18 -> 30000 | D10: ='Richlands Wk 34'!C18 -> 30000 | E10: ='Richlands Wk 34'!D18 -> 60000 | F10: ='Richlands Wk 34'!E18 -> 30000 | G10: ='Richlands Wk 34'!F18 -> 0 | H10: ='Richlands Wk 34'!G18 -> 0 | I10: ='Richlands Wk 34'!H18 -> 0 | J10: ='Richlands Wk 34'!I18 -> 0 | K10: =SUM(C10:J10) -> 150000
B11: Totals | C11: =SUM(C5:C10) -> 128000 | D11: =SUM(D5:D10) -> 234000 | E11: =SUM(E5:E10) -> 168000 | F11: =SUM(F5:F10) -> 218000 | G11: =SUM(G5:G10) -> 101000 | H11: =SUM(H5:H10) -> 34000 | I11: =SUM(I5:I10) -> 41000 | J11: =SUM(J5:J10) -> 30000 | K11: =SUM(C11:J11) -> 954000
B12: Daily Limit | C12: 180000 | D12: 180000 | E12: 180000 | F12: 180000 | G12: 180000 | I12: 40000 | J12: 40000 | K12: =SUM(C12:J12) -> 980000
B14: Farm Daily Limit Guide
B15: Farm | C15: Sunday | D15: Monday | E15: Tuesday | F15: Wednesday | G15: Thursday | H15: Friday | I15: Saturday | J15: Sunday
B16: Porta | C16: ='Porta Wk 34 '!B19 -> 30000 | D16: ='Porta Wk 34 '!C19 -> 30000 | E16: ='Porta Wk 34 '!D19 -> 30000 | F16: ='Porta Wk 34 '!E19 -> 30000 | G16: ='Porta Wk 34 '!F19 -> 30000 | H16: ='Porta Wk 34 '!G19 -> 30000 | I16: ='Porta Wk 34 '!H19 -> 30000 | J16: ='Porta Wk 34 '!I19 -> 210000 | K16: =SUM(C16:J16) -> 420000
B17: Lionshead | C17: ='Lionshead Wk 34'!B19 -> 0 | D17: ='Lionshead Wk 34'!C19 -> 60000 | E17: ='Lionshead Wk 34'!D19 -> 0 | F17: ='Lionshead Wk 34'!E19 -> 0 | G17: ='Lionshead Wk 34'!F19 -> 60000 | H17: ='Lionshead Wk 34'!G19 -> 0 | I17: ='Lionshead Wk 34'!H19 -> 0 | J17: ='Lionshead Wk 34'!I19 -> 0 | K17: =SUM(C17:J17) -> 120000
B18: Grasmere | C18: ='Grasmere Wk 34'!B19 -> 60000 | D18: ='Grasmere Wk 34'!C19 -> 90000 | E18: ='Grasmere Wk 34'!D19 -> 70000 | F18: ='Grasmere Wk 34'!E19 -> 80000 | G18: ='Grasmere Wk 34'!F19 -> 70000 | H18: ='Grasmere Wk 34'!G19 -> 0 | I18: ='Grasmere Wk 34'!H19 -> 0 | J18: ='Grasmere Wk 34'!I19 -> 0 | K18: =SUM(C18:J18) -> 370000
B19: Multiplier | C19: ='Multiplier Wk 34'!B19 -> 10000 | D19: ='Multiplier Wk 34'!C19 -> 10000 | E19: ='Multiplier Wk 34'!D19 -> 10000 | F19: ='Multiplier Wk 34'!E19 -> 10000 | G19: ='Multiplier Wk 34'!F19 -> 10000 | H19: ='Multiplier Wk 34'!G19 -> 0 | I19: ='Multiplier Wk 34'!H19 -> 10000 | J19: ='Multiplier Wk 34'!I19 -> 10000 | K19: =SUM(C19:J19) -> 70000
B20: Learig | C20: ='Learig Wk 34'!B19 -> 0 | D20: ='Learig Wk 34'!C19 -> 30000 | E20: ='Learig Wk 34'!D19 -> 40000 | F20: ='Learig Wk 34'!E19 -> 30000 | G20: ='Learig Wk 34'!F19 -> 0 | H20: ='Learig Wk 34'!G19 -> 0 | I20: ='Learig Wk 34'!H19 -> 0 | J20: ='Learig Wk 34'!I19 -> 0 | K20: =SUM(C20:J20) -> 100000
B21: Richlands | C21: ='Richlands Wk 34'!B19 -> 30000 | D21: ='Richlands Wk 34'!C19 -> 30000 | E21: ='Richlands Wk 34'!D19 -> 60000 | F21: ='Richlands Wk 34'!E19 -> 30000 | G21: ='Richlands Wk 34'!F19 -> 0 | H21: ='Richlands Wk 34'!G19 -> 0 | I21: ='Richlands Wk 34'!H19 -> 0 | J21: ='Richlands Wk 34'!I19 -> 0 | K21: =SUM(C21:J21) -> 150000
B22: Totals | C22: =SUM(C16:C21) -> 130000 | D22: =SUM(D16:D21) -> 250000 | E22: =SUM(E16:E21) -> 210000 | F22: =SUM(F16:F21) -> 180000 | G22: =SUM(G16:G21) -> 170000 | I22: =SUM(I16:I21) -> 40000 | J22: =SUM(J16:J21) -> 220000 | K22: =SUM(C22:J22) -> 1200000
B23: Daily Limit | C23: 180000 | D23: 180000 | E23: 180000 | F23: 180000 | G23: 180000 | I23: 40000 | J23: 40000 | K23: =SUM(C23:J23) -> 980000

Sheet Porta Wk 34 
A1: WEANER BULK FEED ORDER REQUIRED | K1: MAINSITE BULK FEED ORDER REQUIRED
A2: DIET | B2: Mon | C2: Tue | D2: Wed | E2: Thu | F2: Fri | G2: Sat | H2: Sun | K2: DIET | L2: Mon | M2: Tue | N2: Wed | O2: Thu | P2: Fri | Q2: Sat | R2: Sun
A3: Creep 1 | B3: =SUM(T85:T90) -> 0 | C3: =SUM(Z85:Z90) -> 0 | D3: =SUM(AF85:AF90) -> 0 | E3: =SUM(AL85:AL90) -> 0 | F3: =SUM(AR85:AR90) -> 0 | G3: =SUM(BD85:BD90) -> 0 | H3: 0 | K3: Dry Sow | L3: =SUM(T28:T41) -> 3000 | M3: =SUM(Z28:Z41) -> 0 | N3: =SUM(AF28:AF41) -> 0 | O3: =SUM(AL28:AL41) -> 3000 | P3: =SUM(AR28:AR41) -> 6000 | Q3: =SUM(AX28:AX41) -> 0 | R3: =SUM(BD28:BD41) -> 0
A4: Creep 2 | B4: =SUM(U85:U90) -> 0 | C4: =SUM(AA85:AA90) -> 0 | D4: =SUM(AG85:AG90) -> 3000 | E4: =SUM(AM85:AM90) -> 0 | F4: =SUM(AS85:AS90) -> 0 | G4: 0 | H4: =BE85+BE86+BE87+BE88+BE89+BE90 -> 0 | K4: Supa flush | L4: =V34 -> 0 | M4: =AB34 -> 3000 | N4: =AH34 -> 0 | O4: =AN34 -> 0 | P4: =AT34 -> 0 | Q4: =AZ34 -> 0 | R4: =BF34 -> 3000
A5: CREEP 3 | B5: =SUM(V85:V90) -> 0 | C5: =SUM(AB85:AB90) -> 3000 | D5: =SUM(AH85:AH90) -> 0 | E5: =SUM(AN85:AN90) -> 0 | F5: =SUM(AT85:AT90) -> 3000 | G5: =SUM(AZ85:AZ90) -> 3000 | H5: =BF85+BF86+BF87+BF88+BF89+BF90 -> 0 | K5: Dry gilt | L5: =SUM(U28:U41) -> 0 | M5: =SUM(AA28:AA41) -> 3000 | N5: =SUM(AG28:AG41) -> 0 | O5: =SUM(AM28:AM41) -> 0 | P5: =SUM(AS28:AS41) -> 0 | Q5: =SUM(AY28:AY41) -> 3000 | R5: =SUM(BE28:BE41) -> 0
A6: WEAN 1 | B6: =SUM(W85:W90) -> 0 | C6: =SUM(AC85:AC90) -> 0 | D6: =SUM(AI85:AI90) -> 3000 | E6: =SUM(AO85:AO90) -> 0 | F6: =SUM(AU85:AU90) -> 0 | G6: =SUM(BA85:BA90) -> 3000 | H6: =SUM(BG85:BG90) -> 3000 | K6: Lact Sow | L6: =SUM(T47:T62) -> 0 | M6: =SUM(Z47:Z62) -> 0 | N6: =SUM(AF47:AF62) -> 0 | O6: =SUM(AL47:AL62) -> 0 | P6: =SUM(AR47:AR62) -> 0 | Q6: =SUM(AX47:AX62) -> 0 | R6: =SUM(BD47:BD62) -> 0
A7: TOTAL | B7: =SUM(B3:B6) -> 0 | C7: =SUM(C3:C6) -> 3000 | D7: =SUM(D3:D6) -> 6000 | E7: =SUM(E3:E6) -> 0 | F7: =SUM(F3:F6) -> 3000 | G7: =SUM(G3:G6) -> 6000 | H7: =SUM(H3:H6) -> 3000 | K7: Transition | L7: =SUM(V47:V62) -> 3000 | M7: =SUM(AB47:AB62) -> 0 | N7: =SUM(AH47:AH62) -> 0 | O7: =SUM(AN47:AN62) -> 0 | P7: =SUM(AT47:AT62) -> 0 | Q7: =SUM(AZ47:AZ62) -> 0 | R7: =SUM(BF47:BF62) -> 0
K8: Lact gilt | L8: =SUM(U47:U62) -> 0 | M8: =SUM(AA47:AA62) -> 0 | N8: =SUM(AG47:AG62) -> 0 | O8: =SUM(AM47:AM62) -> 3000 | P8: =SUM(AS47:AS62) -> 3000 | Q8: =SUM(AY47:AY62) -> 0 | R8: =SUM(BE47:BE62) -> 3000
A9: GROWER BULK FEED ORDER REQUIRED | K9: 90 plus | L9: =SUM(W28:W41) -> 0 | M9: =SUM(AC28:AC41) -> 0 | O9: =SUM(AO28:AO41) -> 0 | P9: =SUM(AU28:AU41) -> 0 | Q9: =SUM(BA28:BA41) -> 0 | R9: =SUM(BG28:BG41) -> 0
A10: DIET | B10: Mon | C10: Tue | D10: Wed | E10: Thu | F10: Fri | G10: Sat | H10: Sun
A11: W1 | B11: =SUM(T94:T136) -> 3000 | C11: =SUM(Z94:Z136) -> 3000 | D11: =SUM(AF94:AF136) -> 3000 | E11: =SUM(AL94:AL136) -> 0 | F11: =SUM(AR94:AR136) -> 3000 | G11: =SUM(AX94:AX136) -> 6000 | H11: =SUM(BD94:BD136) -> 6000
A12: GR 1 | B12: =SUM(U94:U136) -> 6000 | C12: =SUM(AA94:AA136) -> 6000 | D12: =SUM(AG94:AG136) -> 0 | E12: =SUM(AM94:AM136) -> 6000 | F12: =SUM(AS94:AS136) -> 3000 | G12: =SUM(AY94:AY136) -> 3000 | H12: =SUM(BE94:BE136) -> 3000 | K12: TOTAL | L12: =SUM(L3:L8) -> 6000 | M12: =SUM(M3:M11) -> 6000 | N12: =SUM(N3:N11) -> 0 | O12: =SUM(O3:O11) -> 6000 | P12: =SUM(P3:P11) -> 9000 | Q12: =SUM(Q3:Q11) -> 3000 | R12: =SUM(R3:R11) -> 6000
A13: GR 2 | B13: =SUM(V94:V136) -> 3000 | C13: =SUM(AB94:AB136) -> 6000 | D13: =SUM(AH94:AH136) -> 3000 | E13: =SUM(AN94:AN136) -> 3000 | F13: =SUM(AT94:AT136) -> 6000 | G13: =SUM(AZ106:AZ111) -> 0 | H13: =SUM(BF94:BF136) -> 6000
A14: GR 3 | B14: =SUM(W94:W136) -> 6000 | C14: =SUM(AC94:AC136) -> 0 | D14: =SUM(AI94:AI136) -> 9000 | E14: =SUM(AO94:AO136) -> 9000 | F14: =SUM(AU94:AU136) -> 0 | G14: =SUM(BA112:BA121) -> 6000 | H14: =SUM(BG94:BG136) -> 0 | K14: GILT RATIONS
A15: Fin | B15: =SUM(X94:X136) -> 6000 | C15: =SUM(AD94:AD136) -> 3000 | D15: =SUM(AJ94:AJ136) -> 9000 | E15: =SUM(AP94:AP136) -> 6000 | F15: =SUM(AV94:AV136) -> 6000 | G15: =SUM(BB118:BB136) -> 6000 | H15: =SUM(BH94:BH136) -> 6000 | K15: DIET | L15: Mon | M15: Tue | N15: Wed | O15: Thu | P15: Fri | Q15: Sat | R15: Sun
A16: TOTAL | B16: =SUM(B11:B15) -> 24000 | C16: =SUM(C11:C15) -> 18000 | D16: =SUM(D11:D15) -> 24000 | E16: =SUM(E11:E15) -> 24000 | F16: =SUM(F11:F15) -> 18000 | G16: =SUM(G11:G15) -> 21000 | H16: =SUM(H11:H15) -> 21000 | K16: Gilt 1 | L16: =SUM(T66:T77) -> 0 | M16: =SUM(Z66:Z77) -> 0 | N16: =SUM(AF66:AF77) -> 0 | O16: =SUM(AL66:AL77) -> 0 | P16: =SUM(AR66:AR77) -> 0 | Q16: =SUM(AX66:AX77) -> 0 | R16: =SUM(BD66:BD77) -> 0
I17: TOTAL BULK ORDER | K17: Gilt 2 | L17: =SUM(U66:U77) -> 0 | M17: =SUM(AA66:AA77) -> 0 | N17: =SUM(AG66:AG77) -> 0 | O17: =SUM(AM66:AM77) -> 0 | P17: =SUM(AS66:AS77) -> 0 | Q17: =SUM(AY66:AY77) -> 0 | R17: =SUM(BE66:BE77) -> 0
A18: Comb total | B18: =B7+B16+L12 -> 30000 | C18: =C7+C16+M12 -> 27000 | D18: =D7+D16+N12 -> 30000 | E18: =E7+E16+O12+O25 -> 30000 | F18: =F7+F16+P12 -> 30000 | G18: =G7+G16+Q12 -> 30000 | H18: =H7+H16+R12 -> 30000 | I18: =SUM(B18:H18) -> 207000 | K18: Gilt 3 | L18: =SUM(V66:V77) -> 0 | M18: =SUM(AB66:AB77) -> 0 | N18: =SUM(AH66:AH77) -> 0 | O18: =SUM(AN66:AN77) -> 0 | P18: =SUM(AT66:AT77) -> 0 | Q18: =SUM(AZ66:AZ77) -> 0 | R18: =SUM(BF66:BF77) -> 0
A19: Max allowable | B19: 30000 | C19: 30000 | D19: 30000 | E19: 30000 | F19: 30000 | G19: 30000 | H19: 30000 | I19: =SUM(B19:H19) -> 210000 | K19: Gilt 4 | L19: =SUM(W66:W77) -> 0 | M19: =SUM(AC66:AC77) -> 0 | N19: =SUM(AI66:AI77) -> 0 | O19: =SUM(AO66:AO77) -> 0 | P19: =SUM(AU66:AU77) -> 0 | Q19: =SUM(BA66:BA77) -> 0 | R19: =SUM(BG66:BG77) -> 0
A20: Difference | I20: =I18-I19 -> -3000 | K20: Gilt 4.1 | L20: =SUM(X66:X77) -> 0 | M20: =SUM(AD66:AD77) -> 0 | N20: =SUM(AJ66:AJ77) -> 0 | O20: =SUM(AP66:AP77) -> 0 | P20: =SUM(AV66:AV77) -> 0 | Q20: =SUM(BB66:BB77) -> 0 | R20: =SUM(BH66:BH77) -> 0
K21: Gilt 5 | L21: =SUM(Y66:Y77) -> 0 | M21: =SUM(AE66:AE77) -> 0 | N21: =SUM(AK66:AK77) -> 0 | O21: =SUM(AQ66:AQ77) -> 0 | P21: =SUM(AW66:AW77) -> 0 | Q21: =SUM(BC66:BC77) -> 0 | R21: =SUM(BI66:BI77) -> 0
K25: TOTAL | L25: =SUM(L16:L21) -> 0 | M25: =SUM(M16:M24) -> 0 | N25: =SUM(N16:N24) -> 0 | O25: =SUM(O16:O24) -> 0 | P25: =SUM(P16:P24) -> 0 | Q25: =SUM(Q16:Q24) -> 0 | R25: =SUM(R16:R24) -> 0
A26: MAINSITE BULK FEED ORDER
A27: Batch # | B27: House # | C27: AGE | D27: DIET | E27: INTAKE | F27: Actual intake | G27: NOP | H27: Batch intake | I27: BFT max | J27: BFT level | K27: Monday | L27: Tuesday | M27: Wednesday | N27: Thursday | O27: Friday | P27: Saturday | Q27: Sunday | R27: Monday | S27: Tuesday | T27: Mon-Dry Sow | U27: Mon-Dry Gilt | V27: Mon-Supaflash | W27: Mon-90 Plus | X27: Mon | Y27: Mon | Z27: Tues-Dry Sow | AA27: Tues-Dry Gilt | AB27: Tues-Supaflsh | AC27: Tues-90 plus | AE27: Tues | AF27: Wed-Dry Sow | AG27: Wed-Dry Gilt | AH27: Wed-Supaflash | AI27: Wed- 90 Plus | AJ27: Wed | AK27: Wed | AL27: Thur-Dry Sow | AM27: Thur-Dry Gilt | AN27: Thur-Supaflash | AO27: Thur- 90 plus | AP27: Thur | AQ27: Thur | AR27: Fri-Dry Sow | AS27: Fri-Dry Gilt | AT27: Fri-Supaflash | AU27: Fri - 90 plus | AV27: Fri | AW27: Fri | AX27: Sat-Dry Sow | AY27: Sat-Dry Gilt | AZ27: Sat-Supaflash | BA27: Sat- 90 plus | BB27: Sat | BC27: Sat | BD27: Sun-Dry Sow | BE27: Sun-Dry Gilt | BF27: Sun-Supaflash | BG27: Sun- 90 plus | BH27: Sun | BI27: Sun | BJ27: total delivered | BK27: bft closing | BL27: actual consumed
B28: DS1 | C28: 15wks, 14wks, 13wks, 10wks | D28: Dry Sow | E28: 2.8 | F28: =(BL28/G28)/4 -> 0 | G28: 170 | H28: =G28*E28 -> 476 | I28: 5800 | J28: 0 | K28: 3000 | L28: =K28-$H28 -> 2524 | M28: =L28-$H28 -> 2048 | N28: =M28-$H28 -> 1572 | O28: 4096 | P28: =O28-$H28 -> 3620 | Q28: =P28-$H28 -> 3144 | R28: =Q28-$H28 -> 2668 | S28: =R28-$H28 -> 2192 | T28: 3000 | AR28: 3000
B29: DS2 | C29: 12wk, 11wk, 9wk, 8wk,7wk,6wk, | D29: Dry Sow | E29: 3 | F29: =(BL29/G29)/7 -> 0 | G29: 230 | H29: =G29*E29 -> 690 | I29: 5800 | J29: 5000 | K29: =J29-$H29 -> 4310 | L29: =K29-$H29 -> 3620 | M29: =L29-$H29 -> 2930 | N29: =M29-$H29 -> 2240 | O29: 4550 | P29: =O29-$H29 -> 3860 | Q29: =P29-$H29 -> 3170 | R29: =Q29-$H29 -> 2480 | S29: =R29-$H29 -> 1790 | AR29: 3000
B30: DS4 | C30: 5wk, 4wk, 3wks, 2wks,1wk,0wk | D30: Dry Sow | E30: 2.8 | F30: =(BL30/G30)/7 -> 0 | G30: 230 | H30: =G30*E30 -> 644 | I30: 5800 | J30: 4000 | K30: =J30-$H30 -> 3356 | L30: =K30-$H30 -> 2712 | M30: =L30-$H30 -> 2068 | N30: 4420 | O30: =N30-$H30 -> 3776 | P30: =O30-$H30 -> 3132 | Q30: =P30-$H30 -> 2488 | R30: =Q30-$H30 -> 1844 | S30: =R30-$H30 -> 1200 | AL30: 3000
D31: Dry Sow | E31: 2.5 | F31: =(BL31/G31)/7 -> #DIV/0! | H31: =G31*E31 -> 0 | K31: =J31-$H31 -> 0 | L31: =K31-$H31 -> 0 | M31: =L31-$H31 -> 0 | N31: =M31-$H31 -> 0 | O31: =N31-$H31 -> 0 | P31: =O31-$H31 -> 0 | Q31: =P31-$H31 -> 0 | R31: =Q31-$H31 -> 0 | S31: =R31-$H31 -> 0
D32: Dry Sow | E32: 3 | F32: =(BL32/G32)/7 -> #DIV/0! | H32: =G32*E32 -> 0 | K32: =J32-$H32 -> 0 | L32: =K32-$H32 -> 0 | M32: =L32-$H32 -> 0 | N32: =M32-$H32 -> 0 | O32: =N32-$H32 -> 0 | P32: =O32-$H32 -> 0 | Q32: =P32-$H32 -> 0 | R32: =Q32-$H32 -> 0 | S32: =R32-$H32 -> 0
D33: Dry Sow | E33: 3 | F33: =(BL33/G33)/7 -> #DIV/0! | H33: =G33*E33 -> 0 | K33: =J33-$H33 -> 0 | L33: =K33-$H33 -> 0 | M33: =L33-$H33 -> 0 | N33: =M33-$H33 -> 0 | O33: =N33-$H33 -> 0 | P33: =O33-$H33 -> 0 | Q33: =P33-$H33 -> 0 | R33: =Q33-$H33 -> 0 | S33: =R33-$H33 -> 0
B34: SL | D34: Supa Flush | E34: 6.5 | F34: =(BL34/G34)/7 -> 0 | G34: 89 | H34: =G34*E34 -> 578.5 | I34: 5800 | J34: 1000 | K34: =J34-$H34 -> 421.5 | L34: 3000 | M34: =L34-$H34 -> 2421.5 | N34: =M34-$H34 -> 1843 | O34: =N34-$H34 -> 1264.5 | P34: =O34-$H34 -> 686 | Q34: 3000 | R34: =Q34-$H34 -> 2421.5 | S34: =R34-$H34 -> 1843 | AB34: 3000 | BF34: 3000
B35: SL | D35: Supa Flush | E35: 0 | F35: =(BL35/G35)/7 -> #DIV/0! | H35: =G35*E35 -> 0 | K35: =J35-$H35 -> 0 | L35: =K35-$H35 -> 0 | M35: =L35-$H35 -> 0 | N35: =M35-$H35 -> 0 | O35: =N35-$H35 -> 0 | P35: =O35-$H35 -> 0 | Q35: =P35-$H35 -> 0 | R35: =Q35-$H35 -> 0 | S35: =R35-$H35 -> 0
B36: DS3 | C36: all preg gilts | D36: Dry Gilt | E36: 2.7 | F36: =(BL36/G36)/7 -> 0 | G36: 180 | H36: =G36*E36 -> 486 | I36: 5800 | J36: 2000 | K36: =J36-$H36 -> 1514 | L36: 4028 | M36: =L36-$H36 -> 3542 | N36: =M36-$H36 -> 3056 | O36: =N36-$H36 -> 2570 | P36: 5084 | Q36: =P36-$H36 -> 4598 | R36: =Q36-$H36 -> 4112 | S36: =R36-$H36 -> 3626 | AA36: 3000 | AY36: 3000
D37: Dry Gilt | E37: 2.5 | F37: =(BL37/G37)/7 -> #DIV/0! | H37: =G37*E37 -> 0 | K37: =J37-$H37 -> 0 | L37: =K37-$H37 -> 0 | M37: =L37-$H37 -> 0 | N37: =M37-$H37 -> 0 | O37: =N37-$H37 -> 0 | P37: =O37-$H37 -> 0 | Q37: =P37-$H37 -> 0 | R37: =Q37-$H37 -> 0 | S37: =R37-$H37 -> 0
D38: Dry Gilt | E38: 2.5 | F38: =(BL38/G38)/7 -> #DIV/0! | H38: =G38*E38 -> 0 | K38: =J38-$H38 -> 0 | L38: =K38-$H38 -> 0 | M38: =L38-$H38 -> 0 | N38: =M38-$H38 -> 0 | O38: =N38-$H38 -> 0 | P38: =O38-$H38 -> 0 | Q38: =P38-$H38 -> 0 | R38: =Q38-$H38 -> 0 | S38: =R38-$H38 -> 0
D39: Dry Gilt | E39: 2.5 | F39: =(BL39/G39)/7 -> #DIV/0! | H39: =G39*E39 -> 0 | K39: =J39-$H39 -> 0 | L39: =K39-$H39 -> 0 | M39: =L39-$H39 -> 0 | N39: =M39-$H39 -> 0 | O39: =N39-$H39 -> 0 | P39: =O39-$H39 -> 0 | Q39: =P39-$H39 -> 0 | R39: =Q39-$H39 -> 0 | S39: =R39-$H39 -> 0
D40: Dry Gilt | E40: 3 | F40: =(BL40/G40)/7 -> #DIV/0! | H40: =G40*E40 -> 0 | K40: =J40-$H40 -> 0 | L40: =K40-$H40 -> 0 | M40: =L40-$H40 -> 0 | N40: =M40-$H40 -> 0 | O40: =N40-$H40 -> 0 | P40: =O40-$H40 -> 0 | Q40: =P40-$H40 -> 0 | R40: =Q40-$H40 -> 0 | S40: =R40-$H40 -> 0
D41: Dry Gilt | E41: 3 | F41: =(BL41/G41)/7 -> #DIV/0! | H41: =G41*E41 -> 0 | K41: =J41-$H41 -> 0 | L41: =K41-$H41 -> 0 | M41: =L41-$H41 -> 0 | N41: =M41-$H41 -> 0 | O41: =N41-$H41 -> 0 | P41: =O41-$H41 -> 0 | Q41: =P41-$H41 -> 0 | R41: =Q41-$H41 -> 0 | S41: =R41-$H41 -> 0
A45: MAINSITE BULK FEED ORDER
A46: Batch # | B46: House # | C46: AGE | D46: DIET | E46: INTAKE | F46: Actual intake | G46: NOP | H46: Batch intake | I46: BFT max | J46: BFT level | K46: Monday | L46: Tuesday | M46: Wednesday | N46: Thursday | O46: Friday | P46: Saturday | Q46: Sunday | R46: Monday | S46: Tuesday | T46: Mon-L Sow | U46: Mon- L Gilt | V46: Mon-Trans | W46: Mon | X46: Mon | Y46: Mon | Z46: Tue-L Sow | AA46: Tue- L Gilt | AB46: Tue-Trans | AC46: Tues | AD46: Tues | AE46: Tues | AF46: Wed-L Sow | AG46: Wed- L Gilt | AH46: Wed-Trans | AI46: Wed | AJ46: Wed | AK46: Wed | AL46: Thur-L Sow | AM46: Thur- L Gilt | AN46: Thur-Trans | AO46: Thur | AP46: Thur | AQ46: Thur | AR46: Fri-L Sow | AS46: Fri- L Gilt | AT46: Fri-Trans | AU46: Fri | AV46: Fri | AW46: Fri | AX46: Sat-L Sow | AY46: Sat- L Gilt | AZ46: Sat-Trans | BA46: Sat | BB46: Sat | BC46: Sat | BD46: Sun-L Sow | BE46: Sun- L Gilt | BF46: Sun-Trans | BG46: Sun | BH46: Sun | BI46: Sun | BJ46: total delivered | BK46: bft closing | BL46: actual consumed
...

Sheet Porta L. Instruction
D1: CCC PIGS BULK FEED LOADING AND RECEIVING FORM | H1: CCC PIGS BULK FEED LOADING AND RECEIVING FORM | L1: CCC PIGS BULK FEED LOADING AND RECEIVING FORM | P1: CCC PIGS BULK FEED LOADING AND RECEIVING FORM | T1: CCC PIGS BULK FEED LOADING AND RECEIVING FORM | X1: CCC PIGS BULK FEED LOADING AND RECEIVING FORM | AB1: CCC PIGS BULK FEED LOADING AND RECEIVING FORM
D2: Farm/Site Name: | F2: Driver name: | H2: Farm/Site Name: | J2: Driver name: | L2: Farm/Site Name: | N2: Driver name: | P2: Farm/Site Name: | R2: Driver name: | T2: Farm/Site Name: | V2: Driver name: | X2: Farm/Site Name: | Z2: Driver name: | AB2: Farm/Site Name: | AD2: Driver name:
D3: Week No: | F3: Truck reg: | H3: Week No: | J3: Truck reg: | L3: Week No: | N3: Truck reg: | P3: Week No: | R3: Truck reg: | T3: Week No: | V3: Truck reg: | X3: Week No: | Z3: Truck reg: | AB3: Week No: | AD3: Truck reg:
D4: Date: | F4: Trailer reg: | H4: Date: | J4: Trailer reg: | L4: Date: | N4: Trailer reg: | P4: Date: | R4: Trailer reg: | T4: Date: | V4: Trailer reg: | X4: Date: | Z4: Trailer reg: | AB4: Date: | AD4: Trailer reg:
D5: Weighbridge Ticket No: | F5: System Shipment No: | H5: Weighbridge Ticket No: | J5: System Shipment No: | L5: Weighbridge Ticket No: | N5: System Shipment No: | P5: Weighbridge Ticket No: | R5: System Shipment No: | T5: Weighbridge Ticket No: | V5: System Shipment No: | X5: Weighbridge Ticket No: | Z5: System Shipment No: | AB5: Weighbridge Ticket No: | AD5: System Shipment No:
D6: Load start time: | F6: Load end time: | H6: Load start time: | J6: Load end time: | L6: Load start time: | N6: Load end time: | P6: Load start time: | R6: Load end time: | T6: Load start time: | V6: Load end time: | X6: Load start time: | Z6: Load end time: | AB6: Load start time: | AD6: Load end time:
D7: Offload start time: | F7: Offload end time: | H7: Offload start time: | J7: Offload end time: | L7: Offload start time: | N7: Offload end time: | P7: Offload start time: | R7: Offload end time: | T7: Offload start time: | V7: Offload end time: | X7: Offload start time: | Z7: Offload end time: | AB7: Offload start time: | AD7: Offload end time:
A9: AGE | B9: House # | D9: Monday | H9: Tuesday | L9: Wednesday | P9: Thursday | T9: Friday | X9: Saturday | AB9: Sunday | AF9: Totals
D10: Diet | E10: Kgs Ordered | F10: kgs Loaded | G10: Compartment No. | H10: Diet | I10: Kgs Ordered | J10: kgs Loaded | K10: Compartment No. | L10: Diet | M10: Kgs Ordered | N10: kgs Loaded | O10: Compartment No. | P10: Diet | Q10: Kgs Ordered | R10: kgs Loaded | S10: Compartment No. | T10: Diet | U10: Kgs Ordered | V10: kgs Loaded | W10: Compartment No. | X10: Diet | Y10: Kgs Ordered | Z10: kgs Loaded | AA10: Compartment No. | AB10: Diet | AC10: Kgs Ordered | AD10: kgs Loaded | AE10: Compartment No. | AF10: Kgs Ordered | AG10: Kg delivered
B11: DS1 | D11: Dry Sow | E11: ='[2]Porta Wk 34'!T28 -> 3000 | T11: DRY SOW | U11: 3000 | AF11: =SUM(E11,I11,M11,Q11,U11,Y11,AC11) -> 6000 | AG11: =SUM(F11,J11,N11,R11,V11,Z11,AD11) -> 0
B12: DS2 | E12: ='[2]Porta Wk 34'!T29 -> 0 | H12: D/S | I12: ='[2]Porta Wk 34'!Z29 -> 0 | T12: DRY SOW | U12: 3000 | X12: DRY SOW | AF12: =SUM(E12,I12,M12,Q12,U12,Y12,AC12) -> 3000 | AG12: =SUM(F12,J12,N12,R12,V12,Z12,AD12) -> 0
B13: DS4 | E13: ='[2]Porta Wk 34'!T30 -> 0 | P13: DRY SOW | Q13: 3000 | AF13: =SUM(E13,I13,M13,Q13,U13,Y13,AC13) -> 3000 | AG13: =SUM(F13,J13,N13,R13,V13,Z13,AD13) -> 0
B14: S/L | E14: ='[2]Porta Wk 34'!V34 -> 0 | H14: SUPER FLUSH | I14: ='[2]Porta Wk 34'!AB34 -> 3000 | AB14: SUPER FLUSH | AC14: 3000 | AF14: =SUM(E14,I14,M14,Q14,U14,Y14,AC14) -> 6000 | AG14: =SUM(F14,J14,N14,R14,V14,Z14,AD14) -> 0
B15: FH1 and 2 | D15: TRANSITION | E15: ='[2]Porta Wk 34'!V49 -> 3000 | T15: LG | U15: 3000 | AF15: =SUM(E15,I15,M15,Q15,U15,Y15,AC15) -> 6000 | AG15: =SUM(F15,J15,N15,R15,V15,Z15,AD15) -> 0
B16: FH3 and 4 | P16: LACTATE GILT | Q16: 3000 | AB16: LACTATE GILT | AC16: 3000 | AF16: =SUM(E16,I16,M16,Q16,U16,Y16,AC16) -> 6000 | AG16: =SUM(F16,J16,N16,R16,V16,Z16,AD16) -> 0
B17: DG3 | H17: Dry Gilt | I17: ='[2]Porta Wk 34'!AA36 -> 3000 | X17: DRY GILT | Y17: 3000 | AF17: =SUM(E17,I17,M17,Q17,U17,Y17,AC17) -> 6000 | AG17: =SUM(F17,J17,N17,R17,V17,Z17,AD17) -> 0
B18: FH 5 | AF18: =SUM(E18,I18,M18,Q18,U18,Y18,AC18) -> 0 | AG18: =SUM(F18,J18,N18,R18,V18,Z18,AD18) -> 0
A19: 4 Weeks | B19: W5 | I19: ='[2]Porta Wk 34'!AA85 -> 0 | L19: CREEP 2 | M19: ='[2]Porta Wk 34'!AG85 -> 3000 | Q19: ='[2]Porta Wk 34'!AM85 -> 0 | U19: ='[2]Porta Wk 34'!AS85 -> 0 | Y19: ='[2]Porta Wk 34'!AZ85 -> 0 | AC19: ='[2]Porta Wk 34'!BE85 -> 0 | AF19: =SUM(E19,I19,M19,Q19,U19,Y19,AC19) -> 3000 | AG19: =SUM(F19,J19,N19,R19,V19,Z19,AD19) -> 0
A20: 5 Weeks | B20: W4 | E20: ='[2]Porta Wk 34'!V86 -> 0 | H20: CREEP 3 | I20: ='[2]Porta Wk 34'!AB86 -> 3000 | M20: ='[2]Porta Wk 34'!AH86 -> 0 | Q20: ='[2]Porta Wk 34'!AN86 -> 0 | T20: CREEP 3 | U20: ='[2]Porta Wk 34'!AT86 -> 3000 | Y20: ='[2]Porta Wk 34'!AZ86 -> 0 | AC20: ='[2]Porta Wk 34'!BF86 -> 0 | AF20: =SUM(E20,I20,M20,Q20,U20,Y20,AC20) -> 6000 | AG20: =SUM(F20,J20,N20,R20,V20,Z20,AD20) -> 0
A21: 6 Weeks | B21: W3 | E21: ='[2]Porta Wk 34'!V87 -> 0 | I21: ='[2]Porta Wk 34'!AB87 -> 0 | M21: ='[2]Porta Wk 34'!AH87 -> 0 | Q21: ='[2]Porta Wk 34'!AN87 -> 0 | U21: ='[2]Porta Wk 34'!AT87 -> 0 | X21: CREEP 3 | Y21: ='[2]Porta Wk 34'!AZ87 -> 3000 | AC21: ='[2]Porta Wk 34'!BF87 -> 0 | AF21: =SUM(E21,I21,M21,Q21,U21,Y21,AC21) -> 3000 | AG21: =SUM(F21,J21,N21,R21,V21,Z21,AD21) -> 0
A22: 7 Weeks | B22: W2 | E22: ='[2]Porta Wk 34'!V88 -> 0 | I22: ='[2]Porta Wk 34'!AB88 -> 0 | M22: ='[2]Porta Wk 34'!AH88 -> 0 | Q22: ='[2]Porta Wk 34'!AO88 -> 0 | U22: ='[2]Porta Wk 34'!AU88 -> 0 | Y22: ='[2]Porta Wk 34'!AZ88 -> 0 | AB22: WEAN 1 CARA | AC22: ='[2]Porta Wk 34'!BG88 -> 3000 | AF22: =SUM(E22,I22,M22,Q22,U22,Y22,AC22) -> 3000 | AG22: =SUM(F22,J22,N22,R22,V22,Z22,AD22) -> 0
A23: 8 Weeks | B23: W1 | E23: ='[2]Porta Wk 34'!W89 -> 0 | I23: ='[2]Porta Wk 34'!AC89 -> 0 | L23: WEAN 1 CARA | M23: ='[2]Porta Wk 34'!AI89 -> 3000 | Q23: ='[2]Porta Wk 34'!AO89 -> 0 | U23: ='[2]Porta Wk 34'!AU89 -> 0 | X23: WEAN 1 CARA | Y23: ='[2]Porta Wk 34'!BA89 -> 3000 | AC23: ='[2]Porta Wk 34'!BG89 -> 0 | AF23: =SUM(E23,I23,M23,Q23,U23,Y23,AC23) -> 6000 | AG23: =SUM(F23,J23,N23,R23,V23,Z23,AD23) -> 0
A24: 9 Weeks | B24: W6 | E24: ='[2]Porta Wk 34'!W90 -> 0 | I24: ='[2]Porta Wk 34'!AC90 -> 0 | M24: ='[2]Porta Wk 34'!AI90 -> 0 | Q24: ='[2]Porta Wk 34'!AO90 -> 0 | U24: ='[2]Porta Wk 34'!AU90 -> 0 | Y24: ='[2]Porta Wk 34'!BA90 -> 0 | AC24: ='[2]Porta Wk 34'!BG90 -> 0 | AF24: =SUM(E24,I24,M24,Q24,U24,Y24,AC24) -> 0 | AG24: =SUM(F24,J24,N24,R24,V24,Z24,AD24) -> 0
A25: 10 Weeks | B25: DST3 | D25: WEAN 1 OTC | E25: ='[2]Porta Wk 34'!T94 -> 3000 | I25: ='[2]Porta Wk 34'!Z94 -> 0 | L25: WEAN 1 OTC | M25: ='[2]Porta Wk 34'!AF94 -> 3000 | Q25: ='[2]Porta Wk 34'!AL94 -> 0 | U25: ='[2]Porta Wk 34'!AR94 -> 0 | X25: WEAN 1 OTC | Y25: ='[2]Porta Wk 34'!AX94 -> 3000 | AF25: =SUM(E25,I25,M25,Q25,U25,Y25,AC25) -> 9000 | AG25: =SUM(F25,J25,N25,R25,V25,Z25,AD25) -> 0
A26: 11 Weeks | B26: DST2 | E26: ='[2]Porta Wk 34'!T97 -> 0 | H26: WEAN 1 OTC | I26: ='[2]Porta Wk 34'!Z97 -> 3000 | M26: ='[2]Porta Wk 34'!AF97 -> 0 | Q26: ='[2]Porta Wk 34'!AL97 -> 0 | T26: WEAN 1 OTC | U26: ='[2]Porta Wk 34'!AR97 -> 3000 | Y26: ='[2]Porta Wk 34'!AX97 -> 0 | AB26: Wean 1 OTC | AC26: ='[2]Porta Wk 34'!BD97 -> 3000 | AF26: =SUM(E26,I26,M26,Q26,U26,Y26,AC26) -> 9000 | AG26: =SUM(F26,J26,N26,R26,V26,Z26,AD26) -> 0
A27: 12 Weeks | B27: DST1 | D27: GROWER 1 | E27: ='[2]Porta Wk 34'!U100 -> 3000 | H27: GROWER 1 | I27: ='[2]Porta Wk 34'!AA100 -> 3000 | M27: ='[2]Porta Wk 34'!AG100 -> 0 | P27: WEAN 1 OTC | Q27: ='[2]Porta Wk 34'!AM100 -> 3000 | U27: ='[2]Porta Wk 34'!AS100 -> 0 | X27: GROWER 1 | Y27: ='[2]Porta Wk 34'!AY100 -> 3000 | AC27: ='[2]Porta Wk 34'!BE100 -> 0 | AF27: =SUM(E27,I27,M27,Q27,U27,Y27,AC27) -> 12000 | AG27: =SUM(F27,J27,N27,R27,V27,Z27,AD27) -> 0
A28: 13 Weeks | B28: DST4/G8 | D28: GROWER 1 | E28: ='[2]Porta Wk 34'!U103 -> 3000 | H28: GROWER 1 | I28: ='[2]Porta Wk 34'!AA103 -> 3000 | M28: ='[2]Porta Wk 34'!AG103 -> 0 | P28: GROWER 1 | Q28: ='[2]Porta Wk 34'!AM103 -> 3000 | T28: GROWER 2 | U28: ='[2]Porta Wk 34'!AS103 -> 3000 | Y28: ='[2]Porta Wk 34'!AY103 -> 0 | AB28: GROWER 1 | AC28: ='[2]Porta Wk 34'!BE103 -> 3000 | AF28: =SUM(E28,I28,M28,Q28,U28,Y28,AC28) -> 15000 | AG28: =SUM(F28,J28,N28,R28,V28,Z28,AD28) -> 0
A29: 14 Weeks | B29: G7 | D29: GROWER 2 | E29: ='[2]Porta Wk 34'!V106 -> 3000 | H29: GROWER 2 | I29: ='[2]Porta Wk 34'!AB106 -> 3000 | M29: ='[2]Porta Wk 34'!AH106 -> 0 | P29: GROWER 2 | Q29: ='[2]Porta Wk 34'!AN106 -> 3000 | T29: Grower 1 | U29: ='[2]Porta Wk 34'!AT106 -> 3000 | Y29: ='[2]Porta Wk 34'!AZ106 -> 0 | AB29: GROWER 1 | AC29: ='[2]Porta Wk 34'!BF106 -> 3000 | AF29: =SUM(E29,I29,M29,Q29,U29,Y29,AC29) -> 15000 | AG29: =SUM(F29,J29,N29,R29,V29,Z29,AD29) -> 0
A30: 15 Weeks | B30: G6 | E30: ='[2]Porta Wk 34'!V109 -> 0 | H30: GROWER 2 | I30: ='[2]Porta Wk 34'!AB109 -> 3000 | L30: GROWER 2 | M30: ='[2]Porta Wk 34'!AH109 -> 3000 | Q30: ='[2]Porta Wk 34'!AN109 -> 0 | T30: GROWER 2 | U30: ='[2]Porta Wk 34'!AT109 -> 3000 | Y30: ='[2]Porta Wk 34'!AZ109 -> 0 | AB30: GROWER 2 | AC30: ='[2]Porta Wk 34'!BF109 -> 3000 | AF30: =SUM(E30,I30,M30,Q30,U30,Y30,AC30) -> 12000 | AG30: =SUM(F30,J30,N30,R30,V30,Z30,AD30) -> 0
A31: 16 Weeks | B31: G5 | E31: ='[2]Porta Wk 34'!W112 -> 0 | I31: ='[2]Porta Wk 34'!AC112 -> 0 | L31: GROWER 3 | M31: ='[2]Porta Wk 34'!AI112 -> 3000 | P31: GROWER 3 | Q31: ='[2]Porta Wk 34'!AO112 -> 3000 | U31: ='[2]Porta Wk 34'!AU112 -> 0 | X31: GROWER 3 | Y31: ='[2]Porta Wk 34'!BA112 -> 3000 | AC31: ='[2]Porta Wk 34'!BG112 -> 0 | AF31: =SUM(E31,I31,M31,Q31,U31,Y31,AC31) -> 9000 | AG31: =SUM(F31,J31,N31,R31,V31,Z31,AD31) -> 0
