Workbook

Sheet April journals
A2: Triple C Pigs Books
A5: CR | B5: 1700/065 | C5: Feed ingredients other | G5: ='Pigs Cost'!G174+'Pigs Cost'!H174+'Pigs Cost'!I174 -> 15900000000000
A6: DR | B6: 6136/000 | C6: Zimbo intra-company | F6: ='Pigs Cost'!H174 -> 5700000000000
A7: DR | B7: 6137/000 | C7: Trade winds-intra company | F7: ='Pigs Cost'!G174 -> 9900000000000
A8: DR | B8: 6141/000 | C8: Quarantine - Outgrowers | F8: ='Pigs Cost'!I174 -> 300000000000
F10: =SUM(F6:F9) -> 15900000000000 | G10: =SUM(G5:G9) -> 15900000000000
A14: CR | B14: 1500/010 | C14: AI Consumables | G14: 5500
A15: CR | B15: 1500/025 | C15: Consumables | G15: 1053881
A16: CR | B16: 1400/030 | C16: Consultancy Fees | G16: 966060
A17: CR | B17: 1500/095 | C17: Training - External Consultants | G17: 4552000
A18: CR | B18: 1600/010 | C18: Cimas | G18: 884201
A19: CR | B19: 1600/030 | C19: Nssa | G19: 159193.72
A20: CR | B20: 1600/040 | C20: Protective Clothing | G20: 33033193
A21: CR | B21: 1600/050 | C21: Salaries | G21: 47297172
A22: CR | B22: 1600/070 | C22: Wages | G22: 9591454
A23: CR | B23: 1600/080 | C23: Welfare & Training | G23: 2215498
A24: CR | B24: 1750/010 | C24: Cimas | G24: 614798
A25: CR | B25: 1750/030 | C25: Nssa | G25: 65700
... A34: CR | B34: 1400/120 | C34: Veterinary | G34: 18000
A35: DR | B35: 6136/000 | C35: Zimbo intra-company | F35: ='Pigs Cost'!H176 -> 0
A36: DR | B36: 6137/000 | C36: Trade winds-intra company | F36: ='Pigs Cost'!#REF! -> #REF!
A37: DR | B37: 6141/000 | C37: Quarantine - Outgrowers | F37: ='Pigs Cost'!I176 -> 0
A38: DR | B38: 0300/030 | C38: Followers | F38: 5500
A39: DR | B39: 0300/015 | C39: Gilts | F39: ='Pigs Cost'!G16 -> 0
A40: DR | B40: 0300/030 | C40: Followers | F40: ='Pigs Cost'!G13+'Pigs Cost'!G14+'Pigs Cost'!G15 -> #REF!
A41: DR | B41: 0300/015 | C41: Gilts | F41: ='Pigs Cost'!H16 -> 0
A42: DR | B42: 0300/030 | C42: Followers | F42: ='Pigs Cost'!H13+'Pigs Cost'!H14+'Pigs Cost'!H15 -> #REF!
A43: DR | B43: 0300/015 | C43: Gilts | F43: ='Pigs Cost'!I16 -> 0
A44: DR | B44: 0300/030 | C44: Followers | F44: ='Pigs Cost'!I13+'Pigs Cost'!I14+'Pigs Cost'!I15 -> 0
A45: DR | B45: 0300/015 | C45: Gilts | F45: ='Pigs Cost'!L16 -> 0
A46: DR | B46: 0300/030 | C46: Followers | F46: ='Pigs Cost'!L15+'Pigs Cost'!L14+'Pigs Cost'!L13 -> #REF!
L47: =J34-L34 -> 0
F48: =SUM(F14:F47) -> #REF! | G48: =SUM(G14:G47) -> 6.9578096e+08
A50: DR | B50: 1500/015 | C50: Cost of sales | F50: 2.836853e+09
A51: CR | B51: 0300/030 | C51: Followers | G51: =F50 -> 2.836853e+09
F53: =SUM(F50:F52) -> 2.836853e+09 | G53: =SUM(G50:G52) -> 2.836853e+09
A56: Zimbo Books
A58: DR | B58: 0300/020 | C58: Sows | F58: 4707650
A59: CR | C59: Triple C Pigs | G59: 4707650
F60: =SUM(F58:F59) -> 4707650 | G60: =SUM(G58:G59) -> 4707650
...

Sheet Outgrower feed
D3: Dry Sow | E3: Gilt | F3: Creep | G3: Lactate | H3: Wean1 | I3: Wean2 | J3: Grower 2 | K3: Grower 1 | L3: Grower 4 | M3: Grower 3 | N3: Wheat bran | O3: Total
A5: Tradewinds | C5: Tonnage | D5: 1 | F5: 3 | G5: 1 | H5: 1 | I5: 1 | J5: 2 | K5: 1 | L5: 3 | M5: 11 | O5: =SUM(D5:N5) -> 24
C6: Unit cost
C8: Total | D8: =D6*D5 -> 0 | F8: =F6*F5 -> 0 | G8: =G6*G5 -> 0 | I8: =I6*I5 -> 0 | J8: =J6*J5 -> 0 | K8: =K6*K5 -> 0 | M8: =M6*M5 -> 0 | O8: =SUM(D8:M8) -> 0
A10: Zimbo | C10: Tonnage | D10: 15 | E10: 2 | F10: 1 | G10: 3 | H10: 1 | N10: 0.5 | O10: =SUM(D10:N10) -> 22.5
C11: Unit cost
C13: Total | D13: =D11*D10 -> 0 | F13: =F11*F10 -> 0 | G13: =G11*G10 -> 0 | I13: =I11*I10 -> 0 | J13: =J11*J10 -> 0 | K13: =K11*K10 -> 0 | M13: =M11*M10 -> 0 | O13: =SUM(D13:M13) -> 0
A15: Quarantine | C15: Tonnage | D15: 1 | E15: 5 | O15: =SUM(D15:N15) -> 6
C16: Unit cost
C18: Total | D18: =D16*D15 -> 0 | F18: =F16*F15 -> 0 | G18: =G16*G15 -> 0 | I18: =I16*I15 -> 0 | J18: =J16*J15 -> 0 | K18: =K16*K15 -> 0 | M18: =M16*M15 -> 0 | O18: =SUM(D18:M18) -> 0
A20: Rotgate | C20: Tonnage | E20: 11 | G20: 1 | J20: 4 | K20: 1 | O20: =SUM(D20:N20) -> 17
C21: Unit cost
C23: Total | D23: =D21*D20 -> 0 | F23: =F21*F20 -> 0 | G23: =G21*G20 -> 0 | I23: =I21*I20 -> 0 | J23: =J21*J20 -> 0 | K23: =K21*K20 -> 0 | M23: =M21*M20 -> 0 | O23: =SUM(D23:M23) -> 0

Sheet March pigs Journals
A3: Triple C Pigs Books
A7: CR | B7: 0300/010 | C7: Boars | E7: 3838761.6
A8: CR | B8: 0300/015 | C8: Gilts | E8: 0
A9: CR | B9: 0300/020 | C9: Sows | E9: 1.8578716e+08
A10: CR | B10: 0300/030 | C10: Followers | E10: =123971125.515872+1.23 -> 1.2397113e+08
A11: DR | B11: 6137/000 | C11: Trade winds-intra company | F11: 152819698
A12: DR | B12: 6141/000 | C12: Quarantine - Outgrowers | F12: 160777350
E14: =SUM(E7:E13) -> 3.1359705e+08 | F14: =SUM(F11:F13) -> 313597048
A17: Trade Winds Books
A20: DR | B20: 0300/010 | C20: Boars | E20: =1%*'Pigs Cost'!C29 -> 0
A21: DR | B21: 0300/015 | C21: Gilts
A22: DR | B22: 0300/020 | C22: Sows | E22: =99%*'Pigs Cost'!C29 -> 0
A23: DR | B23: 0300/030 | C23: Followers | E23: ='Pigs Cost'!C25 -> 0
A24: CR | C24: Triple C Pigs | F24: 152819698
E26: =SUM(E20:E24) -> 0 | F26: =SUM(F24:F25) -> 152819698
A28: Quarantine Books
A30: DR | B30: 0300/010 | C30: Boars
A31: DR | B31: 0300/015 | C31: Gilts
A32: DR | B32: 0300/020 | C32: Sows | E32: 160777350
A33: DR | B33: 0300/030 | C33: Followers
A34: CR | C34: Triple C Pigs | F34: 160777350
E36: =SUM(E32:E35) -> 160777350 | F36: =SUM(F34:F35) -> 160777350

Sheet Pigs Cost after IAS 41
A1: COLCOM HOLDINGS LIMITED
A3: TRIPLE C PIGS
A5: LIVESTOCK ANALYSIS SCHEDULE INCLUDING IAS 41
A8: COST | B8: GRASMERE FARM
A10: SITE:
A12: DESCRIPTION | B12: SITE | C12: OPENING | D12: PIG PURCHASES | E12: TRANSFER IN | F12: A I CONSUMMABLES | G12: BEDDING AND CONSUMMABLES | H12: CONSULTANCY FEES | I12: DIRECT STAFF COSTS | J12: STOCK FEED | K12: SUNDRY TOOLS | L12: VETERINARY | M12: TOTAL COST | N12: AVERAGE COST | O12: TRANSFER OUT | P12: SALES | Q12: IAS 41 ADJ. | R12: CLOSING
A13: PIGLETS | B13: MAIN | C13: ='Pigs Cost'!C13 -> 7.6193293e+10 | D13: ='Pigs Cost'!D13 -> 0 | E13: ='Pigs Cost'!E13 -> 0 | F13: ='Pigs Cost'!F13 -> 0 | G13: ='Pigs Cost'!G13 -> #REF! | H13: ='Pigs Cost'!H13 -> #REF! | I13: ='Pigs Cost'!I13 -> 0 | J13: ='Pigs Cost'!J13 -> #REF! | ... L13: ='Pigs Cost'!L13 -> #REF! | M13: =SUM(C13:L13) -> #REF! | N13: ='Pigs Cost'!N13 -> #REF! | O13: ='Pigs Cost'!O13 -> #REF! | P13: ='Pigs Cost'!P13 -> #REF! | Q13: ='[5]PigsMay 07 '!$H34 -> 9.3648212e+10 | R13: =M13+O13+P13+Q13 -> #REF!
A14: WEANERS | B14: WEANER | C14: ='Pigs Cost'!C14 -> 1.0410751e+11 | D14: ='Pigs Cost'!D14 -> 0 | E14: ='Pigs Cost'!E14 -> #REF! | F14: ='Pigs Cost'!F14 -> 0 | G14: ='Pigs Cost'!G14 -> #REF! | H14: ='Pigs Cost'!H14 -> #REF! | I14: ='Pigs Cost'!I14 -> 0 | J14: ='Pigs Cost'!J14 -> #REF! | ... L14: ='Pigs Cost'!L14 -> #REF! | M14: =SUM(C14:L14) -> #REF! | N14: ='Pigs Cost'!N14 -> #REF! | O14: ='Pigs Cost'!O14 -> #REF! | P14: ='Pigs Cost'!P14 -> #REF! | Q14: ='[5]PigsMay 07 '!$H35 -> 9.2282436e+11 | R14: =M14+O14+P14+Q14 -> #REF!
A15: GROWERS | B15: GROWER | C15: ='Pigs Cost'!C15 -> 2.2702568e+11 | D15: ='Pigs Cost'!D15 -> 0 | E15: ='Pigs Cost'!E15 -> #REF! | F15: ='Pigs Cost'!F15 -> 0 | G15: ='Pigs Cost'!G15 -> #REF! | H15: ='Pigs Cost'!H15 -> #REF! | I15: ='Pigs Cost'!I15 -> 0 | J15: ='Pigs Cost'!J15 -> #REF! | ... L15: ='Pigs Cost'!L15 -> #REF! | M15: =SUM(C15:L15) -> #REF! | N15: ='Pigs Cost'!N15 -> #REF! | O15: ='Pigs Cost'!O15 -> #REF! | P15: ='Pigs Cost'!P15 -> #REF! | Q15: ='[5]PigsMay 07 '!$H36 -> 3.4016397e+12 | R15: =M15+O15+P15+Q15 -> #REF!
A16: GILTS | B16: MAIN | C16: ='Pigs Cost'!C16 -> 3.0124651e+09 | D16: ='Pigs Cost'!D16 -> 0 | E16: ='Pigs Cost'!E16 -> #REF! | F16: ='Pigs Cost'!F16 -> 0 | G16: ='Pigs Cost'!G16 -> 0 | H16: ='Pigs Cost'!H16 -> 0 | I16: ='Pigs Cost'!I16 -> 0 | J16: ='Pigs Cost'!J16 -> 0 | ... L16: ='Pigs Cost'!L16 -> 0 | M16: =SUM(C16:L16) -> #REF! | N16: ='Pigs Cost'!N16 -> #REF! | O16: ='Pigs Cost'!O16 -> #REF! | P16: ='Pigs Cost'!P16 -> #REF! | Q16: ='[5]PigsMay 07 '!$H37 -> 1.1569961e+11 | R16: =M16+O16+P16+Q16 -> #REF!
A17: SOWS | B17: MAIN | C17: ='Pigs Cost'!C17 -> 7.0513089e+08 | D17: ='Pigs Cost'!D17 -> 0 | E17: ='Pigs Cost'!E17 -> #REF! | F17: ='Pigs Cost'!F17 -> 0 | G17: ='Pigs Cost'!G17 -> 0 | H17: ='Pigs Cost'!H17 -> 0 | I17: ='Pigs Cost'!I17 -> 0 | J17: ='Pigs Cost'!J17 -> 0 | ... L17: ='Pigs Cost'!L17 -> 0 | M17: =SUM(C17:L17) -> #REF! | N17: ='Pigs Cost'!N17 -> #REF! | O17: ='Pigs Cost'!O17 -> #REF! | P17: ='Pigs Cost'!P17 -> #REF! | Q17: ='[5]PigsMay 07 '!$H38 -> 5.0044882e+11 | R17: =M17+O17+P17+Q17 -> #REF!
A18: BOARS | B18: AI | C18: ='Pigs Cost'!C18 -> 109058.54 | D18: ='Pigs Cost'!D18 -> 0 | E18: ='Pigs Cost'!E18 -> #REF! | F18: ='Pigs Cost'!F18 -> 0 | G18: ='Pigs Cost'!G18 -> 0 | H18: ='Pigs Cost'!H18 -> 0 | I18: ='Pigs Cost'!I18 -> 0 | J18: ='Pigs Cost'!J18 -> 0 | ... L18: ='Pigs Cost'!L18 -> 0 | M18: =SUM(C18:L18) -> #REF! | N18: ='Pigs Cost'!N18 -> #REF! | O18: ='Pigs Cost'!O18 -> #REF! | P18: ='Pigs Cost'!P18 -> #REF! | Q18: ='[5]PigsMay 07 '!$H39 -> 1.6625728e+10 | R18: =M18+O18+P18+Q18 -> #REF!
A19: TOTAL | C19: =SUM(C13:C18) -> 4.1104419e+11 | D19: =SUM(D13:D18) -> 0 | E19: =SUM(E13:E18) -> #REF! | F19: =SUM(F13:F18) -> 0 | G19: =SUM(G13:G18) -> #REF! | H19: =SUM(H13:H18) -> #REF! | I19: =SUM(I13:I18) -> 0 | J19: =SUM(J13:J18) -> #REF! | ... R19: =SUM(R13:R18) -> #REF! | S19: =R19-'[5]PigsMay 07 '!$G$40 -> #REF! | T19: =Q19-'[5]PigsMay 07 '!$H$40 -> 0
N20: =N19-'Pigs Cost'!N19 -> #REF! | Q20: =Q19-'[5]PigsMay 07 '!$H$40 -> 0
L21: =+(G19+H19+I19+K19+L19+J19+F19)-J107 -> #REF!
A22: SITE: | B22: TRADE WINDS
A24: DESCRIPTION | B24: SITE | C24: OPENING | D24: PIG PURCHASES | E24: TRANSFER IN | F24: A I CONSUMMABLES | G24: BEDDING AND CONSUMMABLES | H24: CONSULTANCY FEES | I24: DIRECT STAFF COSTS | J24: STOCK FEED | K24: SUNDRY TOOLS | L24: VETERINARY | M24: TOTAL COST | N24: AVERAGE COST | O24: TRANSFER OUT | P24: SALES | Q24: IAS 41 ADJ. | R24: CLOSING
A25: PIGLETS | B25: MAIN | C25: ='Pigs Cost'!C25 -> 0 | D25: ='Pigs Cost'!D25 -> 0 | E25: ='Pigs Cost'!E25 -> #REF! | F25: ='Pigs Cost'!F25 -> 0 | G25: ='Pigs Cost'!G25 -> #REF! | H25: ='Pigs Cost'!H25 -> #REF! | I25: ='Pigs Cost'!I25 -> #REF! | J25: ='Pigs Cost'!J25 -> #REF! | ... L25: ='Pigs Cost'!L25 -> #REF! | M25: =SUM(C25:L25) -> #REF! | N25: ='Pigs Cost'!N25 -> 0 | O25: ='Pigs Cost'!O25 -> #REF! | P25: ='Pigs Cost'!P25 -> #REF! | Q25: ='[5]Outgrower pigs Sept07 TRADE WIN'!$H34 -> 0 | R25: =M25+O25+P25+Q25 -> #REF!
A26: WEANERS | B26: WEANER | C26: ='Pigs Cost'!C26 -> 0 | D26: ='Pigs Cost'!D26 -> 0 | E26: ='Pigs Cost'!E26 -> 0 | F26: ='Pigs Cost'!F26 -> 0 | G26: ='Pigs Cost'!G26 -> #REF! | H26: ='Pigs Cost'!H26 -> #REF! | I26: ='Pigs Cost'!I26 -> #REF! | J26: ='Pigs Cost'!J26 -> #REF! | ... L26: ='Pigs Cost'!L26 -> 0 | M26: =SUM(C26:L26) -> #REF! | N26: ='Pigs Cost'!N26 -> 0 | O26: ='Pigs Cost'!O26 -> #REF! | P26: ='Pigs Cost'!P26 -> #REF! | Q26: ='[5]Outgrower pigs Sept07 TRADE WIN'!$H35 -> 8.8755496e+10 | R26: =M26+O26+P26+Q26 -> #REF!
A27: GROWERS | B27: GROWER | C27: ='Pigs Cost'!C27 -> 1.4341696e+10 | D27: ='Pigs Cost'!D27 -> 0 | E27: ='Pigs Cost'!E27 -> #REF! | F27: ='Pigs Cost'!F27 -> 0 | G27: ='Pigs Cost'!G27 -> #REF! | H27: ='Pigs Cost'!H27 -> #REF! | I27: ='Pigs Cost'!I27 -> #REF! | J27: ='Pigs Cost'!J27 -> #REF! | ... L27: ='Pigs Cost'!L27 -> #REF! | M27: =SUM(C27:L27) -> #REF! | N27: ='Pigs Cost'!N27 -> #REF! | O27: ='Pigs Cost'!O27 -> #REF! | P27: ='Pigs Cost'!P27 -> #REF! | Q27: ='[5]Outgrower pigs Sept07 TRADE WIN'!$H36 -> 1.0256305e+11 | R27: =M27+O27+P27+Q27 -> #REF!
A28: GILTS | B28: MAIN | C28: ='Pigs Cost'!C28 -> 0 | D28: ='Pigs Cost'!D28 -> 0 | E28: ='Pigs Cost'!E28 -> #REF! | F28: ='Pigs Cost'!F28 -> 0 | G28: ='Pigs Cost'!G28 -> 0 | H28: ='Pigs Cost'!H28 -> 0 | I28: ='Pigs Cost'!I28 -> 0 | J28: ='Pigs Cost'!J28 -> 0 | ... L28: ='Pigs Cost'!L28 -> 0 | N28: ='Pigs Cost'!N28 -> 0 | O28: ='Pigs Cost'!O28 -> #REF! | P28: ='Pigs Cost'!P28 -> #REF! | Q28: ='[5]Outgrower pigs Sept07 TRADE WIN'!$H37 -> 0 | R28: =M28+O28+P28+Q28 -> #REF!
A29: SOWS | B29: MAIN | C29: ='Pigs Cost'!C29 -> 0 | D29: ='Pigs Cost'!D29 -> 0 | E29: ='Pigs Cost'!E29 -> 0 | F29: ='Pigs Cost'!F29 -> 0 | G29: ='Pigs Cost'!G29 -> 0 | H29: ='Pigs Cost'!H29 -> #REF! | I29: ='Pigs Cost'!I29 -> 0 | J29: ='Pigs Cost'!J29 -> 0 | ... L29: ='Pigs Cost'!L29 -> 0 | M29: =SUM(C29:L29) -> #REF! | N29: ='Pigs Cost'!N29 -> 0 | O29: ='Pigs Cost'!O29 -> #REF! | P29: ='Pigs Cost'!P29 -> #REF! | Q29: ='[5]Outgrower pigs Sept07 TRADE WIN'!$H38 -> 0 | R29: =M29+O29+P29+Q29 -> #REF!
A30: BOARS | C30: ='Pigs Cost'!C30 -> 0 | D30: ='Pigs Cost'!D30 -> 0 | E30: ='Pigs Cost'!E30 -> #REF! | F30: ='Pigs Cost'!F30 -> 0 | G30: ='Pigs Cost'!G30 -> 0 | H30: ='Pigs Cost'!H30 -> 0 | I30: ='Pigs Cost'!I30 -> 0 | J30: ='Pigs Cost'!J30 -> 0 | ... L30: ='Pigs Cost'!L30 -> 0 | M30: =SUM(C30:L30) -> #REF! | N30: ='Pigs Cost'!N30 -> 0 | O30: ='Pigs Cost'!O30 -> #REF! | P30: ='Pigs Cost'!P30 -> 0 | Q30: ='[5]Outgrower pigs Sept07 TRADE WIN'!$H39 -> 0 | R30: =SUM(C30:L30) -> #REF!
A31: TOTAL | C31: =SUM(C25:C30) -> 1.4341696e+10 | D31: =SUM(D25:D30) -> 0 | E31: =SUM(E25:E29) -> #REF! | F31: =SUM(F25:F30) -> 0 | G31: =SUM(G25:G30) -> #REF! | H31: =SUM(H25:H30) -> #REF! | I31: =SUM(I25:I30) -> #REF! | J31: =SUM(J25:J30) -> #REF! | K31: =SUM(K25:K30) -> #REF! | L31: =SUM(L25:L30) -> #REF! | M31: =SUM(M25:M30) -> #REF! | ... R31: =SUM(R25:R30) -> #REF! | S31: ='[5]Outgrower pigs Sept07 TRADE WIN'!$G$40-R31 -> #REF! | T31: =Q31-'[5]Outgrower pigs Sept07 TRADE WIN'!$H$40 -> 0
A34: SITE: | B34: ZIMBO
A36: DESCRIPTION | B36: SITE | C36: OPENING | D36: PIG PURCHASES | E36: TRANSFER IN | F36: A I CONSUMMABLES | G36: BEDDING AND CONSUMMABLES | H36: CONSULTANCY FEES | I36: DIRECT STAFF COSTS | J36: STOCK FEED | K36: SUNDRY TOOLS | L36: VETERINARY | M36: TOTAL COST | N36: AVERAGE COST | O36: TRANSFER OUT | P36: SALES | Q36: IAS 41 ADJ. | R36: CLOSING
A37: PIGLETS | B37: MAIN | C37: ='Pigs Cost'!C37 -> 3.1052778e+09 | D37: ='Pigs Cost'!D37 -> 0 | E37: ='Pigs Cost'!E37 -> 0 | F37: ='Pigs Cost'!F37 -> #REF! | G37: ='Pigs Cost'!G37 -> 0 | H37: ='Pigs Cost'!H37 -> 0 | I37: ='Pigs Cost'!I37 -> 0 | J37: ='Pigs Cost'!J37 -> 1.4288071e+12 | ... L37: ='Pigs Cost'!L37 -> 0 | M37: =SUM(C37:L37) -> #REF! | N37: ='Pigs Cost'!N37 -> #REF! | O37: ='Pigs Cost'!O37 -> #REF! | P37: ='Pigs Cost'!P37 -> #REF! | Q37: ='[5]Outgrower pigs Sept 07 ZIMBO'!$H34 -> 1.7778681e+10 | R37: =M37+O37+P37+Q37 -> #REF!
A38: WEANERS | B38: WEANER | C38: ='Pigs Cost'!C38 -> 0 | D38: ='Pigs Cost'!D38 -> 0 | E38: ='Pigs Cost'!E38 -> 0 | F38: ='Pigs Cost'!F38 -> #REF! | G38: ='Pigs Cost'!G38 -> 0 | H38: ='Pigs Cost'!H38 -> 0 | I38: ='Pigs Cost'!I38 -> 0 | J38: ='Pigs Cost'!J38 -> 1.471066e+12 | ... L38: ='Pigs Cost'!L38 -> 0 | M38: =SUM(C38:L38) -> #REF! | N38: ='Pigs Cost'!N38 -> 0 | O38: ='Pigs Cost'!O38 -> 0 | P38: ='Pigs Cost'!P38 -> #REF! | Q38: ='[5]Outgrower pigs Sept 07 ZIMBO'!$H35 -> 3.4863215e+10 | R38: =M38+O38+P38+Q38 -> #REF!
A39: GROWERS | B39: GROWER | C39: ='Pigs Cost'!C39 -> -5.9604645e-18 | D39: ='Pigs Cost'!D39 -> 0 | E39: ='Pigs Cost'!E39 -> 0 | F39: ='Pigs Cost'!F39 -> #REF! | G39: ='Pigs Cost'!G39 -> 0 | H39: ='Pigs Cost'!H39 -> 0 | I39: ='Pigs Cost'!I39 -> 0 | J39: ='Pigs Cost'!J39 -> 2.8001269e+12 | ... L39: ='Pigs Cost'!L39 -> 0 | M39: =SUM(C39:L39) -> #REF! | N39: ='Pigs Cost'!N39 -> 0 | O39: ='Pigs Cost'!O39 -> 0 | P39: ='Pigs Cost'!P39 -> #REF! | Q39: ='[5]Outgrower pigs Sept 07 ZIMBO'!$H36 -> 0 | R39: =M39+O39+P39+Q39 -> #REF!
A40: GILTS | B40: MAIN | C40: ='Pigs Cost'!C40 -> 0 | D40: ='Pigs Cost'!D40 -> 0 | E40: ='Pigs Cost'!E40 -> #REF! | F40: ='Pigs Cost'!F40 -> #REF! | G40: ='Pigs Cost'!G40 -> 0 | H40: ='Pigs Cost'!H40 -> 0 | I40: ='Pigs Cost'!I40 -> 0 | J40: ='Pigs Cost'!J40 -> 0 | ... L40: ='Pigs Cost'!L40 -> 0 | M40: =SUM(C40:L40) -> #REF! | N40: ='Pigs Cost'!N40 -> #REF! | O40: ='Pigs Cost'!O40 -> #REF! | P40: ='Pigs Cost'!P40 -> #REF! | Q40: ='[5]Outgrower pigs Sept 07 ZIMBO'!$H37 -> 1.0013995e+09 | R40: =M40+O40+P40+Q40 -> #REF!
A41: SOWS | B41: MAIN | C41: ='Pigs Cost'!C41 -> 146128.33 | D41: ='Pigs Cost'!D41 -> 0 | E41: ='Pigs Cost'!E41 -> #REF! | F41: ='Pigs Cost'!F41 -> #REF! | G41: ='Pigs Cost'!G41 -> 0 | H41: ='Pigs Cost'!H41 -> 0 | I41: ='Pigs Cost'!I41 -> 0 | J41: ='Pigs Cost'!J41 -> 0 | ... L41: ='Pigs Cost'!L41 -> 0 | M41: =SUM(C41:L41) -> #REF! | N41: ='Pigs Cost'!N41 -> #REF! | O41: ='Pigs Cost'!O41 -> #REF! | P41: ='Pigs Cost'!P41 -> #REF! | Q41: ='[5]Outgrower pigs Sept 07 ZIMBO'!$H38 -> 9.4184319e+10 | R41: =M41+O41+P41+Q41 -> #REF!
A42: BOARS | C42: ='Pigs Cost'!C42 -> 0.013277874 | D42: ='Pigs Cost'!D42 -> 0 | E42: ='Pigs Cost'!E42 -> 0 | F42: ='Pigs Cost'!F42 -> 0 | G42: ='Pigs Cost'!G42 -> 0 | H42: ='Pigs Cost'!H42 -> 0 | I42: ='Pigs Cost'!I42 -> 0 | J42: ='Pigs Cost'!J42 -> 0 | ... L42: ='Pigs Cost'!L42 -> 0 | M42: =SUM(C42:L42) -> 0.013277874 | N42: ='Pigs Cost'!N42 -> #REF! | O42: ='Pigs Cost'!O42 -> #REF! | P42: ='Pigs Cost'!P42 -> #REF! | Q42: ='[5]Outgrower pigs Sept 07 ZIMBO'!$H39 -> 1.1299301e+09 | R42: =M42+O42+P42+Q42 -> #REF!
A43: TOTAL | C43: =SUM(C37:C42) -> 3.1054239e+09 | D43: =SUM(D37:D42) -> 0 | E43: =SUM(E37:E41) -> #REF! | F43: =SUM(F37:F42) -> #REF! | G43: =SUM(G37:G42) -> 0 | H43: =SUM(H37:H42) -> 0 | I43: =SUM(I37:I42) -> 0 | J43: =SUM(J37:J42) -> 5700000000000 | K43: =SUM(K37:K42) -> 0 | L43: =SUM(L37:L42) -> 0 | M43: =SUM(M37:M42) -> #REF! | ... R43: =SUM(R37:R42) -> #REF! | S43: =R43-'[5]Outgrower pigs Sept 07 ZIMBO'!$G$40 -> #REF! | T43: =Q43-'[5]Outgrower pigs Sept 07 ZIMBO'!$H$40 -> 0
Q44: =Q43-'[5]Outgrower pigs Sept 07 ZIMBO'!$H$40 -> 0
L45: =+(G43+H43+I43+K43+L43+J43)-H107 -> 5699980512623
L48: =+(L43+K43+J43+I43+H43+G43+F43)-H107 -> #REF!
A49: SITE: | B49: ROGATE
A51: DESCRIPTION | B51: SITE | C51: OPENING | D51: PIG PURCHASES | E51: TRANSFER IN | F51: A I CONSUMMABLES | G51: BEDDING AND CONSUMMABLES | H51: CONSULTANCY FEES | I51: DIRECT STAFF COSTS | J51: STOCK FEED | K51: SUNDRY TOOLS | L51: VETERINARY | M51: TOTAL COST | N51: AVERAGE COST | O51: TRANSFER OUT | P51: SALES | Q51: IAS 41 ADJ. | R51: CLOSING
A52: PIGLETS | B52: MAIN | C52: ='Pigs Cost'!C52 -> 1.7388984e+10 | D52: ='Pigs Cost'!D52 -> 0 | E52: ='Pigs Cost'!E52 -> #REF! | F52: ='Pigs Cost'!F52 -> 0 | G52: ='Pigs Cost'!G52 -> 0 | H52: ='Pigs Cost'!H52 -> 0 | I52: ='Pigs Cost'!I52 -> 0 | J52: ='Pigs Cost'!J52 -> 3.7202398e+12 | ... L52: ='Pigs Cost'!L52 -> 0 | M52: =SUM(C52:L52) -> #REF! | N52: ='Pigs Cost'!N52 -> #REF! | O52: ='Pigs Cost'!O52 -> #REF! | P52: ='Pigs Cost'!P52 -> 0 | Q52: ='[5]Outgrower pigs Sept 07 ROGATE'!$H34 -> 2.460632e+10 | R52: =M52+O52+P52+Q52 -> #REF!
A53: WEANERS | B53: WEANER | C53: ='Pigs Cost'!C53 -> 3.8118878e+09 | D53: ='Pigs Cost'!D53 -> 0 | E53: ='Pigs Cost'!E53 -> #REF! | F53: ='Pigs Cost'!F53 -> 0 | G53: ='Pigs Cost'!G53 -> 0 | H53: ='Pigs Cost'!H53 -> 0 | I53: ='Pigs Cost'!I53 -> 0 | J53: ='Pigs Cost'!J53 -> 2.3306964e+12 | ... L53: ='Pigs Cost'!L53 -> 0 | M53: =SUM(C53:L53) -> #REF! | N53: ='Pigs Cost'!N53 -> #REF! | O53: ='Pigs Cost'!O53 -> #REF! | P53: ='Pigs Cost'!P53 -> 0 | Q53: ='[5]Outgrower pigs Sept 07 ROGATE'!$H35 -> 9.9324083e+10 | R53: =M53+O53+P53+Q53 -> #REF!
...

Sheet Pigs Cost
A1: COLCOM HOLDINGS LIMITED
T2: =+'Summary Total Pigs'!C3 -> 46226
A3: TRIPLE C PIGS
A5: LIVESTOCK ANALYSIS SCHEDULE
A7: COST
A10: SITE: | B10: GRASMERE FARM
A12: DESCRIPTION | B12: SITE | C12: OPENING | D12: PIG PURCHASES | E12: TRANSFER IN | F12: A I CONSUMMABLES | G12: BEDDING AND CONSUMMABLES | H12: CONSULTANCY FEES | I12: DIRECT STAFF COSTS | J12: STOCK FEED | K12: SUNDRY TOOLS | L12: VETERINARY | M12: TOTAL COST | N12: AVERAGE COST | O12: TRANSFER OUT | P12: SALES | Q12: ='Summary Total Pigs'!#REF! -> #REF! | R12: CULLS | S12: STOCK ADJMNT | T12: CLOSING
A13: PIGLETS | B13: MAIN | C13: ='[16]Pigs Cost'!$T13 -> 7.6193293e+10 | F13: =E170 -> 0 | G13: =('Summary Total Pigs'!AE12+'Summary Total Pigs'!AE15+'Summary Total Pigs'!AE16+'Summary Total Pigs'!AE17)/'Summary Total Pigs'!#REF!*'Pigs Cost'!E171 -> #REF! | H13: =('Summary Total Pigs'!AE12+'Summary Total Pigs'!AE15+'Summary Total Pigs'!AE16+'Summary Total Pigs'!AE17)/'Summary Total Pigs'!#REF!*'Pigs Cost'!E172 -> #REF! | I13: =E173/3 -> 0 | J13: =('Summary Total Pigs'!AE12+'Summary Total Pigs'!AE15+'Summary Total Pigs'!AE16+'Summary Total Pigs'!AE17)/'Summary Total Pigs'!#REF!*'Pigs Cost'!J174 -> #REF! | K13: =('Summary Total Pigs'!AE12+'Summary Total Pigs'!AE15+'Summary Total Pigs'!AE16+'Summary Total Pigs'!AE17)/'Summary Total Pigs'!#REF!*'Pigs Cost'!E175 -> #REF! | L13: =('Summary Total Pigs'!AE12+'Summary Total Pigs'!AE15+'Summary Total Pigs'!AE16+'Summary Total Pigs'!AE17)/'Summary Total Pigs'!#REF!*'Pigs Cost'!J176 -> #REF! | M13: =SUM(C13:L13) -> #REF! | N13: =M13/'Summary Total Pigs'!#REF! -> #REF! | O13: =N13*'Summary Total Pigs'!#REF! -> #REF! | P13: =N13*'Summary Total Pigs'!X12 -> #REF! | Q13: ='Summary Total Pigs'!#REF!*'Pigs Cost'!N13 -> #REF! | R13: =N13*'Summary Total Pigs'!Z12 -> #REF! | S13: ='Summary Total Pigs'!#REF!*'Pigs Cost'!N13 -> #REF! | T13: =M13+O13+P13+R13+S13+Q13 -> #REF! | V13: =[17]Sheet1!$E163 -> 2.2668926e+08 | W13: =T13-V13 -> #REF!
A14: WEANERS | B14: WEANER | C14: ='[16]Pigs Cost'!$T14 -> 1.0410751e+11 | E14: ='Summary Total Pigs'!D13*N13 -> #REF! | G14: ='Summary Total Pigs'!AE13/'Summary Total Pigs'!#REF!*'Pigs Cost'!E171 -> #REF! | H14: ='Summary Total Pigs'!AE13/'Summary Total Pigs'!#REF!*'Pigs Cost'!E172 -> #REF! | I14: =I13 -> 0 | J14: ='Summary Total Pigs'!AE13/'Summary Total Pigs'!#REF!*'Pigs Cost'!J174 -> #REF! | K14: =('Summary Total Pigs'!AE13)/'Summary Total Pigs'!#REF!*'Pigs Cost'!E175 -> #REF! | L14: ='Summary Total Pigs'!AE13/'Summary Total Pigs'!#REF!*'Pigs Cost'!J176 -> #REF! | M14: =SUM(C14:L14) -> #REF! | N14: =M14/'Summary Total Pigs'!#REF! -> #REF! | O14: =N14*'Summary Total Pigs'!#REF! -> #REF! | P14: =N14*'Summary Total Pigs'!X13 -> #REF! | Q14: ='Summary Total Pigs'!#REF!*'Pigs Cost'!N14 -> #REF! | R14: =N14*'Summary Total Pigs'!Z13 -> #REF! | S14: ='Summary Total Pigs'!#REF!*'Pigs Cost'!N14 -> #REF! | T14: =M14+O14+P14+R14+S14+Q14 -> #REF! | V14: =[17]Sheet1!$E164 -> 2.6090144e+08 | W14: =T14-V14 -> #REF!
A15: GROWERS | B15: GROWER | C15: ='[16]Pigs Cost'!$T15 -> 2.2702568e+11 | E15: =3838*N14+19*N16 -> #REF! | G15: ='Summary Total Pigs'!AE14/'Summary Total Pigs'!#REF!*'Pigs Cost'!E171 -> #REF! | H15: ='Summary Total Pigs'!AE14/'Summary Total Pigs'!#REF!*'Pigs Cost'!E172 -> #REF! | I15: =I14 -> 0 | J15: ='Summary Total Pigs'!AE14/'Summary Total Pigs'!#REF!*'Pigs Cost'!J174 -> #REF! | K15: =('Summary Total Pigs'!AE14)/'Summary Total Pigs'!#REF!*'Pigs Cost'!E175 -> #REF! | L15: ='Summary Total Pigs'!AE14/'Summary Total Pigs'!#REF!*'Pigs Cost'!J176 -> #REF! | M15: =SUM(C15:L15) -> #REF! | N15: =M15/'Summary Total Pigs'!#REF! -> #REF! | O15: =N15*'Summary Total Pigs'!#REF! -> #REF! | P15: =N15*'Summary Total Pigs'!X14 -> #REF! | Q15: ='Summary Total Pigs'!#REF!*'Pigs Cost'!N15 -> #REF! | R15: =N15*'Summary Total Pigs'!Z14 -> #REF! | S15: ='Summary Total Pigs'!#REF!*'Pigs Cost'!N15 -> #REF! | T15: =M15+O15+P15+R15+S15+Q15 -> #REF! | V15: =[17]Sheet1!$E165 -> 5.2935144e+08 | W15: =T15-V15 -> #REF!
A16: GILTS | B16: MAIN | C16: ='[16]Pigs Cost'!$T16 -> 3.0124651e+09 | D16: 0 | E16: =N13*'Summary Total Pigs'!D15 -> #REF! | G16: 0 | H16: 0 | I16: 0 | J16: 0 | K16: 0 | L16: 0 | M16: =SUM(C16:L16) -> #REF! | N16: =M16/'Summary Total Pigs'!#REF! -> #REF! | O16: =N16*'Summary Total Pigs'!#REF! -> #REF! | P16: ='Summary Total Pigs'!X15*'Pigs Cost'!N16 -> #REF! | Q16: ='Summary Total Pigs'!#REF!*'Pigs Cost'!N16 -> #REF! | R16: =N16*'Summary Total Pigs'!Z15 -> #REF! | S16: ='Summary Total Pigs'!#REF!*'Pigs Cost'!N16 -> #REF! | T16: =M16+O16+P16+R16+S16+Q16 -> #REF! | V16: =[17]Sheet1!$E166 -> 13324897 | W16: =T16-V16 -> #REF!
A17: SOWS | B17: MAIN | C17: ='[16]Pigs Cost'!$T17 -> 7.0513089e+08 | E17: ='Summary Total Pigs'!D16*N16 -> #REF! | G17: 0 | H17: 0 | I17: =I16 -> 0 | J17: 0 | K17: 0 | L17: 0 | M17: =SUM(C17:L17) -> #REF! | N17: =M17/'Summary Total Pigs'!#REF! -> #REF! | O17: =N17*'Summary Total Pigs'!#REF! -> #REF! | P17: =N17*'Summary Total Pigs'!X16 -> #REF! | Q17: ='Summary Total Pigs'!#REF!*'Pigs Cost'!N17 -> #REF! | R17: =N17*'Summary Total Pigs'!Z16 -> #REF! | S17: ='Summary Total Pigs'!#REF!*'Pigs Cost'!N17 -> #REF! | T17: =M17+O17+P17+R17+S17+Q17 -> #REF! | V17: =[17]Sheet1!$E167 -> 792833.6 | W17: =T17-V17 -> #REF!
A18: BOARS | B18: AI | C18: ='[16]Pigs Cost'!$T18 -> 109058.54 | E18: ='Summary Total Pigs'!D17*N15 -> #REF! | F18: 0 | G18: 0 | H18: 0 | I18: =I17 -> 0 | J18: 0 | K18: 0 | L18: 0 | M18: =SUM(C18:L18) -> #REF! | N18: =M18/'Summary Total Pigs'!#REF! -> #REF! | O18: =N18*'Summary Total Pigs'!#REF! -> #REF! | P18: =N18*'Summary Total Pigs'!X17 -> #REF! | Q18: ='Summary Total Pigs'!#REF!*'Pigs Cost'!N18 -> #REF! | R18: =N18*'Summary Total Pigs'!Z17 -> #REF! | S18: ='Summary Total Pigs'!#REF!*'Pigs Cost'!N18 -> #REF! | T18: =M18+O18+P18+R18+S18+Q18 -> #REF! | V18: =[17]Sheet1!$E168 -> 109058.54 | W18: =T18-V18 -> #REF!
A19: TOTAL | C19: =SUM(C13:C18) -> 4.1104419e+11 | D19: =SUM(D13:D18) -> 0 | E19: =SUM(E13:E18) -> #REF! | F19: =SUM(F13:F18) -> 0 | G19: =SUM(G13:G18) -> #REF! | H19: =SUM(H13:H18) -> #REF! | I19: =SUM(I13:I18) -> 0 | J19: =SUM(J13:J18) -> #REF! | ... T19: =SUM(T13:T18) -> #REF! | V19: =SUM(V13:V18) -> 1.0311689e+09 | W19: =T19-V19 -> #REF!
E20: =E19+O19 -> #REF! | F20: =F19-E170 -> 0 | G20: =G19-E171 -> #REF! | H20: =H19-E172 -> #REF! | I20: =I19-E173 -> 0 | J20: =J19-J174 -> #REF! | K20: =K19-E175 -> #REF! | L20: =L19-E176 -> #REF! | V20: =C20/$B$178 -> 0
E21: =E20+Sheet1!C14 -> #REF! | L21: =+(G19+H19+I19+K19+L19+J19+F19)-J178 -> #REF! | V21: =C21/$B$178 -> 0
A22: SITE: | B22: TRADE WINDS | V22: =C22/$B$178 -> 0
V23: =C23/$B$178 -> 0
A24: DESCRIPTION | B24: SITE | C24: =+C12 -> OPENING | D24: PIG PURCHASES | E24: TRANSFER IN | F24: A I CONSUMMABLES | G24: BEDDING AND CONSUMMABLES | H24: CONSULTANCY FEES | I24: DIRECT STAFF COSTS | J24: STOCK FEED | K24: SUNDRY TOOLS | L24: VETERINARY | M24: TOTAL COST | N24: AVERAGE COST | O24: TRANSFER OUT | P24: SALES | Q24: ='Summary Total Pigs'!#REF! -> #REF! | R24: =R12 -> CULLS | S24: =+S12 -> STOCK ADJMNT | T24: CLOSING
A25: PIGLETS | B25: MAIN | C25: ='[16]Pigs Cost'!$T25 -> 0 | E25: ='Summary Total Pigs'!#REF!*N23 -> #REF! | G25: =('Summary Total Pigs'!#REF!+'Summary Total Pigs'!#REF!)/'Summary Total Pigs'!#REF!*$G$171 -> #REF! | H25: =('Summary Total Pigs'!#REF!+'Summary Total Pigs'!#REF!)/'Summary Total Pigs'!#REF!*'Pigs Cost'!$G$172 -> #REF! | I25: =('Summary Total Pigs'!#REF!+'Summary Total Pigs'!#REF!)/'Summary Total Pigs'!#REF!*'Pigs Cost'!$G$173 -> #REF! | J25: =('Summary Total Pigs'!#REF!+'Summary Total Pigs'!#REF!)/'Summary Total Pigs'!#REF!*'Pigs Cost'!$G$174 -> #REF! | K25: =('Summary Total Pigs'!#REF!/'Summary Total Pigs'!#REF!)*'Pigs Cost'!$G$175 -> #REF! | L25: =('Summary Total Pigs'!#REF!+'Summary Total Pigs'!#REF!)/'Summary Total Pigs'!#REF!*G176 -> #REF! | M25: =SUM(C25:L25) -> #REF! | N25: 0 | O25: =N25*'Summary Total Pigs'!#REF! -> #REF! | P25: =N25*'Summary Total Pigs'!#REF! -> #REF! | Q25: ='Summary Total Pigs'!#REF!*'Pigs Cost'!N25 -> #REF! | R25: =N25*'Summary Total Pigs'!#REF! -> #REF! | S25: ='Summary Total Pigs'!#REF!*'Pigs Cost'!N25 -> #REF! | T25: =M25+O25+P25+R25+S25+Q25 -> #REF! | V25: =C25/$B$178 -> 0
A26: WEANERS | B26: WEANER | C26: ='[16]Pigs Cost'!$T26 -> 0 | E26: 0 | G26: =('Summary Total Pigs'!#REF!)/'Summary Total Pigs'!#REF!*$G$171 -> #REF! | H26: =('Summary Total Pigs'!#REF!)/'Summary Total Pigs'!#REF!*'Pigs Cost'!G172 -> #REF! | I26: =('Summary Total Pigs'!#REF!)/'Summary Total Pigs'!#REF!*'Pigs Cost'!$G$173 -> #REF! | J26: =('Summary Total Pigs'!#REF!)/'Summary Total Pigs'!#REF!*'Pigs Cost'!$G$174 -> #REF! | K26: =('Summary Total Pigs'!#REF!/'Summary Total Pigs'!#REF!)*'Pigs Cost'!$G$175 -> #REF! | M26: =SUM(C26:L26) -> #REF! | N26: 0 | O26: =N26*'Summary Total Pigs'!#REF! -> #REF! | P26: =N26*'Summary Total Pigs'!#REF! -> #REF! | Q26: ='Summary Total Pigs'!#REF!*'Pigs Cost'!N26 -> #REF! | R26: =N26*'Summary Total Pigs'!#REF! -> #REF! | S26: ='Summary Total Pigs'!#REF!*'Pigs Cost'!N26 -> #REF! | T26: =M26+O26+P26+R26+S26+Q26 -> #REF! | V26: =C26/$B$178 -> 0
A27: GROWERS | B27: GROWER | C27: ='[16]Pigs Cost'!$T27 -> 1.4341696e+10 | E27: =N101*'Summary Total Pigs'!#REF! -> #REF! | G27: =('Summary Total Pigs'!#REF!)/'Summary Total Pigs'!#REF!*$G$171 -> #REF! | H27: =('Summary Total Pigs'!#REF!)/'Summary Total Pigs'!#REF!*'Pigs Cost'!$G$172 -> #REF! | I27: =('Summary Total Pigs'!#REF!)/'Summary Total Pigs'!#REF!*'Pigs Cost'!$G$173 -> #REF! | J27: =('Summary Total Pigs'!#REF!)/'Summary Total Pigs'!#REF!*'Pigs Cost'!$G$174 -> #REF! | K27: =('Summary Total Pigs'!#REF!/'Summary Total Pigs'!#REF!)*'Pigs Cost'!$G$175 -> #REF! | L27: ='Summary Total Pigs'!#REF!/'Summary Total Pigs'!#REF!*G176 -> #REF! | M27: =SUM(C27:L27) -> #REF! | N27: =M27/'Summary Total Pigs'!#REF! -> #REF! | O27: =N27*'Summary Total Pigs'!#REF! -> #REF! | P27: =N27*'Summary Total Pigs'!#REF! -> #REF! | Q27: ='Summary Total Pigs'!#REF!*'Pigs Cost'!N27 -> #REF! | R27: =N27*'Summary Total Pigs'!#REF! -> #REF! | S27: ='Summary Total Pigs'!#REF!*'Pigs Cost'!N27 -> #REF! | T27: =M27+O27+P27+R27+S27+Q27 -> #REF! | V27: =[17]Sheet1!$O$165 -> 35912726 | W27: =T27-V27 -> #REF!
A28: GILTS | B28: MAIN | C28: ='[16]Pigs Cost'!$T28 -> 0 | E28: ='Summary Total Pigs'!#REF!*N26 -> #REF! | K28: =('Summary Total Pigs'!#REF!/'Summary Total Pigs'!#REF!)*'Pigs Cost'!$G$175 -> #REF! | M28: 0 | O28: =N28*'Summary Total Pigs'!#REF! -> #REF! | P28: =N28*'Summary Total Pigs'!#REF! -> #REF! | Q28: ='Summary Total Pigs'!#REF!*'Pigs Cost'!N28 -> #REF! | R28: =N28*'Summary Total Pigs'!#REF! -> #REF! | S28: ='Summary Total Pigs'!#REF!*'Pigs Cost'!N28 -> #REF! | T28: =M28+O28+P28+R28+S28+Q28 -> #REF! | V28: =C28/$B$178 -> 0
A29: SOWS | B29: MAIN | C29: ='[16]Pigs Cost'!$T29 -> 0 | E29: 0 | H29: =('Summary Total Pigs'!#REF!)/'Summary Total Pigs'!#REF!*'Pigs Cost'!$G$172 -> #REF! | K29: =('Summary Total Pigs'!#REF!/'Summary Total Pigs'!#REF!)*'Pigs Cost'!$G$175 -> #REF! | M29: =SUM(C29:L29) -> #REF! | O29: =N29*'Summary Total Pigs'!#REF! -> #REF! | P29: =N29*'Summary Total Pigs'!#REF! -> #REF! | Q29: ='Summary Total Pigs'!#REF!*'Pigs Cost'!N29 -> #REF! | R29: =N29*'Summary Total Pigs'!#REF! -> #REF! | S29: ='Summary Total Pigs'!#REF!*'Pigs Cost'!N29 -> #REF! | T29: =M29+O29+P29+R29+S29+Q29 -> #REF! | V29: =C29/$B$178 -> 0
A30: BOARS | C30: ='[16]Pigs Cost'!$T30 -> 0 | E30: ='Summary Total Pigs'!#REF!*N28 -> #REF! | K30: =('Summary Total Pigs'!#REF!/'Summary Total Pigs'!#REF!)*'Pigs Cost'!$G$175 -> #REF! | M30: =SUM(C30:L30) -> #REF! | O30: =N30*'Summary Total Pigs'!#REF! -> #REF! | Q30: ='Summary Total Pigs'!#REF!*'Pigs Cost'!N30 -> #REF! | R30: =N30*'Summary Total Pigs'!#REF! -> #REF! | S30: ='Summary Total Pigs'!#REF!*'Pigs Cost'!N30 -> #REF! | T30: =M30+O30+P30+R30+S30+Q30 -> #REF! | V30: =C30/$B$178 -> 0
A31: TOTAL | C31: =SUM(C25:C30) -> 1.4341696e+10 | D31: =SUM(D25:D30) -> 0 | E31: =SUM(E25:E30) -> #REF! | F31: =SUM(F25:F30) -> 0 | G31: =SUM(G25:G30) -> #REF! | H31: =SUM(H25:H30) -> #REF! | I31: =SUM(I25:I30) -> #REF! | J31: =SUM(J25:J30) -> #REF! | ... T31: =SUM(T25:T30) -> #REF! | V31: =C31/$B$178 -> 1.4341696
J32: =J31-G174 -> #REF! | K32: =+K31-G175 -> #REF! | V32: =C32/$B$178 -> 0
L33: =+(G31+H31+I31+K31+L31+J31)-G178 -> #REF! | V33: =C33/$B$178 -> 0
A34: SITE: | B34: ZIMBO | V34: =C34/$B$178 -> 0
V35: =C35/$B$178 -> 0
A36: DESCRIPTION | B36: SITE | C36: =+C24 -> OPENING | D36: PIG PURCHASES | E36: TRANSFER IN | F36: A I CONSUMMABLES | G36: BEDDING AND CONSUMMABLES | H36: CONSULTANCY FEES | I36: DIRECT STAFF COSTS | J36: STOCK FEED | K36: SUNDRY TOOLS | L36: VETERINARY | M36: TOTAL COST | N36: AVERAGE COST | O36: TRANSFER OUT | P36: SALES | Q36: ='Summary Total Pigs'!W49 -> Deaths | R36: =R24 -> CULLS | S36: =+S24 -> STOCK ADJMNT | T36: CLOSING
A37: PIGLETS | B37: MAIN | C37: ='[16]Pigs Cost'!$T37 -> 3.1052778e+09 | F37: =+$H$169*'Summary Total Pigs'!#REF!/'Summary Total Pigs'!#REF! -> #REF! | G37: =('Summary Total Pigs'!AE50+'Summary Total Pigs'!AE54)/'Summary Total Pigs'!AE56*'Pigs Cost'!$H$171 -> 0 | H37: =('Summary Total Pigs'!AE50+'Summary Total Pigs'!$AE$54)/'Summary Total Pigs'!$AE$56*'Pigs Cost'!$H$172 -> 0 | I37: =('Summary Total Pigs'!AE50+'Summary Total Pigs'!$AE$54)/'Summary Total Pigs'!$AE$56*'Pigs Cost'!$H$173 -> 0 | J37: =('Summary Total Pigs'!AE50+'Summary Total Pigs'!AE53+'Summary Total Pigs'!AE54+'Summary Total Pigs'!AE55)/'Summary Total Pigs'!$AE$56*'Pigs Cost'!$H$174 -> 1.4288071e+12 | K37: =('Summary Total Pigs'!AE50+'Summary Total Pigs'!$AE$54)/'Summary Total Pigs'!$AE$56*'Pigs Cost'!$H$175 -> 0 | L37: =('Summary Total Pigs'!$AE$50+'Summary Total Pigs'!$AE$54)/'Summary Total Pigs'!$AE$56*'Pigs Cost'!$H$176 -> 0 | M37: =SUM(C37:L37) -> #REF! | N37: =M37/'Summary Total Pigs'!#REF! -> #REF! | O37: ='Summary Total Pigs'!N50*'Pigs Cost'!N37 -> #REF! | P37: =N37*'Summary Total Pigs'!#REF! -> #REF! | Q37: ='Summary Total Pigs'!W50*'Pigs Cost'!N37 -> #REF! | R37: ='Summary Total Pigs'!X50*'Pigs Cost'!N37 -> #REF! | S37: ='Summary Total Pigs'!AD50*'Pigs Cost'!N37 -> #REF! | T37: =M37+O37+P37+R37+S37+Q37 -> #REF! | V37: =[17]Sheet1!$Q163 -> 34479972 | W37: =T37-V37 -> #REF!
A38: WEANERS | B38: WEANER | C38: ='[16]Pigs Cost'!$T38 -> 0 | F38: =+$H$169*'Summary Total Pigs'!#REF!/'Summary Total Pigs'!#REF! -> #REF! | G38: =('Summary Total Pigs'!AE51)/'Summary Total Pigs'!$AE$56*'Pigs Cost'!$H$171 -> 0 | H38: =('Summary Total Pigs'!AE51)/'Summary Total Pigs'!$AE$56*'Pigs Cost'!$H$172 -> 0 | I38: =('Summary Total Pigs'!AE51)/'Summary Total Pigs'!$AE$56*'Pigs Cost'!$H$173 -> 0 | J38: =('Summary Total Pigs'!AE51)/'Summary Total Pigs'!$AE$56*'Pigs Cost'!$H$174 -> 1.471066e+12 | K38: =('Summary Total Pigs'!AE51)/'Summary Total Pigs'!$AE$56*'Pigs Cost'!$H$175 -> 0 | L38: =('Summary Total Pigs'!AE51)/'Summary Total Pigs'!$AE$56*'Pigs Cost'!$H$176 -> 0 | M38: =SUM(C38:L38) -> #REF! | O38: ='Summary Total Pigs'!N51*'Pigs Cost'!N38 -> 0 | P38: =N38*'Summary Total Pigs'!#REF! -> #REF! | Q38: ='Summary Total Pigs'!W51*'Pigs Cost'!N38 -> 0 | R38: ='Summary Total Pigs'!X51*'Pigs Cost'!N38 -> 0 | S38: ='Summary Total Pigs'!AD51*'Pigs Cost'!N38 -> 0 | T38: =M38+O38+P38+R38+S38+Q38 -> #REF! | V38: =[17]Sheet1!$Q164
A39: GROWERS | B39: GROWER | C39: ='[16]Pigs Cost'!$T39 -> -5.9604645e-18 | F39: =+$H$169*'Summary Total Pigs'!#REF!/'Summary Total Pigs'!#REF! -> #REF! | G39: =('Summary Total Pigs'!AE52)/'Summary Total Pigs'!$AE$56*'Pigs Cost'!$H$171 -> 0 | H39: =('Summary Total Pigs'!AE52)/'Summary Total Pigs'!$AE$56*'Pigs Cost'!$H$172 -> 0 | I39: =('Summary Total Pigs'!AE52)/'Summary Total Pigs'!$AE$56*'Pigs Cost'!$H$173 -> 0 | J39: =('Summary Total Pigs'!AE52)/'Summary Total Pigs'!$AE$56*'Pigs Cost'!$H$174 -> 2.8001269e+12 | K39: =('Summary Total Pigs'!AE52)/'Summary Total Pigs'!$AE$56*'Pigs Cost'!$H$175 -> 0 | L39: =('Summary Total Pigs'!AE52)/'Summary Total Pigs'!$AE$56*'Pigs Cost'!$H$176 -> 0 | M39: =SUM(C39:L39) -> #REF! | O39: ='Summary Total Pigs'!N52*'Pigs Cost'!N39 -> 0 | P39: =N39*'Summary Total Pigs'!#REF! -> #REF! | Q39: ='Summary Total Pigs'!W52*'Pigs Cost'!N39 -> 0 | R39: ='Summary Total Pigs'!X52*'Pigs Cost'!N39 -> 0 | S39: ='Summary Total Pigs'!AD52*'Pigs Cost'!N39 -> 0 | T39: =M39+O39+P39+R39+S39+Q39 -> #REF! | V39: =[17]Sheet1!$Q165
A40: GILTS | B40: MAIN | C40: ='[16]Pigs Cost'!$T40 -> 0 | E40: =N66*'Summary Total Pigs'!D53 -> #REF! | F40: =+$H$169*'Summary Total Pigs'!#REF!/'Summary Total Pigs'!#REF! -> #REF! | G40: =('Summary Total Pigs'!AE53)/'Summary Total Pigs'!$AE$56*'Pigs Cost'!$H$171 -> 0 | H40: =('Summary Total Pigs'!AE53)/'Summary Total Pigs'!$AE$56*'Pigs Cost'!$H$172 -> 0 | I40: =('Summary Total Pigs'!AE53)/'Summary Total Pigs'!$AE$56*'Pigs Cost'!$H$173 -> 0 | J40: 0 | K40: =('Summary Total Pigs'!AE53)/'Summary Total Pigs'!$AE$56*'Pigs Cost'!$H$175 -> 0 | L40: =('Summary Total Pigs'!AE53)/'Summary Total Pigs'!$AE$56*'Pigs Cost'!$H$176 -> 0 | M40: =SUM(C40:L40) -> #REF! | N40: =M40/'Summary Total Pigs'!#REF! -> #REF! | O40: ='Summary Total Pigs'!N53*'Pigs Cost'!N40 -> #REF! | P40: =N40*'Summary Total Pigs'!#REF! -> #REF! | Q40: ='Summary Total Pigs'!W53*'Pigs Cost'!N40 -> #REF! | R40: ='Summary Total Pigs'!X53*'Pigs Cost'!N40 -> #REF! | S40: ='Summary Total Pigs'!AD53*'Pigs Cost'!N40 -> #REF! | T40: =M40+O40+P40+R40+S40+Q40 -> #REF! | V40: =[17]Sheet1!$Q166
A41: SOWS | B41: MAIN | C41: ='[16]Pigs Cost'!$T41 -> 146128.33 | E41: =N40*'Summary Total Pigs'!D54 -> #REF! | F41: =+$H$169*'Summary Total Pigs'!#REF!/'Summary Total Pigs'!#REF! -> #REF! | J41: 0 | K41: =('Summary Total Pigs'!AE53)/'Summary Total Pigs'!$AE$56*'Pigs Cost'!$H$175 -> 0 | L41: =H176 -> 0 | M41: =SUM(C41:L41) -> #REF! | N41: =M41/'Summary Total Pigs'!#REF! -> #REF! | O41: ='Summary Total Pigs'!N54*'Pigs Cost'!N41 -> #REF! | P41: =N41*'Summary Total Pigs'!#REF! -> #REF! | Q41: ='Summary Total Pigs'!W54*'Pigs Cost'!N41 -> #REF! | R41: ='Summary Total Pigs'!X54*'Pigs Cost'!N41 -> #REF! | S41: ='Summary Total Pigs'!AD54*'Pigs Cost'!N41 -> #REF! | T41: =M41+O41+P41+R41+S41+Q41 -> #REF! | V41: =[17]Sheet1!$Q167 -> 155612.62 | W41: =T41-V41 -> #REF!
A42: BOARS | C42: ='[16]Pigs Cost'!$T42 -> 0.013277874 | J42: 0 | M42: =SUM(C42:L42) -> 0.013277874 | N42: =M42/'Summary Total Pigs'!#REF! -> #REF! | O42: ='Summary Total Pigs'!N55*'Pigs Cost'!N42 -> #REF! | P42: =N42*'Summary Total Pigs'!#REF! -> #REF! | Q42: ='Summary Total Pigs'!W55*'Pigs Cost'!N42 -> #REF! | R42: ='Summary Total Pigs'!X55*'Pigs Cost'!N42 -> #REF! | S42: ='Summary Total Pigs'!AD55*'Pigs Cost'!N42 -> #REF! | T42: =M42+O42+P42+R42+S42+Q42 -> #REF! | V42: =[17]Sheet1!$Q168
A43: TOTAL | C43: =SUM(C37:C42) -> 3.1054239e+09 | D43: =SUM(D37:D42) -> 0 | E43: =SUM(E37:E42) -> #REF! | F43: =SUM(F37:F42) -> #REF! | G43: =SUM(G37:G42) -> 0 | H43: =SUM(H37:H42) -> 0 | I43: =SUM(I37:I42) -> 0 | J43: =SUM(J37:J42) -> 5700000000000 | ... T43: =SUM(T37:T42) -> #REF! | V43: =SUM(V37:V42) -> 34635585 | W43: =T43-V43 -> #REF!
J44: =J43-H174 -> 0 | P44: 0 | V44: =C44/$B$178 -> 0
L45: =+(G43+H43+I43+K43+L43+J43)-H178 -> 0 | V45: =C45/$B$178 -> 0
...

Sheet IAS 41 Mvmnt Pigs
A1: COLCOM HOLDINGS LIMITED
L2: =+'Pigs Cost'!T2 -> 46226
A3: TRIPLE C PIGS
A5: LIVESTOCK ANALYSIS SCHEDULE
A8: IAS 41 MOVEMENT
A10: SITE: | B10: GRASMERE FARM
A12: DESCRIPTION | B12: SITE | C12: OPENING | D12: TRANSFER IN | E12: TOTAL COST | F12: AVERAGE COST | G12: TRANSFER OUT | H12: SALES | I12: ='Pigs Cost'!Q12 -> #REF! | J12: CULLS | K12: STOCK ADJMNT | L12: SUB TOTAL | M12: CURRENT ADJMNT | N12: CLOSING BAL | O12: CLOSING BAL
A13: PIGLETS | B13: MAIN | C13: ='[16]IAS 41 Mvmnt Pigs'!$N13 -> 1.2957317e+08 | E13: =SUM(C13:D13) -> 1.2957317e+08 | F13: =$E13/'Summary Total Pigs'!#REF! -> #REF! | G13: ='Summary Total Pigs'!#REF!*'IAS 41 Mvmnt Pigs'!F13 -> #REF! | H13: =$F13*'Summary Total Pigs'!$X12 -> #REF! | I13: ='Summary Total Pigs'!#REF!*'IAS 41 Mvmnt Pigs'!F13 -> #REF! | J13: =$F13*'Summary Total Pigs'!$Z12 -> #REF! | K13: ='Summary Total Pigs'!#REF!*'IAS 41 Mvmnt Pigs'!F13 -> #REF! | L13: =E13+G13+H13+J13+K13+I13 -> #REF! | M13: 0 | N13: =+L13+M13 -> #REF! | O13: =[17]Sheet1!$E169 -> 2.8784866e+08 | P13: =N13-O13 -> #REF!
A14: WEANERS | B14: WEANER | C14: ='[16]IAS 41 Mvmnt Pigs'!$N14 -> 2.1078684e+09 | D14: ='Summary Total Pigs'!D13*F13 -> #REF! | E14: =SUM(C14:D14) -> #REF! | F14: =$E14/'Summary Total Pigs'!#REF! -> #REF! | G14: ='Summary Total Pigs'!#REF!*'IAS 41 Mvmnt Pigs'!F14 -> #REF! | H14: =$F14*'Summary Total Pigs'!$X13 -> #REF! | I14: ='Summary Total Pigs'!#REF!*'IAS 41 Mvmnt Pigs'!F14 -> #REF! | J14: =$F14*'Summary Total Pigs'!$Z13 -> #REF! | K14: ='Summary Total Pigs'!#REF!*'IAS 41 Mvmnt Pigs'!F14 -> #REF! | L14: =E14+G14+H14+J14+K14+I14 -> #REF! | M14: 0 | N14: =+L14+M14 -> #REF! | O14: =[17]Sheet1!$E170 -> 4.040958e+09 | P14: =N14-O14 -> #REF!
A15: GROWERS | B15: GROWER | C15: ='[16]IAS 41 Mvmnt Pigs'!$N15 -> 8.4247275e+09 | D15: =3838*F14+19*F16 -> #REF! | E15: =SUM(C15:D15) -> #REF! | F15: =$E15/'Summary Total Pigs'!#REF! -> #REF! | G15: ='Summary Total Pigs'!#REF!*'IAS 41 Mvmnt Pigs'!F15 -> #REF! | H15: ='Summary Total Pigs'!X14*'IAS 41 Mvmnt Pigs'!F15 -> #REF! | I15: ='Summary Total Pigs'!#REF!*'IAS 41 Mvmnt Pigs'!F15 -> #REF! | J15: =$F15*'Summary Total Pigs'!$Z14 -> #REF! | K15: ='Summary Total Pigs'!#REF!*'IAS 41 Mvmnt Pigs'!F15 -> #REF! | L15: =E15+G15+H15+J15+K15+I15 -> #REF! | M15: 0 | N15: =+L15+M15 -> #REF! | O15: =[17]Sheet1!$E171 -> 1.0392149e+10 | P15: =N15-O15 -> #REF!
A16: GILTS | B16: MAIN | C16: ='[16]IAS 41 Mvmnt Pigs'!$N16 -> 9.3443108e+08 | D16: =F13*'Summary Total Pigs'!D15 -> #REF! | E16: =SUM(C16:D16) -> #REF! | F16: =$E16/'Summary Total Pigs'!#REF! -> #REF! | G16: ='Summary Total Pigs'!#REF!*'IAS 41 Mvmnt Pigs'!F16 -> #REF! | H16: =$F16*'Summary Total Pigs'!$X15 -> #REF! | I16: ='Summary Total Pigs'!#REF!*'IAS 41 Mvmnt Pigs'!F16 -> #REF! | J16: =$F16*'Summary Total Pigs'!$Z15 -> #REF! | K16: ='Summary Total Pigs'!#REF!*'IAS 41 Mvmnt Pigs'!F16 -> #REF! | L16: =E16+G16+H16+J16+K16+I16 -> #REF! | M16: 0 | N16: =+L16+M16 -> #REF! | O16: =[17]Sheet1!$E172 -> 1.1174234e+09 | P16: =N16-O16 -> #REF!
A17: SOWS | B17: MAIN | C17: ='[16]IAS 41 Mvmnt Pigs'!$N17 -> 2.024274e+09 | D17: =F16*'Summary Total Pigs'!D16 -> #REF! | E17: =SUM(C17:D17) -> #REF! | F17: =$E17/'Summary Total Pigs'!#REF! -> #REF! | G17: ='Summary Total Pigs'!#REF!*'IAS 41 Mvmnt Pigs'!F17 -> #REF! | H17: =$F17*'Summary Total Pigs'!$X16 -> #REF! | I17: ='Summary Total Pigs'!#REF!*'IAS 41 Mvmnt Pigs'!F17 -> #REF! | J17: =$F17*'Summary Total Pigs'!$Z16 -> #REF! | K17: ='Summary Total Pigs'!#REF!*'IAS 41 Mvmnt Pigs'!F17 -> #REF! | L17: =E17+G17+H17+J17+K17+I17 -> #REF! | M17: 0 | N17: =+L17+M17 -> #REF! | O17: =[17]Sheet1!$E173 -> 2.0925556e+09 | P17: =N17-O17 -> #REF!
A18: BOARS | B18: AI | C18: ='[16]IAS 41 Mvmnt Pigs'!$N18 -> 64762941 | D18: ='Summary Total Pigs'!D17*F15 -> #REF! | E18: =SUM(C18:D18) -> #REF! | F18: =$E18/'Summary Total Pigs'!#REF! -> #REF! | G18: ='Summary Total Pigs'!#REF!*'IAS 41 Mvmnt Pigs'!F18 -> #REF! | H18: =$F18*'Summary Total Pigs'!$X17 -> #REF! | I18: ='Summary Total Pigs'!#REF!*'IAS 41 Mvmnt Pigs'!F18 -> #REF! | J18: =$F18*'Summary Total Pigs'!$Z17 -> #REF! | K18: ='Summary Total Pigs'!#REF!*'IAS 41 Mvmnt Pigs'!F18 -> #REF! | L18: =E18+G18+H18+J18+K18+I18 -> #REF! | M18: 0 | N18: =+L18+M18 -> #REF! | O18: =[17]Sheet1!$E174 -> 64762941 | P18: =N18-O18 -> #REF!
A19: TOTAL | C19: =SUM(C13:C18) -> 1.3685637e+10 | D19: =SUM(D13:D18) -> #REF! | E19: =SUM(E13:E18) -> #REF! | F19: =SUM(F13:F18) -> #REF! | G19: =SUM(G13:G18) -> #REF! | H19: =SUM(H13:H18) -> #REF! | I19: =SUM(I13:I18) -> #REF! | J19: =SUM(J13:J18) -> #REF! | ... O19: =SUM(O13:O18) -> 1.7995697e+10 | P19: =N19-O19 -> #REF! | Q19: =[17]Sheet1!$E$16 -> -1.7992163e+10
D20: =D19+G19 -> #REF! | L20: =E19+G19+H19+J19+K19+I19 -> #REF! | Q20: =Q19+M19 -> -1.7992163e+10
L21: =+L19-L20 -> #REF!
A22: SITE: | B22: TRADE WINDS
A24: DESCRIPTION | B24: SITE | C24: OPENING | D24: TRANSFER IN | E24: TOTAL COST | F24: AVERAGE COST | G24: TRANSFER OUT | H24: SALES | I24: =I12 -> #REF! | J24: =J12 -> CULLS | K24: =+K12 -> STOCK ADJMNT | L24: SUB TOTAL | M24: =M12 -> CURRENT ADJMNT | N24: =+N12 -> CLOSING BAL | O24: CLOSING BAL
A25: PIGLETS | B25: MAIN | C25: ='[16]IAS 41 Mvmnt Pigs'!$N25 -> 0 | D25: ='Summary Total Pigs'!#REF!*M23 -> #REF! | E25: =SUM(C25:D25) -> #REF! | F25: 0 | G25: ='Summary Total Pigs'!#REF!*'IAS 41 Mvmnt Pigs'!F25 -> #REF! | H25: =F25*'Summary Total Pigs'!#REF! -> #REF! | I25: =F25*'Summary Total Pigs'!#REF! -> #REF! | J25: =F25*'Summary Total Pigs'!#REF! -> #REF! | K25: ='Summary Total Pigs'!#REF!*'IAS 41 Mvmnt Pigs'!F25 -> #REF! | L25: =E25+G25+H25+J25+K25+I25 -> #REF! | M25: 0 | N25: =+L25+M25 -> #REF! | O25: =[17]Sheet1!$O163
A26: WEANERS | B26: WEANER | C26: ='[16]IAS 41 Mvmnt Pigs'!$N26 -> 0 | D26: 0 | E26: =SUM(C26:D26) -> 0 | F26: 0 | G26: ='Summary Total Pigs'!#REF!*'IAS 41 Mvmnt Pigs'!F26 -> #REF! | H26: =F26*'Summary Total Pigs'!#REF! -> #REF! | I26: =F26*'Summary Total Pigs'!#REF! -> #REF! | J26: =F26*'Summary Total Pigs'!#REF! -> #REF! | K26: ='Summary Total Pigs'!#REF!*'IAS 41 Mvmnt Pigs'!F26 -> #REF! | L26: =E26+G26+H26+J26+K26+I26 -> #REF! | M26: 0 | N26: =+L26+M26 -> #REF! | O26: 0 | P26: =N26-O26 -> #REF!
A27: GROWERS | B27: GROWER | C27: ='[16]IAS 41 Mvmnt Pigs'!$N27 -> 3.8161986e+08 | D27: =F101*'Summary Total Pigs'!#REF! -> #REF! | E27: =SUM(C27:D27) -> #REF! | F27: =$E27/'Summary Total Pigs'!#REF! -> #REF! | G27: ='Summary Total Pigs'!#REF!*'IAS 41 Mvmnt Pigs'!F27 -> #REF! | H27: =F27*'Summary Total Pigs'!#REF! -> #REF! | I27: =F27*'Summary Total Pigs'!#REF! -> #REF! | J27: =F27*'Summary Total Pigs'!#REF! -> #REF! | K27: ='Summary Total Pigs'!#REF!*'IAS 41 Mvmnt Pigs'!F27 -> #REF! | L27: =E27+G27+H27+J27+K27+I27 -> #REF! | M27: 0 | N27: =+L27+M27 -> #REF! | O27: =[17]Sheet1!$O$171 -> 6.7846227e+08 | P27: =N27-O27 -> #REF!
A28: GILTS | B28: MAIN | C28: ='[16]IAS 41 Mvmnt Pigs'!$N28 -> 0 | D28: ='Summary Total Pigs'!#REF!*M26 -> #REF! | E28: =SUM(C28:D28) -> #REF! | F28: 0 | G28: ='Summary Total Pigs'!#REF!*'IAS 41 Mvmnt Pigs'!F28 -> #REF! | H28: =F28*'Summary Total Pigs'!#REF! -> #REF! | I28: =F28*'Summary Total Pigs'!#REF! -> #REF! | J28: =F28*'Summary Total Pigs'!#REF! -> #REF! | K28: ='Summary Total Pigs'!#REF!*'IAS 41 Mvmnt Pigs'!F28 -> #REF! | L28: =E28+G28+H28+J28+K28+I28 -> #REF! | M28: 0 | N28: =+L28+M28 -> #REF! | O28: 0 | P28: =N28-O28 -> #REF!
A29: SOWS | B29: MAIN | C29: ='[16]IAS 41 Mvmnt Pigs'!$N29 -> 0 | D29: 0 | E29: =SUM(C29:D29) -> 0 | F29: 0 | G29: ='Summary Total Pigs'!#REF!*'IAS 41 Mvmnt Pigs'!F29 -> #REF! | H29: =F29*'Summary Total Pigs'!#REF! -> #REF! | I29: =F29*'Summary Total Pigs'!#REF! -> #REF! | J29: =F29*'Summary Total Pigs'!#REF! -> #REF! | K29: ='Summary Total Pigs'!#REF!*'IAS 41 Mvmnt Pigs'!F29 -> #REF! | L29: =E29+G29+H29+J29+K29+I29 -> #REF! | M29: 0 | N29: =+L29+M29 -> #REF! | O29: 0 | P29: =N29-O29 -> #REF!
A30: BOARS | C30: ='[16]IAS 41 Mvmnt Pigs'!$N30 -> 0 | D30: ='Summary Total Pigs'!#REF!*M28 -> #REF! | E30: =SUM(C30:D30) -> #REF! | F30: 0 | G30: ='Summary Total Pigs'!#REF!*'IAS 41 Mvmnt Pigs'!F30 -> #REF! | H30: =F30*'Summary Total Pigs'!#REF! -> #REF! | I30: =F30*'Summary Total Pigs'!#REF! -> #REF! | J30: =F30*'Summary Total Pigs'!#REF! -> #REF! | K30: ='Summary Total Pigs'!#REF!*'IAS 41 Mvmnt Pigs'!F30 -> #REF! | L30: =E30+G30+H30+J30+K30+I30 -> #REF! | M30: 0 | N30: =+L30+M30 -> #REF! | O30: 0 | P30: =N30-O30 -> #REF!
A31: TOTAL | C31: =SUM(C25:C30) -> 3.8161986e+08 | D31: =SUM(D25:D29) -> #REF! | E31: =SUM(E25:E30) -> #REF! | F31: =SUM(F25:F30) -> #REF! | G31: =SUM(G25:G30) -> #REF! | H31: =SUM(H25:H30) -> #REF! | I31: =SUM(I25:I30) -> #REF! | J31: =SUM(J25:J30) -> #REF! | K31: =SUM(K25:K30) -> #REF! | L31: =SUM(L25:L30) -> #REF! | ... N31: =SUM(N25:N30) -> #REF! | O31: =SUM(O26:O30) -> 6.7846227e+08 | P31: =N31-O31 -> #REF! | Q31: =[17]Sheet1!$O$16 -> -6.7827279e+08
Q32: =M31+Q31 -> -6.7827279e+08
A34: SITE: | B34: ZIMBO | E34: =21*2127853690 -> 44684927490 | G34: =393+34 -> 427
A36: DESCRIPTION | B36: SITE | C36: OPENING | D36: TRANSFER IN | E36: TOTAL COST | F36: AVERAGE COST | G36: TRANSFER OUT | H36: SALES | I36: =I24 -> #REF! | J36: =+J24 -> CULLS | K36: =+K24 -> STOCK ADJMNT | L36: SUB TOTAL | M36: =+M24 -> CURRENT ADJMNT | N36: =+N24 -> CLOSING BAL | O36: CLOSING BAL
A37: PIGLETS | B37: MAIN | C37: ='[16]IAS 41 Mvmnt Pigs'!$N37 -> 16928588 | E37: =SUM(C37:D37) -> 16928588 | F37: =$E37/'Summary Total Pigs'!#REF! -> #REF! | G37: ='Summary Total Pigs'!N50*'IAS 41 Mvmnt Pigs'!F37 -> #REF! | H37: ='Summary Total Pigs'!#REF!*F37 -> #REF! | I37: =F37*'Summary Total Pigs'!W50 -> #REF! | J37: ='Summary Total Pigs'!X50*'IAS 41 Mvmnt Pigs'!F37 -> #REF! | K37: ='Summary Total Pigs'!AD50*'IAS 41 Mvmnt Pigs'!F37 -> #REF! | L37: =E37+G37+H37+J37+K37+I37 -> #REF! | M37: 0 | N37: =+L37+M37 -> #REF! | O37: =[17]Sheet1!$Q169 -> 32013468 | P37: =N37-O37 -> #REF!
A38: WEANERS | B38: WEANER | C38: ='[16]IAS 41 Mvmnt Pigs'!$N38 -> 0 | E38: =SUM(C38:D38) -> 0 | G38: ='Summary Total Pigs'!N51*'IAS 41 Mvmnt Pigs'!F38 -> 0 | H38: ='Summary Total Pigs'!#REF!*'IAS 41 Mvmnt Pigs'!F38 -> #REF! | I38: =F38*'Summary Total Pigs'!W51 -> 0 | J38: ='Summary Total Pigs'!X51*'IAS 41 Mvmnt Pigs'!F38 -> 0 | K38: ='Summary Total Pigs'!AD51*'IAS 41 Mvmnt Pigs'!F38 -> 0 | L38: =E38+G38+H38+J38+K38+I38 -> #REF! | M38: 0 | N38: =+L38+M38 -> #REF! | O38: =[17]Sheet1!$Q170
A39: GROWERS | B39: GROWER | C39: ='[16]IAS 41 Mvmnt Pigs'!$N39 -> 5.9604645e-18 | E39: =SUM(C39:D39) -> 5.9604645e-18 | G39: ='Summary Total Pigs'!N52*'IAS 41 Mvmnt Pigs'!F39 -> 0 | H39: ='Summary Total Pigs'!#REF!*'IAS 41 Mvmnt Pigs'!F39 -> #REF! | I39: =F39*'Summary Total Pigs'!W52 -> 0 | J39: ='Summary Total Pigs'!X52*'IAS 41 Mvmnt Pigs'!F39 -> 0 | K39: ='Summary Total Pigs'!AD52*'IAS 41 Mvmnt Pigs'!F39 -> 0 | L39: =E39+G39+H39+J39+K39+I39 -> #REF! | M39: 0 | N39: =+L39+M39 -> #REF! | O39: =[17]Sheet1!$Q171
A40: GILTS | B40: MAIN | C40: ='[16]IAS 41 Mvmnt Pigs'!$N40 -> 0 | D40: =F66*'Summary Total Pigs'!D53 -> #REF! | E40: =SUM(C40:D40) -> #REF! | F40: =$E40/'Summary Total Pigs'!#REF! -> #REF! | G40: ='Summary Total Pigs'!N53*'IAS 41 Mvmnt Pigs'!F40 -> #REF! | H40: ='Summary Total Pigs'!#REF!*'IAS 41 Mvmnt Pigs'!F40 -> #REF! | I40: =F40*'Summary Total Pigs'!W53 -> #REF! | J40: ='Summary Total Pigs'!X53*'IAS 41 Mvmnt Pigs'!F40 -> #REF! | K40: ='Summary Total Pigs'!AD53*'IAS 41 Mvmnt Pigs'!F40 -> #REF! | L40: =E40+G40+H40+J40+K40+I40 -> #REF! | M40: 0 | N40: =+L40+M40 -> #REF! | O40: =[17]Sheet1!$Q172
A41: SOWS | B41: MAIN | C41: ='[16]IAS 41 Mvmnt Pigs'!$N41 -> 3.9690606e+08 | D41: =F40*'Summary Total Pigs'!D54 -> #REF! | E41: =SUM(C41:D41) -> #REF! | F41: =$E41/'Summary Total Pigs'!#REF! -> #REF! | G41: ='Summary Total Pigs'!N54*'IAS 41 Mvmnt Pigs'!F41 -> #REF! | H41: ='Summary Total Pigs'!#REF!*'IAS 41 Mvmnt Pigs'!F41 -> #REF! | I41: =F41*'Summary Total Pigs'!W54 -> #REF! | J41: ='Summary Total Pigs'!X54*'IAS 41 Mvmnt Pigs'!F41 -> #REF! | K41: ='Summary Total Pigs'!AD54*'IAS 41 Mvmnt Pigs'!F41 -> #REF! | L41: =E41+G41+H41+J41+K41+I41 -> #REF! | M41: 0 | N41: =+L41+M41 -> #REF! | O41: =[17]Sheet1!$Q173 -> 4.2266679e+08 | P41: =N41-O41 -> #REF!
A42: BOARS | C42: ='[16]IAS 41 Mvmnt Pigs'!$N42 -> 6081750 | E42: =SUM(C42:D42) -> 6081750 | F42: =$E42/'Summary Total Pigs'!#REF! -> #REF! | G42: ='Summary Total Pigs'!N55*'IAS 41 Mvmnt Pigs'!F42 -> #REF! | H42: ='Summary Total Pigs'!#REF!*'IAS 41 Mvmnt Pigs'!$F42 -> #REF! | I42: =F42*'Summary Total Pigs'!W55 -> #REF! | J42: ='Summary Total Pigs'!X55*'IAS 41 Mvmnt Pigs'!F42 -> #REF! | K42: ='Summary Total Pigs'!AD55*'IAS 41 Mvmnt Pigs'!F42 -> #REF! | L42: =E42+G42+H42+J42+K42+I42 -> #REF! | M42: 0 | N42: =+L42+M42 -> #REF! | O42: =[17]Sheet1!$Q174 -> 6081750 | P42: =N42-O42 -> #REF!
A43: TOTAL | C43: =SUM(C37:C42) -> 4.199164e+08 | D43: =SUM(D37:D41) -> #REF! | E43: =SUM(E37:E42) -> #REF! | F43: =SUM(F37:F42) -> #REF! | G43: =SUM(G37:G42) -> #REF! | H43: =SUM(H37:H42) -> #REF! | I43: =SUM(I37:I42) -> #REF! | J43: =SUM(J37:J42) -> #REF! | K43: =SUM(K37:K42) -> #REF! | L43: =SUM(L37:L42) -> #REF! | ... O43: =SUM(O37:O42) -> 4.6076201e+08 | P43: =N43-O43 -> #REF! | Q43: =[17]Sheet1!$Q$16 -> -4.605947e+08
Q44: =M43+Q43 -> -4.605947e+08
A49: SITE: | B49: ROGATE
A51: DESCRIPTION | B51: SITE | C51: OPENING | D51: TRANSFER IN | E51: TOTAL COST | F51: AVERAGE COST | G51: TRANSFER OUT | H51: SALES | I51: =I36 -> #REF! | J51: =+J36 -> CULLS | K51: =+K36 -> STOCK ADJMNT | L51: SUB TOTAL | M51: =+M36 -> CURRENT ADJMNT | N51: =+N36 -> CLOSING BAL | O51: CLOSING BAL
A52: PIGLETS | B52: MAIN | C52: ='[16]IAS 41 Mvmnt Pigs'!$N52 -> 14314484 | D52: ='Summary Total Pigs'!D89*F37 -> #REF! | E52: =SUM(C52:D52) -> #REF! | F52: =$E52/'Summary Total Pigs'!$M89 -> #REF! | G52: ='Summary Total Pigs'!N89*'IAS 41 Mvmnt Pigs'!F52 -> #REF! | H52: ='Summary Total Pigs'!#REF!*'IAS 41 Mvmnt Pigs'!F52 -> #REF! | I52: =F52*'Summary Total Pigs'!#REF! -> #REF! | J52: ='Summary Total Pigs'!Z89*'IAS 41 Mvmnt Pigs'!F52 -> #REF! | K52: ='Summary Total Pigs'!#REF!*'IAS 41 Mvmnt Pigs'!F52 -> #REF! | L52: =E52+G52+H52+J52+K52+I52 -> #REF! | M52: 0 | N52: =+L52+M52 -> #REF! | O52: =[17]Sheet1!$M169 -> 30151786 | P52: =N52-O52 -> #REF!
A53: WEANERS | B53: WEANER | C53: ='[16]IAS 41 Mvmnt Pigs'!$N53 -> 1.8133208e+08 | D53: ='Summary Total Pigs'!D90*F52 -> #REF! | E53: =SUM(C53:D53) -> #REF! | F53: =$E53/'Summary Total Pigs'!$M90 -> #REF! | G53: ='Summary Total Pigs'!N90*'IAS 41 Mvmnt Pigs'!F53 -> #REF! | H53: ='Summary Total Pigs'!#REF!*'IAS 41 Mvmnt Pigs'!F53 -> #REF! | I53: =F53*'Summary Total Pigs'!#REF! -> #REF! | J53: ='Summary Total Pigs'!Z90*'IAS 41 Mvmnt Pigs'!F53 -> #REF! | K53: ='Summary Total Pigs'!#REF!*'IAS 41 Mvmnt Pigs'!F53 -> #REF! | L53: =E53+G53+H53+J53+K53+I53 -> #REF! | M53: 0 | N53: =+L53+M53 -> #REF! | O53: =[17]Sheet1!$M170 -> 3.1258197e+08 | P53: =N53-O53 -> #REF!
...

Sheet USD
A1: COLCOM HOLDINGS LIMITED
T2: =+'Summary Total Pigs'!C3 -> 46226
A3: TRIPLE C PIGS
A5: LIVESTOCK ANALYSIS SCHEDULE
A7: =[23]USD!$A$7 -> COST USD
A10: SITE: | B10: GRASMERE FARM
A12: DESCRIPTION | B12: SITE | C12: OPENING | D12: PIG PURCHASES | E12: TRANSFER IN | F12: A I CONSUMMABLES | G12: BEDDING AND CONSUMMABLES | H12: CONSULTANCY FEES | I12: DIRECT STAFF COSTS | J12: STOCK FEED | K12: SUNDRY TOOLS | L12: VETERINARY | M12: TOTAL COST | N12: AVERAGE COST | O12: TRANSFER OUT | P12: SALES | Q12: ='Summary Total Pigs'!#REF! -> #REF! | R12: CULLS | S12: STOCK ADJMNT | T12: CLOSING
A13: PIGLETS | B13: MAIN | C13: =[16]USD!$T13 -> 170498.14 | F13: =E170 -> 0 | G13: =('Summary Total Pigs'!AE12+'Summary Total Pigs'!AE15+'Summary Total Pigs'!AE16+'Summary Total Pigs'!AE17)/'Summary Total Pigs'!#REF!*'Pigs Cost'!E171 -> #REF! | H13: =('Summary Total Pigs'!AE12+'Summary Total Pigs'!AE15+'Summary Total Pigs'!AE16+'Summary Total Pigs'!AE17)/'Summary Total Pigs'!#REF!*'Pigs Cost'!E172 -> #REF! | I13: =E173/3 -> 0 | J13: =('Summary Total Pigs'!AE12+'Summary Total Pigs'!AE15+'Summary Total Pigs'!AE16+'Summary Total Pigs'!AE17)/'Summary Total Pigs'!#REF!*J174 -> #REF! | K13: =('Summary Total Pigs'!AE12+'Summary Total Pigs'!AE15+'Summary Total Pigs'!AE16+'Summary Total Pigs'!AE17)/'Summary Total Pigs'!#REF!*'Pigs Cost'!E175 -> #REF! | L13: =('Summary Total Pigs'!AE12+'Summary Total Pigs'!AE15+'Summary Total Pigs'!AE16+'Summary Total Pigs'!AE17)/'Summary Total Pigs'!#REF!*'Pigs Cost'!J176 -> #REF! | M13: =SUM(C13:L13) -> #REF! | N13: =M13/'Summary Total Pigs'!#REF! -> #REF! | O13: =N13*'Summary Total Pigs'!#REF! -> #REF! | P13: =N13*'Summary Total Pigs'!X12 -> #REF! | Q13: ='Summary Total Pigs'!#REF!*N13 -> #REF! | R13: =N13*'Summary Total Pigs'!Z12 -> #REF! | S13: ='Summary Total Pigs'!#REF!*N13 -> #REF! | T13: =M13+O13+P13+R13+S13+Q13 -> #REF! | V13: =C13/$B$178 -> 1.7049814e-05
A14: WEANERS | B14: WEANER | C14: =[16]USD!$T14 -> 327744.46 | E14: ='Summary Total Pigs'!D13*N13 -> #REF! | G14: ='Summary Total Pigs'!AE13/'Summary Total Pigs'!#REF!*'Pigs Cost'!E171 -> #REF! | H14: ='Summary Total Pigs'!AE13/'Summary Total Pigs'!#REF!*'Pigs Cost'!E172 -> #REF! | I14: =I13 -> 0 | J14: ='Summary Total Pigs'!AE13/'Summary Total Pigs'!#REF!*J174 -> #REF! | K14: =('Summary Total Pigs'!AE13)/'Summary Total Pigs'!#REF!*'Pigs Cost'!E175 -> #REF! | L14: ='Summary Total Pigs'!AE13/'Summary Total Pigs'!#REF!*'Pigs Cost'!J176 -> #REF! | M14: =SUM(C14:L14) -> #REF! | N14: =M14/'Summary Total Pigs'!#REF! -> #REF! | O14: =N14*'Summary Total Pigs'!#REF! -> #REF! | P14: =N14*'Summary Total Pigs'!X13 -> #REF! | Q14: ='Summary Total Pigs'!#REF!*N14 -> #REF! | R14: =N14*'Summary Total Pigs'!Z13 -> #REF! | S14: ='Summary Total Pigs'!#REF!*N14 -> #REF! | T14: =M14+O14+P14+R14+S14+Q14 -> #REF! | V14: =C14/$B$178 -> 3.2774446e-05
A15: GROWERS | B15: GROWER | C15: =[16]USD!$T15 -> 1109796.3 | E15: =3838*N14+19*N16 -> #REF! | G15: ='Summary Total Pigs'!AE14/'Summary Total Pigs'!#REF!*'Pigs Cost'!E171 -> #REF! | H15: ='Summary Total Pigs'!AE14/'Summary Total Pigs'!#REF!*'Pigs Cost'!E172 -> #REF! | I15: =I14 -> 0 | J15: ='Summary Total Pigs'!AE14/'Summary Total Pigs'!#REF!*J174 -> #REF! | K15: =('Summary Total Pigs'!AE14)/'Summary Total Pigs'!#REF!*'Pigs Cost'!E175 -> #REF! | L15: ='Summary Total Pigs'!AE14/'Summary Total Pigs'!#REF!*'Pigs Cost'!J176 -> #REF! | M15: =SUM(C15:L15) -> #REF! | N15: =M15/'Summary Total Pigs'!#REF! -> #REF! | O15: =N15*'Summary Total Pigs'!#REF! -> #REF! | P15: =N15*'Summary Total Pigs'!X14 -> #REF! | Q15: ='Summary Total Pigs'!#REF!*N15 -> #REF! | R15: =N15*'Summary Total Pigs'!Z14 -> #REF! | S15: ='Summary Total Pigs'!#REF!*N15 -> #REF! | T15: =M15+O15+P15+R15+S15+Q15 -> #REF! | V15: =C15/$B$178 -> 0.00011097963
A16: GILTS | B16: MAIN | C16: =[16]USD!$T16 -> 56382.007 | D16: 0 | E16: =106*N13 -> #REF! | G16: 0 | H16: 0 | I16: 0 | J16: 0 | K16: 0 | L16: 0 | M16: =SUM(C16:L16) -> #REF! | N16: =M16/'Summary Total Pigs'!#REF! -> #REF! | O16: =N16*'Summary Total Pigs'!#REF! -> #REF! | P16: ='Summary Total Pigs'!X15*N16 -> #REF! | Q16: ='Summary Total Pigs'!#REF!*N16 -> #REF! | R16: =N16*'Summary Total Pigs'!Z15 -> #REF! | S16: ='Summary Total Pigs'!#REF!*N16 -> #REF! | T16: =M16+O16+P16+R16+S16+Q16 -> #REF! | V16: =C16/$B$178 -> 5.6382007e-06
A17: SOWS | B17: MAIN | C17: =[16]USD!$T17 -> 150254.39 | E17: ='Summary Total Pigs'!D16*N16 -> #REF! | G17: 0 | H17: 0 | I17: =I16 -> 0 | J17: 0 | K17: 0 | L17: 0 | M17: =SUM(C17:L17) -> #REF! | N17: =M17/'Summary Total Pigs'!#REF! -> #REF! | O17: =N17*'Summary Total Pigs'!#REF! -> #REF! | P17: =N17*'Summary Total Pigs'!X16 -> #REF! | Q17: ='Summary Total Pigs'!#REF!*N17 -> #REF! | R17: =N17*'Summary Total Pigs'!Z16 -> #REF! | S17: ='Summary Total Pigs'!#REF!*N17 -> #REF! | T17: =M17+O17+P17+R17+S17+Q17 -> #REF! | V17: =C17/$B$178 -> 1.5025439e-05
A18: BOARS | B18: AI | C18: =[16]USD!$T18 -> 4774.3468 | E18: ='Summary Total Pigs'!D17*N15 -> #REF! | F18: 0 | G18: 0 | H18: 0 | I18: =I17 -> 0 | J18: 0 | K18: 0 | L18: 0 | M18: =SUM(C18:L18) -> #REF! | N18: =M18/'Summary Total Pigs'!#REF! -> #REF! | O18: =N18*'Summary Total Pigs'!Q218 -> #REF! | P18: =N18*'Summary Total Pigs'!X17 -> #REF! | Q18: ='Summary Total Pigs'!#REF!*N18 -> #REF! | R18: =N18*'Summary Total Pigs'!Z17 -> #REF! | S18: ='Summary Total Pigs'!#REF!*N18 -> #REF! | T18: =M18+O18+P18+R18+S18+Q18 -> #REF! | V18: =C18/$B$178 -> 4.7743468e-07
A19: TOTAL | C19: =SUM(C13:C18) -> 1819449.6 | D19: =SUM(D13:D18) -> 0 | E19: =SUM(E13:E18) -> #REF! | F19: =SUM(F13:F18) -> 0 | G19: =SUM(G13:G18) -> #REF! | H19: =SUM(H13:H18) -> #REF! | I19: =SUM(I13:I18) -> 0 | J19: =SUM(J13:J18) -> #REF! | ... T19: =SUM(T13:T18) -> #REF! | V19: =C19/$B$178 -> 0.00018194496
E20: =E19+O19 -> #REF! | F20: =F19-E170 -> 0 | G20: =G19-E171 -> #REF! | H20: =H19-E172 -> #REF! | I20: =I19-E173 -> 0 | J20: =J19-J174 -> #REF! | K20: =K19-E175 -> #REF! | L20: =L19-E176 -> #REF! | M20: ='Summary Total Pigs'!#REF!*N15 -> #REF! | V20: =C20/$B$178 -> 0
L21: =+(G19+H19+I19+K19+L19+J19+F19)-J178 -> #REF! | M21: =E20-M20 -> #REF! | V21: =C21/$B$178 -> 0
A22: SITE: | B22: TRADE WINDS | V22: =C22/$B$178 -> 0
V23: =C23/$B$178 -> 0
A24: DESCRIPTION | B24: SITE | C24: =+C12 -> OPENING | D24: PIG PURCHASES | E24: TRANSFER IN | F24: A I CONSUMMABLES | G24: BEDDING AND CONSUMMABLES | H24: CONSULTANCY FEES | I24: DIRECT STAFF COSTS | J24: STOCK FEED | K24: SUNDRY TOOLS | L24: VETERINARY | M24: TOTAL COST | N24: AVERAGE COST | O24: TRANSFER OUT | P24: SALES | Q24: ='Summary Total Pigs'!#REF! -> #REF! | R24: =R12 -> CULLS | S24: =+S12 -> STOCK ADJMNT | T24: CLOSING | V24: =C24/$B$178 -> #VALUE!
