Workbook

Sheet Combined Avg CDM actual vs  (7)
O1: NB only pigs sent to Colcom
O2: sows and growers
B20: 45839 | C20: 45870 | D20: 45901 | E20: 45931 | F20: 45962 | G20: 45992 | H20: 46023 | I20: 46054 | J20: 46082 | K20: 46113 | L20: 46143 | M20: 46174
A21: FY26 - Avg CDM to Colcom | B21: =SUM('Combined total CDM to Colco (7)'!B24+'Combined total CDM to Colco (7)'!B25+'Combined total CDM to Colco (7)'!B26+'Combined total CDM to Colco (7)'!B27+'Combined total CDM to Colco (7)'!B34+'Combined total CDM to Colco (7)'!B35+'Combined total CDM to Colco (7)'!B36+'Combined total CDM to Colco (7)'!B37+'Combined total CDM to Colco (7)'!B44+'Combined total CDM to Colco (7)'!B45+'Combined total CDM to Colco (7)'!B46+'Combined total CDM to Colco (7)'!B47+'Combined total CDM to Colco (7)'!B54+'Combined total CDM to Colco (7)'!B55+'Combined total CDM to Colco (7)'!B56+'Combined total CDM to Colco (7)'!B57+'Combined total CDM to Colco (7)'!B63+'Combined total CDM to Colco (7)'!B66)/SUM('Combined pigs sold to colco (7)'!B25+'Combined pigs sold to colco (7)'!B26+'Combined pigs sold to colco (7)'!B27+'Combined pigs sold to colco (7)'!B28+'Combined pigs sold to colco (7)'!B35+'Combined pigs sold to colco (7)'!B36+'Combined pigs sold to colco (7)'!B37+'Combined pigs sold to colco (7)'!B38+'Combined pigs sold to colco (7)'!B45+'Combined pigs sold to colco (7)'!B46+'Combined pigs sold to colco (7)'!B47+'Combined pigs sold to colco (7)'!B48+'Combined pigs sold to colco (7)'!B55+'Combined pigs sold to colco (7)'!B56+'Combined pigs sold to colco (7)'!B57+'Combined pigs sold to colco (7)'!B58+'Combined pigs sold to colco (7)'!B67+'Combined pigs sold to colco (7)'!B70) -> 95.685859 | C21: =SUM('Combined total CDM to Colco (7)'!C24+'Combined total CDM to Colco (7)'!C25+'Combined total CDM to Colco (7)'!C26+'Combined total CDM to Colco (7)'!C27+'Combined total CDM to Colco (7)'!C34+'Combined total CDM to Colco (7)'!C35+'Combined total CDM to Colco (7)'!C36+'Combined total CDM to Colco (7)'!C37+'Combined total CDM to Colco (7)'!C44+'Combined total CDM to Colco (7)'!C45+'Combined total CDM to Colco (7)'!C46+'Combined total CDM to Colco (7)'!C47+'Combined total CDM to Colco (7)'!C54+'Combined total CDM to Colco (7)'!C55+'Combined total CDM to Colco (7)'!C56+'Combined total CDM to Colco (7)'!C57+'Combined total CDM to Colco (7)'!C63+'Combined total CDM to Colco (7)'!C66)/SUM('Combined pigs sold to colco (7)'!C25+'Combined pigs sold to colco (7)'!C26+'Combined pigs sold to colco (7)'!C27+'Combined pigs sold to colco (7)'!C28+'Combined pigs sold to colco (7)'!C35+'Combined pigs sold to colco (7)'!C36+'Combined pigs sold to colco (7)'!C37+'Combined pigs sold to colco (7)'!C38+'Combined pigs sold to colco (7)'!C45+'Combined pigs sold to colco (7)'!C46+'Combined pigs sold to colco (7)'!C47+'Combined pigs sold to colco (7)'!C48+'Combined pigs sold to colco (7)'!C55+'Combined pigs sold to colco (7)'!C56+'Combined pigs sold to colco (7)'!C57+'Combined pigs sold to colco (7)'!C58+'Combined pigs sold to colco (7)'!C67+'Combined pigs sold to colco (7)'!C70) -> 95.07222 | D21: =SUM('Combined total CDM to Colco (7)'!D24+'Combined total CDM to Colco (7)'!D25+'Combined total CDM to Colco (7)'!D26+'Combined total CDM to Colco (7)'!D27+'Combined total CDM to Colco (7)'!D34+'Combined total CDM to Colco (7)'!D35+'Combined total CDM to Colco (7)'!D36+'Combined total CDM to Colco (7)'!D37+'Combined total CDM to Colco (7)'!D44+'Combined total CDM to Colco (7)'!D45+'Combined total CDM to Colco (7)'!D46+'Combined total CDM to Colco (7)'!D47+'Combined total CDM to Colco (7)'!D54+'Combined total CDM to Colco (7)'!D55+'Combined total CDM to Colco (7)'!D56+'Combined total CDM to Colco (7)'!D57+'Combined total CDM to Colco (7)'!D63+'Combined total CDM to Colco (7)'!D66+'Combined total CDM to Colco (7)'!D73+'Combined total CDM to Colco (7)'!D76)/SUM('Combined pigs sold to colco (7)'!D25+'Combined pigs sold to colco (7)'!D26+'Combined pigs sold to colco (7)'!D27+'Combined pigs sold to colco (7)'!D28+'Combined pigs sold to colco (7)'!D35+'Combined pigs sold to colco (7)'!D36+'Combined pigs sold to colco (7)'!D37+'Combined pigs sold to colco (7)'!D38+'Combined pigs sold to colco (7)'!D45+'Combined pigs sold to colco (7)'!D46+'Combined pigs sold to colco (7)'!D47+'Combined pigs sold to colco (7)'!D48+'Combined pigs sold to colco (7)'!D55+'Combined pigs sold to colco (7)'!D56+'Combined pigs sold to colco (7)'!D57+'Combined pigs sold to colco (7)'!D58+'Combined pigs sold to colco (7)'!D67+'Combined pigs sold to colco (7)'!D70+'Combined pigs sold to colco (7)'!D77+'Combined pigs sold to colco (7)'!D80) -> 92.526227 | E21: =SUM('Combined total CDM to Colco (7)'!E24+'Combined total CDM to Colco (7)'!E25+'Combined total CDM to Colco (7)'!E26+'Combined total CDM to Colco (7)'!E27+'Combined total CDM to Colco (7)'!E34+'Combined total CDM to Colco (7)'!E35+'Combined total CDM to Colco (7)'!E36+'Combined total CDM to Colco (7)'!E37+'Combined total CDM to Colco (7)'!E44+'Combined total CDM to Colco (7)'!E45+'Combined total CDM to Colco (7)'!E46+'Combined total CDM to Colco (7)'!E47+'Combined total CDM to Colco (7)'!E54+'Combined total CDM to Colco (7)'!E55+'Combined total CDM to Colco (7)'!E56+'Combined total CDM to Colco (7)'!E57+'Combined total CDM to Colco (7)'!E63+'Combined total CDM to Colco (7)'!E66+'Combined total CDM to Colco (7)'!E73+'Combined total CDM to Colco (7)'!E76)/SUM('Combined pigs sold to colco (7)'!E25+'Combined pigs sold to colco (7)'!E26+'Combined pigs sold to colco (7)'!E27+'Combined pigs sold to colco (7)'!E28+'Combined pigs sold to colco (7)'!E35+'Combined pigs sold to colco (7)'!E36+'Combined pigs sold to colco (7)'!E37+'Combined pigs sold to colco (7)'!E38+'Combined pigs sold to colco (7)'!E45+'Combined pigs sold to colco (7)'!E46+'Combined pigs sold to colco (7)'!E47+'Combined pigs sold to colco (7)'!E48+'Combined pigs sold to colco (7)'!E55+'Combined pigs sold to colco (7)'!E56+'Combined pigs sold to colco (7)'!E57+'Combined pigs sold to colco (7)'!E58+'Combined pigs sold to colco (7)'!E67+'Combined pigs sold to colco (7)'!E70+'Combined pigs sold to colco (7)'!E77+'Combined pigs sold to colco (7)'!E80) -> 91.462909 | F21: =SUM('Combined total CDM to Colco (7)'!F24+'Combined total CDM to Colco (7)'!F25+'Combined total CDM to Colco (7)'!F26+'Combined total CDM to Colco (7)'!F27+'Combined total CDM to Colco (7)'!F34+'Combined total CDM to Colco (7)'!F35+'Combined total CDM to Colco (7)'!F36+'Combined total CDM to Colco (7)'!F37+'Combined total CDM to Colco (7)'!F44+'Combined total CDM to Colco (7)'!F45+'Combined total CDM to Colco (7)'!F46+'Combined total CDM to Colco (7)'!F47+'Combined total CDM to Colco (7)'!F54+'Combined total CDM to Colco (7)'!F55+'Combined total CDM to Colco (7)'!F56+'Combined total CDM to Colco (7)'!F57+'Combined total CDM to Colco (7)'!F63+'Combined total CDM to Colco (7)'!F66+'Combined total CDM to Colco (7)'!F73+'Combined total CDM to Colco (7)'!F76)/SUM('Combined pigs sold to colco (7)'!F25+'Combined pigs sold to colco (7)'!F26+'Combined pigs sold to colco (7)'!F27+'Combined pigs sold to colco (7)'!F28+'Combined pigs sold to colco (7)'!F35+'Combined pigs sold to colco (7)'!F36+'Combined pigs sold to colco (7)'!F37+'Combined pigs sold to colco (7)'!F38+'Combined pigs sold to colco (7)'!F45+'Combined pigs sold to colco (7)'!F46+'Combined pigs sold to colco (7)'!F47+'Combined pigs sold to colco (7)'!F48+'Combined pigs sold to colco (7)'!F55+'Combined pigs sold to colco (7)'!F56+'Combined pigs sold to colco (7)'!F57+'Combined pigs sold to colco (7)'!F58+'Combined pigs sold to colco (7)'!F67+'Combined pigs sold to colco (7)'!F70+'Combined pigs sold to colco (7)'!F77+'Combined pigs sold to colco (7)'!F80) -> 90.962207 | G21: =SUM('Combined total CDM to Colco (7)'!G24+'Combined total CDM to Colco (7)'!G25+'Combined total CDM to Colco (7)'!G26+'Combined total CDM to Colco (7)'!G27+'Combined total CDM to Colco (7)'!G34+'Combined total CDM to Colco (7)'!G35+'Combined total CDM to Colco (7)'!G36+'Combined total CDM to Colco (7)'!G37+'Combined total CDM to Colco (7)'!G44+'Combined total CDM to Colco (7)'!G45+'Combined total CDM to Colco (7)'!G46+'Combined total CDM to Colco (7)'!G47+'Combined total CDM to Colco (7)'!G54+'Combined total CDM to Colco (7)'!G55+'Combined total CDM to Colco (7)'!G56+'Combined total CDM to Colco (7)'!G57+'Combined total CDM to Colco (7)'!G63+'Combined total CDM to Colco (7)'!G66+'Combined total CDM to Colco (7)'!G73+'Combined total CDM to Colco (7)'!G76)/SUM('Combined pigs sold to colco (7)'!G25+'Combined pigs sold to colco (7)'!G26+'Combined pigs sold to colco (7)'!G27+'Combined pigs sold to colco (7)'!G28+'Combined pigs sold to colco (7)'!G35+'Combined pigs sold to colco (7)'!G36+'Combined pigs sold to colco (7)'!G37+'Combined pigs sold to colco (7)'!G38+'Combined pigs sold to colco (7)'!G45+'Combined pigs sold to colco (7)'!G46+'Combined pigs sold to colco (7)'!G47+'Combined pigs sold to colco (7)'!G48+'Combined pigs sold to colco (7)'!G55+'Combined pigs sold to colco (7)'!G56+'Combined pigs sold to colco (7)'!G57+'Combined pigs sold to colco (7)'!G58+'Combined pigs sold to colco (7)'!G67+'Combined pigs sold to colco (7)'!G70+'Combined pigs sold to colco (7)'!G77+'Combined pigs sold to colco (7)'!G80) -> 90.748738 | H21: =SUM('Combined total CDM to Colco (7)'!H24+'Combined total CDM to Colco (7)'!H25+'Combined total CDM to Colco (7)'!H26+'Combined total CDM to Colco (7)'!H27+'Combined total CDM to Colco (7)'!H34+'Combined total CDM to Colco (7)'!H35+'Combined total CDM to Colco (7)'!H36+'Combined total CDM to Colco (7)'!H37+'Combined total CDM to Colco (7)'!H44+'Combined total CDM to Colco (7)'!H45+'Combined total CDM to Colco (7)'!H46+'Combined total CDM to Colco (7)'!H47+'Combined total CDM to Colco (7)'!H54+'Combined total CDM to Colco (7)'!H55+'Combined total CDM to Colco (7)'!H56+'Combined total CDM to Colco (7)'!H57+'Combined total CDM to Colco (7)'!H63+'Combined total CDM to Colco (7)'!H66+'Combined total CDM to Colco (7)'!H73+'Combined total CDM to Colco (7)'!H76)/SUM('Combined pigs sold to colco (7)'!H25+'Combined pigs sold to colco (7)'!H26+'Combined pigs sold to colco (7)'!H27+'Combined pigs sold to colco (7)'!H28+'Combined pigs sold to colco (7)'!H35+'Combined pigs sold to colco (7)'!H36+'Combined pigs sold to colco (7)'!H37+'Combined pigs sold to colco (7)'!H38+'Combined pigs sold to colco (7)'!H45+'Combined pigs sold to colco (7)'!H46+'Combined pigs sold to colco (7)'!H47+'Combined pigs sold to colco (7)'!H48+'Combined pigs sold to colco (7)'!H55+'Combined pigs sold to colco (7)'!H56+'Combined pigs sold to colco (7)'!H57+'Combined pigs sold to colco (7)'!H58+'Combined pigs sold to colco (7)'!H67+'Combined pigs sold to colco (7)'!H70+'Combined pigs sold to colco (7)'!H77+'Combined pigs sold to colco (7)'!H80) -> 92.946092 | I21: =SUM('Combined total CDM to Colco (7)'!I24+'Combined total CDM to Colco (7)'!I25+'Combined total CDM to Colco (7)'!I26+'Combined total CDM to Colco (7)'!I27+'Combined total CDM to Colco (7)'!I34+'Combined total CDM to Colco (7)'!I35+'Combined total CDM to Colco (7)'!I36+'Combined total CDM to Colco (7)'!I37+'Combined total CDM to Colco (7)'!I44+'Combined total CDM to Colco (7)'!I45+'Combined total CDM to Colco (7)'!I46+'Combined total CDM to Colco (7)'!I47+'Combined total CDM to Colco (7)'!I54+'Combined total CDM to Colco (7)'!I55+'Combined total CDM to Colco (7)'!I56+'Combined total CDM to Colco (7)'!I57+'Combined total CDM to Colco (7)'!I63+'Combined total CDM to Colco (7)'!I66+'Combined total CDM to Colco (7)'!I73+'Combined total CDM to Colco (7)'!I76)/SUM('Combined pigs sold to colco (7)'!I25+'Combined pigs sold to colco (7)'!I26+'Combined pigs sold to colco (7)'!I27+'Combined pigs sold to colco (7)'!I28+'Combined pigs sold to colco (7)'!I35+'Combined pigs sold to colco (7)'!I36+'Combined pigs sold to colco (7)'!I37+'Combined pigs sold to colco (7)'!I38+'Combined pigs sold to colco (7)'!I45+'Combined pigs sold to colco (7)'!I46+'Combined pigs sold to colco (7)'!I47+'Combined pigs sold to colco (7)'!I48+'Combined pigs sold to colco (7)'!I55+'Combined pigs sold to colco (7)'!I56+'Combined pigs sold to colco (7)'!I57+'Combined pigs sold to colco (7)'!I58+'Combined pigs sold to colco (7)'!I67+'Combined pigs sold to colco (7)'!I70+'Combined pigs sold to colco (7)'!I77+'Combined pigs sold to colco (7)'!I80) -> 92.253642 | J21: =SUM('Combined total CDM to Colco (7)'!J24+'Combined total CDM to Colco (7)'!J25+'Combined total CDM to Colco (7)'!J26+'Combined total CDM to Colco (7)'!J27+'Combined total CDM to Colco (7)'!J34+'Combined total CDM to Colco (7)'!J35+'Combined total CDM to Colco (7)'!J36+'Combined total CDM to Colco (7)'!J37+'Combined total CDM to Colco (7)'!J44+'Combined total CDM to Colco (7)'!J45+'Combined total CDM to Colco (7)'!J46+'Combined total CDM to Colco (7)'!J47+'Combined total CDM to Colco (7)'!J54+'Combined total CDM to Colco (7)'!J55+'Combined total CDM to Colco (7)'!J56+'Combined total CDM to Colco (7)'!J57+'Combined total CDM to Colco (7)'!J63+'Combined total CDM to Colco (7)'!J66+'Combined total CDM to Colco (7)'!J73+'Combined total CDM to Colco (7)'!J76)/SUM('Combined pigs sold to colco (7)'!J25+'Combined pigs sold to colco (7)'!J26+'Combined pigs sold to colco (7)'!J27+'Combined pigs sold to colco (7)'!J28+'Combined pigs sold to colco (7)'!J35+'Combined pigs sold to colco (7)'!J36+'Combined pigs sold to colco (7)'!J37+'Combined pigs sold to colco (7)'!J38+'Combined pigs sold to colco (7)'!J45+'Combined pigs sold to colco (7)'!J46+'Combined pigs sold to colco (7)'!J47+'Combined pigs sold to colco (7)'!J48+'Combined pigs sold to colco (7)'!J55+'Combined pigs sold to colco (7)'!J56+'Combined pigs sold to colco (7)'!J57+'Combined pigs sold to colco (7)'!J58+'Combined pigs sold to colco (7)'!J67+'Combined pigs sold to colco (7)'!J70+'Combined pigs sold to colco (7)'!J77+'Combined pigs sold to colco (7)'!J80) -> 91.085258 | K21: =SUM('Combined total CDM to Colco (7)'!K24+'Combined total CDM to Colco (7)'!K25+'Combined total CDM to Colco (7)'!K26+'Combined total CDM to Colco (7)'!K27+'Combined total CDM to Colco (7)'!K34+'Combined total CDM to Colco (7)'!K35+'Combined total CDM to Colco (7)'!K36+'Combined total CDM to Colco (7)'!K37+'Combined total CDM to Colco (7)'!K44+'Combined total CDM to Colco (7)'!K45+'Combined total CDM to Colco (7)'!K46+'Combined total CDM to Colco (7)'!K47+'Combined total CDM to Colco (7)'!K54+'Combined total CDM to Colco (7)'!K55+'Combined total CDM to Colco (7)'!K56+'Combined total CDM to Colco (7)'!K57+'Combined total CDM to Colco (7)'!K63+'Combined total CDM to Colco (7)'!K66+'Combined total CDM to Colco (7)'!K73+'Combined total CDM to Colco (7)'!K76)/SUM('Combined pigs sold to colco (7)'!K25+'Combined pigs sold to colco (7)'!K26+'Combined pigs sold to colco (7)'!K27+'Combined pigs sold to colco (7)'!K28+'Combined pigs sold to colco (7)'!K35+'Combined pigs sold to colco (7)'!K36+'Combined pigs sold to colco (7)'!K37+'Combined pigs sold to colco (7)'!K38+'Combined pigs sold to colco (7)'!K45+'Combined pigs sold to colco (7)'!K46+'Combined pigs sold to colco (7)'!K47+'Combined pigs sold to colco (7)'!K48+'Combined pigs sold to colco (7)'!K55+'Combined pigs sold to colco (7)'!K56+'Combined pigs sold to colco (7)'!K57+'Combined pigs sold to colco (7)'!K58+'Combined pigs sold to colco (7)'!K67+'Combined pigs sold to colco (7)'!K70+'Combined pigs sold to colco (7)'!K77+'Combined pigs sold to colco (7)'!K80) -> 92.810121 | ... M21: =SUM('Combined total CDM to Colco (7)'!M24+'Combined total CDM to Colco (7)'!M25+'Combined total CDM to Colco (7)'!M26+'Combined total CDM to Colco (7)'!M27+'Combined total CDM to Colco (7)'!M34+'Combined total CDM to Colco (7)'!M35+'Combined total CDM to Colco (7)'!M36+'Combined total CDM to Colco (7)'!M37+'Combined total CDM to Colco (7)'!M44+'Combined total CDM to Colco (7)'!M45+'Combined total CDM to Colco (7)'!M46+'Combined total CDM to Colco (7)'!M47+'Combined total CDM to Colco (7)'!M54+'Combined total CDM to Colco (7)'!M55+'Combined total CDM to Colco (7)'!M56+'Combined total CDM to Colco (7)'!M57+'Combined total CDM to Colco (7)'!M63+'Combined total CDM to Colco (7)'!M66+'Combined total CDM to Colco (7)'!M73+'Combined total CDM to Colco (7)'!M76)/SUM('Combined pigs sold to colco (7)'!M25+'Combined pigs sold to colco (7)'!M26+'Combined pigs sold to colco (7)'!M27+'Combined pigs sold to colco (7)'!M28+'Combined pigs sold to colco (7)'!M35+'Combined pigs sold to colco (7)'!M36+'Combined pigs sold to colco (7)'!M37+'Combined pigs sold to colco (7)'!M38+'Combined pigs sold to colco (7)'!M45+'Combined pigs sold to colco (7)'!M46+'Combined pigs sold to colco (7)'!M47+'Combined pigs sold to colco (7)'!M48+'Combined pigs sold to colco (7)'!M55+'Combined pigs sold to colco (7)'!M56+'Combined pigs sold to colco (7)'!M57+'Combined pigs sold to colco (7)'!M58+'Combined pigs sold to colco (7)'!M67+'Combined pigs sold to colco (7)'!M70+'Combined pigs sold to colco (7)'!M77+'Combined pigs sold to colco (7)'!M80) -> 93.757083 | N21: =AVERAGE(B21:M21) -> 92.689329
A22: Budgeted to colcom | B22: ='[3]Combined Avg CDM actual vs (7)'!B22 -> 92.897182 | C22: ='[3]Combined Avg CDM actual vs (7)'!C22 -> 92.925316 | D22: ='[3]Combined Avg CDM actual vs (7)'!D22 -> 90.60396 | E22: ='[3]Combined Avg CDM actual vs (7)'!E22 -> 90.596892 | F22: ='[3]Combined Avg CDM actual vs (7)'!F22 -> 90.61382 | G22: ='[3]Combined Avg CDM actual vs (7)'!G22 -> 90.62354 | H22: ='[3]Combined Avg CDM actual vs (7)'!H22 -> 90.597443 | I22: ='[3]Combined Avg CDM actual vs (7)'!I22 -> 90.568708 | ... M22: ='[3]Combined Avg CDM actual vs (7)'!M22 -> 92.776936 | N22: =AVERAGE(B22:M22) -> 91.519243 | O22: =N21-N22 -> 1.1700856 | P22: ahead of budget
A23: Fy 25 | B23: ='[4]Combined Avg CDM actual vs (7)'!B21 -> 91.501317 | C23: ='[4]Combined Avg CDM actual vs (7)'!C21 -> 95.226758 | D23: ='[4]Combined Avg CDM actual vs (7)'!D21 -> 95.959414 | E23: ='[4]Combined Avg CDM actual vs (7)'!E21 -> 96.068907 | F23: ='[4]Combined Avg CDM actual vs (7)'!F21 -> 94.114944 | G23: ='[4]Combined Avg CDM actual vs (7)'!G21 -> 92.134462 | H23: ='[4]Combined Avg CDM actual vs (7)'!H21 -> 94.300437 | I23: ='[4]Combined Avg CDM actual vs (7)'!I21 -> 93.798979 | ... M23: ='[4]Combined Avg CDM actual vs (7)'!M21 -> 94.974267
A24: Fy24 | B24: ='[4]Combined Avg CDM actual vs (7)'!B23 -> 87.051416 | C24: ='[4]Combined Avg CDM actual vs (7)'!C23 -> 90.591373 | D24: ='[4]Combined Avg CDM actual vs (7)'!D23 -> 90.507186 | E24: ='[4]Combined Avg CDM actual vs (7)'!E23 -> 88.923795 | F24: ='[4]Combined Avg CDM actual vs (7)'!F23 -> 88.692625 | G24: ='[4]Combined Avg CDM actual vs (7)'!G23 -> 88.543657 | H24: ='[4]Combined Avg CDM actual vs (7)'!H23 -> 88.74445 | I24: ='[4]Combined Avg CDM actual vs (7)'!I23 -> 87.2017 | ... M24: ='[4]Combined Avg CDM actual vs (7)'!M23 -> 86.658772
A25: FY23 | B25: 87.051416 | C25: 90.591373 | D25: 90.507186 | E25: 88.923795 | F25: 88.692625 | G25: 88.543657 | H25: 88.74445 | I25: 87.2017 | J25: 84.531381 | K25: 86.554336 | L25: 87.220425 | M25: 86.658772
B27: 45839 | C27: 45870 | D27: 45901 | E27: 45931 | F27: 45962 | G27: 45992 | H27: 46023 | I27: 46054 | J27: 46082 | K27: 46113 | L27: 46143 | M27: 46174 | N27: Total
A28: Grasmere grower | B28: =IFERROR('Combined total CDM to Colco (7)'!B24/'Combined pigs sold to colco (7)'!B25,0) -> 97.118378 | C28: =IFERROR('Combined total CDM to Colco (7)'!C24/'Combined pigs sold to colco (7)'!C25,0) -> 96.123267 | D28: =IFERROR('Combined total CDM to Colco (7)'!D24/'Combined pigs sold to colco (7)'!D25,0) -> 94.753575 | E28: =IFERROR('Combined total CDM to Colco (7)'!E24/'Combined pigs sold to colco (7)'!E25,0) -> 92.617441 | F28: =IFERROR('Combined total CDM to Colco (7)'!F24/'Combined pigs sold to colco (7)'!F25,0) -> 92.111768 | G28: =IFERROR('Combined total CDM to Colco (7)'!G24/'Combined pigs sold to colco (7)'!G25,0) -> 89.73756 | H28: =IFERROR('Combined total CDM to Colco (7)'!H24/'Combined pigs sold to colco (7)'!H25,0) -> 95.159898 | I28: =IFERROR('Combined total CDM to Colco (7)'!I24/'Combined pigs sold to colco (7)'!I25,0) -> 94.147987 | ... M28: =IFERROR('Combined total CDM to Colco (7)'!M24/'Combined pigs sold to colco (7)'!M25,0) -> 95.851922 | N28: =SUM(B28:M28) -> 1130.7727
A29: Grasmere LH ext | B29: =IFERROR('Combined total CDM to Colco (7)'!B25/'Combined pigs sold to colco (7)'!B26,0) -> 0 | C29: =IFERROR('Combined total CDM to Colco (7)'!C25/'Combined pigs sold to colco (7)'!C26,0) -> 0 | D29: =IFERROR('Combined total CDM to Colco (7)'!D25/'Combined pigs sold to colco (7)'!D26,0) -> 0 | E29: =IFERROR('Combined total CDM to Colco (7)'!E25/'Combined pigs sold to colco (7)'!E26,0) -> 0 | F29: =IFERROR('Combined total CDM to Colco (7)'!F25/'Combined pigs sold to colco (7)'!F26,0) -> 0 | G29: =IFERROR('Combined total CDM to Colco (7)'!G25/'Combined pigs sold to colco (7)'!G26,0) -> 0 | H29: =IFERROR('Combined total CDM to Colco (7)'!H25/'Combined pigs sold to colco (7)'!H26,0) -> 0 | I29: =IFERROR('Combined total CDM to Colco (7)'!I25/'Combined pigs sold to colco (7)'!I26,0) -> 0 | ... M29: =IFERROR('Combined total CDM to Colco (7)'!M25/'Combined pigs sold to colco (7)'!M26,0) -> 0 | N29: =SUM(B29:M29) -> 81.272
A30: Grasmere Learig | B30: =IFERROR('Combined total CDM to Colco (7)'!B26/'Combined pigs sold to colco (7)'!B27,0) -> 98.361596 | C30: =IFERROR('Combined total CDM to Colco (7)'!C26/'Combined pigs sold to colco (7)'!C27,0) -> 99.271238 | D30: =IFERROR('Combined total CDM to Colco (7)'!D26/'Combined pigs sold to colco (7)'!D27,0) -> 97.391463 | E30: =IFERROR('Combined total CDM to Colco (7)'!E26/'Combined pigs sold to colco (7)'!E27,0) -> 97.30958 | F30: =IFERROR('Combined total CDM to Colco (7)'!F26/'Combined pigs sold to colco (7)'!F27,0) -> 97.532155 | G30: =IFERROR('Combined total CDM to Colco (7)'!G26/'Combined pigs sold to colco (7)'!G27,0) -> 95.664332 | H30: =IFERROR('Combined total CDM to Colco (7)'!H26/'Combined pigs sold to colco (7)'!H27,0) -> 96.733025 | I30: =IFERROR('Combined total CDM to Colco (7)'!I26/'Combined pigs sold to colco (7)'!I27,0) -> 98.839798 | ... M30: =IFERROR('Combined total CDM to Colco (7)'!M26/'Combined pigs sold to colco (7)'!M27,0) -> 99.054169 | N30: =SUM(B30:M30) -> 1178.0258
A31: Grasmere sow | B31: =IFERROR('Combined total CDM to Colco (7)'!B27/'Combined pigs sold to colco (7)'!B28,0) -> 154.99388 | C31: =IFERROR('Combined total CDM to Colco (7)'!C27/'Combined pigs sold to colco (7)'!C28,0) -> 0 | D31: =IFERROR('Combined total CDM to Colco (7)'!D27/'Combined pigs sold to colco (7)'!D28,0) -> 194.4 | E31: =IFERROR('Combined total CDM to Colco (7)'!E27/'Combined pigs sold to colco (7)'!E28,0) -> 0 | F31: =IFERROR('Combined total CDM to Colco (7)'!F27/'Combined pigs sold to colco (7)'!F28,0) -> 174.97826 | G31: =IFERROR('Combined total CDM to Colco (7)'!G27/'Combined pigs sold to colco (7)'!G28,0) -> 147.55714 | H31: =IFERROR('Combined total CDM to Colco (7)'!H27/'Combined pigs sold to colco (7)'!H28,0) -> 169.31 | I31: =IFERROR('Combined total CDM to Colco (7)'!I27/'Combined pigs sold to colco (7)'!I28,0) -> 167.93846 | ... M31: =IFERROR('Combined total CDM to Colco (7)'!M27/'Combined pigs sold to colco (7)'!M28,0) -> 179.20588 | N31: =SUM(B31:M31) -> 1699.1769
A32: Grasmere ration & donations | B32: =IFERROR('Combined total CDM to Colco (7)'!B28/'Combined pigs sold to colco (7)'!B29,0) -> 140.86 | C32: =IFERROR('Combined total CDM to Colco (7)'!C28/'Combined pigs sold to colco (7)'!C29,0) -> 127.2 | D32: =IFERROR('Combined total CDM to Colco (7)'!D28/'Combined pigs sold to colco (7)'!D29,0) -> 147.18889 | E32: =IFERROR('Combined total CDM to Colco (7)'!E28/'Combined pigs sold to colco (7)'!E29,0) -> 141.66286 | F32: =IFERROR('Combined total CDM to Colco (7)'!F28/'Combined pigs sold to colco (7)'!F29,0) -> 80.641971 | G32: =IFERROR('Combined total CDM to Colco (7)'!G28/'Combined pigs sold to colco (7)'!G29,0) -> 92.402716 | H32: =IFERROR('Combined total CDM to Colco (7)'!H28/'Combined pigs sold to colco (7)'!H29,0) -> 73.788674 | I32: =IFERROR('Combined total CDM to Colco (7)'!I28/'Combined pigs sold to colco (7)'!I29,0) -> 129.81919 | ... M32: =IFERROR('Combined total CDM to Colco (7)'!M28/'Combined pigs sold to colco (7)'!M29,0) -> 105.16355 | N32: =SUM(B32:M32) -> 1310.6535
A33: Grasmere internal gilts & out growers
A34: Grasmere external farm sales
A35: Pet Food | B35: =IFERROR('Combined total CDM to Colco (7)'!B31/'Combined pigs sold to colco (7)'!B32,0) -> 0 | C35: =IFERROR('Combined total CDM to Colco (7)'!C31/'Combined pigs sold to colco (7)'!C32,0) -> 0 | D35: =IFERROR('Combined total CDM to Colco (7)'!D31/'Combined pigs sold to colco (7)'!D32,0) -> 0 | E35: =IFERROR('Combined total CDM to Colco (7)'!E31/'Combined pigs sold to colco (7)'!E32,0) -> 0 | N35: =SUM(B35:M35) -> 0
B36: =IFERROR('Combined total CDM to Colco (7)'!B32/'Combined pigs sold to colco (7)'!B33,0) -> 93.266627 | C36: =IFERROR('Combined total CDM to Colco (7)'!C32/'Combined pigs sold to colco (7)'!C33,0) -> 90.915318 | D36: =IFERROR('Combined total CDM to Colco (7)'!D32/'Combined pigs sold to colco (7)'!D33,0) -> 89.802528 | E36: =IFERROR('Combined total CDM to Colco (7)'!E32/'Combined pigs sold to colco (7)'!E33,0) -> 89.353864 | F36: =IFERROR('Combined total CDM to Colco (7)'!F32/'Combined pigs sold to colco (7)'!F33,0) -> 92.194795 | G36: =IFERROR('Combined total CDM to Colco (7)'!G32/'Combined pigs sold to colco (7)'!G33,0) -> 90.511495 | H36: =IFERROR('Combined total CDM to Colco (7)'!H32/'Combined pigs sold to colco (7)'!H33,0) -> 94.606726 | I36: =IFERROR('Combined total CDM to Colco (7)'!I32/'Combined pigs sold to colco (7)'!I33,0) -> 95.529111 | ... M36: =IFERROR('Combined total CDM to Colco (7)'!M32/'Combined pigs sold to colco (7)'!M33,0) -> 96.979281 | N36: =SUM(N28:N35) -> 5399.9009
A38: Richlands grower | B38: =IFERROR('Combined total CDM to Colco (7)'!B34/'Combined pigs sold to colco (7)'!B35,0) -> 91.033564 | C38: =IFERROR('Combined total CDM to Colco (7)'!C34/'Combined pigs sold to colco (7)'!C35,0) -> 93.094761 | D38: =IFERROR('Combined total CDM to Colco (7)'!D34/'Combined pigs sold to colco (7)'!D35,0) -> 90.934743 | E38: =IFERROR('Combined total CDM to Colco (7)'!E34/'Combined pigs sold to colco (7)'!E35,0) -> 89.357998 | F38: =IFERROR('Combined total CDM to Colco (7)'!F34/'Combined pigs sold to colco (7)'!F35,0) -> 88.21032 | G38: =IFERROR('Combined total CDM to Colco (7)'!G34/'Combined pigs sold to colco (7)'!G35,0) -> 88.607769 | H38: =IFERROR('Combined total CDM to Colco (7)'!H34/'Combined pigs sold to colco (7)'!H35,0) -> 88.224721 | I38: =IFERROR('Combined total CDM to Colco (7)'!I34/'Combined pigs sold to colco (7)'!I35,0) -> 87.922888 | ... M38: =IFERROR('Combined total CDM to Colco (7)'!M34/'Combined pigs sold to colco (7)'!M35,0) -> 89.798669 | N38: =SUM(B38:M38) -> 1068.7217
A39: Richlands LH ext | B39: =IFERROR('Combined total CDM to Colco (7)'!B35/'Combined pigs sold to colco (7)'!B36,0) -> 91.31374 | C39: =IFERROR('Combined total CDM to Colco (7)'!C35/'Combined pigs sold to colco (7)'!C36,0) -> 95.885769 | D39: =IFERROR('Combined total CDM to Colco (7)'!D35/'Combined pigs sold to colco (7)'!D36,0) -> 91.928342 | E39: =IFERROR('Combined total CDM to Colco (7)'!E35/'Combined pigs sold to colco (7)'!E36,0) -> 87.854194 | F39: =IFERROR('Combined total CDM to Colco (7)'!F35/'Combined pigs sold to colco (7)'!F36,0) -> 91.24 | G39: =IFERROR('Combined total CDM to Colco (7)'!G35/'Combined pigs sold to colco (7)'!G36,0) -> 85.6725 | H39: =IFERROR('Combined total CDM to Colco (7)'!H35/'Combined pigs sold to colco (7)'!H36,0) -> 83.060465 | I39: =IFERROR('Combined total CDM to Colco (7)'!I35/'Combined pigs sold to colco (7)'!I36,0) -> 85.586849 | ... M39: =IFERROR('Combined total CDM to Colco (7)'!M35/'Combined pigs sold to colco (7)'!M36,0) -> 89.113684 | N39: =SUM(B39:M39) -> 1066.0094
A40: Richlands Learig | B40: =IFERROR('Combined total CDM to Colco (7)'!B36/'Combined pigs sold to colco (7)'!B37,0) -> 96.75 | C40: =IFERROR('Combined total CDM to Colco (7)'!C36/'Combined pigs sold to colco (7)'!C37,0) -> 100.11993 | D40: =IFERROR('Combined total CDM to Colco (7)'!D36/'Combined pigs sold to colco (7)'!D37,0) -> 96.280822 | E40: =IFERROR('Combined total CDM to Colco (7)'!E36/'Combined pigs sold to colco (7)'!E37,0) -> 99.050427 | F40: =IFERROR('Combined total CDM to Colco (7)'!F36/'Combined pigs sold to colco (7)'!F37,0) -> 95.314078 | G40: =IFERROR('Combined total CDM to Colco (7)'!G36/'Combined pigs sold to colco (7)'!G37,0) -> 89.510895 | H40: =IFERROR('Combined total CDM to Colco (7)'!H36/'Combined pigs sold to colco (7)'!H37,0) -> 92.608247 | I40: =IFERROR('Combined total CDM to Colco (7)'!I36/'Combined pigs sold to colco (7)'!I37,0) -> 91.698485 | ... M40: =IFERROR('Combined total CDM to Colco (7)'!M36/'Combined pigs sold to colco (7)'!M37,0) -> 96.319732 | N40: =SUM(B40:M40) -> 954.31883
A41: Richlands sow | B41: =IFERROR('Combined total CDM to Colco (7)'!B37/'Combined pigs sold to colco (7)'!B38,0) -> 175.6 | C41: =IFERROR('Combined total CDM to Colco (7)'!C37/'Combined pigs sold to colco (7)'!C38,0) -> 172.835 | D41: =IFERROR('Combined total CDM to Colco (7)'!D37/'Combined pigs sold to colco (7)'!D38,0) -> 173.66818 | E41: =IFERROR('Combined total CDM to Colco (7)'!E37/'Combined pigs sold to colco (7)'!E38,0) -> 169.39512 | F41: =IFERROR('Combined total CDM to Colco (7)'!F37/'Combined pigs sold to colco (7)'!F38,0) -> 168.15357 | G41: =IFERROR('Combined total CDM to Colco (7)'!G37/'Combined pigs sold to colco (7)'!G38,0) -> 157.20588 | H41: =IFERROR('Combined total CDM to Colco (7)'!H37/'Combined pigs sold to colco (7)'!H38,0) -> 173.5359 | I41: =IFERROR('Combined total CDM to Colco (7)'!I37/'Combined pigs sold to colco (7)'!I38,0) -> 168.06047 | ... M41: =IFERROR('Combined total CDM to Colco (7)'!M37/'Combined pigs sold to colco (7)'!M38,0) -> 178.17059 | N41: =SUM(B41:M41) -> 2038.0292
A42: Richlands ration & donations | B42: =IFERROR('Combined total CDM to Colco (7)'!B38/'Combined pigs sold to colco (7)'!B39,0) -> 66.336364 | C42: =IFERROR('Combined total CDM to Colco (7)'!C38/'Combined pigs sold to colco (7)'!C39,0) -> 62.808333 | D42: =IFERROR('Combined total CDM to Colco (7)'!D38/'Combined pigs sold to colco (7)'!D39,0) -> 65.7875 | E42: =IFERROR('Combined total CDM to Colco (7)'!E38/'Combined pigs sold to colco (7)'!E39,0) -> 60.308333 | F42: =IFERROR('Combined total CDM to Colco (7)'!F38/'Combined pigs sold to colco (7)'!F39,0) -> 104.74286 | G42: =IFERROR('Combined total CDM to Colco (7)'!G38/'Combined pigs sold to colco (7)'!G39,0) -> 53.631579 | H42: =IFERROR('Combined total CDM to Colco (7)'!H38/'Combined pigs sold to colco (7)'!H39,0) -> 60.641667 | I42: =IFERROR('Combined total CDM to Colco (7)'!I38/'Combined pigs sold to colco (7)'!I39,0) -> 42.983333 | ... M42: =IFERROR('Combined total CDM to Colco (7)'!M38/'Combined pigs sold to colco (7)'!M39,0) -> 57.870588 | N42: =SUM(B42:M42) -> 761.27944
A43: Richlands internal gilts & out growers | L43: =IFERROR('[5]COMBINED CDM (5)'!L40/'[5]COMBINED PIGS SOLD (5)'!L40,0) -> 0 | M43: =IFERROR('[5]COMBINED CDM (5)'!M40/'[5]COMBINED PIGS SOLD (5)'!M40,0) -> 0
A44: Richlands external farm sales | L44: =IFERROR('[5]COMBINED CDM (5)'!L41/'[5]COMBINED PIGS SOLD (5)'!L41,0) -> 0 | M44: =IFERROR('[5]COMBINED CDM (5)'!M41/'[5]COMBINED PIGS SOLD (5)'!M41,0) -> 0
A45: Pet Food | L45: =IFERROR('[5]COMBINED CDM (5)'!L42/'[5]COMBINED PIGS SOLD (5)'!L42,0) -> 0 | M45: =IFERROR('[5]COMBINED CDM (5)'!M42/'[5]COMBINED PIGS SOLD (5)'!M42,0) -> 0 | N45: =SUM(B45:M45) -> 0
B46: =IFERROR('Combined total CDM to Colco (7)'!B42/'Combined pigs sold to colco (7)'!B43,0) -> 90.6943 | C46: =IFERROR('Combined total CDM to Colco (7)'!C42/'Combined pigs sold to colco (7)'!C43,0) -> 93.008613 | D46: =IFERROR('Combined total CDM to Colco (7)'!D42/'Combined pigs sold to colco (7)'!D43,0) -> 91.02378 | E46: =IFERROR('Combined total CDM to Colco (7)'!E42/'Combined pigs sold to colco (7)'!E43,0) -> 89.169141 | F46: =IFERROR('Combined total CDM to Colco (7)'!F42/'Combined pigs sold to colco (7)'!F43,0) -> 89.216565 | G46: =IFERROR('Combined total CDM to Colco (7)'!G42/'Combined pigs sold to colco (7)'!G43,0) -> 87.005552 | H46: =IFERROR('Combined total CDM to Colco (7)'!H42/'Combined pigs sold to colco (7)'!H43,0) -> 87.16113 | I46: =IFERROR('Combined total CDM to Colco (7)'!I42/'Combined pigs sold to colco (7)'!I43,0) -> 87.117085 | ... M46: =IFERROR('Combined total CDM to Colco (7)'!M42/'Combined pigs sold to colco (7)'!M43,0) -> 89.775151 | N46: =SUM(N38:N45) -> 5888.3586
A48: Lions Head grower | B48: =IFERROR('Combined total CDM to Colco (7)'!B44/'Combined pigs sold to colco (7)'!B45,0) -> 91.825945 | C48: =IFERROR('Combined total CDM to Colco (7)'!C44/'Combined pigs sold to colco (7)'!C45,0) -> 91.745983 | D48: =IFERROR('Combined total CDM to Colco (7)'!D44/'Combined pigs sold to colco (7)'!D45,0) -> 90.447366 | E48: =IFERROR('Combined total CDM to Colco (7)'!E44/'Combined pigs sold to colco (7)'!E45,0) -> 89.297288 | F48: =IFERROR('Combined total CDM to Colco (7)'!F44/'Combined pigs sold to colco (7)'!F45,0) -> 89.414393 | G48: =IFERROR('Combined total CDM to Colco (7)'!G44/'Combined pigs sold to colco (7)'!G45,0) -> 89.827884 | H48: =IFERROR('Combined total CDM to Colco (7)'!H44/'Combined pigs sold to colco (7)'!H45,0) -> 88.086641 | I48: =IFERROR('Combined total CDM to Colco (7)'!I44/'Combined pigs sold to colco (7)'!I45,0) -> 85.81671 | ... M48: =IFERROR('Combined total CDM to Colco (7)'!M44/'Combined pigs sold to colco (7)'!M45,0) -> 88.785949 | N48: =SUM(B48:M48) -> 1068.8356
A49: Lions Head LH ext | B49: =IFERROR('Combined total CDM to Colco (7)'!B45/'Combined pigs sold to colco (7)'!B46,0) -> 92.901295 | C49: =IFERROR('Combined total CDM to Colco (7)'!C45/'Combined pigs sold to colco (7)'!C46,0) -> 96.21811 | D49: =IFERROR('Combined total CDM to Colco (7)'!D45/'Combined pigs sold to colco (7)'!D46,0) -> 91.204811 | E49: =IFERROR('Combined total CDM to Colco (7)'!E45/'Combined pigs sold to colco (7)'!E46,0) -> 93.184932 | F49: =IFERROR('Combined total CDM to Colco (7)'!F45/'Combined pigs sold to colco (7)'!F46,0) -> 88.01685 | G49: =IFERROR('Combined total CDM to Colco (7)'!G45/'Combined pigs sold to colco (7)'!G46,0) -> 89.408824 | H49: =IFERROR('Combined total CDM to Colco (7)'!H45/'Combined pigs sold to colco (7)'!H46,0) -> 83.060905 | I49: =IFERROR('Combined total CDM to Colco (7)'!I45/'Combined pigs sold to colco (7)'!I46,0) -> 85.302655 | ... M49: =IFERROR('Combined total CDM to Colco (7)'!M45/'Combined pigs sold to colco (7)'!M46,0) -> 89.151399 | N49: =SUM(B49:M49) -> 1065.6519
A50: Lions Head Learig | B50: =IFERROR('Combined total CDM to Colco (7)'!B46/'Combined pigs sold to colco (7)'!B47,0) -> 0 | C50: =IFERROR('Combined total CDM to Colco (7)'!C46/'Combined pigs sold to colco (7)'!C47,0) -> 0 | D50: =IFERROR('Combined total CDM to Colco (7)'!D46/'Combined pigs sold to colco (7)'!D47,0) -> 0 | E50: =IFERROR('Combined total CDM to Colco (7)'!E46/'Combined pigs sold to colco (7)'!E47,0) -> 0 | F50: =IFERROR('Combined total CDM to Colco (7)'!F46/'Combined pigs sold to colco (7)'!F47,0) -> 0 | G50: =IFERROR('Combined total CDM to Colco (7)'!G46/'Combined pigs sold to colco (7)'!G47,0) -> 0 | H50: =IFERROR('Combined total CDM to Colco (7)'!H46/'Combined pigs sold to colco (7)'!H47,0) -> 0 | I50: =IFERROR('Combined total CDM to Colco (7)'!I46/'Combined pigs sold to colco (7)'!I47,0) -> 0 | ... M50: =IFERROR('Combined total CDM to Colco (7)'!M46/'Combined pigs sold to colco (7)'!M47,0) -> 0 | N50: =SUM(B50:M50) -> 0
A51: Lions Head sow | B51: =IFERROR('Combined total CDM to Colco (7)'!B47/'Combined pigs sold to colco (7)'!B48,0) -> 165.99444 | C51: =IFERROR('Combined total CDM to Colco (7)'!C47/'Combined pigs sold to colco (7)'!C48,0) -> 173.26 | D51: =IFERROR('Combined total CDM to Colco (7)'!D47/'Combined pigs sold to colco (7)'!D48,0) -> 158.51429 | E51: =IFERROR('Combined total CDM to Colco (7)'!E47/'Combined pigs sold to colco (7)'!E48,0) -> 166.91471 | F51: =IFERROR('Combined total CDM to Colco (7)'!F47/'Combined pigs sold to colco (7)'!F48,0) -> 158.40833 | G51: =IFERROR('Combined total CDM to Colco (7)'!G47/'Combined pigs sold to colco (7)'!G48,0) -> 168.00556 | H51: =IFERROR('Combined total CDM to Colco (7)'!H47/'Combined pigs sold to colco (7)'!H48,0) -> 180.496 | I51: =IFERROR('Combined total CDM to Colco (7)'!I47/'Combined pigs sold to colco (7)'!I48,0) -> 174.475 | ... M51: =IFERROR('Combined total CDM to Colco (7)'!M47/'Combined pigs sold to colco (7)'!M48,0) -> 177.39643 | N51: =SUM(B51:M51) -> 2054.633
A52: Lions Head ration & donations | B52: =IFERROR('Combined total CDM to Colco (7)'!B48/'Combined pigs sold to colco (7)'!B49,0) -> 58.896667 | C52: =IFERROR('Combined total CDM to Colco (7)'!C48/'Combined pigs sold to colco (7)'!C49,0) -> 38.744222 | D52: =IFERROR('Combined total CDM to Colco (7)'!D48/'Combined pigs sold to colco (7)'!D49,0) -> 76.406897 | E52: =IFERROR('Combined total CDM to Colco (7)'!E48/'Combined pigs sold to colco (7)'!E49,0) -> 82.645455 | F52: =IFERROR('Combined total CDM to Colco (7)'!F48/'Combined pigs sold to colco (7)'!F49,0) -> 84.482273 | G52: =IFERROR('Combined total CDM to Colco (7)'!G48/'Combined pigs sold to colco (7)'!G49,0) -> 71.539062 | H52: =IFERROR('Combined total CDM to Colco (7)'!H48/'Combined pigs sold to colco (7)'!H49,0) -> 57.340909 | I52: =IFERROR('Combined total CDM to Colco (7)'!I48/'Combined pigs sold to colco (7)'!I49,0) -> 66.14 | ... M52: =IFERROR('Combined total CDM to Colco (7)'!M48/'Combined pigs sold to colco (7)'!M49,0) -> 78.207692 | N52: =SUM(B52:M52) -> 884.27302
A53: Lionshead internal gilts & out growers | L53: =IFERROR('[5]COMBINED CDM (5)'!L50/'[5]COMBINED PIGS SOLD (5)'!L50,0) -> 0 | M53: =IFERROR('[5]COMBINED CDM (5)'!M50/'[5]COMBINED PIGS SOLD (5)'!M50,0) -> 0
A54: Lionshead external farm sales | L54: =IFERROR('[5]COMBINED CDM (5)'!L51/'[5]COMBINED PIGS SOLD (5)'!L51,0) -> 0 | M54: =IFERROR('[5]COMBINED CDM (5)'!M51/'[5]COMBINED PIGS SOLD (5)'!M51,0) -> 0
A55: Pet Food | L55: =IFERROR('[5]COMBINED CDM (5)'!L52/'[5]COMBINED PIGS SOLD (5)'!L52,0) -> 0 | M55: =IFERROR('[5]COMBINED CDM (5)'!M52/'[5]COMBINED PIGS SOLD (5)'!M52,0) -> 0 | N55: =SUM(B55:M55) -> 0
B56: =IFERROR('Combined total CDM to Colco (7)'!B52/'Combined pigs sold to colco (7)'!B53,0) -> 92.107422 | C56: =IFERROR('Combined total CDM to Colco (7)'!C52/'Combined pigs sold to colco (7)'!C53,0) -> 91.144383 | D56: =IFERROR('Combined total CDM to Colco (7)'!D52/'Combined pigs sold to colco (7)'!D53,0) -> 90.542012 | E56: =IFERROR('Combined total CDM to Colco (7)'!E52/'Combined pigs sold to colco (7)'!E53,0) -> 90.491764 | F56: =IFERROR('Combined total CDM to Colco (7)'!F52/'Combined pigs sold to colco (7)'!F53,0) -> 89.891211 | G56: =IFERROR('Combined total CDM to Colco (7)'!G52/'Combined pigs sold to colco (7)'!G53,0) -> 90.06522 | H56: =IFERROR('Combined total CDM to Colco (7)'!H52/'Combined pigs sold to colco (7)'!H53,0) -> 88.244232 | I56: =IFERROR('Combined total CDM to Colco (7)'!I52/'Combined pigs sold to colco (7)'!I53,0) -> 86.780721 | ... M56: =IFERROR('Combined total CDM to Colco (7)'!M52/'Combined pigs sold to colco (7)'!M53,0) -> 89.471187 | N56: =SUM(N48:N55) -> 5073.3934
A58: Villa grower | B58: =IFERROR('Combined total CDM to Colco (7)'!B54/'Combined pigs sold to colco (7)'!B55,0) -> 95.706365 | C58: =IFERROR('Combined total CDM to Colco (7)'!C54/'Combined pigs sold to colco (7)'!C55,0) -> 97.683595 | D58: =IFERROR('Combined total CDM to Colco (7)'!D54/'Combined pigs sold to colco (7)'!D55,0) -> 93.888743 | E58: =IFERROR('Combined total CDM to Colco (7)'!E54/'Combined pigs sold to colco (7)'!E55,0) -> 96.313306 | F58: =IFERROR('Combined total CDM to Colco (7)'!F54/'Combined pigs sold to colco (7)'!F55,0) -> 96.654269 | G58: =IFERROR('Combined total CDM to Colco (7)'!G54/'Combined pigs sold to colco (7)'!G55,0) -> 94.258199 | H58: =IFERROR('Combined total CDM to Colco (7)'!H54/'Combined pigs sold to colco (7)'!H55,0) -> 96.337475 | I58: =IFERROR('Combined total CDM to Colco (7)'!I54/'Combined pigs sold to colco (7)'!I55,0) -> 95.300319 | ... M58: =IFERROR('Combined total CDM to Colco (7)'!M54/'Combined pigs sold to colco (7)'!M55,0) -> 95.268556 | N58: =SUM(B58:M58) -> 1132.2398
A59: Villa LH ext | B59: =IFERROR('Combined total CDM to Colco (7)'!B55/'Combined pigs sold to colco (7)'!B56,0) -> 90.856522 | C59: =IFERROR('Combined total CDM to Colco (7)'!C55/'Combined pigs sold to colco (7)'!C56,0) -> 94.224725 | D59: =IFERROR('Combined total CDM to Colco (7)'!D55/'Combined pigs sold to colco (7)'!D56,0) -> 91.505848 | E59: =IFERROR('Combined total CDM to Colco (7)'!E55/'Combined pigs sold to colco (7)'!E56,0) -> 84.333047 | F59: =IFERROR('Combined total CDM to Colco (7)'!F55/'Combined pigs sold to colco (7)'!F56,0) -> 85.387407 | G59: =IFERROR('Combined total CDM to Colco (7)'!G55/'Combined pigs sold to colco (7)'!G56,0) -> 83.269712 | H59: =IFERROR('Combined total CDM to Colco (7)'!H55/'Combined pigs sold to colco (7)'!H56,0) -> 88.916239 | I59: =IFERROR('Combined total CDM to Colco (7)'!I55/'Combined pigs sold to colco (7)'!I56,0) -> 85.943478 | ... M59: =IFERROR('Combined total CDM to Colco (7)'!M55/'Combined pigs sold to colco (7)'!M56,0) -> 88.233803 | N59: =SUM(B59:M59) -> 1051.7161
A60: Villa Learig | B60: =IFERROR('Combined total CDM to Colco (7)'!B56/'Combined pigs sold to colco (7)'!B57,0) -> 96.207563 | C60: =IFERROR('Combined total CDM to Colco (7)'!C56/'Combined pigs sold to colco (7)'!C57,0) -> 99.276289 | D60: =IFERROR('Combined total CDM to Colco (7)'!D56/'Combined pigs sold to colco (7)'!D57,0) -> 97.178743 | E60: =IFERROR('Combined total CDM to Colco (7)'!E56/'Combined pigs sold to colco (7)'!E57,0) -> 98.072908 | F60: =IFERROR('Combined total CDM to Colco (7)'!F56/'Combined pigs sold to colco (7)'!F57,0) -> 95.878986 | G60: =IFERROR('Combined total CDM to Colco (7)'!G56/'Combined pigs sold to colco (7)'!G57,0) -> 97.484112 | H60: =IFERROR('Combined total CDM to Colco (7)'!H56/'Combined pigs sold to colco (7)'!H57,0) -> 91.362736 | I60: =IFERROR('Combined total CDM to Colco (7)'!I56/'Combined pigs sold to colco (7)'!I57,0) -> 96.701439 | ... M60: =IFERROR('Combined total CDM to Colco (7)'!M56/'Combined pigs sold to colco (7)'!M57,0) -> 92.927174 | N60: =SUM(B60:M60) -> 1152.4703
A61: Villa sow | B61: =IFERROR('Combined total CDM to Colco (7)'!B57/'Combined pigs sold to colco (7)'!B58,0) -> 188.82778 | C61: =IFERROR('Combined total CDM to Colco (7)'!C57/'Combined pigs sold to colco (7)'!C58,0) -> 185.41875 | D61: =IFERROR('Combined total CDM to Colco (7)'!D57/'Combined pigs sold to colco (7)'!D58,0) -> 182.0619 | E61: =IFERROR('Combined total CDM to Colco (7)'!E57/'Combined pigs sold to colco (7)'!E58,0) -> 173.74167 | F61: =IFERROR('Combined total CDM to Colco (7)'!F57/'Combined pigs sold to colco (7)'!F58,0) -> 179.55 | G61: =IFERROR('Combined total CDM to Colco (7)'!G57/'Combined pigs sold to colco (7)'!G58,0) -> 163.31667 | H61: =IFERROR('Combined total CDM to Colco (7)'!H57/'Combined pigs sold to colco (7)'!H58,0) -> 173.30625 | I61: =IFERROR('Combined total CDM to Colco (7)'!I57/'Combined pigs sold to colco (7)'!I58,0) -> 180.17273 | ... M61: =IFERROR('Combined total CDM to Colco (7)'!M57/'Combined pigs sold to colco (7)'!M58,0) -> 178.47778 | N61: =SUM(B61:M61) -> 2121.2204
...

Sheet Combined pigs sold to colco (7)
N2: excludes gilts, pet food, ration etc etc
A3: Combined number of pigs to colcom only. Sows and growers. Exclude everything else | N3: includes sows and growers to colcom only
N4: excludes gilt sales to other farms
B18: 45839 | C18: 45870 | D18: 45901 | E18: 45931 | F18: 45962 | G18: 45992 | H18: 46023 | I18: 46054 | J18: 46082 | K18: 46113 | L18: 46143 | M18: 46174
A19: FY26 | B19: =SUM(B25:B28,B35:B38,B55:B58,B45:B48,B67:B70,B77:B80) -> 12702 | C19: =SUM(C25:C28,C35:C38,C55:C58,C45:C48,C67:C70,C77:C80) -> 12574 | D19: =SUM(D25:D28,D35:D38,D55:D58,D45:D48,D67:D70,D77:D80) -> 16281 | E19: =SUM(E25:E28,E35:E38,E55:E58,E45:E48,E67:E70,E77:E80) -> 13615 | F19: =SUM(F25:F28,F35:F38,F55:F58,F45:F48,F67:F70,F77:F80) -> 12833 | G19: =SUM(G25:G28,G35:G38,G55:G58,G45:G48,G67:G70,G77:G80) -> 16244 | H19: =SUM(H25:H28,H35:H38,H55:H58,H45:H48,H67:H70,H77:H80) -> 13100 | I19: =SUM(I25:I28,I35:I38,I55:I58,I45:I48,I67:I70,I77:I80) -> 13661 | ... M19: =SUM(M25:M28,M35:M38,M55:M58,M45:M48,M67:M70,M77:M80) -> 19340 | N19: =SUM(B19:M19) -> 177605
A20: prior year | B20: ='[4]Combined pigs sold to colco (7)'!B19 -> 10100 | C20: ='[4]Combined pigs sold to colco (7)'!C19 -> 9313 | D20: ='[4]Combined pigs sold to colco (7)'!D19 -> 13268 | E20: ='[4]Combined pigs sold to colco (7)'!E19 -> 10526 | F20: ='[4]Combined pigs sold to colco (7)'!F19 -> 10633 | G20: ='[4]Combined pigs sold to colco (7)'!G19 -> 12264 | H20: ='[4]Combined pigs sold to colco (7)'!H19 -> 11208 | I20: ='[4]Combined pigs sold to colco (7)'!I19 -> 10775 | ... M20: ='[4]Combined pigs sold to colco (7)'!M19 -> 13399 | N20: =SUM(B20:M20) -> 138022 | O20: =N19-N20 -> 39583 | P20: =O20/52 -> 761.21154
A21: Budgeted # of pigs | B21: ='[3]Combined pigs sold to colco (7)'!B21 -> 12656.395 | C21: ='[3]Combined pigs sold to colco (7)'!C21 -> 13012.06 | D21: ='[3]Combined pigs sold to colco (7)'!D21 -> 16042.489 | E21: ='[3]Combined pigs sold to colco (7)'!E21 -> 13241.776 | F21: ='[3]Combined pigs sold to colco (7)'!F21 -> 13202.782 | G21: ='[3]Combined pigs sold to colco (7)'!G21 -> 16360.742 | H21: ='[3]Combined pigs sold to colco (7)'!H21 -> 13231.3 | I21: ='[3]Combined pigs sold to colco (7)'!I21 -> 13356.296 | ... M21: ='[3]Combined pigs sold to colco (7)'!M21 -> 17060.024 | N21: =SUM(B21:M21) -> 173122.18 | O21: =N19-N21 -> 4482.82 | P21: =O21/52 -> 86.208077
B24: 45839 | C24: 45870 | D24: 45901 | E24: 45931 | F24: 45962 | G24: 45992 | H24: 46023 | I24: 46054 | J24: 46082 | K24: 46113 | L24: 46143 | M24: 46174 | Q24: 216 | R24: Grasmere
A25: Grasmere grower | B25: =[7]CCC!$C$28-[7]CCC!$C$17 -> 3896 | C25: =[8]CCC!$C$27 -> 3563 | D25: =[9]CCC!$C$27-[9]CCC!$C$16 -> 4601 | E25: =[10]CCC!$C$27-[10]CCC!$C$28 -> 3790 | F25: =[11]CCC!$C$26-[11]CCC!$C$16 -> 3671 | G25: =[12]CCC!$C$27-[12]CCC!$C$17 -> 4763 | H25: =[13]CCC!$C$27-[13]CCC!$C$17 -> 3708 | I25: =[14]CCC!$C$26-[14]CCC!$C$16 -> 3874 | J25: =[15]CCC!$C$28-[15]CCC!$C$17 -> 4840 | K25: =_xlfn.XLOOKUP(" Total:",[16]CCC!$A$1:$A$65536,[16]CCC!$C$1:$C$65536,0)-_xlfn.XLOOKUP("PCSAS",[16]CCC!$A$1:$A$65536,[16]CCC!$C$1:$C$65536,0) -> 3856 | L25: =_xlfn.XLOOKUP(" Total:",[17]CCC!$A$1:$A$65536,[17]CCC!$C$1:$C$65536,0)-_xlfn.XLOOKUP("PCSAS",[17]CCC!$A$1:$A$65536,[17]CCC!$C$1:$C$65536,0) -> 4032 | M25: =_xlfn.XLOOKUP(" Total:",[18]CCC!$A$1:$A$65536,[18]CCC!$C$1:$C$65536,0)-_xlfn.XLOOKUP("PCSAS",[18]CCC!$A$1:$A$65536,[18]CCC!$C$1:$C$65536,0) -> 5204 | Q25: 104 | R25: richlands
A26: Grasmere LH ext | B26: ='[7]CCC Extension'!$C$13 -> 0 | C26: ='[8]CCC Extension'!$C$18 -> 0 | D26: 0 | E26: 0 | G26: ='[12]CCC Extension'!$C$7 -> 0 | I26: 0 | L26: =_xlfn.XLOOKUP(" Total:",'[17]CCC Ext'!$A$1:$A$65536,'[17]CCC Ext'!$C$1:$C$65536,0)-_xlfn.XLOOKUP("PCSAS",'[17]CCC Ext'!$A$1:$A$65536,'[17]CCC Ext'!$C$1:$C$65536,0) -> 50 | M26: =_xlfn.XLOOKUP(" Total:",'[18]CCC Ext'!$A$1:$A$65536,'[18]CCC Ext'!$C$1:$C$65536,0)-_xlfn.XLOOKUP("PCSAS",'[18]CCC Ext'!$A$1:$A$65536,'[18]CCC Ext'!$C$1:$C$65536,0) -> 0 | Q26: =SUM(Q24:Q25) -> 320 | R26: pigs short weaned as per budget (therefore weaning 1 less sow as per budget per week)
A27: Grasmere Learig | B27: ='[7]Learig CCC'!$C$24 -> 802 | C27: ='[8]Learig CCC'!$C$22 -> 824 | D27: ='[9]Learig CCC'!$C$22 -> 1066 | E27: ='[10]Learig CCC'!$C$24 -> 1023 | F27: ='[11]Learig CCC'!$C$22 -> 905 | G27: ='[12]Learig CCC'!$C$24 -> 1071 | H27: ='[13]Learig CCC'!$C$24 -> 972 | I27: ='[14]Learig CCC'!$C$23 -> 990 | J27: ='[15]Learig CCC'!$C$24 -> 1560 | K27: =_xlfn.XLOOKUP(" Total:",'[16]Learig CCC'!$A$1:$A$65536,'[16]Learig CCC'!$C$1:$C$65536,0)-_xlfn.XLOOKUP("PCSAS",'[16]Learig CCC'!$A$1:$A$65536,'[16]Learig CCC'!$C$1:$C$65536,0) -> 1191 | L27: =_xlfn.XLOOKUP(" Total:",'[17]Learig CCC'!$A$1:$A$65536,'[17]Learig CCC'!$C$1:$C$65536,0)-_xlfn.XLOOKUP("PCSAS",'[17]Learig CCC'!$A$1:$A$65536,'[17]Learig CCC'!$C$1:$C$65536,0) -> 1004 | M27: =_xlfn.XLOOKUP(" Total:",'[18]Learig CCC'!$A$1:$A$65536,'[18]Learig CCC'!$C$1:$C$65536,0)-_xlfn.XLOOKUP("PCSAS",'[18]Learig CCC'!$A$1:$A$65536,'[18]Learig CCC'!$C$1:$C$65536,0) -> 1571
A28: Grasmere sow | B28: =[7]CCC!$C$17 -> 49 | C28: 0 | D28: =[9]CCC!$C$16 -> 3 | E28: =[10]CCC!$C$28 -> 0 | F28: =[11]CCC!$C$16 -> 46 | G28: =[12]CCC!$C$17 -> 28 | H28: =[13]CCC!$C$17 -> 10 | I28: =[14]CCC!$C$16 -> 13 | J28: =[15]CCC!$C$17 -> 18 | K28: =+_xlfn.XLOOKUP("PCSAS",[16]CCC!$A$1:$A$65536,[16]CCC!$C$1:$C$65536,0) -> 42 | L28: =+_xlfn.XLOOKUP("PCSAS",[17]CCC!$A$1:$A$65536,[17]CCC!$C$1:$C$65536,0) -> 32 | M28: =+_xlfn.XLOOKUP("PCSAS",[18]CCC!$A$1:$A$65536,[18]CCC!$C$1:$C$65536,0) -> 51 | O28: 1884 | P28: pigs short to colcom therefore should relate to mortality losses.
A29: Grasmere ration & donations | B29: =-'[19]Summary Total Pigs'!$Z$18-'[19]Summary Total Pigs'!$AA$18 -> 35 | C29: =-'[20]Summary Total Pigs'!$Z$18-'[20]Summary Total Pigs'!$AA$18 -> 38 | D29: =-'[21]Summary Total Pigs'!$Z$18-'[21]Summary Total Pigs'!$AA$18 -> 45 | E29: =-'[22]Summary Total Pigs'!$Z$18-'[22]Summary Total Pigs'!$AA$18 -> 35 | F29: =-'[23]Summary Total Pigs'!$Z$18 -> 51 | G29: =-'[24]Summary Total Pigs'!$Z$18 -> 53 | H29: =-'[25]Summary Total Pigs'!$Z$18 -> 61 | I29: =-'[26]Summary Total Pigs'!$Z$18 -> 33 | J29: =-'[27]Summary Total Pigs'!$Z$18 -> 66 | K29: =-'[28]Summary Total Pigs'!$Z$18 -> 55 | L29: =-'[29]Summary Total Pigs'!$Z$18 -> 47 | M29: =-'[30]Summary Total Pigs'!$Z$18 -> 55
A30: Grasmere internal gilts & out growers | B30: =-'[19]Grasmere Pig Cost'!$AU$23 -> 254 | C30: =-'[20]Grasmere Pig Cost'!$AU$23 -> 276 | D30: =-'[21]Grasmere Pig Cost'!$AU$23 -> 354 | E30: =-'[22]Grasmere Pig Cost'!$AU$23 -> 239 | F30: =-'[23]Grasmere Pig Cost'!$AV$23 -> 58 | G30: =-'[24]Grasmere Pig Cost'!$AV$23 -> 0 | H30: =-'[25]Grasmere Pig Cost'!$AV$23 -> 0 | I30: =-'[26]Grasmere Pig Cost'!$AV$23 -> 0 | J30: =-'[27]Grasmere Pig Cost'!$AV$23 -> 0 | K30: =-'[28]Grasmere Pig Cost'!$AV$23 -> 0 | L30: =-'[29]Grasmere Pig Cost'!$AV$23 -> 0 | M30: =-'[30]Grasmere Pig Cost'!$AV$23 -> 0
A31: Grasmere external farm sales | B31: =-'[19]Summary Total Pigs'!$AC$18 -> 1 | C31: =-'[20]Summary Total Pigs'!$AC$18 -> 19 | D31: =-'[21]Summary Total Pigs'!$AC$18 -> 22 | E31: =-'[22]Summary Total Pigs'!$AC$18 -> 11 | F31: =-'[23]Grasmere Pig Cost'!$AV$27 -> 26 | G31: =-'[24]Grasmere Pig Cost'!$AV$27 -> 39 | H31: =-'[25]Grasmere Pig Cost'!$AV$27 -> 38 | I31: =-'[26]Grasmere Pig Cost'!$AV$27 -> 0 | J31: =-'[27]Grasmere Pig Cost'!$AV$27 -> 94 | K31: =-'[28]Grasmere Pig Cost'!$AV$27 -> 46 | L31: =-'[29]Grasmere Pig Cost'!$AV$27 -> 22 | M31: =-'[30]Grasmere Pig Cost'!$AV$27 -> 21 | O31: gras | P31: 1204
A32: Pet Food | B32: =-'[19]Summary Total Pigs'!$AB$18 -> 0 | C32: =-'[20]Summary Total Pigs'!$AB$18 -> 0 | D32: =-'[21]Summary Total Pigs'!$AB$18 -> 0 | E32: =-'[22]Summary Total Pigs'!$AB$18 -> 0 | F32: =-'[31]Summary Total Pigs'!$AB$18 -> 0 | G32: =-'[32]Summary Total Pigs'!$AB$18 -> 0 | H32: =-'[25]Summary Total Pigs'!$AB$18 -> 0 | I32: =-'[26]Summary Total Pigs'!$AB$18 -> 0 | J32: =-'[27]Summary Total Pigs'!$AB$18 -> 0 | K32: =-'[28]Summary Total Pigs'!$AB$18 -> 0 | L32: =-'[29]Summary Total Pigs'!$AB$18 -> 0 | M32: =-'[30]Summary Total Pigs'!$AB$18 -> 0 | O32: rich | P32: 580
B33: =SUM(B25:B32) -> 5037 | C33: =SUM(C25:C32) -> 4720 | D33: =SUM(D25:D32) -> 6091 | E33: =SUM(E25:E32) -> 5098 | F33: =SUM(F25:F32) -> 4757 | G33: =SUM(G25:G32) -> 5954 | H33: =SUM(H25:H32) -> 4789 | I33: =SUM(I25:I32) -> 4910 | ... M33: =SUM(M25:M32) -> 6902 | O33: LH | P33: 614
O34: villa | P34: 260
A35: Richlands grower | B35: =[7]Richlands!$C$27-[7]Richlands!$C$17 -> 2023 | C35: =[8]Richlands!$C$23-[8]Richlands!$C$14 -> 1966 | D35: =[9]Richlands!$C$28-[9]Richlands!$C$17 -> 2507 | E35: =[10]Richlands!$C$24-[10]Richlands!$C$15 -> 2038 | F35: =[11]Richlands!$C$24-[11]Richlands!$C$15 -> 1967 | G35: =[12]Richlands!$C$23-[12]Richlands!$C$15 -> 2523 | H35: =[13]Richlands!$C$23-[13]Richlands!$C$16 -> 2059 | I35: =[14]Richlands!$C$24-[14]Richlands!$C$15 -> 2036 | J35: =[15]Richlands!$C$26-[15]Richlands!$C$18 -> 2750 | K35: =_xlfn.XLOOKUP(" Total:",[16]Richlands!$A$1:$A$65536,[16]Richlands!$C$1:$C$65536,0)-_xlfn.XLOOKUP("PCSAS",[16]Richlands!$A$1:$A$65536,[16]Richlands!$C$1:$C$65536,0) -> 1998 | L35: =_xlfn.XLOOKUP(" Total:",[17]Richlands!$A$1:$A$65536,[17]Richlands!$C$1:$C$65536,0)-_xlfn.XLOOKUP("PCSAS",[17]Richlands!$A$1:$A$65536,[17]Richlands!$C$1:$C$65536,0) -> 2185 | M35: =_xlfn.XLOOKUP(" Total:",[18]Richlands!$A$1:$A$65536,[18]Richlands!$C$1:$C$65536,0)-_xlfn.XLOOKUP("PCSAS",[18]Richlands!$A$1:$A$65536,[18]Richlands!$C$1:$C$65536,0) -> 2780 | P35: =SUM(P31:P34) -> 2658 | Q35: =P35*26 -> 69108
A36: Richlands LH ext | B36: ='[7]Richlands Extension'!$C$19 -> 131 | C36: ='[8]Richlands Extension'!$C$19 -> 260 | D36: ='[9]Richlands Extension'!$C$20 -> 187 | E36: ='[10]Richlands Extension'!$C$19 -> 155 | F36: ='[11]Richlands Extension'!$C$14 -> 15 | G36: ='[12]Richlands Extension'!$C$21 -> 280 | H36: ='[13]Richlands Extension'!$C$21 -> 344 | I36: ='[14]Richlands Extension'!$C$20 -> 403 | J36: ='[15]Richlands Extension'!$C$21 -> 417 | K36: =_xlfn.XLOOKUP(" Total:",'[16]Richlands Extension'!$A$1:$A$65536,'[16]Richlands Extension'!$C$1:$C$65536,0)-_xlfn.XLOOKUP("PCSAS",'[16]Richlands Extension'!$A$1:$A$65536,'[16]Richlands Extension'!$C$1:$C$65536,0) -> 234 | L36: =_xlfn.XLOOKUP(" Total:",'[17]Richlands Extension'!$A$1:$A$65536,'[17]Richlands Extension'!$C$1:$C$65536,0)-_xlfn.XLOOKUP("PCSAS",'[17]Richlands Extension'!$A$1:$A$65536,'[17]Richlands Extension'!$C$1:$C$65536,0) -> 328 | M36: =_xlfn.XLOOKUP(" Total:",'[18]Richlands Extension'!$A$1:$A$65536,'[18]Richlands Extension'!$C$1:$C$65536,0)-_xlfn.XLOOKUP("PCSAS",'[18]Richlands Extension'!$A$1:$A$65536,'[18]Richlands Extension'!$C$1:$C$65536,0) -> 95 | Q36: Therefore mortality is 2.7% higher than expected
A37: Richlands Learig | B37: ='[7]Learig Richlands'!$C$22 -> 312 | C37: ='[8]Learig Richlands'!$C$22 -> 286 | D37: ='[9]Learig Richlands'!$C$20 -> 365 | E37: ='[10]Learig Richlands'!$C$20 -> 117 | F37: ='[11]Learig Richlands'!$C$19 -> 206 | G37: ='[12]Learig Richlands'!$C$19 -> 257 | H37: ='[13]Learig Richlands'!$C$18 -> 97 | I37: ='[14]Learig Richlands'!$C$18 -> 198 | K37: =_xlfn.XLOOKUP(" Total:",'[16]Learig Richlands'!$A$1:$A$65536,'[16]Learig Richlands'!$C$1:$C$65536,0)-_xlfn.XLOOKUP("PCSAS",'[16]Learig Richlands'!$A$1:$A$65536,'[16]Learig Richlands'!$C$1:$C$65536,0) -> 74 | L37: =_xlfn.XLOOKUP(" Total:",'[17]Learig Richlands'!$A$1:$A$65536,'[17]Learig Richlands'!$C$1:$C$65536,0)-_xlfn.XLOOKUP("PCSAS",'[17]Learig Richlands'!$A$1:$A$65536,'[17]Learig Richlands'!$C$1:$C$65536,0) -> 0 | M37: =_xlfn.XLOOKUP(" Total:",'[18]Learig Richlands'!$A$1:$A$65536,'[18]Learig Richlands'!$C$1:$C$65536,0)-_xlfn.XLOOKUP("PCSAS",'[18]Learig Richlands'!$A$1:$A$65536,'[18]Learig Richlands'!$C$1:$C$65536,0) -> 299 | Q37: Budgeted 3% mortality
A38: Richlands sow | B38: =[7]Richlands!$C$17 -> 21 | C38: =[8]Richlands!$C$14 -> 20 | D38: =[9]Richlands!$C$17 -> 44 | E38: =[10]Richlands!$C$15 -> 41 | F38: =[11]Richlands!$C$15 -> 56 | G38: =[12]Richlands!$C$15 -> 17 | H38: =[13]Richlands!$C$16 -> 39 | I38: =[14]Richlands!$C$15 -> 43 | J38: =[15]Richlands!$C$18 -> 39 | K38: =_xlfn.XLOOKUP("PCSAS",[16]Richlands!$A$1:$A$65536,[16]Richlands!$C$1:$C$65536,0) -> 34 | L38: =_xlfn.XLOOKUP("PCSAS",[17]Richlands!$A$1:$A$65536,[17]Richlands!$C$1:$C$65536,0) -> 21 | M38: =_xlfn.XLOOKUP("PCSAS",[18]Richlands!$A$1:$A$65536,[18]Richlands!$C$1:$C$65536,0) -> 51
A39: Richlands ration & donations | B39: =-'[19]Summary Total Pigs'!$Z$114-'[19]Summary Total Pigs'!$AA$114 -> 11 | C39: =-'[20]Summary Total Pigs'!$Z$114-'[20]Summary Total Pigs'!$AA$114 -> 12 | D39: =-'[21]Summary Total Pigs'!$Z$114-'[21]Summary Total Pigs'!$AA$114 -> 16 | E39: =-'[22]Summary Total Pigs'!$Z$114-'[22]Summary Total Pigs'!$AA$114 -> 12 | F39: =-'[33]Summary Total Pigs'!$Z$114-'[33]Summary Total Pigs'!$AA$114 -> 7 | G39: =-'[34]Summary Total Pigs'!$Z$114-'[34]Summary Total Pigs'!$AA$114 -> 19 | H39: =-'[35]Summary Total Pigs'!$Z$114-'[35]Summary Total Pigs'!$AA$114 -> 12 | I39: =-'[36]Summary Total Pigs'!$Z$114-'[36]Summary Total Pigs'!$AA$114 -> 18 | J39: =-'[27]Summary Total Pigs'!$Z$114-'[27]Summary Total Pigs'!$AA$114 -> 15 | K39: =-'[28]Summary Total Pigs'!$Z$114-'[28]Summary Total Pigs'!$AA$114 -> 9 | L39: =-'[29]Summary Total Pigs'!$Z$114-'[29]Summary Total Pigs'!$AA$114 -> 18 | M39: =-'[30]Summary Total Pigs'!$Z$114-'[30]Summary Total Pigs'!$AA$114 -> 17
A40: Richlands internal gilts & out growers | B40: ='[19]Summary Total Pigs'!$D$111 -> 46 | C40: ='[20]Summary Total Pigs'!$D$111 -> 45 | D40: ='[21]Summary Total Pigs'!$D$111 -> 56 | E40: ='[22]Summary Total Pigs'!$D$111 -> 48 | F40: ='[23]Summary Total Pigs'!$D$111 -> 43 | G40: ='[24]Summary Total Pigs'!$D$111 -> 56 | H40: ='[25]Summary Total Pigs'!$D$111 -> 50 | I40: ='[26]Summary Total Pigs'!$D$111 -> 53 | J40: ='[27]Summary Total Pigs'!$D$111 -> 66 | K40: ='[28]Summary Total Pigs'!$D$111 -> 50 | L40: ='[29]Summary Total Pigs'!$D$111 -> 49 | M40: ='[30]Summary Total Pigs'!$D$111 -> 66
A41: Richlands external farm sales
A42: Pet Food | B42: =-'[37]Summary Total Pigs'!$AA$114 -> 0 | C42: =-'[37]Summary Total Pigs'!$AA$114 -> 0
B43: =SUM(B35:B42) -> 2544 | C43: =SUM(C35:C42) -> 2589 | D43: =SUM(D35:D42) -> 3175 | E43: =SUM(E35:E42) -> 2411 | F43: =SUM(F35:F42) -> 2294 | G43: =SUM(G35:G42) -> 3152 | H43: =SUM(H35:H42) -> 2601 | I43: =SUM(I35:I42) -> 2751 | ... M43: =SUM(M35:M42) -> 3308
A45: Lions Head grower | B45: =[7]LionsHead!$C$28-[7]LionsHead!$C$17 -> 2274 | C45: =[8]LionsHead!$C$25-[8]LionsHead!$C$14 -> 2166 | D45: =[9]LionsHead!$C$27-[9]LionsHead!$C$16 -> 2734 | E45: =[10]LionsHead!$C$25-[10]LionsHead!$C$16 -> 2360 | F45: =[11]LionsHead!$C$21-[11]LionsHead!$C$14 -> 2126 | G45: =[12]LionsHead!$C$25-[12]LionsHead!$C$16 -> 2661 | H45: =[13]LionsHead!$C$24-[13]LionsHead!$C$15 -> 2328 | I45: =[14]LionsHead!$C$24-[14]LionsHead!$C$16 -> 2286 | J45: =[15]LionsHead!$C$28-[15]LionsHead!$C$17 -> 2986 | K45: =_xlfn.XLOOKUP(" Total:",[16]LionsHead!$A$1:$A$65536,[16]LionsHead!$C$1:$C$65536,0)-_xlfn.XLOOKUP("PCSAS",[16]LionsHead!$A$1:$A$65536,[16]LionsHead!$C$1:$C$65536,0) -> 2357 | L45: =_xlfn.XLOOKUP(" Total:",[17]LionsHead!$A$1:$A$65536,[17]LionsHead!$C$1:$C$65536,0)-_xlfn.XLOOKUP("PCSAS",[17]LionsHead!$A$1:$A$65536,[17]LionsHead!$C$1:$C$65536,0) -> 2281 | M45: =_xlfn.XLOOKUP(" Total:",[18]LionsHead!$A$1:$A$65536,[18]LionsHead!$C$1:$C$65536,0)-_xlfn.XLOOKUP("PCSAS",[18]LionsHead!$A$1:$A$65536,[18]LionsHead!$C$1:$C$65536,0) -> 2982
A46: Lions Head LH ext | B46: ='[7]LionsHead Extension'!$C$24 -> 386 | C46: ='[8]LionsHead Extension'!$C$19 -> 127 | D46: ='[9]LionsHead Extension'!$C$20 -> 291 | E46: ='[10]LionsHead Extension'!$C$20 -> 146 | F46: ='[11]LionsHead Extension'!$C$20 -> 273 | G46: ='[12]LionsHead Extension'!$C$21 -> 272 | H46: ='[13]LionsHead Extension'!$C$20 -> 243 | I46: ='[14]LionsHead Extension'!$C$20 -> 226 | J46: ='[15]LionsHead Extension'!$C$22 -> 351 | K46: =_xlfn.XLOOKUP(" Total:",'[16]LionsHead Extension'!$A$1:$A$65536,'[16]LionsHead Extension'!$C$1:$C$65536,0)-_xlfn.XLOOKUP("PCSAS",'[16]LionsHead Extension'!$A$1:$A$65536,'[16]LionsHead Extension'!$C$1:$C$65536,0) -> 300 | L46: =_xlfn.XLOOKUP(" Total:",'[17]LionsHead Extension'!$A$1:$A$65536,'[17]LionsHead Extension'!$C$1:$C$65536,0)-_xlfn.XLOOKUP("PCSAS",'[17]LionsHead Extension'!$A$1:$A$65536,'[17]LionsHead Extension'!$C$1:$C$65536,0) -> 267 | M46: =_xlfn.XLOOKUP(" Total:",'[18]LionsHead Extension'!$A$1:$A$65536,'[18]LionsHead Extension'!$C$1:$C$65536,0)-_xlfn.XLOOKUP("PCSAS",'[18]LionsHead Extension'!$A$1:$A$65536,'[18]LionsHead Extension'!$C$1:$C$65536,0) -> 393
