Workbook

Sheet week 01
A1: Collector | B1: Boar | C1: TSI | D1: Genetic level | E1: Genetic Rank | F1: Last recorded raw Semen collected (mls) | G1: Last recorded Doses | H1: Dose rank | I1: Last recorded Morphology | J1: Morphology rank | K1: Overal Grading | L1: Overal Rank | N1: MULTIPLER SITE | Y1: 45677
N2: Sunday | O2: Sunday | P2: Sunday | Q2: Wed | R2: Wed | S2: Wed
A3: AW | B3: LA0499 | C3: 114 | D3: Above average | E3: 1 | F3: 250 | G3: 41 | H3: =RANK(G3,$G$3:$G$10) -> 3 | I3: 89 | J3: =RANK(I3,$I$3:$I$10)+COUNTIF(I3:$I$3,I3)-1 -> 1 | K3: =(E3+J3)/2 -> 1 | L3: =RANK(K3,$K$3:$K$10,1)+COUNTIF(K3:$K$6,K3)-1 -> 1 | N3: required | O3: estimate | P3: actual | Q3: required | R3: estimate | S3: actual
A4: AW | B4: LA0752 | C4: 108 | D4: Average | E4: 2 | F4: 152 | G4: 34 | H4: =RANK(G4,$G$3:$G$10) -> 5 | I4: 88 | J4: =RANK(I4,$I$3:$I$10)+COUNTIF(I$3:$I4,I4)-1 -> 3 | K4: =(E4+J4)/2 -> 2.5 | L4: =RANK(K4,$K$3:$K$10,1)+COUNTIF(K4:$K$6,K4)-1 -> 3 | N4: 50 | O4: 120 | P4: 127 | Q4: 20 | R4: 30 | S4: 48 | T4: TOTAL OF THE WEEK
A5: AW | B5: LA0724 | C5: 108 | D5: Average | E5: 3 | F5: 310 | G5: 37 | H5: =RANK(G5,$G$3:$G$10) -> 4 | I5: 89 | J5: =RANK(I5,$I$3:$I$10)+COUNTIF(I$3:$I5,I5)-1 -> 2 | K5: =(E5+J5)/2 -> 2.5 | L5: =RANK(K5,$K$3:$K$10,1)+COUNTIF(K5:$K$6,K5)-1 -> 2 | T5: Estimated total | U5: Actual total
A6: CM | B6: CL1114 | C6: 92 | D6: Low | E6: 4 | F6: 326 | G6: 14 | H6: =RANK(G6,$G$3:$G$10) -> 6 | I6: 87 | J6: =RANK(I6,$I$3:$I$10)+COUNTIF(I$3:$I6,I6)-1 -> 5 | K6: =(E6+J6)/2 -> 4.5 | L6: =RANK(K6,$K$3:$K$10,1)+COUNTIF(K6:$K$6,K6)-1 -> 4 | T6: =O4+R4 -> 150 | U6: =P4+S4 -> 175
A7: CM | B7: LA0117 | C7: 85 | D7: Low | E7: 5 | F7: 434 | G7: 49 | H7: =RANK(G7,$G$3:$G$10) -> 1 | I7: 87 | J7: =RANK(I7,$I$3:$I$10)+COUNTIF(I$3:$I7,I7)-1 -> 6 | K7: =(E7+J7)/2 -> 5.5 | L7: =RANK(K7,$K$3:$K$10,1)+COUNTIF(K$6:$K7,K7)-1 -> 6
B8: CL6865 | C8: 85 | D8: Low | E8: 6 | F8: 321 | G8: 47 | H8: =RANK(G8,$G$3:$G$10) -> 2 | I8: 88 | J8: =RANK(I8,$I$3:$I$10)+COUNTIF(I$3:$I8,I8)-1 -> 4 | K8: =(E8+J8)/2 -> 5 | L8: =RANK(K8,$K$3:$K$10,1)+COUNTIF(K$6:$K8,K8)-1 -> 5
B9: CL6866 | C9: 83 | D9: Low | E9: 7 | J9: =RANK(I9,$I$3:$I$10)+COUNTIF(I$6:$I9,I9)-1 -> #N/A
B11: SUNDAY | C11: WEDNESDAY
B12: L1 | C12: L2
B13: SUNDAY | C13: WEDNESDAY
C15: NO LONGER IN USE AWAITING TOBE TEASER BOARS

Sheet week 02
A1: Collector | B1: Boar | C1: TSI | D1: Genetic level | E1: Genetic Rank | F1: Last recorded raw Semen collected (mls) | G1: Last recorded Doses | H1: Dose rank | I1: Last recorded Morphology | J1: Morphology rank | K1: Overal Grading | L1: Overal Rank | N1: MULTIPLER SITE | Y1: 45677
N2: Sunday | O2: Sunday | P2: Sunday | Q2: Wed | R2: Wed | S2: Wed
A3: AW | B3: LA0499 | C3: 114 | D3: Above average | E3: 1 | F3: 546 | G3: 39 | H3: =RANK(G3,$G$3:$G$10) -> 3 | I3: 89 | J3: =RANK(I3,$I$3:$I$10)+COUNTIF(I3:$I$3,I3)-1 -> 1 | K3: =(E3+J3)/2 -> 1 | L3: =RANK(K3,$K$3:$K$10,1)+COUNTIF(K3:$K$6,K3)-1 -> 1 | N3: required | O3: estimate | P3: actual | Q3: required | R3: estimate | S3: actual
A4: AW | B4: LA0752 | C4: 108 | D4: Average | E4: 2 | F4: 264 | G4: 30 | H4: =RANK(G4,$G$3:$G$10) -> 4 | I4: 87 | J4: =RANK(I4,$I$3:$I$10)+COUNTIF(I$3:$I4,I4)-1 -> 6 | K4: =(E4+J4)/2 -> 4 | L4: =RANK(K4,$K$3:$K$10,1)+COUNTIF(K4:$K$6,K4)-1 -> 5 | N4: 50 | O4: 127 | P4: 84 | Q4: 20 | R4: 48 | S4: 96
A5: CM | B5: LA0724 | C5: 108 | D5: Average | E5: 3 | F5: 262 | G5: 66 | H5: =RANK(G5,$G$3:$G$10) -> 1 | I5: 88 | J5: =RANK(I5,$I$3:$I$10)+COUNTIF(I$3:$I5,I5)-1 -> 3 | K5: =(E5+J5)/2 -> 3 | L5: =RANK(K5,$K$3:$K$10,1)+COUNTIF(K5:$K$6,K5)-1 -> 2 | T5: TOTAL OF THE WEEK
A6: TA | B6: CL1114 | C6: 92 | D6: Low | E6: 4 | F6: 201 | G6: 15 | H6: =RANK(G6,$G$3:$G$10) -> 6 | I6: 88 | J6: =RANK(I6,$I$3:$I$10)+COUNTIF(I$3:$I6,I6)-1 -> 4 | K6: =(E6+J6)/2 -> 4 | L6: =RANK(K6,$K$3:$K$10,1)+COUNTIF(K6:$K$6,K6)-1 -> 4 | T6: Estimated total | U6: Actual total
A7: CM | B7: LA0117 | C7: 85 | D7: Low | E7: 5 | F7: 176 | G7: 30 | H7: =RANK(G7,$G$3:$G$10) -> 4 | I7: 89 | J7: =RANK(I7,$I$3:$I$10)+COUNTIF(I$3:$I7,I7)-1 -> 2 | K7: =(E7+J7)/2 -> 3.5 | L7: =RANK(K7,$K$3:$K$10,1)+COUNTIF(K$6:$K7,K7)-1 -> 3 | T7: =O4+R4 -> 175 | U7: =P4+S4 -> 180
B8: CL6865 | C8: 85 | D8: Low | E8: 6 | F8: 210 | G8: 47 | H8: =RANK(G8,$G$3:$G$10) -> 2 | I8: 88 | J8: =RANK(I8,$I$3:$I$10)+COUNTIF(I$3:$I8,I8)-1 -> 5 | K8: =(E8+J8)/2 -> 5.5 | L8: =RANK(K8,$K$3:$K$10,1)+COUNTIF(K$6:$K8,K8)-1 -> 6
B9: CL6866 | C9: 83 | D9: Low | E9: 7 | J9: =RANK(I9,$I$3:$I$10)+COUNTIF(I$6:$I9,I9)-1 -> #N/A
B11: SUNDAY | C11: WEDNESDAY
B12: L1 | C12: L2
B13: SUNDAY | C13: WEDNESDAY
C15: NO LONGER IN USE AWAITING TOBE TEASER BOARS

Sheet week 03
A1: Collector | B1: Boar | C1: TSI | D1: Genetic level | E1: Genetic Rank | F1: Last recorded raw Semen collected (mls) | G1: Last recorded Doses | H1: Dose rank | I1: Last recorded Morphology | J1: Morphology rank | K1: Overal Grading | L1: Overal Rank | O1: MULTIPLER SITE | Z1: 45677
O2: Sunday | P2: Sunday | Q2: Sunday | R2: Wed | S2: Wed | T2: Wed
A3: AW | B3: LA0499 | C3: 114 | D3: Above average | E3: 1 | F3: 203 | G3: 30 | H3: =RANK(G3,$G$3:$G$10) -> 5 | I3: 89 | J3: =RANK(I3,$I$3:$I$10)+COUNTIF(I3:$I$3,I3)-1 -> 1 | K3: =(E3+J3)/2 -> 1 | L3: =RANK(K3,$K$3:$K$10,1)+COUNTIF(K3:$K$6,K3)-1 -> 1 | O3: required | P3: estimate | Q3: actual | R3: required | S3: estimate | T3: actual
A4: TA | B4: LA0752 | C4: 108 | D4: Average | E4: 2 | F4: 168 | G4: 39 | H4: =RANK(G4,$G$3:$G$10) -> 3 | I4: 88 | J4: =RANK(I4,$I$3:$I$10)+COUNTIF(I$3:$I4,I4)-1 -> 3 | K4: =(E4+J4)/2 -> 2.5 | L4: =RANK(K4,$K$3:$K$10,1)+COUNTIF(K4:$K$6,K4)-1 -> 3 | O4: 50 | P4: 84 | Q4: 98 | R4: 20 | S4: 96 | T4: 67
A5: CM | B5: LA0724 | C5: 108 | D5: Average | E5: 3 | F5: 310 | G5: 37 | H5: =RANK(G5,$G$3:$G$10) -> 4 | I5: 89 | J5: =RANK(I5,$I$3:$I$10)+COUNTIF(I$3:$I5,I5)-1 -> 2 | K5: =(E5+J5)/2 -> 2.5 | L5: =RANK(K5,$K$3:$K$10,1)+COUNTIF(K5:$K$6,K5)-1 -> 2 | U5: TOTAL OF THE WEEK
A6: CM | B6: CL1114 | C6: 92 | D6: Low | E6: 4 | F6: 142 | G6: 10 | H6: =RANK(G6,$G$3:$G$10) -> 6 | I6: 87 | J6: =RANK(I6,$I$3:$I$10)+COUNTIF(I$3:$I6,I6)-1 -> 6 | K6: =(E6+J6)/2 -> 5 | L6: =RANK(K6,$K$3:$K$10,1)+COUNTIF(K6:$K$6,K6)-1 -> 6 | U6: Estimated total | V6: Actual total
A7: AW | B7: LA0117 | C7: 85 | D7: Low | E7: 5 | F7: 434 | G7: 49 | H7: =RANK(G7,$G$3:$G$10) -> 1 | I7: 88 | J7: =RANK(I7,$I$3:$I$10)+COUNTIF(I$3:$I7,I7)-1 -> 4 | K7: =(E7+J7)/2 -> 4.5 | L7: =RANK(K7,$K$3:$K$10,1)+COUNTIF(K$6:$K7,K7)-1 -> 5 | U7: =P4+S4 -> 180 | V7: =Q4+T4 -> 165
B8: CL6865 | C8: 85 | D8: Low | E8: 6 | F8: 321 | G8: 47 | H8: =RANK(G8,$G$3:$G$10) -> 2 | I8: 88 | J8: =RANK(I8,$I$3:$I$10)+COUNTIF(I$3:$I8,I8)-1 -> 5 | K8: =(E8+J8)/2 -> 5.5 | L8: =RANK(K8,$K$3:$K$10,1)+COUNTIF(K$6:$K8,K8)-1 -> 7
B9: CL6866 | C9: 83 | D9: Low | E9: 7 | K9: =(E9+J9)/2 -> 3.5 | L9: =RANK(K9,$K$3:$K$10,1)+COUNTIF(K$6:$K9,K9)-1 -> 4
B11: SUNDAY | C11: WEDNESDAY
B12: L1 | C12: L2
B13: SUNDAY | C13: WEDNESDAY
C15: NO LONGER IN USE AWAITING TO BE TEASER BOARS

Sheet week 04
A1: Collector | B1: Boar | C1: TSI | D1: Genetic level | E1: Genetic Rank | F1: Last recorded raw Semen collected (mls) | G1: Last recorded Doses | H1: Dose rank | I1: Last recorded Morphology | J1: Morphology rank | K1: Overal Grading | L1: Overal Rank | O1: MULTIPLER SITE | Z1: 45677
O2: Sunday | P2: Sunday | Q2: Sunday | R2: Wed | S2: Wed | T2: Wed
A3: TA | B3: LA0499 | C3: 114 | D3: Above average | E3: 1 | F3: 321 | G3: 28 | H3: =RANK(G3,$G$3:$G$10) -> 5 | I3: 88 | J3: =RANK(I3,$I$3:$I$10)+COUNTIF(I3:$I$3,I3)-1 -> 2 | K3: =(E3+J3)/2 -> 1.5 | L3: =RANK(K3,$K$3:$K$10,1)+COUNTIF(K3:$K$6,K3)-1 -> 2 | O3: required | P3: estimate | Q3: actual | R3: required | S3: estimate | T3: actual
A4: AW | B4: LA0752 | C4: 108 | D4: Average | E4: 2 | F4: 338 | G4: 70 | H4: =RANK(G4,$G$3:$G$10) -> 1 | I4: 90 | J4: =RANK(I4,$I$3:$I$10)+COUNTIF(I$3:$I4,I4)-1 -> 1 | K4: =(E4+J4)/2 -> 1.5 | L4: =RANK(K4,$K$3:$K$10,1)+COUNTIF(K4:$K$6,K4)-1 -> 1 | O4: 50 | P4: 98 | Q4: 121 | R4: 20 | S4: 67 | T4: 97 | U4: TOTAL OF THE WEEK
A5: CM | B5: LA0724 | C5: 108 | D5: Average | E5: 3 | F5: 332 | G5: 50 | H5: =RANK(G5,$G$3:$G$10) -> 2 | I5: 88 | J5: =RANK(I5,$I$3:$I$10)+COUNTIF(I$3:$I5,I5)-1 -> 3 | K5: =(E5+J5)/2 -> 3 | L5: =RANK(K5,$K$3:$K$10,1)+COUNTIF(K5:$K$6,K5)-1 -> 3 | U5: Estimated total | V5: Actual total
A6: CM | B6: CL1114 | C6: 92 | D6: Low | E6: 4 | F6: 274 | G6: 27 | H6: =RANK(G6,$G$3:$G$10) -> 6 | I6: 87 | J6: =RANK(I6,$I$3:$I$10)+COUNTIF(I$3:$I6,I6)-1 -> 5 | K6: =(E6+J6)/2 -> 4.5 | L6: =RANK(K6,$K$3:$K$10,1)+COUNTIF(K6:$K$6,K6)-1 -> 4 | U6: =P4+S4 -> 165 | V6: =Q4+T4 -> 218
A7: AW | B7: LA0117 | C7: 85 | D7: Low | E7: 5 | F7: 330 | G7: 43 | H7: =RANK(G7,$G$3:$G$10) -> 4 | I7: 86 | J7: =RANK(I7,$I$3:$I$10)+COUNTIF(I$3:$I7,I7)-1 -> 6 | K7: =(E7+J7)/2 -> 5.5 | L7: =RANK(K7,$K$3:$K$10,1)+COUNTIF(K$6:$K7,K7)-1 -> 6
B8: CL6865 | C8: 85 | D8: Low | E8: 6 | F8: 321 | G8: 47 | H8: =RANK(G8,$G$3:$G$10) -> 3 | I8: 88 | J8: =RANK(I8,$I$3:$I$10)+COUNTIF(I$3:$I8,I8)-1 -> 4 | K8: =(E8+J8)/2 -> 5 | L8: =RANK(K8,$K$3:$K$10,1)+COUNTIF(K$6:$K8,K8)-1 -> 5
B9: CL6866 | C9: 83 | D9: Low | E9: 7
B11: SUNDAY | C11: WEDNESDAY
B12: L1 | C12: L2
B13: SUNDAY | C13: WEDNESDAY
C15: NO LONGER IN USE AWAITING TO BE TEASER BOARS

Sheet week 05
A1: Collector | B1: Boar | C1: TSI | D1: Genetic level | E1: Genetic Rank | F1: Last recorded raw Semen collected (mls) | G1: Last recorded Doses | H1: Dose rank | I1: Last recorded Morphology | J1: Morphology rank | K1: Overal Grading | L1: Overal Rank | O1: MULTIPLER SITE | Z1: 45677
O2: Sunday | P2: Sunday | Q2: Sunday | R2: Wed | S2: Wed | T2: Wed
A3: AW | B3: LA0499 | C3: 114 | D3: Above average | E3: 1 | F3: 184 | G3: 47 | H3: =RANK(G3,$G$3:$G$10) -> 1 | I3: 88 | J3: =RANK(I3,$I$3:$I$10)+COUNTIF(I3:$I$3,I3)-1 -> 2 | K3: =(E3+J3)/2 -> 1.5 | L3: =RANK(K3,$K$3:$K$10,1)+COUNTIF(K3:$K$6,K3)-1 -> 2 | O3: required | P3: estimate | Q3: actual | R3: required | S3: estimate | T3: actual
A4: AW | B4: LA0752 | C4: 108 | D4: Average | E4: 2 | F4: 234 | G4: 44 | H4: =RANK(G4,$G$3:$G$10) -> 3 | I4: 89 | J4: =RANK(I4,$I$3:$I$10)+COUNTIF(I$3:$I4,I4)-1 -> 1 | K4: =(E4+J4)/2 -> 1.5 | L4: =RANK(K4,$K$3:$K$10,1)+COUNTIF(K4:$K$6,K4)-1 -> 1 | O4: 50 | P4: 121 | Q4: 74 | R4: 20 | S4: 97 | T4: 84
A5: CM | B5: LA0724 | C5: 108 | D5: Average | E5: 3 | F5: 302 | G5: 30 | H5: =RANK(G5,$G$3:$G$10) -> 6 | I5: 88 | J5: =RANK(I5,$I$3:$I$10)+COUNTIF(I$3:$I5,I5)-1 -> 3 | K5: =(E5+J5)/2 -> 3 | L5: =RANK(K5,$K$3:$K$10,1)+COUNTIF(K5:$K$6,K5)-1 -> 3 | U5: TOTAL OF THE WEEK
A6: AW | B6: CL1114 | C6: 92 | D6: Low | E6: 4 | F6: 206 | G6: 37 | H6: =RANK(G6,$G$3:$G$10) -> 5 | I6: 88 | J6: =RANK(I6,$I$3:$I$10)+COUNTIF(I$3:$I6,I6)-1 -> 4 | K6: =(E6+J6)/2 -> 4 | L6: =RANK(K6,$K$3:$K$10,1)+COUNTIF(K6:$K$6,K6)-1 -> 4 | U6: Estimated total | V6: Actual total
B7: LA0117 | C7: 85 | D7: Low | E7: 5 | F7: 330 | G7: 43 | H7: =RANK(G7,$G$3:$G$10) -> 4 | I7: 86 | J7: =RANK(I7,$I$3:$I$10)+COUNTIF(I$3:$I7,I7)-1 -> 6 | K7: =(E7+J7)/2 -> 5.5 | L7: =RANK(K7,$K$3:$K$10,1)+COUNTIF(K$6:$K7,K7)-1 -> 5 | U7: =P4+S4 -> 218 | V7: =Q4+T4 -> 158
B8: CL6865 | C8: 85 | D8: Low | E8: 6 | F8: 321 | G8: 47 | H8: =RANK(G8,$G$3:$G$10) -> 1 | I8: 88 | J8: =RANK(I8,$I$3:$I$10)+COUNTIF(I$3:$I8,I8)-1 -> 5 | K8: =(E8+J8)/2 -> 5.5 | L8: =RANK(K8,$K$3:$K$10,1)+COUNTIF(K$6:$K8,K8)-1 -> 6
B9: CL6866 | C9: 83 | D9: Low | E9: 7
B11: SUNDAY | C11: WEDNESDAY
B12: L1 | C12: L2
B13: SUNDAY | C13: WEDNESDAY
B14: Comment
B15: LA17;CL65 rested
C17: NO LONGER IN USE AWAITING TOBE TEASER BOARS

Sheet week 06
A1: Collector | B1: Boar | C1: TSI | D1: Genetic level | E1: Genetic Rank | F1: Last recorded raw Semen collected (mls) | G1: Last recorded Doses | H1: Dose rank | I1: Last recorded Morphology | J1: Morphology rank | K1: Overal Grading | L1: Overal Rank | O1: MULTIPLER SITE | Z1: 45677
O2: Sunday | P2: Sunday | Q2: Sunday | R2: Wed | S2: Wed | T2: Wed
A3: AW | B3: LA0499 | C3: 114 | D3: Above average | E3: 1 | F3: 184 | G3: 47 | H3: =RANK(G3,$G$3:$G$10) -> 2 | I3: 87 | J3: =RANK(I3,$I$3:$I$10)+COUNTIF(I3:$I$3,I3)-1 -> 4 | K3: =(E3+J3)/2 -> 2.5 | L3: =RANK(K3,$K$3:$K$10,1)+COUNTIF(K3:$K$6,K3)-1 -> 3 | O3: required | P3: estimate | Q3: actual | R3: required | S3: estimate | T3: actual
A4: CM | B4: LA0752 | C4: 108 | D4: Average | E4: 2 | F4: 292 | G4: 51 | H4: =RANK(G4,$G$3:$G$10) -> 1 | I4: 88 | J4: =RANK(I4,$I$3:$I$10)+COUNTIF(I$3:$I4,I4)-1 -> 2 | K4: =(E4+J4)/2 -> 2 | L4: =RANK(K4,$K$3:$K$10,1)+COUNTIF(K4:$K$6,K4)-1 -> 1 | O4: 50 | P4: 74 | Q4: 88 | R4: 20 | S4: 84 | T4: 83
A5: CM | B5: LA0724 | C5: 108 | D5: Average | E5: 3 | F5: 302 | G5: 30 | H5: =RANK(G5,$G$3:$G$10) -> 5 | I5: 87 | J5: =RANK(I5,$I$3:$I$10)+COUNTIF(I$3:$I5,I5)-1 -> 5 | K5: =(E5+J5)/2 -> 4 | L5: =RANK(K5,$K$3:$K$10,1)+COUNTIF(K5:$K$6,K5)-1 -> 4 | U5: TOTAL OF THE WEEK
A6: TA | B6: CL1114 | C6: 92 | D6: Low | E6: 4 | F6: 140 | G6: 17 | H6: =RANK(G6,$G$3:$G$10) -> 6 | I6: 89 | J6: =RANK(I6,$I$3:$I$10)+COUNTIF(I$3:$I6,I6)-1 -> 1 | K6: =(E6+J6)/2 -> 2.5 | L6: =RANK(K6,$K$3:$K$10,1)+COUNTIF(K6:$K$6,K6)-1 -> 2 | U6: Estimated total | V6: Actual total
A7: CM | B7: LA0117 | C7: 85 | D7: Low | E7: 5 | F7: 296 | G7: 36 | H7: =RANK(G7,$G$3:$G$10) -> 4 | I7: 88 | J7: =RANK(I7,$I$3:$I$10)+COUNTIF(I$3:$I7,I7)-1 -> 3 | K7: =(E7+J7)/2 -> 4 | L7: =RANK(K7,$K$3:$K$10,1)+COUNTIF(K$6:$K7,K7)-1 -> 4 | U7: =P4+S4 -> 158 | V7: =Q4+T4 -> 171
A8: AW | B8: CL6865 | C8: 85 | D8: Low | E8: 6 | F8: 200 | G8: 37 | H8: =RANK(G8,$G$3:$G$10) -> 3 | I8: 87 | J8: =RANK(I8,$I$3:$I$10)+COUNTIF(I$3:$I8,I8)-1 -> 6 | K8: =(E8+J8)/2 -> 6 | L8: =RANK(K8,$K$3:$K$10,1)+COUNTIF(K$6:$K8,K8)-1 -> 6
B9: CL6866 | C9: 83 | D9: Low | E9: 7
B11: SUNDAY | C11: WEDNESDAY
B12: L1 | C12: L2
B13: SUNDAY | C13: WEDNESDAY
B15: Comment
B16: LA99 rested
C17: Nolonger in use waiting to be teaser boar

Sheet week 07
A1: Collector | B1: Boar | C1: TSI | D1: Genetic level | E1: Genetic Rank | F1: Last recorded raw Semen collected (mls) | G1: Last recorded Doses | H1: Dose rank | I1: Last recorded Morphology | J1: Morphology rank | K1: Overal Grading | L1: Overal Rank | O1: MULTIPLER SITE | Z1: 45677
O2: Sunday | P2: Sunday | Q2: Sunday | R2: Wed | S2: Wed | T2: Wed
A3: CM | B3: LA0499 | C3: 114 | D3: Above average | E3: 1 | F3: 242 | G3: 65 | H3: =RANK(G3,$G$3:$G$10) -> 1 | I3: 88 | J3: =RANK(I3,$I$3:$I$10)+COUNTIF(I3:$I$3,I3)-1 -> 3 | K3: =(E3+J3)/2 -> 2 | L3: =RANK(K3,$K$3:$K$10,1)+COUNTIF(K3:$K$6,K3)-1 -> 2 | O3: required | P3: estimate | Q3: actual | R3: required | S3: estimate | T3: actual
A4: CM | B4: LA0752 | C4: 108 | D4: Average | E4: 2 | F4: 318 | G4: 52 | H4: =RANK(G4,$G$3:$G$10) -> 2 | I4: 89 | J4: =RANK(I4,$I$3:$I$10)+COUNTIF(I$3:$I4,I4)-1 -> 1 | K4: =(E4+J4)/2 -> 1.5 | L4: =RANK(K4,$K$3:$K$10,1)+COUNTIF(K4:$K$6,K4)-1 -> 1 | O4: 50 | P4: 88 | Q4: 82 | R4: 20 | S4: 83 | T4: 107
A5: TA | B5: LA0724 | C5: 108 | D5: Average | E5: 3 | F5: 148 | G5: 30 | H5: =RANK(G5,$G$3:$G$10) -> 5 | I5: 87 | J5: =RANK(I5,$I$3:$I$10)+COUNTIF(I$3:$I5,I5)-1 -> 6 | K5: =(E5+J5)/2 -> 4.5 | L5: =RANK(K5,$K$3:$K$10,1)+COUNTIF(K5:$K$6,K5)-1 -> 5 | U5: TOTAL OF THE WEEK
B6: CL1114 | C6: 92 | D6: Low | E6: 4 | F6: 140 | G6: 17 | H6: =RANK(G6,$G$3:$G$10) -> 6 | I6: 88 | J6: =RANK(I6,$I$3:$I$10)+COUNTIF(I$3:$I6,I6)-1 -> 4 | K6: =(E6+J6)/2 -> 4 | L6: =RANK(K6,$K$3:$K$10,1)+COUNTIF(K6:$K$6,K6)-1 -> 4 | U6: Estimated total | V6: Actual total
A7: CM | B7: LA0117 | C7: 85 | D7: Low | E7: 5 | F7: 302 | G7: 42 | H7: =RANK(G7,$G$3:$G$10) -> 3 | I7: 89 | J7: =RANK(I7,$I$3:$I$10)+COUNTIF(I$3:$I7,I7)-1 -> 2 | K7: =(E7+J7)/2 -> 3.5 | L7: =RANK(K7,$K$3:$K$10,1)+COUNTIF(K$6:$K7,K7)-1 -> 3 | U7: =P4+S4 -> 171 | V7: =Q4+T4 -> 189
A8: AW | B8: CL6865 | C8: 85 | D8: Low | E8: 6 | F8: 200 | G8: 37 | H8: =RANK(G8,$G$3:$G$10) -> 4 | I8: 88 | J8: =RANK(I8,$I$3:$I$10)+COUNTIF(I$3:$I8,I8)-1 -> 5 | K8: =(E8+J8)/2 -> 5.5 | L8: =RANK(K8,$K$3:$K$10,1)+COUNTIF(K$6:$K8,K8)-1 -> 6
B9: CL6866 | C9: 83 | D9: Low | E9: 7
B11: SUNDAY | C11: WEDNESDAY
B12: L1 | C12: L2
B13: SUNDAY | C13: WEDNESDAY
B15: Comment
B16: CL14,CL65 rested
C17: Nolonger in use waiting to be teaser boar

Sheet week 08
A1: Collector | B1: Boar | C1: TSI | D1: Genetic level | E1: Genetic Rank | F1: Last recorded raw Semen collected (mls) | G1: Last recorded Doses | H1: Dose rank | I1: Last recorded Morphology | J1: Morphology rank | K1: Overal Grading | L1: Overal Rank | O1: MULTIPLER SITE | Z1: 45677
O2: Sunday | P2: Sunday | Q2: Sunday | R2: Wed | S2: Wed | T2: Wed
A3: CM | B3: LA0499 | C3: 114 | D3: Above average | E3: 1 | F3: 250 | G3: 78 | H3: =RANK(G3,$G$3:$G$10) -> 1 | I3: 88 | J3: =RANK(I3,$I$3:$I$10)+COUNTIF(I3:$I$3,I3)-1 -> 3 | K3: =(E3+J3)/2 -> 2 | L3: =RANK(K3,$K$3:$K$10,1)+COUNTIF(K3:$K$6,K3)-1 -> 1 | O3: required | P3: estimate | Q3: actual | R3: required | S3: estimate | T3: actual
A4: TA | B4: LA0752 | C4: 108 | D4: Average | E4: 2 | F4: 200 | G4: 34 | H4: =RANK(G4,$G$3:$G$10) -> 6 | I4: 87 | J4: =RANK(I4,$I$3:$I$10)+COUNTIF(I$3:$I4,I4)-1 -> 6 | K4: =(E4+J4)/2 -> 4 | L4: =RANK(K4,$K$3:$K$10,1)+COUNTIF(K4:$K$6,K4)-1 -> 4 | O4: 50 | P4: 73 | R4: 20
A5: TA | B5: LA0724 | C5: 108 | D5: Average | E5: 3 | F5: 136 | G5: 39 | H5: =RANK(G5,$G$3:$G$10) -> 5 | I5: 88 | J5: =RANK(I5,$I$3:$I$10)+COUNTIF(I$3:$I5,I5)-1 -> 4 | K5: =(E5+J5)/2 -> 3.5 | L5: =RANK(K5,$K$3:$K$10,1)+COUNTIF(K5:$K$6,K5)-1 -> 3 | U5: TOTAL OF THE WEEK
A6: CM | B6: CL1114 | C6: 92 | D6: Low | E6: 4 | F6: 105 | G6: 45 | H6: =RANK(G6,$G$3:$G$10) -> 4 | I6: 89 | J6: =RANK(I6,$I$3:$I$10)+COUNTIF(I$3:$I6,I6)-1 -> 1 | K6: =(E6+J6)/2 -> 2.5 | L6: =RANK(K6,$K$3:$K$10,1)+COUNTIF(K6:$K$6,K6)-1 -> 2 | U6: Estimated total | V6: Actual total
A7: TA | B7: LA0117 | C7: 85 | D7: Low | E7: 5 | F7: 260 | G7: 66 | H7: =RANK(G7,$G$3:$G$10) -> 2 | I7: 88 | J7: =RANK(I7,$I$3:$I$10)+COUNTIF(I$3:$I7,I7)-1 -> 5 | K7: =(E7+J7)/2 -> 5 | L7: =RANK(K7,$K$3:$K$10,1)+COUNTIF(K$6:$K7,K7)-1 -> 6 | U7: =P4+S4 -> 73 | V7: =Q4+T4 -> 0
A8: AW | B8: CL6865 | C8: 85 | D8: Low | E8: 6 | F8: 294 | G8: 64 | H8: =RANK(G8,$G$3:$G$10) -> 3 | I8: 89 | J8: =RANK(I8,$I$3:$I$10)+COUNTIF(I$3:$I8,I8)-1 -> 2 | K8: =(E8+J8)/2 -> 4 | L8: =RANK(K8,$K$3:$K$10,1)+COUNTIF(K$6:$K8,K8)-1 -> 4
B9: CL6866 | C9: 83 | D9: Low | E9: 7
B11: SUNDAY | C11: WEDNESDAY
B12: L1 | C12: L2
B13: SUNDAY | C13: WEDNESDAY
B15: Comment
B16: CL14,CL65 rested
C17: Nolonger in use waiting to be teaser boar

Sheet week 09
A1: Collector | B1: Boar | C1: TSI | D1: Genetic level | E1: Genetic Rank | F1: Last recorded raw Semen collected (mls) | G1: Last recorded Doses | H1: Dose rank | I1: Last recorded Morphology | J1: Morphology rank | K1: Overal Grading | L1: Overal Rank | O1: MULTIPLER SITE | Z1: 45677
O2: Sunday | P2: Sunday | Q2: Sunday | R2: Wed | S2: Wed | T2: Wed
A3: CM | B3: LA0499 | C3: 114 | D3: Above average | E3: 1 | F3: 274 | G3: 45 | H3: =RANK(G3,$G$3:$G$10) -> 3 | I3: 88 | J3: =RANK(I3,$I$3:$I$10)+COUNTIF(I3:$I$3,I3)-1 -> 2 | K3: =(E3+J3)/2 -> 1.5 | L3: =RANK(K3,$K$3:$K$10,1)+COUNTIF(K3:$K$6,K3)-1 -> 2 | O3: required | P3: estimate | Q3: actual | R3: required | S3: estimate | T3: actual
A4: CM | B4: LA0752 | C4: 108 | D4: Average | E4: 2 | F4: 318 | G4: 52 | H4: =RANK(G4,$G$3:$G$10) -> 1 | I4: 89 | J4: =RANK(I4,$I$3:$I$10)+COUNTIF(I$3:$I4,I4)-1 -> 1 | K4: =(E4+J4)/2 -> 1.5 | L4: =RANK(K4,$K$3:$K$10,1)+COUNTIF(K4:$K$6,K4)-1 -> 1 | O4: 50 | R4: 20
A5: TA | B5: LA0724 | C5: 108 | D5: Average | E5: 3 | F5: 148 | G5: 30 | H5: =RANK(G5,$G$3:$G$10) -> 6 | I5: 87 | J5: =RANK(I5,$I$3:$I$10)+COUNTIF(I$3:$I5,I5)-1 -> 5 | K5: =(E5+J5)/2 -> 4 | L5: =RANK(K5,$K$3:$K$10,1)+COUNTIF(K5:$K$6,K5)-1 -> 4 | U5: TOTAL OF THE WEEK
A6: TA | B6: CL1114 | C6: 92 | D6: Low | E6: 4 | F6: 118 | G6: 37 | H6: =RANK(G6,$G$3:$G$10) -> 5 | I6: 88 | J6: =RANK(I6,$I$3:$I$10)+COUNTIF(I$3:$I6,I6)-1 -> 3 | K6: =(E6+J6)/2 -> 3.5 | L6: =RANK(K6,$K$3:$K$10,1)+COUNTIF(K6:$K$6,K6)-1 -> 3 | U6: Estimated total | V6: Actual total
A7: CM | B7: LA0117 | C7: 85 | D7: Low | E7: 5 | F7: 204 | G7: 40 | H7: =RANK(G7,$G$3:$G$10) -> 4 | I7: 88 | J7: =RANK(I7,$I$3:$I$10)+COUNTIF(I$3:$I7,I7)-1 -> 4 | K7: =(E7+J7)/2 -> 4.5 | L7: =RANK(K7,$K$3:$K$10,1)+COUNTIF(K$6:$K7,K7)-1 -> 5 | U7: =P4+S4 -> 0 | V7: =Q4+T4 -> 0
A8: AW | B8: CL6865 | C8: 85 | D8: Low | E8: 6 | F8: 201 | G8: 50 | H8: =RANK(G8,$G$3:$G$10) -> 2 | I8: 87 | J8: =RANK(I8,$I$3:$I$10)+COUNTIF(I$3:$I8,I8)-1 -> 6 | K8: =(E8+J8)/2 -> 6 | L8: =RANK(K8,$K$3:$K$10,1)+COUNTIF(K$6:$K8,K8)-1 -> 6
B9: CL6866 | C9: 83 | D9: Low | E9: 7
B11: SUNDAY | C11: WEDNESDAY
B12: L1 | C12: L2
B13: SUNDAY | C13: WEDNESDAY
B15: Comment
B16: CL14,CL65 rested
C17: Nolonger in use waiting to be teaser boar

Sheet week 10
A1: Collector | B1: Boar | C1: TSI | D1: Genetic level | E1: Genetic Rank | F1: Last recorded raw Semen collected (mls) | G1: Last recorded Doses | H1: Dose rank | I1: Last recorded Morphology | J1: Morphology rank | K1: Overal Grading | L1: Overal Rank | O1: MULTIPLER SITE | Z1: 45677
O2: Sunday | P2: Sunday | Q2: Sunday | R2: Wed | S2: Wed | T2: Wed
A3: TA | B3: LA0499 | C3: 107 | D3: Average | E3: 1 | F3: 264 | G3: 48 | H3: =RANK(G3,$G$3:$G$9) -> 3 | I3: 88 | J3: =RANK(I3,$I$3:$I$9)+COUNTIF(I3:$I$3,I3)-1 -> 1 | K3: =(E3+J3)/2 -> 1 | L3: =RANK(K3,$K$3:$K$9,1)+COUNTIF(K3:$K$6,K3)-1 -> 1 | O3: required | P3: estimate | Q3: actual | R3: required | S3: estimate | T3: actual
A4: AW | B4: LA0724 | C4: 104 | D4: Average | E4: 2 | F4: 250 | G4: 73 | H4: =RANK(G4,$G$3:$G$9) -> 1 | I4: 87 | J4: =RANK(I4,$I$3:$I$9)+COUNTIF(I$3:$I4,I4)-1 -> 3 | K4: =(E4+J4)/2 -> 2.5 | L4: =RANK(K4,$K$3:$K$9,1)+COUNTIF(K4:$K$6,K4)-1 -> 3 | O4: 50 | R4: 20
A5: CM | B5: LA0752 | C5: 103 | D5: Average | E5: 3 | F5: 318 | G5: 52 | H5: =RANK(G5,$G$3:$G$9) -> 2 | I5: 88 | J5: =RANK(I5,$I$3:$I$9)+COUNTIF(I$3:$I5,I5)-1 -> 2 | K5: =(E5+J5)/2 -> 2.5 | L5: =RANK(K5,$K$3:$K$9,1)+COUNTIF(K5:$K$6,K5)-1 -> 2 | U5: TOTAL OF THE WEEK
B6: LA0946 | C6: 102 | D6: Average | E6: 4 | U6: Estimated total | V6: Actual total
A7: AW | B7: CL1114 | C7: 86 | D7: Very low | E7: 5 | F7: 320 | G7: 29 | H7: =RANK(G7,$G$3:$G$9) -> 5 | I7: 87 | J7: =RANK(I7,$I$3:$I$9)+COUNTIF(I$3:$I7,I7)-1 -> 4 | K7: =(E7+J7)/2 -> 4.5 | L7: =RANK(K7,$K$3:$K$9,1)+COUNTIF(K$6:$K7,K7)-1 -> 4 | U7: =P4+S4 -> 0 | V7: =Q4+T4 -> 0
A8: TA | B8: LA0117 | C8: 82 | D8: Very low | E8: 6 | F8: 600 | G8: 36 | H8: =RANK(G8,$G$3:$G$9) -> 4 | I8: 86 | J8: =RANK(I8,$I$3:$I$9)+COUNTIF(I$3:$I8,I8)-1 -> 5 | K8: =(E8+J8)/2 -> 5.5 | L8: =RANK(K8,$K$3:$K$9,1)+COUNTIF(K$6:$K8,K8)-1 -> 5
B12: SUNDAY | C12: WEDNESDAY
B13: L1 | C13: L2
B14: SUNDAY | C14: WEDNESDAY
B16: Comment
C17: Not yet in use

Sheet week 11
B1: Collector | C1: Boar | D1: TSI | E1: Genetic level | F1: Genetic Rank | G1: Last recorded raw Semen collected (mls) | H1: Last recorded Doses | I1: Dose rank | J1: Last recorded Morphology | K1: Morphology rank | L1: Overal Grading | M1: Overal Rank | P1: MULTIPLER SITE | AA1: 45677
P2: Sunday | Q2: Sunday | R2: Sunday | S2: Wed | T2: Wed | U2: Wed
B3: AW | C3: LA0499 | D3: 107 | E3: Average | F3: 1 | G3: 362 | H3: 75 | I3: =RANK(H3,$H$3:$H$9) -> 1 | J3: 87 | K3: =RANK(J3,$J$3:$J$9)+COUNTIF(J3:$J$3,J3)-1 -> 3 | L3: =(F3+K3)/2 -> 2 | M3: =RANK(L3,$L$3:$L$9,1)+COUNTIF(L3:$L$6,L3)-1 -> 1 | P3: required | Q3: estimate | R3: actual | S3: required | T3: estimate | U3: actual
B4: TA | C4: LA0724 | D4: 104 | E4: Average | F4: 2 | G4: 164 | H4: 64 | I4: =RANK(H4,$H$3:$H$9) -> 2 | J4: 86 | K4: =RANK(J4,$J$3:$J$9)+COUNTIF(J$3:$J4,J4)-1 -> 4 | L4: =(F4+K4)/2 -> 3 | M4: =RANK(L4,$L$3:$L$9,1)+COUNTIF(L4:$L$6,L4)-1 -> 2 | P4: 50 | S4: 20
B5: CM | C5: LA0752 | D5: 103 | E5: Average | F5: 3 | G5: 318 | H5: 52 | I5: =RANK(H5,$H$3:$H$9) -> 3 | J5: 86 | K5: =RANK(J5,$J$3:$J$9)+COUNTIF(J$3:$J5,J5)-1 -> 5 | L5: =(F5+K5)/2 -> 4 | M5: =RANK(L5,$L$3:$L$9,1)+COUNTIF(L5:$L$6,L5)-1 -> 4 | V5: TOTAL OF THE WEEK
C6: LA0946 | D6: 102 | E6: Average | F6: 4 | V6: Estimated total | W6: Actual total
B7: CM | C7: CL1114 | D7: 86 | E7: Very low | F7: 5 | G7: 246 | H7: 20 | I7: =RANK(H7,$H$3:$H$9) -> 5 | J7: 88 | K7: =RANK(J7,$J$3:$J$9)+COUNTIF(J$3:$J7,J7)-1 -> 1 | L7: =(F7+K7)/2 -> 3 | M7: =RANK(L7,$L$3:$L$9,1)+COUNTIF(L$6:$L7,L7)-1 -> 2 | V7: =Q4+T4 -> 0 | W7: =R4+U4 -> 0
A8: CULL | B8: CM | C8: LA0117 | D8: 82 | E8: Very low | F8: 6 | G8: 384 | H8: 43 | I8: =RANK(H8,$H$3:$H$9) -> 4 | J8: 88 | K8: =RANK(J8,$J$3:$J$9)+COUNTIF(J$3:$J8,J8)-1 -> 2 | L8: =(F8+K8)/2 -> 4 | M8: =RANK(L8,$L$3:$L$9,1)+COUNTIF(L$6:$L8,L8)-1 -> 4
A10: CULL | C10: cl66
A11: CULL | C11: CL65
C12: SUNDAY | D12: WEDNESDAY
C13: L1 | D13: L2
C14: SUNDAY | D14: WEDNESDAY
C16: Comment
D17: Not yet in use

Sheet week 12
A1: Collector | B1: Boar | C1: TSI | D1: Genetic level | E1: Genetic Rank | F1: Last recorded raw Semen collected (mls) | G1: Last recorded Doses | H1: Dose rank | I1: Last recorded Morphology | J1: Morphology rank | K1: Overal Grading | L1: Overal Rank | O1: MULTIPLER SITE | Z1: 45677
O2: Sunday | P2: Sunday | Q2: Sunday | R2: Wed | S2: Wed | T2: Wed
A3: TA | B3: LA0499 | C3: 107 | D3: Average | E3: 1 | F3: 266 | G3: 46 | H3: =RANK(G3,$G$3:$G$9) -> 1 | I3: 87 | J3: =RANK(I3,$I$3:$I$9)+COUNTIF(I3:$I$3,I3)-1 -> 4 | K3: =(E3+J3)/2 -> 2.5 | L3: =RANK(K3,$K$3:$K$9,1)+COUNTIF(K3:$K$6,K3)-1 -> 2 | O3: required | P3: estimate | Q3: actual | R3: required | S3: estimate | T3: actual
A4: CM | B4: LA0724 | C4: 104 | D4: Average | E4: 2 | F4: 201 | G4: 41 | H4: =RANK(G4,$G$3:$G$9) -> 3 | I4: 88 | J4: =RANK(I4,$I$3:$I$9)+COUNTIF(I$3:$I4,I4)-1 -> 2 | K4: =(E4+J4)/2 -> 2 | L4: =RANK(K4,$K$3:$K$9,1)+COUNTIF(K4:$K$6,K4)-1 -> 1 | O4: 50 | R4: 20
A5: AW | B5: LA0752 | C5: 103 | D5: Average | E5: 3 | F5: 201 | G5: 45 | H5: =RANK(G5,$G$3:$G$9) -> 2 | I5: 88 | J5: =RANK(I5,$I$3:$I$9)+COUNTIF(I$3:$I5,I5)-1 -> 3 | K5: =(E5+J5)/2 -> 3 | L5: =RANK(K5,$K$3:$K$9,1)+COUNTIF(K5:$K$6,K5)-1 -> 3 | U5: TOTAL OF THE WEEK
B6: LA0946 | C6: 102 | D6: Average | E6: 4 | I6: 87 | U6: Estimated total | V6: Actual total
A7: TA | B7: CL1114 | C7: 86 | D7: Very low | E7: 5 | F7: 210 | G7: 22 | H7: =RANK(G7,$G$3:$G$9) -> 5 | I7: 87 | J7: =RANK(I7,$I$3:$I$9)+COUNTIF(I$3:$I7,I7)-1 -> 6 | K7: =(E7+J7)/2 -> 5.5 | L7: =RANK(K7,$K$3:$K$9,1)+COUNTIF(K$6:$K7,K7)-1 -> 5 | U7: =P4+S4 -> 0 | V7: =Q4+T4 -> 0
A8: AW | B8: LA0117 | C8: 82 | D8: Very low | E8: 6 | F8: 203 | G8: 23 | H8: =RANK(G8,$G$3:$G$9) -> 4 | I8: 89 | J8: =RANK(I8,$I$3:$I$9)+COUNTIF(I$3:$I8,I8)-1 -> 1 | K8: =(E8+J8)/2 -> 3.5 | L8: =RANK(K8,$K$3:$K$9,1)+COUNTIF(K$6:$K8,K8)-1 -> 4
B13: SUNDAY | C13: WEDNESDAY
B14: L1 | C14: L2
B15: SUNDAY | C15: WEDNESDAY
B17: Comment
C18: Not yet in use

Sheet week 13
A1: Collector | B1: Boar | C1: TSI | D1: Genetic level | E1: Genetic Rank | F1: Last recorded raw Semen collected (mls) | G1: Last recorded Doses | H1: Dose rank | I1: Last recorded Morphology | J1: Morphology rank | K1: Overal Grading | L1: Overal Rank | O1: MULTIPLER SITE | Z1: 45677
O2: Sunday | P2: Sunday | Q2: Sunday | R2: Wed | S2: Wed | T2: Wed
A3: CM | B3: LA0499 | C3: 107 | D3: Average | E3: 1 | F3: 232 | G3: 42 | H3: =RANK(G3,$G$3:$G$9) -> 1 | I3: 89 | J3: =RANK(I3,$I$3:$I$9)+COUNTIF(I3:$I$3,I3)-1 -> 1 | K3: =(E3+J3)/2 -> 1 | L3: =RANK(K3,$K$3:$K$9,1)+COUNTIF(K3:$K$6,K3)-1 -> 1 | O3: required | P3: estimate | Q3: actual | R3: required | S3: estimate | T3: actual
A4: TA | B4: LA0724 | C4: 104 | D4: Average | E4: 2 | F4: 206 | G4: 26 | H4: =RANK(G4,$G$3:$G$9) -> 3 | I4: 88 | J4: =RANK(I4,$I$3:$I$9)+COUNTIF(I$3:$I4,I4)-1 -> 3 | K4: =(E4+J4)/2 -> 2.5 | L4: =RANK(K4,$K$3:$K$9,1)+COUNTIF(K4:$K$6,K4)-1 -> 2 | O4: 50 | R4: 20
A5: TA | B5: LA0752 | C5: 103 | D5: Average | E5: 3 | F5: 231 | G5: 34 | H5: =RANK(G5,$G$3:$G$9) -> 2 | I5: 87 | J5: =RANK(I5,$I$3:$I$9)+COUNTIF(I$3:$I5,I5)-1 -> 4 | K5: =(E5+J5)/2 -> 3.5 | L5: =RANK(K5,$K$3:$K$9,1)+COUNTIF(K5:$K$6,K5)-1 -> 3 | U5: TOTAL OF THE WEEK
B6: LA0946 | C6: 102 | D6: Average | E6: 4 | I6: 87 | U6: Estimated total | V6: Actual total
A7: AW | B7: CL1114 | C7: 86 | D7: Very low | E7: 5 | F7: 302 | G7: 26 | H7: =RANK(G7,$G$3:$G$9) -> 3 | I7: 87 | J7: =RANK(I7,$I$3:$I$9)+COUNTIF(I$3:$I7,I7)-1 -> 6 | K7: =(E7+J7)/2 -> 5.5 | L7: =RANK(K7,$K$3:$K$9,1)+COUNTIF(K$6:$K7,K7)-1 -> 5 | U7: =P4+S4 -> 0 | V7: =Q4+T4 -> 0
A8: CM | B8: LA0117 | C8: 82 | D8: Very low | E8: 6 | F8: 203 | G8: 23 | H8: =RANK(G8,$G$3:$G$9) -> 5 | I8: 89 | J8: =RANK(I8,$I$3:$I$9)+COUNTIF(I$3:$I8,I8)-1 -> 2 | K8: =(E8+J8)/2 -> 4 | L8: =RANK(K8,$K$3:$K$9,1)+COUNTIF(K$6:$K8,K8)-1 -> 4
B12: SUNDAY | C12: WEDNESDAY
B13: L1 | C13: L2
B14: SUNDAY | C14: WEDNESDAY
B16: Comment
C17: Not yet in use

Sheet week 14
A1: Collector | B1: Boar | C1: TSI | D1: Genetic level | E1: Genetic Rank | F1: Last recorded raw Semen collected (mls) | G1: Last recorded Doses | H1: Dose rank | I1: Last recorded Morphology | J1: Morphology rank | K1: Overal Grading | L1: Overal Rank | O1: MULTIPLER SITE | Z1: 45677
O2: Sunday | P2: Sunday | Q2: Sunday | R2: Wed | S2: Wed | T2: Wed
A3: CM | B3: LA0499 | C3: 107 | D3: Average | E3: 1 | F3: 356 | G3: 59 | H3: =RANK(G3,$G$3:$G$9) -> 1 | I3: 88 | J3: =RANK(I3,$I$3:$I$9)+COUNTIF(I3:$I$3,I3)-1 -> 2 | K3: =(E3+J3)/2 -> 1.5 | L3: =RANK(K3,$K$3:$K$9,1)+COUNTIF(K3:$K$6,K3)-1 -> 1 | O3: required | P3: estimate | Q3: actual | R3: required | S3: estimate | T3: actual
A4: TA | B4: LA0724 | C4: 104 | D4: Average | E4: 2 | F4: 201 | G4: 51 | H4: =RANK(G4,$G$3:$G$9) -> 3 | I4: 87 | J4: =RANK(I4,$I$3:$I$9)+COUNTIF(I$3:$I4,I4)-1 -> 4 | K4: =(E4+J4)/2 -> 3 | L4: =RANK(K4,$K$3:$K$9,1)+COUNTIF(K4:$K$6,K4)-1 -> 3 | O4: 50 | R4: 20
A5: AW | B5: LA0752 | C5: 103 | D5: Average | E5: 3 | F5: 149 | G5: 47 | H5: =RANK(G5,$G$3:$G$9) -> 4 | I5: 88 | J5: =RANK(I5,$I$3:$I$9)+COUNTIF(I$3:$I5,I5)-1 -> 3 | K5: =(E5+J5)/2 -> 3 | L5: =RANK(K5,$K$3:$K$9,1)+COUNTIF(K5:$K$6,K5)-1 -> 2 | U5: TOTAL OF THE WEEK
A6: TA | B6: LA0946 | C6: 102 | D6: Average | E6: 4 | I6: 87 | U6: Estimated total | V6: Actual total
A7: AW | B7: CL1114 | C7: 86 | D7: Very low | E7: 5 | F7: 354 | G7: 54 | H7: =RANK(G7,$G$3:$G$9) -> 2 | I7: 87 | J7: =RANK(I7,$I$3:$I$9)+COUNTIF(I$3:$I7,I7)-1 -> 6 | K7: =(E7+J7)/2 -> 5.5 | L7: =RANK(K7,$K$3:$K$9,1)+COUNTIF(K$6:$K7,K7)-1 -> 5 | U7: =P4+S4 -> 0 | V7: =Q4+T4 -> 0
A8: CM | B8: LA0117 | C8: 82 | D8: Very low | E8: 6 | F8: 203 | G8: 23 | H8: =RANK(G8,$G$3:$G$9) -> 5 | I8: 89 | J8: =RANK(I8,$I$3:$I$9)+COUNTIF(I$3:$I8,I8)-1 -> 1 | K8: =(E8+J8)/2 -> 3.5 | L8: =RANK(K8,$K$3:$K$9,1)+COUNTIF(K$6:$K8,K8)-1 -> 4
B12: SUNDAY | C12: WEDNESDAY
B13: L1 | C13: L2
B14: SUNDAY | C14: WEDNESDAY
B16: Comment
C17: Not yet in use

Sheet week 15
A1: Collector | B1: Boar | C1: TSI | D1: Genetic level | E1: Genetic Rank | F1: Last recorded raw Semen collected (mls) | G1: Last recorded Doses | H1: Dose rank | I1: Last recorded Morphology | J1: Morphology rank | K1: Overal Grading | L1: Overal Rank | O1: MULTIPLER SITE | Z1: 45677
O2: Sunday | P2: Sunday | Q2: Sunday | R2: Wed | S2: Wed | T2: Wed
A3: AW | B3: LA0499 | C3: 107 | D3: Average | E3: 1 | F3: 120 | G3: 51 | H3: =RANK(G3,$G$3:$G$9) -> 1 | I3: 87 | J3: =RANK(I3,$I$3:$I$9)+COUNTIF(I3:$I$3,I3)-1 -> 5 | K3: =(E3+J3)/2 -> 3 | L3: =RANK(K3,$K$3:$K$9,1)+COUNTIF(K3:$K$6,K3)-1 -> 3 | O3: required | P3: estimate | Q3: actual | R3: required | S3: estimate | T3: actual
A4: TA | B4: LA0724 | C4: 104 | D4: Average | E4: 2 | F4: 164 | G4: 21 | H4: =RANK(G4,$G$3:$G$9) -> 3 | I4: 89 | J4: =RANK(I4,$I$3:$I$9)+COUNTIF(I$3:$I4,I4)-1 -> 1 | K4: =(E4+J4)/2 -> 1.5 | L4: =RANK(K4,$K$3:$K$9,1)+COUNTIF(K4:$K$6,K4)-1 -> 1 | O4: 50 | R4: 20
A5: AW | B5: LA0752 | C5: 103 | D5: Average | E5: 3 | F5: 158 | G5: 16 | H5: =RANK(G5,$G$3:$G$9) -> 4 | I5: 88 | J5: =RANK(I5,$I$3:$I$9)+COUNTIF(I$3:$I5,I5)-1 -> 3 | K5: =(E5+J5)/2 -> 3 | L5: =RANK(K5,$K$3:$K$9,1)+COUNTIF(K5:$K$6,K5)-1 -> 2 | U5: TOTAL OF THE WEEK
B6: LA0946 | C6: 102 | D6: Average | E6: 4 | I6: 87 | U6: Estimated total | V6: Actual total
A7: TA | B7: CL1114 | C7: 86 | D7: Very low | E7: 5 | F7: 284 | G7: 10 | H7: =RANK(G7,$G$3:$G$9) -> 5 | I7: 88 | J7: =RANK(I7,$I$3:$I$9)+COUNTIF(I$3:$I7,I7)-1 -> 4 | K7: =(E7+J7)/2 -> 4.5 | L7: =RANK(K7,$K$3:$K$9,1)+COUNTIF(K$6:$K7,K7)-1 -> 5 | U7: =P4+S4 -> 0 | V7: =Q4+T4 -> 0
B8: LA0117 | C8: 82 | D8: Very low | E8: 6 | F8: 203 | G8: 23 | H8: 4 | I8: 89 | J8: =RANK(I8,$I$3:$I$9)+COUNTIF(I$3:$I8,I8)-1 -> 2 | K8: =(E8+J8)/2 -> 4 | L8: =RANK(K8,$K$3:$K$9,1)+COUNTIF(K$6:$K8,K8)-1 -> 4
B12: SUNDAY | C12: WEDNESDAY
B13: L1 | C13: L2
B14: SUNDAY | C14: WEDNESDAY
B16: Comment
C17: Not yet in use

Sheet week 16
A1: Collector | B1: Boar | C1: TSI | D1: Genetic level | E1: Genetic Rank | F1: Last recorded raw Semen collected (mls) | G1: Last recorded Doses | H1: Dose rank | I1: Last recorded Morphology | J1: Morphology rank | K1: Overal Grading | L1: Overal Rank | O1: MULTIPLER SITE | Z1: 45677
O2: Sunday | P2: Sunday | Q2: Sunday | R2: Wed | S2: Wed | T2: Wed
A3: TA | B3: LA0499 | C3: 107 | D3: Average | E3: 1 | F3: 94 | G3: 25 | H3: =RANK(G3,$G$3:$G$9) -> 2 | I3: 88 | J3: =RANK(I3,$I$3:$I$9)+COUNTIF(I3:$I$3,I3)-1 -> 3 | K3: =(E3+J3)/2 -> 2 | L3: =RANK(K3,$K$3:$K$9,1)+COUNTIF(K3:$K$6,K3)-1 -> 1 | O3: required | P3: estimate | Q3: actual | R3: required | S3: estimate | T3: actual
A4: CM | B4: LA0724 | C4: 104 | D4: Average | E4: 2 | F4: 87 | G4: 41 | H4: =RANK(G4,$G$3:$G$9) -> 1 | I4: 88 | J4: =RANK(I4,$I$3:$I$9)+COUNTIF(I$3:$I4,I4)-1 -> 4 | K4: =(E4+J4)/2 -> 3 | L4: =RANK(K4,$K$3:$K$9,1)+COUNTIF(K4:$K$6,K4)-1 -> 2 | O4: 50 | R4: 20
A5: CM | B5: LA0752 | C5: 103 | D5: Average | E5: 3 | F5: 114 | G5: 25 | H5: =RANK(G5,$G$3:$G$9) -> 2 | I5: 87 | J5: =RANK(I5,$I$3:$I$9)+COUNTIF(I$3:$I5,I5)-1 -> 6 | K5: =(E5+J5)/2 -> 4.5 | L5: =RANK(K5,$K$3:$K$9,1)+COUNTIF(K5:$K$6,K5)-1 -> 4 | U5: TOTAL OF THE WEEK
A6: AW | B6: LA0946 | C6: 102 | D6: Average | E6: 4 | I6: 89 | U6: Estimated total | V6: Actual total
A7: AW | B7: CL1114 | C7: 86 | D7: Very low | E7: 5 | F7: 310 | G7: 25 | H7: =RANK(G7,$G$3:$G$9) -> 2 | I7: 88 | J7: =RANK(I7,$I$3:$I$9)+COUNTIF(I$3:$I7,I7)-1 -> 5 | K7: =(E7+J7)/2 -> 5 | L7: =RANK(K7,$K$3:$K$9,1)+COUNTIF(K$6:$K7,K7)-1 -> 5 | U7: =P4+S4 -> 0 | V7: =Q4+T4 -> 0
B8: LA0117 | C8: 82 | D8: Very low | E8: 6 | F8: 203 | G8: 23 | H8: =RANK(G8,$G$3:$G$9) -> 5 | I8: 89 | J8: =RANK(I8,$I$3:$I$9)+COUNTIF(I$3:$I8,I8)-1 -> 2 | K8: =(E8+J8)/2 -> 4 | L8: =RANK(K8,$K$3:$K$9,1)+COUNTIF(K$6:$K8,K8)-1 -> 3
B12: SUNDAY | C12: WEDNESDAY
B13: L1 | C13: L2
B14: SUNDAY | C14: WEDNESDAY
B16: Comment
C17: Not yet in use

Sheet week 17
A1: Collector | B1: Boar | C1: TSI | D1: Genetic level | E1: Genetic Rank | F1: Last recorded raw Semen collected (mls) | G1: Last recorded Doses | H1: Dose rank | I1: Last recorded Morphology | J1: Morphology rank | K1: Overal Grading | L1: Overal Rank | O1: MULTIPLER SITE | Z1: 45677
O2: Sunday | P2: Sunday | Q2: Sunday | R2: Wed | S2: Wed | T2: Wed
A3: TA | B3: LA0499 | C3: 107 | D3: Average | E3: 1 | F3: 228 | G3: 34 | H3: =RANK(G3,$G$3:$G$9) -> 2 | I3: 89 | J3: =RANK(I3,$I$3:$I$9)+COUNTIF(I3:$I$3,I3)-1 -> 1 | K3: =(E3+J3)/2 -> 1 | L3: =RANK(K3,$K$3:$K$9,1)+COUNTIF(K3:$K$6,K3)-1 -> 1 | O3: required | P3: estimate | Q3: actual | R3: required | S3: estimate | T3: actual
A4: CM | B4: LA0724 | C4: 104 | D4: Average | E4: 2 | F4: 223 | G4: 41 | H4: =RANK(G4,$G$3:$G$9) -> 1 | I4: 88 | J4: =RANK(I4,$I$3:$I$9)+COUNTIF(I$3:$I4,I4)-1 -> 4 | K4: =(E4+J4)/2 -> 3 | L4: =RANK(K4,$K$3:$K$9,1)+COUNTIF(K4:$K$6,K4)-1 -> 2 | O4: 50 | Q4: 52 | R4: 20
A5: TA | B5: LA0752 | C5: 103 | D5: Average | E5: 3 | F5: 154 | G5: 29 | H5: =RANK(G5,$G$3:$G$9) -> 3 | I5: 87 | J5: =RANK(I5,$I$3:$I$9)+COUNTIF(I$3:$I5,I5)-1 -> 6 | K5: =(E5+J5)/2 -> 4.5 | L5: =RANK(K5,$K$3:$K$9,1)+COUNTIF(K5:$K$6,K5)-1 -> 4 | U5: TOTAL OF THE WEEK
A6: AW | B6: LA0946 | C6: 102 | D6: Average | E6: 4 | F6: 201 | G6: 11 | I6: 88 | U6: Estimated total | V6: Actual total
A7: CM | B7: CL1114 | C7: 86 | D7: Very low | E7: 5 | F7: 248 | G7: 20 | H7: =RANK(G7,$G$3:$G$9) -> 5 | I7: 89 | J7: =RANK(I7,$I$3:$I$9)+COUNTIF(I$3:$I7,I7)-1 -> 2 | K7: =(E7+J7)/2 -> 3.5 | L7: =RANK(K7,$K$3:$K$9,1)+COUNTIF(K$6:$K7,K7)-1 -> 3 | U7: =P4+S4 -> 0 | V7: =Q4+T4 -> 52
B8: LA0117 | C8: 82 | D8: Very low | E8: 6 | F8: 203 | G8: 23 | H8: =RANK(G8,$G$3:$G$9) -> 4 | I8: 89 | J8: =RANK(I8,$I$3:$I$9)+COUNTIF(I$3:$I8,I8)-1 -> 3 | K8: =(E8+J8)/2 -> 4.5 | L8: =RANK(K8,$K$3:$K$9,1)+COUNTIF(K$6:$K8,K8)-1 -> 4
B12: SUNDAY | C12: WEDNESDAY
B13: L1 | C13: L2
B14: SUNDAY | C14: WEDNESDAY
B16: Comment
C17: Not yet in use

Sheet week 18
A1: Collector | B1: Boar | C1: TSI | D1: Genetic level | E1: Genetic Rank | F1: Last recorded raw Semen collected (mls) | G1: Last recorded Doses | H1: Dose rank | I1: Last recorded Morphology | J1: Morphology rank | K1: Overal Grading | L1: Overal Rank | O1: MULTIPLER SITE | Z1: 45677
O2: Sunday | P2: Sunday | Q2: Sunday | R2: Wed | S2: Wed | T2: Wed
A3: CM | B3: LA0499 | C3: 107 | D3: Average | E3: 1 | F3: 272 | G3: 51 | H3: =RANK(G3,$G$3:$G$9) -> 2 | I3: 88 | J3: =RANK(I3,$I$3:$I$9)+COUNTIF(I3:$I$3,I3)-1 -> 3 | K3: =(E3+J3)/2 -> 2 | L3: =RANK(K3,$K$3:$K$9,1)+COUNTIF(K3:$K$6,K3)-1 -> 1 | O3: required | P3: estimate | Q3: actual | R3: required | S3: estimate | T3: actual
A4: TA | B4: LA0724 | C4: 104 | D4: Average | E4: 2 | F4: 220 | G4: 67 | H4: =RANK(G4,$G$3:$G$9) -> 1 | I4: 87 | J4: =RANK(I4,$I$3:$I$9)+COUNTIF(I$3:$I4,I4)-1 -> 6 | K4: =(E4+J4)/2 -> 4 | L4: =RANK(K4,$K$3:$K$9,1)+COUNTIF(K4:$K$6,K4)-1 -> 4 | O4: 50 | P4: 52 | Q4: 103 | R4: 20
A5: CM | B5: LA0752 | C5: 103 | D5: Average | E5: 3 | F5: 296 | G5: 36 | H5: =RANK(G5,$G$3:$G$9) -> 4 | I5: 88 | J5: =RANK(I5,$I$3:$I$9)+COUNTIF(I$3:$I5,I5)-1 -> 4 | K5: =(E5+J5)/2 -> 3.5 | L5: =RANK(K5,$K$3:$K$9,1)+COUNTIF(K5:$K$6,K5)-1 -> 3 | U5: TOTAL OF THE WEEK
A6: AW | B6: LA0946 | C6: 102 | D6: Average | E6: 4 | F6: 102 | G6: 10 | H6: =RANK(G6,$G$3:$G$9) -> 6 | I6: 89 | J6: =RANK(I6,$I$3:$I$9)+COUNTIF(I$3:$I6,I6)-1 -> 1 | K6: =(E6+J6)/2 -> 2.5 | L6: =RANK(K6,$K$3:$K$9,1)+COUNTIF(K$6:$K6,K6)-1 -> 2 | U6: Estimated total | V6: Actual total
A7: AW | B7: CL1114 | C7: 86 | D7: Very low | E7: 5 | F7: 362 | G7: 47 | H7: =RANK(G7,$G$3:$G$9) -> 3 | I7: 88 | J7: =RANK(I7,$I$3:$I$9)+COUNTIF(I$3:$I7,I7)-1 -> 5 | K7: =(E7+J7)/2 -> 5 | L7: =RANK(K7,$K$3:$K$9,1)+COUNTIF(K$6:$K7,K7)-1 -> 5 | U7: =P4+S4 -> 52 | V7: =Q4+T4 -> 103
B8: LA0117 | C8: 82 | D8: Very low | E8: 6 | F8: 203 | G8: 23 | H8: =RANK(G8,$G$3:$G$9) -> 5 | I8: 89
B12: SUNDAY | C12: WEDNESDAY
B13: L1 | C13: L2
B14: SUNDAY | C14: WEDNESDAY
B16: Comment
C17: Not yet in use

Sheet week 19
A1: Collector | B1: Boar | C1: TSI | D1: Genetic level | E1: Genetic Rank | F1: Last recorded raw Semen collected (mls) | G1: Last recorded Doses | H1: Dose rank | I1: Last recorded Morphology | J1: Morphology rank | K1: Overal Grading | L1: Overal Rank | O1: MULTIPLER SITE | Z1: 45677
O2: Sunday | P2: Sunday | Q2: Sunday | R2: Wed | S2: Wed | T2: Wed
A3: TA | B3: LA0499 | C3: 107 | D3: Average | E3: 1 | F3: 208 | G3: 10 | H3: =RANK(G3,$G$3:$G$9) -> 6 | I3: 88 | J3: =RANK(I3,$I$3:$I$9)+COUNTIF(I3:$I$3,I3)-1 -> 3 | K3: =(E3+J3)/2 -> 2 | L3: =RANK(K3,$K$3:$K$9,1)+COUNTIF(K3:$K$6,K3)-1 -> 1 | O3: required | P3: estimate | Q3: actual | R3: required | S3: estimate | T3: actual
A4: TA | B4: LA0724 | C4: 104 | D4: Average | E4: 2 | F4: 158 | G4: 50 | H4: =RANK(G4,$G$3:$G$9) -> 1 | I4: 87 | J4: =RANK(I4,$I$3:$I$9)+COUNTIF(I$3:$I4,I4)-1 -> 6 | K4: =(E4+J4)/2 -> 4 | L4: =RANK(K4,$K$3:$K$9,1)+COUNTIF(K4:$K$6,K4)-1 -> 4 | O4: 50 | P4: 103 | Q4: 74 | R4: 20
A5: CM | B5: LA0752 | C5: 103 | D5: Average | E5: 3 | F5: 296 | G5: 36 | H5: =RANK(G5,$G$3:$G$9) -> 2 | I5: 88 | J5: =RANK(I5,$I$3:$I$9)+COUNTIF(I$3:$I5,I5)-1 -> 4 | K5: =(E5+J5)/2 -> 3.5 | L5: =RANK(K5,$K$3:$K$9,1)+COUNTIF(K5:$K$6,K5)-1 -> 3 | U5: TOTAL OF THE WEEK
A6: AW | B6: LA0946 | C6: 102 | D6: Average | E6: 4 | F6: 114 | G6: 24 | H6: =RANK(G6,$G$3:$G$9) -> 4 | I6: 89 | J6: =RANK(I6,$I$3:$I$9)+COUNTIF(I$3:$I6,I6)-1 -> 1 | K6: =(E6+J6)/2 -> 2.5 | L6: =RANK(K6,$K$3:$K$9,1)+COUNTIF(K$6:$K6,K6)-1 -> 2 | U6: Estimated total | V6: Actual total
A7: CM | B7: CL1114 | C7: 86 | D7: Very low | E7: 5 | F7: 302 | G7: 31 | H7: =RANK(G7,$G$3:$G$9) -> 3 | I7: 88 | J7: =RANK(I7,$I$3:$I$9)+COUNTIF(I$3:$I7,I7)-1 -> 5 | K7: =(E7+J7)/2 -> 5 | L7: =RANK(K7,$K$3:$K$9,1)+COUNTIF(K$6:$K7,K7)-1 -> 5 | U7: =P4+S4 -> 103 | V7: =Q4+T4 -> 74
B8: LA0117 | C8: 82 | D8: Very low | E8: 6 | F8: 203 | G8: 23 | H8: =RANK(G8,$G$3:$G$9) -> 5 | I8: 89
B12: SUNDAY | C12: WEDNESDAY
B13: L1 | C13: L2
B14: SUNDAY | C14: WEDNESDAY
B16: Comment
C17: Not yet in use

Sheet week 20
A1: Collector | B1: Boar | C1: TSI | D1: Genetic level | E1: Genetic Rank | F1: Last recorded raw Semen collected (mls) | G1: Last recorded Doses | H1: Dose rank | I1: Last recorded Morphology | J1: Morphology rank | K1: Overal Grading | L1: Overal Rank | O1: MULTIPLER SITE | Z1: 45677
O2: Sunday | P2: Sunday | Q2: Sunday | R2: Wed | S2: Wed | T2: Wed
A3: CM | B3: LA0499 | C3: 107 | D3: Average | E3: 1 | F3: 182 | G3: 22 | H3: =RANK(G3,$G$3:$G$9) -> 5 | I3: 89 | J3: =RANK(I3,$I$3:$I$9)+COUNTIF(I3:$I$3,I3)-1 -> 1 | K3: =(E3+J3)/2 -> 1 | L3: =RANK(K3,$K$3:$K$9,1)+COUNTIF(K3:$K$6,K3)-1 -> 1 | O3: required | P3: estimate | Q3: actual | R3: required | S3: estimate | T3: actual
A4: TA | B4: LA0724 | C4: 104 | D4: Average | E4: 2 | F4: 242 | G4: 28 | H4: =RANK(G4,$G$3:$G$9) -> 2 | I4: 87 | J4: =RANK(I4,$I$3:$I$9)+COUNTIF(I$3:$I4,I4)-1 -> 5 | K4: =(E4+J4)/2 -> 3.5 | L4: =RANK(K4,$K$3:$K$9,1)+COUNTIF(K4:$K$6,K4)-1 -> 4 | O4: 50 | P4: 74 | Q4: 62 | R4: 20
A5: CM | B5: LA0752 | C5: 103 | D5: Average | E5: 3 | F5: 258 | G5: 34 | H5: =RANK(G5,$G$3:$G$9) -> 1 | I5: 88 | J5: =RANK(I5,$I$3:$I$9)+COUNTIF(I$3:$I5,I5)-1 -> 3 | K5: =(E5+J5)/2 -> 3 | L5: =RANK(K5,$K$3:$K$9,1)+COUNTIF(K5:$K$6,K5)-1 -> 3 | U5: TOTAL OF THE WEEK
A6: AW | B6: LA0946 | C6: 102 | D6: Average | E6: 4 | F6: 102 | G6: 23 | H6: =RANK(G6,$G$3:$G$9) -> 3 | I6: 89 | J6: =RANK(I6,$I$3:$I$9)+COUNTIF(I$3:$I6,I6)-1 -> 2 | K6: =(E6+J6)/2 -> 3 | L6: =RANK(K6,$K$3:$K$9,1)+COUNTIF(K$6:$K6,K6)-1 -> 2 | U6: Estimated total | V6: Actual total
A7: AW | B7: CL1114 | C7: 86 | D7: Very low | E7: 5 | F7: 282 | G7: 22 | H7: =RANK(G7,$G$3:$G$9) -> 5 | I7: 87 | J7: =RANK(I7,$I$3:$I$9)+COUNTIF(I$3:$I7,I7)-1 -> 6 | K7: =(E7+J7)/2 -> 5.5 | L7: =RANK(K7,$K$3:$K$9,1)+COUNTIF(K$6:$K7,K7)-1 -> 5 | U7: =P4+S4 -> 74 | V7: =Q4+T4 -> 62
B8: LA0117 | C8: 82 | D8: Very low | E8: 6 | F8: 203 | G8: 23 | H8: =RANK(G8,$G$3:$G$9) -> 3 | I8: 88
B12: SUNDAY | C12: WEDNESDAY
B13: L1 | C13: L2
B14: SUNDAY | C14: WEDNESDAY
B16: Comment
C17: Not yet in use

Sheet week 21
A1: Collector | B1: Boar | C1: AGE | D1: TSI | E1: Genetic level | F1: Genetic Rank | G1: Last recorded raw Semen collected (mls) | H1: Last recorded Doses | I1: Dose rank | J1: Last recorded Morphology | K1: Morphology rank | L1: Overal Grading | M1: Overal Rank | P1: MULTIPLER SITE | AA1: 45677
P2: Sunday | Q2: Sunday | R2: Sunday | S2: Wed | T2: Wed | U2: Wed
A3: TA | B3: LA0499 | D3: 107 | E3: Average | F3: 1 | G3: 238 | H3: 42 | I3: =RANK(H3,$H$3:$H$9) -> 4 | J3: 89 | K3: =RANK(J3,$J$3:$J$9)+COUNTIF(J3:$J$3,J3)-1 -> 1 | L3: =(F3+K3)/2 -> 1 | M3: =RANK(L3,$L$3:$L$9,1)+COUNTIF(L3:$L$6,L3)-1 -> 1 | P3: required | Q3: estimate | R3: actual | S3: required | T3: estimate | U3: actual
A4: TA | B4: LA0724 | D4: 104 | E4: Average | F4: 2 | G4: 286 | H4: 71 | I4: =RANK(H4,$H$3:$H$9) -> 1 | J4: 87 | K4: =RANK(J4,$J$3:$J$9)+COUNTIF(J$3:$J4,J4)-1 -> 5 | L4: =(F4+K4)/2 -> 3.5 | M4: =RANK(L4,$L$3:$L$9,1)+COUNTIF(L4:$L$6,L4)-1 -> 4 | P4: 50 | Q4: 62 | R4: 116 | S4: 20
A5: CM | B5: LA0752 | D5: 103 | E5: Average | F5: 3 | G5: 178 | H5: 45 | I5: =RANK(H5,$H$3:$H$9) -> 3 | J5: 89 | K5: =RANK(J5,$J$3:$J$9)+COUNTIF(J$3:$J5,J5)-1 -> 2 | L5: =(F5+K5)/2 -> 2.5 | M5: =RANK(L5,$L$3:$L$9,1)+COUNTIF(L5:$L$6,L5)-1 -> 2 | V5: TOTAL OF THE WEEK
A6: AW | B6: LA0946 | D6: 102 | E6: Average | F6: 4 | G6: 280 | H6: 71 | I6: =RANK(H6,$H$3:$H$9) -> 1 | J6: 88 | K6: =RANK(J6,$J$3:$J$9)+COUNTIF(J$3:$J6,J6)-1 -> 3 | L6: =(F6+K6)/2 -> 3.5 | M6: =RANK(L6,$L$3:$L$9,1)+COUNTIF(L$6:$L6,L6)-1 -> 3 | V6: Estimated total | W6: Actual total
B7: CL1114 | D7: 86 | E7: Very low | F7: 5 | G7: 282 | H7: 22 | I7: =RANK(H7,$H$3:$H$9) -> 5 | J7: 88 | K7: =RANK(J7,$J$3:$J$9)+COUNTIF(J$3:$J7,J7)-1 -> 4 | L7: =(F7+K7)/2 -> 4.5 | M7: =RANK(L7,$L$3:$L$9,1)+COUNTIF(L$6:$L7,L7)-1 -> 5 | V7: =Q4+T4 -> 62 | W7: =R4+U4 -> 116
B12: SUNDAY | D12: WEDNESDAY
B13: L1 | D13: L2
B14: SUNDAY | D14: WEDNESDAY
B16: Comment
D17: Not yet in use

Sheet week 22
A1: Collector | B1: Boar | C1: AGE | D1: TSI | E1: Genetic level | F1: Genetic Rank | G1: Last recorded raw Semen collected (mls) | H1: Last recorded Doses | I1: Dose rank | J1: Last recorded Morphology | K1: Morphology rank | L1: Overal Grading | M1: Overal Rank | P1: MULTIPLER SITE | AA1: 45677
P2: Sunday | Q2: Sunday | R2: Sunday | S2: Wed | T2: Wed | U2: Wed
A3: CM | B3: LA0499 | D3: 107 | E3: Average | F3: 1 | G3: 224 | H3: 40 | I3: =RANK(H3,$H$3:$H$9) -> 4 | J3: 89 | K3: =RANK(J3,$J$3:$J$9)+COUNTIF(J3:$J$3,J3)-1 -> 1 | L3: =(F3+K3)/2 -> 1 | M3: =RANK(L3,$L$3:$L$9,1)+COUNTIF(L3:$L$6,L3)-1 -> 1 | P3: required | Q3: estimate | R3: actual | S3: required | T3: estimate | U3: actual
A4: TA | B4: LA0724 | D4: 104 | E4: Average | F4: 2 | G4: 218 | H4: 42 | I4: =RANK(H4,$H$3:$H$9) -> 3 | J4: 89 | K4: =RANK(J4,$J$3:$J$9)+COUNTIF(J$3:$J4,J4)-1 -> 2 | L4: =(F4+K4)/2 -> 2 | M4: =RANK(L4,$L$3:$L$9,1)+COUNTIF(L4:$L$6,L4)-1 -> 2 | P4: 50 | Q4: 116 | R4: 97 | S4: 20
A5: CM | B5: LA0752 | D5: 103 | E5: Average | F5: 3 | G5: 386 | H5: 55 | I5: =RANK(H5,$H$3:$H$9) -> 2 | J5: 87 | K5: =RANK(J5,$J$3:$J$9)+COUNTIF(J$3:$J5,J5)-1 -> 3 | L5: =(F5+K5)/2 -> 3 | M5: =RANK(L5,$L$3:$L$9,1)+COUNTIF(L5:$L$6,L5)-1 -> 3 | V5: TOTAL OF THE WEEK
A6: AW | B6: LA0946 | D6: 102 | E6: Average | F6: 4 | G6: 306 | H6: 72 | I6: =RANK(H6,$H$3:$H$9) -> 1 | J6: 86 | K6: =RANK(J6,$J$3:$J$9)+COUNTIF(J$3:$J6,J6)-1 -> 5 | L6: =(F6+K6)/2 -> 4.5 | M6: =RANK(L6,$L$3:$L$9,1)+COUNTIF(L$6:$L6,L6)-1 -> 4 | V6: Estimated total | W6: Actual total
B7: CL1114 | D7: 86 | E7: Very low | F7: 5 | G7: 282 | H7: 22 | I7: =RANK(H7,$H$3:$H$9) -> 5 | J7: 87 | K7: =RANK(J7,$J$3:$J$9)+COUNTIF(J$3:$J7,J7)-1 -> 4 | L7: =(F7+K7)/2 -> 4.5 | M7: =RANK(L7,$L$3:$L$9,1)+COUNTIF(L$6:$L7,L7)-1 -> 5 | V7: =Q4+T4 -> 116 | W7: =R4+U4 -> 97
B12: SUNDAY | D12: WEDNESDAY
B13: L1 | D13: L2
B14: SUNDAY | D14: WEDNESDAY
B16: Comment
D17: Not yet in use

Sheet week 23
A1: Collector | B1: Boar | C1: AGE | D1: TSI | E1: Genetic level | F1: Genetic Rank | G1: Last recorded raw Semen collected (mls) | H1: Last recorded Doses | I1: Dose rank | J1: Last recorded Morphology | K1: Morphology rank | L1: Overal Grading | M1: Overal Rank | P1: MULTIPLER SITE | AA1: 45677
P2: Sunday | Q2: Sunday | R2: Sunday | S2: Wed | T2: Wed | U2: Wed
A3: AW | B3: LA0499 | D3: 107 | E3: Average | F3: 1 | G3: 174 | H3: 73 | I3: =RANK(H3,$H$3:$H$9) -> 1 | J3: 89 | K3: =RANK(J3,$J$3:$J$9)+COUNTIF(J3:$J$3,J3)-1 -> 1 | L3: =(F3+K3)/2 -> 1 | M3: =RANK(L3,$L$3:$L$9,1)+COUNTIF(L3:$L$6,L3)-1 -> 1 | P3: required | Q3: estimate | R3: actual | S3: required | T3: estimate | U3: actual
A4: CM | B4: LA0724 | D4: 104 | E4: Average | F4: 2 | G4: 262 | H4: 70 | I4: =RANK(H4,$H$3:$H$9) -> 3 | J4: 87 | K4: =RANK(J4,$J$3:$J$9)+COUNTIF(J$3:$J4,J4)-1 -> 4 | L4: =(F4+K4)/2 -> 3 | M4: =RANK(L4,$L$3:$L$9,1)+COUNTIF(L4:$L$6,L4)-1 -> 3 | P4: 50 | Q4: 97 | R4: 89 | S4: 20
A5: AW | B5: LA0752 | D5: 103 | E5: Average | F5: 3 | G5: 98 | H5: 19 | I5: =RANK(H5,$H$3:$H$9) -> 5 | J5: 88 | K5: =RANK(J5,$J$3:$J$9)+COUNTIF(J$3:$J5,J5)-1 -> 3 | L5: =(F5+K5)/2 -> 3 | M5: =RANK(L5,$L$3:$L$9,1)+COUNTIF(L5:$L$6,L5)-1 -> 2 | V5: TOTAL OF THE WEEK
A6: TA | B6: LA0946 | D6: 102 | E6: Average | F6: 4 | G6: 138 | H6: 71 | I6: =RANK(H6,$H$3:$H$9) -> 2 | J6: 87 | K6: =RANK(J6,$J$3:$J$9)+COUNTIF(J$3:$J6,J6)-1 -> 5 | L6: =(F6+K6)/2 -> 4.5 | M6: =RANK(L6,$L$3:$L$9,1)+COUNTIF(L$6:$L6,L6)-1 -> 5 | V6: Estimated total | W6: Actual total
B7: CL1114 | D7: 86 | E7: Very low | F7: 5 | G7: 282 | H7: 22 | I7: =RANK(H7,$H$3:$H$9) -> 4 | J7: 89 | K7: =RANK(J7,$J$3:$J$9)+COUNTIF(J$3:$J7,J7)-1 -> 2 | L7: =(F7+K7)/2 -> 3.5 | M7: =RANK(L7,$L$3:$L$9,1)+COUNTIF(L$6:$L7,L7)-1 -> 4 | V7: =Q4+T4 -> 97 | W7: =R4+U4 -> 89
B12: SUNDAY | D12: WEDNESDAY
B13: L1 | D13: L2
B14: SUNDAY | D14: WEDNESDAY
B16: Comment
D17: Not yet in use

Sheet week 24
A1: Collector | B1: Boar | C1: AGE | D1: TSI | E1: Genetic level | F1: Genetic Rank | G1: Last recorded raw Semen collected (mls) | H1: Last recorded Doses | I1: Dose rank | J1: Last recorded Morphology | K1: Morphology rank | L1: Overal Grading | M1: Overal Rank | P1: MULTIPLER SITE | AA1: 45677
P2: Sunday | Q2: Sunday | R2: Sunday | S2: Wed | T2: Wed | U2: Wed
A3: CM | B3: LA0499 | D3: 107 | E3: Average | F3: 1 | G3: 114 | H3: 29 | I3: =RANK(H3,$H$3:$H$9) -> 3 | J3: 87 | K3: =RANK(J3,$J$3:$J$9)+COUNTIF(J3:$J$3,J3)-1 -> 4 | L3: =(F3+K3)/2 -> 2.5 | M3: =RANK(L3,$L$3:$L$9,1)+COUNTIF(L3:$L$6,L3)-1 -> 3 | P3: required | Q3: estimate | R3: actual | S3: required | T3: estimate | U3: actual
A4: TA | B4: LA0724 | D4: 104 | E4: Average | F4: 2 | G4: 294 | H4: 90 | I4: =RANK(H4,$H$3:$H$9) -> 1 | J4: 88 | K4: =RANK(J4,$J$3:$J$9)+COUNTIF(J$3:$J4,J4)-1 -> 2 | L4: =(F4+K4)/2 -> 2 | M4: =RANK(L4,$L$3:$L$9,1)+COUNTIF(L4:$L$6,L4)-1 -> 2 | P4: 50 | Q4: 89 | R4: 140 | S4: 20
A5: AW | B5: LA0752 | D5: 103 | E5: Average | F5: 3 | G5: 302 | H5: 50 | I5: =RANK(H5,$H$3:$H$9) -> 2 | J5: 89 | K5: =RANK(J5,$J$3:$J$9)+COUNTIF(J$3:$J5,J5)-1 -> 1 | L5: =(F5+K5)/2 -> 2 | M5: =RANK(L5,$L$3:$L$9,1)+COUNTIF(L5:$L$6,L5)-1 -> 1 | V5: TOTAL OF THE WEEK
A6: AW | B6: LA0946 | D6: 102 | E6: Average | F6: 4 | G6: 166 | H6: 21 | I6: =RANK(H6,$H$3:$H$9) -> 5 | J6: 88 | K6: =RANK(J6,$J$3:$J$9)+COUNTIF(J$3:$J6,J6)-1 -> 3 | L6: =(F6+K6)/2 -> 3.5 | M6: =RANK(L6,$L$3:$L$9,1)+COUNTIF(L$6:$L6,L6)-1 -> 4 | V6: Estimated total | W6: Actual total
B7: CL1114 | D7: 86 | E7: Very low | F7: 5 | G7: 282 | H7: 22 | I7: =RANK(H7,$H$3:$H$9) -> 4 | J7: 87 | K7: =RANK(J7,$J$3:$J$9)+COUNTIF(J$3:$J7,J7)-1 -> 5 | L7: =(F7+K7)/2 -> 5 | M7: =RANK(L7,$L$3:$L$9,1)+COUNTIF(L$6:$L7,L7)-1 -> 5 | V7: =Q4+T4 -> 89 | W7: =R4+U4 -> 140
B12: SUNDAY | D12: WEDNESDAY
B13: L1 | D13: L2
B14: SUNDAY | D14: WEDNESDAY
B16: Comment
D17: Not yet in use

Sheet week 25
A1: Collector | B1: Boar | C1: AGE | D1: TSI | E1: Genetic level | F1: Genetic Rank | G1: Last recorded raw Semen collected (mls) | H1: Last recorded Doses | I1: Dose rank | J1: Last recorded Morphology | K1: Morphology rank | L1: Overal Grading | M1: Overal Rank | P1: MULTIPLER SITE | AA1: 45677
P2: Sunday | Q2: Sunday | R2: Sunday | S2: Wed | T2: Wed | U2: Wed
A3: CM | B3: LA0499 | D3: 107 | E3: Average | F3: 1 | G3: 252 | H3: 41 | I3: =RANK(H3,$H$3:$H$9) -> 3 | J3: 88 | K3: =RANK(J3,$J$3:$J$9)+COUNTIF(J3:$J$3,J3)-1 -> 2 | L3: =(F3+K3)/2 -> 1.5 | M3: =RANK(L3,$L$3:$L$9,1)+COUNTIF(L3:$L$6,L3)-1 -> 1 | P3: required | Q3: estimate | R3: actual | S3: required | T3: estimate | U3: actual
A4: TA | B4: LA0724 | D4: 104 | E4: Average | F4: 2 | G4: 160 | H4: 47 | I4: =RANK(H4,$H$3:$H$9) -> 2 | J4: 87 | K4: =RANK(J4,$J$3:$J$9)+COUNTIF(J$3:$J4,J4)-1 -> 4 | L4: =(F4+K4)/2 -> 3 | M4: =RANK(L4,$L$3:$L$9,1)+COUNTIF(L4:$L$6,L4)-1 -> 4 | P4: 50 | S4: 20
A5: CM | B5: LA0752 | D5: 103 | E5: Average | F5: 3 | G5: 170 | H5: 39 | I5: =RANK(H5,$H$3:$H$9) -> 4 | J5: 88 | K5: =RANK(J5,$J$3:$J$9)+COUNTIF(J$3:$J5,J5)-1 -> 3 | L5: =(F5+K5)/2 -> 3 | M5: =RANK(L5,$L$3:$L$9,1)+COUNTIF(L5:$L$6,L5)-1 -> 3 | V5: TOTAL OF THE WEEK
A6: TA | B6: LA0946 | D6: 102 | E6: Average | F6: 4 | G6: 200 | H6: 48 | I6: =RANK(H6,$H$3:$H$9) -> 1 | J6: 89 | K6: =RANK(J6,$J$3:$J$9)+COUNTIF(J$3:$J6,J6)-1 -> 1 | L6: =(F6+K6)/2 -> 2.5 | M6: =RANK(L6,$L$3:$L$9,1)+COUNTIF(L$6:$L6,L6)-1 -> 2 | V6: Estimated total | W6: Actual total
V7: =Q4+T4 -> 0 | W7: =R4+U4 -> 0
B12: SUNDAY | D12: WEDNESDAY
B13: L1 | D13: L2
B14: SUNDAY | D14: WEDNESDAY
B16: Comment
D17: Not yet in use

Sheet week 26 
A1: Collector | B1: Boar | C1: AGE | D1: TSI | E1: Genetic level | F1: Genetic Rank | G1: Last recorded raw Semen collected (mls) | H1: Last recorded Doses | I1: Dose rank | J1: Last recorded Morphology | K1: Morphology rank | L1: Overal Grading | M1: Overal Rank | P1: MULTIPLER SITE | AA1: 45677
P2: Sunday | Q2: Sunday | R2: Sunday | S2: Wed | T2: Wed | U2: Wed
A3: AW | B3: LA0499 | D3: 107 | E3: Average | F3: 1 | G3: 150 | H3: 50 | I3: =RANK(H3,$H$3:$H$9) -> 2 | J3: 89 | K3: =RANK(J3,$J$3:$J$9)+COUNTIF(J3:$J$3,J3)-1 -> 1 | L3: =(F3+K3)/2 -> 1 | M3: =RANK(L3,$L$3:$L$9,1)+COUNTIF(L3:$L$6,L3)-1 -> 1 | P3: required | Q3: estimate | R3: actual | S3: required | T3: estimate | U3: actual
A4: TA | B4: LA0724 | D4: 104 | E4: Average | F4: 2 | G4: 262 | H4: 29 | I4: =RANK(H4,$H$3:$H$9) -> 4 | J4: 88 | K4: =RANK(J4,$J$3:$J$9)+COUNTIF(J$3:$J4,J4)-1 -> 2 | L4: =(F4+K4)/2 -> 2 | M4: =RANK(L4,$L$3:$L$9,1)+COUNTIF(L4:$L$6,L4)-1 -> 2 | P4: 50 | S4: 20
A5: CM | B5: LA0752 | D5: 103 | E5: Average | F5: 3 | G5: 258 | H5: 41 | I5: =RANK(H5,$H$3:$H$9) -> 3 | J5: 87 | K5: =RANK(J5,$J$3:$J$9)+COUNTIF(J$3:$J5,J5)-1 -> 4 | L5: =(F5+K5)/2 -> 3.5 | M5: =RANK(L5,$L$3:$L$9,1)+COUNTIF(L5:$L$6,L5)-1 -> 4 | V5: TOTAL OF THE WEEK
A6: CM | B6: LA0946 | D6: 102 | E6: Average | F6: 4 | G6: 390 | H6: 91 | I6: =RANK(H6,$H$3:$H$9) -> 1 | J6: 88 | K6: =RANK(J6,$J$3:$J$9)+COUNTIF(J$3:$J6,J6)-1 -> 3 | L6: =(F6+K6)/2 -> 3.5 | M6: =RANK(L6,$L$3:$L$9,1)+COUNTIF(L$6:$L6,L6)-1 -> 3 | V6: Estimated total | W6: Actual total
V7: =Q4+T4 -> 0 | W7: =R4+U4 -> 0
B12: SUNDAY | D12: WEDNESDAY
B13: L1 | D13: L2
B14: SUNDAY | D14: WEDNESDAY
B16: Comment
D17: Not yet in use

Sheet week 27
A1: Collector | B1: Boar | C1: AGE | D1: TSI | E1: Genetic level | F1: Genetic Rank | G1: Last recorded raw Semen collected (mls) | H1: Last recorded Doses | I1: Dose rank | J1: Last recorded Morphology | K1: Morphology rank | L1: Overal Grading | M1: Overal Rank | P1: MULTIPLER SITE | AA1: 45677
P2: Sunday | Q2: Sunday | R2: Sunday | S2: Wed | T2: Wed | U2: Wed
A3: CM | B3: LA0499 | D3: 107 | E3: Average | F3: 1 | G3: 142 | H3: 38 | I3: =RANK(H3,$H$3:$H$9) -> 3 | J3: 87 | K3: =RANK(J3,$J$3:$J$9)+COUNTIF(J3:$J$3,J3)-1 -> 2 | L3: =(F3+K3)/2 -> 1.5 | M3: =RANK(L3,$L$3:$L$9,1)+COUNTIF(L3:$L$6,L3)-1 -> 2 | P3: required | Q3: estimate | R3: actual | S3: required | T3: estimate | U3: actual
A4: TA | B4: LA0724 | D4: 104 | E4: Average | F4: 2 | G4: 200 | H4: 76 | I4: =RANK(H4,$H$3:$H$9) -> 1 | J4: 88 | K4: =RANK(J4,$J$3:$J$9)+COUNTIF(J$3:$J4,J4)-1 -> 1 | L4: =(F4+K4)/2 -> 1.5 | M4: =RANK(L4,$L$3:$L$9,1)+COUNTIF(L4:$L$6,L4)-1 -> 1 | P4: 50 | S4: 20
A5: AW | B5: LA0752 | D5: 103 | E5: Average | F5: 3 | G5: 156 | H5: 38 | I5: =RANK(H5,$H$3:$H$9) -> 3 | J5: 87 | K5: =RANK(J5,$J$3:$J$9)+COUNTIF(J$3:$J5,J5)-1 -> 3 | L5: =(F5+K5)/2 -> 3 | M5: =RANK(L5,$L$3:$L$9,1)+COUNTIF(L5:$L$6,L5)-1 -> 3 | V5: TOTAL OF THE WEEK
A6: CM | B6: LA0946 | D6: 102 | E6: Average | F6: 4 | G6: 192 | H6: 45 | I6: =RANK(H6,$H$3:$H$9) -> 2 | J6: 87 | K6: =RANK(J6,$J$3:$J$9)+COUNTIF(J$3:$J6,J6)-1 -> 4 | L6: =(F6+K6)/2 -> 4 | M6: =RANK(L6,$L$3:$L$9,1)+COUNTIF(L$6:$L6,L6)-1 -> 4 | V6: Estimated total | W6: Actual total
V7: =Q4+T4 -> 0 | W7: =R4+U4 -> 0
B12: SUNDAY | D12: WEDNESDAY
B13: L1 | D13: L2
B14: SUNDAY | D14: WEDNESDAY
B16: Comment
D17: Not yet in use

Sheet week 28
A1: Collector | B1: Boar | C1: AGE | D1: TSI | E1: Genetic level | F1: Genetic Rank | G1: Last recorded raw Semen collected (mls) | H1: Last recorded Doses | I1: Dose rank | J1: Last recorded Morphology | K1: Morphology rank | L1: Overal Grading | M1: Overal Rank | P1: MULTIPLER SITE | AA1: 45677
P2: Sunday | Q2: Sunday | R2: Sunday | S2: Wed | T2: Wed | U2: Wed
A3: AW | B3: LA0499 | C3: 655 | D3: 107 | E3: Average | F3: 1 | G3: 206 | H3: 22 | I3: =RANK(H3,$H$3:$H$9) -> 4 | J3: 86 | K3: =RANK(J3,$J$3:$J$9)+COUNTIF(J3:$J$3,J3)-1 -> 3 | L3: =(F3+K3)/2 -> 2 | M3: =RANK(L3,$L$3:$L$9,1)+COUNTIF(L3:$L$6,L3)-1 -> 1 | P3: required | Q3: estimate | R3: actual | S3: required | T3: estimate | U3: actual
A4: TA | B4: LA0724 | C4: 492 | D4: 104 | E4: Average | F4: 2 | G4: 188 | H4: 37 | I4: =RANK(H4,$H$3:$H$9) -> 3 | J4: 85 | K4: =RANK(J4,$J$3:$J$9)+COUNTIF(J$3:$J4,J4)-1 -> 4 | L4: =(F4+K4)/2 -> 3 | M4: =RANK(L4,$L$3:$L$9,1)+COUNTIF(L4:$L$6,L4)-1 -> 4 | P4: 50 | R4: 69 | S4: 20
A5: TA | B5: LA0752 | C5: 485 | D5: 103 | E5: Average | F5: 3 | G5: 324 | H5: 47 | I5: =RANK(H5,$H$3:$H$9) -> 2 | J5: 87 | K5: =RANK(J5,$J$3:$J$9)+COUNTIF(J$3:$J5,J5)-1 -> 2 | L5: =(F5+K5)/2 -> 2.5 | M5: =RANK(L5,$L$3:$L$9,1)+COUNTIF(L5:$L$6,L5)-1 -> 3 | V5: TOTAL OF THE WEEK
A6: CM | B6: LA0946 | C6: 359 | D6: 102 | E6: Average | F6: 4 | G6: 318 | H6: 69 | I6: =RANK(H6,$H$3:$H$9) -> 1 | J6: 88 | K6: =RANK(J6,$J$3:$J$9)+COUNTIF(J$3:$J6,J6)-1 -> 1 | L6: =(F6+K6)/2 -> 2.5 | M6: =RANK(L6,$L$3:$L$9,1)+COUNTIF(L$6:$L6,L6)-1 -> 2 | V6: Estimated total | W6: Actual total
V7: =Q4+T4 -> 0 | W7: =R4+U4 -> 69
B12: SUNDAY | D12: WEDNESDAY
B13: L1 | D13: L2
B14: SUNDAY | D14: WEDNESDAY
B16: Comment
D17: Not yet in use

Sheet week 29
A1: Collector | B1: Boar | C1: AGE | D1: TSI | E1: Genetic level | F1: Genetic Rank | G1: Last recorded raw Semen collected (mls) | H1: Last recorded Doses | I1: Dose rank | J1: Last recorded Morphology | K1: Morphology rank | L1: Overal Grading | M1: Overal Rank | P1: MULTIPLER SITE | AA1: 45677
P2: Sunday | Q2: Sunday | R2: Sunday | S2: Wed | T2: Wed | U2: Wed
A3: CM | B3: LA0499 | C3: 662 | D3: 107 | E3: Average | F3: 1 | G3: 174 | H3: 23 | I3: =RANK(H3,$H$3:$H$9) -> 4 | J3: 88 | K3: =RANK(J3,$J$3:$J$9)+COUNTIF(J3:$J$3,J3)-1 -> 1 | L3: =(F3+K3)/2 -> 1 | M3: =RANK(L3,$L$3:$L$9,1)+COUNTIF(L3:$L$6,L3)-1 -> 1 | P3: required | Q3: estimate | R3: actual | S3: required | T3: estimate | U3: actual
A4: AW | B4: LA0724 | C4: 499 | D4: 104 | E4: Average | F4: 2 | G4: 350 | H4: 37 | I4: =RANK(H4,$H$3:$H$9) -> 3 | J4: 87 | K4: =RANK(J4,$J$3:$J$9)+COUNTIF(J$3:$J4,J4)-1 -> 2 | L4: =(F4+K4)/2 -> 2 | M4: =RANK(L4,$L$3:$L$9,1)+COUNTIF(L4:$L$6,L4)-1 -> 2 | P4: 50 | Q4: 69 | R4: 64 | S4: 20
A5: AW | B5: LA0752 | C5: 492 | D5: 103 | E5: Average | F5: 3 | G5: 337 | H5: 41 | I5: =RANK(H5,$H$3:$H$9) -> 2 | J5: 86 | K5: =RANK(J5,$J$3:$J$9)+COUNTIF(J$3:$J5,J5)-1 -> 4 | L5: =(F5+K5)/2 -> 3.5 | M5: =RANK(L5,$L$3:$L$9,1)+COUNTIF(L5:$L$6,L5)-1 -> 4 | V5: TOTAL OF THE WEEK
A6: TA | B6: LA0946 | C6: 366 | D6: 102 | E6: Average | F6: 4 | G6: 228 | H6: 67 | I6: =RANK(H6,$H$3:$H$9) -> 1 | J6: 87 | K6: =RANK(J6,$J$3:$J$9)+COUNTIF(J$3:$J6,J6)-1 -> 3 | L6: =(F6+K6)/2 -> 3.5 | M6: =RANK(L6,$L$3:$L$9,1)+COUNTIF(L$6:$L6,L6)-1 -> 3 | V6: Estimated total | W6: Actual total
V7: =Q4+T4 -> 69 | W7: =R4+U4 -> 64
B12: SUNDAY | D12: WEDNESDAY
B13: L1 | D13: L2
B14: SUNDAY | D14: WEDNESDAY
B16: Comment
D17: Not yet in use

Sheet week 30
A1: Collector | B1: Boar | C1: DoB | D1: Age | E1: TSI | F1: Genetic level | G1: Genetic Rank | H1: Last recorded raw Semen collected (mls) | I1: Last recorded Doses | J1: Dose rank | K1: Last recorded Morphology | L1: Morphology rank | M1: Overal Grading | N1: Overal Rank | Q1: MULTIPLER SITE | AB1: 45677
P2: 46216 | Q2: Sunday | R2: Sunday | S2: Sunday | T2: Wed | U2: Wed | V2: Wed
A3: CM | B3: LA0499 | C3: 45547 | D3: =$P$2-C3 -> 669 | E3: 107 | F3: Average | G3: 1 | H3: 280 | I3: 71 | J3: =RANK(I3,$I$3:$I$9) -> 1 | K3: 87 | L3: =RANK(K3,$K$3:$K$9)+COUNTIF(K3:$K$3,K3)-1 -> 2 | M3: =(G3+L3)/2 -> 1.5 | N3: =RANK(M3,$M$3:$M$9,1)+COUNTIF(M3:$M$6,M3)-1 -> 1 | Q3: required | R3: estimate | S3: actual | T3: required | U3: estimate | V3: actual
A4: AW | B4: LA0724 | C4: 45710 | D4: =$P$2-C4 -> 506 | E4: 104 | F4: Average | G4: 2 | H4: 256 | I4: 60 | J4: =RANK(I4,$I$3:$I$9) -> 2 | K4: 86 | L4: =RANK(K4,$K$3:$K$9)+COUNTIF(K$3:$K4,K4)-1 -> 4 | M4: =(G4+L4)/2 -> 3 | N4: =RANK(M4,$M$3:$M$9,1)+COUNTIF(M4:$M$6,M4)-1 -> 4 | Q4: 50 | T4: 20
A5: AW | B5: LA0752 | C5: 45717 | D5: =$P$2-C5 -> 499 | E5: 103 | F5: Average | G5: 3 | H5: 358 | I5: 28 | J5: =RANK(I5,$I$3:$I$9) -> 4 | K5: 87 | L5: =RANK(K5,$K$3:$K$9)+COUNTIF(K$3:$K5,K5)-1 -> 3 | M5: =(G5+L5)/2 -> 3 | N5: =RANK(M5,$M$3:$M$9,1)+COUNTIF(M5:$M$6,M5)-1 -> 3 | W5: TOTAL OF THE WEEK
A6: CM | B6: LA0946 | C6: 45843 | D6: =$P$2-C6 -> 373 | E6: 102 | F6: Average | G6: 4 | H6: 138 | I6: 40 | J6: =RANK(I6,$I$3:$I$9) -> 3 | K6: 88 | L6: =RANK(K6,$K$3:$K$9)+COUNTIF(K$3:$K6,K6)-1 -> 1 | M6: =(G6+L6)/2 -> 2.5 | N6: =RANK(M6,$M$3:$M$9,1)+COUNTIF(M$6:$M6,M6)-1 -> 2 | W6: Estimated total | X6: Actual total
W7: =R4+U4 -> 0 | X7: =S4+V4 -> 0
B12: SUNDAY | C12: WEDNESDAY
B13: L1 | C13: L2
B14: SUNDAY | C14: WEDNESDAY
B16: Comment
C17: Not yet in use

Sheet week 31
