Workbook

Sheet week 01
A1: Collector ID | B1: Boar | C1: TSI | D1: Genetic level | E1: Genetic Rank | F1: Last recorded raw Semen collected (mls) | G1: Last recorded Doses | H1: Dose rank | I1: Last recorded Morphology | J1: Morphology Rank | K1: Overal Grading | L1: Overal Rank | Y1: 45677
O2: Sunday | P2: Sunday | Q2: Sunday | R2: Wed | S2: Wed | T2: Wed
A3: TA | B3: DA2338 | C3: 114 | D3: Average | E3: 1 | F3: 134 | G3: 30 | H3: =RANK(G3,$G$3:$G$17)+COUNTIF(G3:$G$3,G3)-1 -> 13 | I3: 88 | J3: =RANK(I3,$I$3:$I$17)+COUNTIF(I3:$I$3,I3)-1 -> 5 | K3: =(E3+J3)/2 -> 3 | L3: =RANK(K3,$K$3:$K$17,1)+COUNTIF(K3:$K$3,K3)-1 -> 2 | O3: required | P3: estimate | Q3: actual | R3: required | S3: estimate | T3: actual
A4: AW | B4: DA1669 | C4: 111 | D4: Average | E4: 2 | F4: 360 | G4: 80 | H4: =RANK(G4,$G$3:$G$17)+COUNTIF(G$3:$G4,G4)-1 -> 6 | I4: 87 | J4: =RANK(I4,$I$3:$I$17)+COUNTIF(I$3:$I4,I4)-1 -> 10 | K4: =(E4+J4)/2 -> 6 | L4: =RANK(K4,$K$3:$K$17,1)+COUNTIF(K$3:$K4,K4)-1 -> 4 | N4: total | O4: =SUM(O5:O9) -> 480 | P4: 495 | Q4: 502 | R4: =SUM(R5:R9) -> 180 | S4: 214 | T4: 291
B5: DA2470 | C5: 111 | D5: Average | E5: 3 | F5: 100 | G5: 5 | H5: =RANK(G5,$G$3:$G$17)+COUNTIF(G$3:$G5,G5)-1 -> 14 | I5: 89 | J5: =RANK(I5,$I$3:$I$17)+COUNTIF(I$3:$I5,I5)-1 -> 1 | K5: =(E5+J5)/2 -> 2 | L5: =RANK(K5,$K$3:$K$17,1)+COUNTIF(K$3:$K5,K5)-1 -> 1 | N5: grasmere | O5: 180 | R5: 60
A6: AW | B6: DA1130 | C6: 107 | D6: Average | E6: 4 | F6: 358 | G6: 48 | H6: =RANK(G6,$G$3:$G$17)+COUNTIF(G$3:$G6,G6)-1 -> 10 | I6: 87 | J6: =RANK(I6,$I$3:$I$17)+COUNTIF(I$3:$I6,I6)-1 -> 11 | K6: =(E6+J6)/2 -> 7.5 | L6: =RANK(K6,$K$3:$K$17,1)+COUNTIF(K$3:$K6,K6)-1 -> 7 | N6: richlands | O6: 85 | R6: 35
A7: TA | B7: DA1721 | C7: 107 | D7: Average | E7: 5 | F7: 145 | G7: 154 | H7: =RANK(G7,$G$3:$G$17)+COUNTIF(G$3:$G7,G7)-1 -> 1 | I7: 86 | J7: =RANK(I7,$I$3:$I$17)+COUNTIF(I$3:$I7,I7)-1 -> 15 | K7: =(E7+J7)/2 -> 10 | L7: =RANK(K7,$K$3:$K$17,1)+COUNTIF(K$3:$K7,K7)-1 -> 11 | N7: Villa | O7: 40 | R7: 10 | U7: Actual total | V7: estimated
A8: TA | B8: DA1627 | C8: 106 | D8: Average | E8: 6 | F8: 338 | G8: 83 | H8: =RANK(G8,$G$3:$G$17)+COUNTIF(G$3:$G8,G8)-1 -> 5 | I8: 87 | J8: =RANK(I8,$I$3:$I$17)+COUNTIF(I$3:$I8,I8)-1 -> 12 | K8: =(E8+J8)/2 -> 9 | L8: =RANK(K8,$K$3:$K$17,1)+COUNTIF(K$3:$K8,K8)-1 -> 9 | N8: Lions Head | O8: 95 | R8: 40 | U8: =Q4+T4 -> 793 | V8: =P4+S4 -> 709
B9: DA2477 | C9: 105 | D9: Average | E9: 7 | F9: 0 | G9: 0 | H9: =RANK(G9,$G$3:$G$17)+COUNTIF(G$3:$G9,G9)-1 -> 15 | I9: 87 | J9: =RANK(I9,$I$3:$I$17)+COUNTIF(I$3:$I9,I9)-1 -> 13 | K9: xd | L9: =RANK(K9,$K$3:$K$17,1)+COUNTIF(K$3:$K9,K9)-1 -> #VALUE! | N9: Porta | O9: 80 | R9: 35 | V9: =U8-V8 -> 84
A10: TA | B10: DA2568 | C10: 104 | D10: Average | E10: 8 | F10: 170 | G10: 41 | H10: =RANK(G10,$G$3:$G$17)+COUNTIF(G$3:$G10,G10)-1 -> 11 | I10: 88 | J10: =RANK(I10,$I$3:$I$17)+COUNTIF(I$3:$I10,I10)-1 -> 6 | K10: =(E10+J10)/2 -> 7 | L10: =RANK(K10,$K$3:$K$17,1)+COUNTIF(K$3:$K10,K10)-1 -> 5
A11: TA | B11: CL7180 | C11: 102 | D11: Below average | E11: 9 | F11: 278 | G11: 61 | H11: =RANK(G11,$G$3:$G$17)+COUNTIF(G$3:$G11,G11)-1 -> 9 | I11: 89 | J11: =RANK(I11,$I$3:$I$17)+COUNTIF(I$3:$I11,I11)-1 -> 2 | K11: =(E11+J11)/2 -> 5.5 | L11: =RANK(K11,$K$3:$K$17,1)+COUNTIF(K$3:$K11,K11)-1 -> 3
A12: AW | B12: CJ0211 | C12: 101 | D12: Below average | E12: 10 | F12: 638 | G12: 91 | H12: =RANK(G12,$G$3:$G$17)+COUNTIF(G$3:$G12,G12)-1 -> 3 | I12: 88 | J12: =RANK(I12,$I$3:$I$17)+COUNTIF(I$3:$I12,I12)-1 -> 7 | K12: =(E12+J12)/2 -> 8.5 | L12: =RANK(K12,$K$3:$K$17,1)+COUNTIF(K$3:$K12,K12)-1 -> 8
A13: AW | B13: CL5312 | C13: 98 | D13: Low | E13: 11 | F13: 278 | G13: 71 | H13: =RANK(G13,$G$3:$G$17)+COUNTIF(G$3:$G13,G13)-1 -> 7 | I13: 89 | J13: =RANK(I13,$I$3:$I$17)+COUNTIF(I$3:$I13,I13)-1 -> 3 | K13: =(E13+J13)/2 -> 7 | L13: =RANK(K13,$K$3:$K$17,1)+COUNTIF(K$3:$K13,K13)-1 -> 6
A14: AW | B14: CL3033 | C14: 97 | D14: Low | E14: 12 | F14: 372 | G14: 85 | H14: =RANK(G14,$G$3:$G$17)+COUNTIF(G$3:$G14,G14)-1 -> 4 | I14: 88 | J14: =RANK(I14,$I$3:$I$17)+COUNTIF(I$3:$I14,I14)-1 -> 8 | K14: =(E14+J14)/2 -> 10 | L14: =RANK(K14,$K$3:$K$17,1)+COUNTIF(K$3:$K14,K14)-1 -> 12
A15: CM | B15: DA0379 | C15: 95 | D15: Low | E15: 13 | F15: 318 | G15: 92 | H15: =RANK(G15,$G$3:$G$17)+COUNTIF(G$3:$G15,G15)-1 -> 2 | I15: 87 | J15: =RANK(I15,$I$3:$I$17)+COUNTIF(I$3:$I15,I15)-1 -> 14 | K15: =(E15+J15)/2 -> 13.5 | L15: =RANK(K15,$K$3:$K$17,1)+COUNTIF(K$3:$K15,K15)-1 -> 14
B16: CJ2150 | C16: 91 | D16: Low | E16: 14 | F16: 201 | G16: 41 | H16: =RANK(G16,$G$3:$G$17)+COUNTIF(G$3:$G16,G16)-1 -> 12 | I16: 89 | J16: =RANK(I16,$I$3:$I$17)+COUNTIF(I$3:$I16,I16)-1 -> 4 | K16: =(E16+J16)/2 -> 9 | L16: =RANK(K16,$K$3:$K$17,1)+COUNTIF(K$3:$K16,K16)-1 -> 10
A17: AW | B17: CE6835 | C17: 90 | D17: Low | E17: 15 | F17: 214 | G17: 63 | H17: =RANK(G17,$G$3:$G$17)+COUNTIF(G$3:$G17,G17)-1 -> 8 | I17: 88 | J17: =RANK(I17,$I$3:$I$17)+COUNTIF(I$3:$I17,I17)-1 -> 9 | K17: =(E17+J17)/2 -> 12 | L17: =RANK(K17,$K$3:$K$17,1)+COUNTIF(K$3:$K17,K17)-1 -> 13
B20: Sunday | C20: Wednesday
B21: T1 | C21: T2
B24: COMMENT
B25: DA2477 and DA2470 are still not mounting the dummy and we are currently working on them
B26: CJ50 RESTED IN WEEK 1

Sheet week 02
A1: Collector ID | B1: Boar | C1: TSI | D1: Genetic level | E1: Genetic Rank | F1: Last recorded raw Semen collected (mls) | G1: Last recorded Doses | H1: Dose rank | I1: Last recorded Morphology | J1: Morphology Rank | K1: Overal Grading | L1: Overal Rank | Y1: 45677
O2: Sunday | P2: Sunday | Q2: Sunday | R2: Wed | S2: Wed | T2: Wed
A3: CM | B3: DA2338 | C3: 114 | D3: Average | E3: 1 | F3: 112 | G3: 48 | H3: =RANK(G3,$G$3:$G$17)+COUNTIF(G3:$G$3,G3)-1 -> 8 | I3: 87 | J3: =RANK(I3,$I$3:$I$17)+COUNTIF(I3:$I$3,I3)-1 -> 10 | K3: =(E3+J3)/2 -> 5.5 | L3: =RANK(K3,$K$3:$K$17,1)+COUNTIF(K3:$K$3,K3)-1 -> 3 | O3: required | P3: estimate | Q3: actual | R3: required | S3: estimate | T3: actual
A4: CM | B4: DA1669 | C4: 111 | D4: Average | E4: 2 | F4: 250 | G4: 65 | H4: =RANK(G4,$G$3:$G$17)+COUNTIF(G$3:$G4,G4)-1 -> 5 | I4: 88 | J4: =RANK(I4,$I$3:$I$17)+COUNTIF(I$3:$I4,I4)-1 -> 4 | K4: =(E4+J4)/2 -> 3 | L4: =RANK(K4,$K$3:$K$17,1)+COUNTIF(K$3:$K4,K4)-1 -> 1 | N4: total | O4: =SUM(O5:O9) -> 480 | P4: 509 | Q4: 490 | R4: =SUM(R5:R9) -> 180 | S4: 291 | T4: 211
B5: DA2470 | C5: 111 | D5: Average | E5: 3 | F5: 0 | G5: 0 | H5: =RANK(G5,$G$3:$G$17)+COUNTIF(G$3:$G5,G5)-1 -> 14 | I5: 0 | J5: =RANK(I5,$I$3:$I$17)+COUNTIF(I$3:$I5,I5)-1 -> 14 | K5: =(E5+J5)/2 -> 8.5 | L5: =RANK(K5,$K$3:$K$17,1)+COUNTIF(K$3:$K5,K5)-1 -> 10 | N5: grasmere | O5: 180 | R5: 60
A6: AW | B6: DA1130 | C6: 107 | D6: Average | E6: 4 | F6: 550 | G6: 120 | H6: =RANK(G6,$G$3:$G$17)+COUNTIF(G$3:$G6,G6)-1 -> 1 | I6: 87 | J6: =RANK(I6,$I$3:$I$17)+COUNTIF(I$3:$I6,I6)-1 -> 11 | K6: =(E6+J6)/2 -> 7.5 | L6: =RANK(K6,$K$3:$K$17,1)+COUNTIF(K$3:$K6,K6)-1 -> 6 | N6: richlands | O6: 85 | R6: 35
A7: CM | B7: DA1721 | C7: 107 | D7: Average | E7: 5 | F7: 215 | G7: 45 | H7: =RANK(G7,$G$3:$G$17)+COUNTIF(G$3:$G7,G7)-1 -> 9 | I7: 89 | J7: =RANK(I7,$I$3:$I$17)+COUNTIF(I$3:$I7,I7)-1 -> 2 | K7: =(E7+J7)/2 -> 3.5 | L7: =RANK(K7,$K$3:$K$17,1)+COUNTIF(K$3:$K7,K7)-1 -> 2 | N7: Villa | O7: 40 | R7: 10 | U7: Actual total | V7: estimated
A8: AW | B8: DA1627 | C8: 106 | D8: Average | E8: 6 | F8: 328 | G8: 57 | H8: =RANK(G8,$G$3:$G$17)+COUNTIF(G$3:$G8,G8)-1 -> 7 | I8: 88 | J8: =RANK(I8,$I$3:$I$17)+COUNTIF(I$3:$I8,I8)-1 -> 5 | K8: =(E8+J8)/2 -> 5.5 | L8: =RANK(K8,$K$3:$K$17,1)+COUNTIF(K$3:$K8,K8)-1 -> 4 | N8: Lions Head | O8: 95 | R8: 40 | U8: =Q4+T4 -> 701 | V8: =P4+S4 -> 800
B9: DA2477 | C9: 105 | D9: Average | E9: 7 | F9: 0 | G9: 0 | H9: =RANK(G9,$G$3:$G$17)+COUNTIF(G$3:$G9,G9)-1 -> 15 | I9: 0 | J9: =RANK(I9,$I$3:$I$17)+COUNTIF(I$3:$I9,I9)-1 -> 15 | K9: =(E9+J9)/2 -> 11 | L9: =RANK(K9,$K$3:$K$17,1)+COUNTIF(K$3:$K9,K9)-1 -> 13 | N9: Porta | O9: 80 | R9: 35 | V9: =U8-V8 -> -99
A10: CM | B10: DA2568 | C10: 104 | D10: Average | E10: 8 | F10: 252 | G10: 44 | H10: =RANK(G10,$G$3:$G$17)+COUNTIF(G$3:$G10,G10)-1 -> 10 | I10: 88 | J10: =RANK(I10,$I$3:$I$17)+COUNTIF(I$3:$I10,I10)-1 -> 6 | K10: =(E10+J10)/2 -> 7 | L10: =RANK(K10,$K$3:$K$17,1)+COUNTIF(K$3:$K10,K10)-1 -> 5
A11: CM | B11: CL7180 | C11: 102 | D11: Below average | E11: 9 | F11: 172 | G11: 58 | H11: =RANK(G11,$G$3:$G$17)+COUNTIF(G$3:$G11,G11)-1 -> 6 | I11: 88 | J11: =RANK(I11,$I$3:$I$17)+COUNTIF(I$3:$I11,I11)-1 -> 7 | K11: =(E11+J11)/2 -> 8 | L11: =RANK(K11,$K$3:$K$17,1)+COUNTIF(K$3:$K11,K11)-1 -> 8
A12: CM | B12: CJ0211 | C12: 101 | D12: Below average | E12: 10 | F12: 514 | G12: 94 | H12: =RANK(G12,$G$3:$G$17)+COUNTIF(G$3:$G12,G12)-1 -> 2 | I12: 88 | J12: =RANK(I12,$I$3:$I$17)+COUNTIF(I$3:$I12,I12)-1 -> 8 | K12: =(E12+J12)/2 -> 9 | L12: =RANK(K12,$K$3:$K$17,1)+COUNTIF(K$3:$K12,K12)-1 -> 11
A13: AW | B13: CL5312 | C13: 98 | D13: Low | E13: 11 | F13: 346 | G13: 67 | H13: =RANK(G13,$G$3:$G$17)+COUNTIF(G$3:$G13,G13)-1 -> 4 | I13: 88 | J13: =RANK(I13,$I$3:$I$17)+COUNTIF(I$3:$I13,I13)-1 -> 9 | K13: =(E13+J13)/2 -> 10 | L13: =RANK(K13,$K$3:$K$17,1)+COUNTIF(K$3:$K13,K13)-1 -> 12
A14: AW | B14: CL3033 | C14: 97 | D14: Low | E14: 12 | F14: 372 | G14: 90 | H14: =RANK(G14,$G$3:$G$17)+COUNTIF(G$3:$G14,G14)-1 -> 3 | I14: 87 | J14: =RANK(I14,$I$3:$I$17)+COUNTIF(I$3:$I14,I14)-1 -> 12 | K14: =(E14+J14)/2 -> 12 | L14: =RANK(K14,$K$3:$K$17,1)+COUNTIF(K$3:$K14,K14)-1 -> 14
A15: CM | B15: DA0379 | C15: 95 | D15: Low | E15: 13 | F15: 212 | G15: 34 | H15: =RANK(G15,$G$3:$G$17)+COUNTIF(G$3:$G15,G15)-1 -> 11 | I15: 89 | J15: =RANK(I15,$I$3:$I$17)+COUNTIF(I$3:$I15,I15)-1 -> 3 | K15: =(E15+J15)/2 -> 8 | L15: =RANK(K15,$K$3:$K$17,1)+COUNTIF(K$3:$K15,K15)-1 -> 9
B16: CJ2150 | C16: 91 | D16: Low | E16: 14 | F16: 145 | G16: 26 | H16: =RANK(G16,$G$3:$G$17)+COUNTIF(G$3:$G16,G16)-1 -> 13 | I16: 90 | J16: =RANK(I16,$I$3:$I$17)+COUNTIF(I$3:$I16,I16)-1 -> 1 | K16: =(E16+J16)/2 -> 7.5 | L16: =RANK(K16,$K$3:$K$17,1)+COUNTIF(K$3:$K16,K16)-1 -> 7
A17: CM | B17: CE6835 | C17: 90 | D17: Low | E17: 15 | F17: 226 | G17: 27 | H17: =RANK(G17,$G$3:$G$17)+COUNTIF(G$3:$G17,G17)-1 -> 12 | I17: 87 | J17: =RANK(I17,$I$3:$I$17)+COUNTIF(I$3:$I17,I17)-1 -> 13 | K17: =(E17+J17)/2 -> 14 | L17: =RANK(K17,$K$3:$K$17,1)+COUNTIF(K$3:$K17,K17)-1 -> 15
B20: Sunday | C20: Wednesday
B21: T1 | C21: T2
B24: COMMENT
B25: DA38, CJ50, rested in week 02
B26: DA2477 and DA2470 are still not mounting the dummy and we are currently working on them

Sheet week 03
A1: Collector ID | B1: Boar | C1: TSI | D1: Genetic level | E1: Genetic Rank | F1: Last recorded raw Semen collected (mls) | G1: Last recorded Doses | H1: Dose rank | I1: Last recorded Morphology | J1: Morphology Rank | K1: Overal Grading | L1: Overal Rank | Y1: 45677
O2: Sunday | P2: Sunday | Q2: Sunday | R2: Wed | S2: Wed | T2: Wed
A3: AW | B3: DA2338 | C3: 114 | D3: Average | E3: 1 | F3: 186 | G3: 32 | H3: =RANK(G3,$G$3:$G$17)+COUNTIF(G3:$G$3,G3)-1 -> 12 | I3: 87 | J3: =RANK(I3,$I$3:$I$17)+COUNTIF(I3:$I$3,I3)-1 -> 9 | K3: =(E3+J3)/2 -> 5 | L3: =RANK(K3,$K$3:$K$17,1)+COUNTIF(K3:$K$3,K3)-1 -> 3 | O3: required | P3: estimate | Q3: actual | R3: required | S3: estimate | T3: actual
A4: AW | B4: DA1669 | C4: 111 | D4: Average | E4: 2 | F4: 318 | G4: 45 | H4: =RANK(G4,$G$3:$G$17)+COUNTIF(G$3:$G4,G4)-1 -> 8 | I4: 89 | J4: =RANK(I4,$I$3:$I$17)+COUNTIF(I$3:$I4,I4)-1 -> 3 | K4: =(E4+J4)/2 -> 2.5 | L4: =RANK(K4,$K$3:$K$17,1)+COUNTIF(K$3:$K4,K4)-1 -> 1 | N4: total | O4: =SUM(O5:O9) -> 480 | P4: 490 | Q4: 507 | R4: =SUM(R5:R9) -> 180 | S4: 211 | T4: 217
B5: DA2470 | C5: 111 | D5: Average | E5: 3 | F5: 0 | G5: 0 | H5: =RANK(G5,$G$3:$G$17)+COUNTIF(G$3:$G5,G5)-1 -> 14 | I5: 0 | J5: =RANK(I5,$I$3:$I$17)+COUNTIF(I$3:$I5,I5)-1 -> 14 | K5: =(E5+J5)/2 -> 8.5 | L5: =RANK(K5,$K$3:$K$17,1)+COUNTIF(K$3:$K5,K5)-1 -> 6 | N5: grasmere | O5: 180 | R5: 60
A6: CM | B6: DA1130 | C6: 107 | D6: Average | E6: 4 | F6: 566 | G6: 113 | H6: =RANK(G6,$G$3:$G$17)+COUNTIF(G$3:$G6,G6)-1 -> 1 | I6: 90 | J6: =RANK(I6,$I$3:$I$17)+COUNTIF(I$3:$I6,I6)-1 -> 1 | K6: =(E6+J6)/2 -> 2.5 | L6: =RANK(K6,$K$3:$K$17,1)+COUNTIF(K$3:$K6,K6)-1 -> 2 | N6: richlands | O6: 85 | R6: 35
A7: AW | B7: DA1721 | C7: 107 | D7: Average | E7: 5 | F7: 134 | G7: 37 | H7: =RANK(G7,$G$3:$G$17)+COUNTIF(G$3:$G7,G7)-1 -> 11 | I7: 88 | J7: =RANK(I7,$I$3:$I$17)+COUNTIF(I$3:$I7,I7)-1 -> 6 | K7: =(E7+J7)/2 -> 5.5 | L7: =RANK(K7,$K$3:$K$17,1)+COUNTIF(K$3:$K7,K7)-1 -> 5 | N7: Villa | O7: 40 | R7: 10 | U7: Actual total | V7: estimated
A8: CM | B8: DA1627 | C8: 106 | D8: Average | E8: 6 | F8: 346 | G8: 67 | H8: =RANK(G8,$G$3:$G$17)+COUNTIF(G$3:$G8,G8)-1 -> 5 | I8: 89 | J8: =RANK(I8,$I$3:$I$17)+COUNTIF(I$3:$I8,I8)-1 -> 4 | K8: =(E8+J8)/2 -> 5 | L8: =RANK(K8,$K$3:$K$17,1)+COUNTIF(K$3:$K8,K8)-1 -> 4 | N8: Lions Head | O8: 95 | R8: 40 | U8: =Q4+T4 -> 724 | V8: =P4+S4 -> 701
B9: DA2477 | C9: 105 | D9: Average | E9: 7 | F9: 0 | G9: 0 | H9: =RANK(G9,$G$3:$G$17)+COUNTIF(G$3:$G9,G9)-1 -> 15 | I9: 0 | J9: =RANK(I9,$I$3:$I$17)+COUNTIF(I$3:$I9,I9)-1 -> 15 | K9: =(E9+J9)/2 -> 11 | L9: =RANK(K9,$K$3:$K$17,1)+COUNTIF(K$3:$K9,K9)-1 -> 13 | N9: Porta | O9: 80 | R9: 35 | V9: =U8-V8 -> 23
A10: TA | B10: DA2568 | C10: 104 | D10: Average | E10: 8 | F10: 194 | G10: 43 | H10: =RANK(G10,$G$3:$G$17)+COUNTIF(G$3:$G10,G10)-1 -> 9 | I10: 86 | J10: =RANK(I10,$I$3:$I$17)+COUNTIF(I$3:$I10,I10)-1 -> 12 | K10: =(E10+J10)/2 -> 10 | L10: =RANK(K10,$K$3:$K$17,1)+COUNTIF(K$3:$K10,K10)-1 -> 10
A11: CM | B11: CL7180 | C11: 102 | D11: Below average | E11: 9 | F11: 266 | G11: 55 | H11: =RANK(G11,$G$3:$G$17)+COUNTIF(G$3:$G11,G11)-1 -> 7 | I11: 85 | J11: =RANK(I11,$I$3:$I$17)+COUNTIF(I$3:$I11,I11)-1 -> 13 | K11: =(E11+J11)/2 -> 11 | L11: =RANK(K11,$K$3:$K$17,1)+COUNTIF(K$3:$K11,K11)-1 -> 14
A12: AW | B12: CJ0211 | C12: 101 | D12: Below average | E12: 10 | F12: 406 | G12: 82 | H12: =RANK(G12,$G$3:$G$17)+COUNTIF(G$3:$G12,G12)-1 -> 3 | I12: 88 | J12: =RANK(I12,$I$3:$I$17)+COUNTIF(I$3:$I12,I12)-1 -> 7 | K12: =(E12+J12)/2 -> 8.5 | L12: =RANK(K12,$K$3:$K$17,1)+COUNTIF(K$3:$K12,K12)-1 -> 7
A13: CM | B13: CL5312 | C13: 98 | D13: Low | E13: 11 | F13: 282 | G13: 66 | H13: =RANK(G13,$G$3:$G$17)+COUNTIF(G$3:$G13,G13)-1 -> 6 | I13: 87 | J13: =RANK(I13,$I$3:$I$17)+COUNTIF(I$3:$I13,I13)-1 -> 10 | K13: =(E13+J13)/2 -> 10.5 | L13: =RANK(K13,$K$3:$K$17,1)+COUNTIF(K$3:$K13,K13)-1 -> 12
A14: CM | B14: CL3033 | C14: 97 | D14: Low | E14: 12 | F14: 328 | G14: 92 | H14: =RANK(G14,$G$3:$G$17)+COUNTIF(G$3:$G14,G14)-1 -> 2 | I14: 88 | J14: =RANK(I14,$I$3:$I$17)+COUNTIF(I$3:$I14,I14)-1 -> 8 | K14: =(E14+J14)/2 -> 10 | L14: =RANK(K14,$K$3:$K$17,1)+COUNTIF(K$3:$K14,K14)-1 -> 11
A15: TA | B15: DA0379 | C15: 95 | D15: Low | E15: 13 | F15: 252 | G15: 69 | H15: =RANK(G15,$G$3:$G$17)+COUNTIF(G$3:$G15,G15)-1 -> 4 | I15: 89 | J15: =RANK(I15,$I$3:$I$17)+COUNTIF(I$3:$I15,I15)-1 -> 5 | K15: =(E15+J15)/2 -> 9 | L15: =RANK(K15,$K$3:$K$17,1)+COUNTIF(K$3:$K15,K15)-1 -> 9
B16: CJ2150 | C16: 91 | D16: Low | E16: 14 | F16: 240 | G16: 41 | H16: =RANK(G16,$G$3:$G$17)+COUNTIF(G$3:$G16,G16)-1 -> 10 | I16: 87 | J16: =RANK(I16,$I$3:$I$17)+COUNTIF(I$3:$I16,I16)-1 -> 11 | K16: =(E16+J16)/2 -> 12.5 | L16: =RANK(K16,$K$3:$K$17,1)+COUNTIF(K$3:$K16,K16)-1 -> 15
A17: AW | B17: CE6835 | C17: 90 | D17: Low | E17: 15 | F17: 246 | G17: 23 | H17: =RANK(G17,$G$3:$G$17)+COUNTIF(G$3:$G17,G17)-1 -> 13 | I17: 90 | J17: =RANK(I17,$I$3:$I$17)+COUNTIF(I$3:$I17,I17)-1 -> 2 | K17: =(E17+J17)/2 -> 8.5 | L17: =RANK(K17,$K$3:$K$17,1)+COUNTIF(K$3:$K17,K17)-1 -> 8
B20: Sunday | C20: Wednesday
B21: T1 | C21: T2
B24: COMMENT
B25: CJ50 Rested
B26: DA2477 and DA2470 are still not mounting the dummy and we are currently working on them

Sheet week 04
A1: Collector ID | B1: Boar | C1: TSI | D1: Genetic level | E1: Genetic Rank | F1: Last recorded raw Semen collected (mls) | G1: Last recorded Doses | H1: Dose rank | I1: Last recorded Morphology | J1: Morphology Rank | K1: Overal Grading | L1: Overal Rank | Y1: 45677
O2: Sunday | P2: Sunday | Q2: Sunday | R2: Wed | S2: Wed | T2: Wed
A3: CM | B3: DA2338 | C3: 114 | D3: Average | E3: 1 | F3: 208 | G3: 38 | H3: =RANK(G3,$G$3:$G$17)+COUNTIF(G3:$G$3,G3)-1 -> 12 | I3: 89 | J3: =RANK(I3,$I$3:$I$17)+COUNTIF(I3:$I$3,I3)-1 -> 1 | K3: =(E3+J3)/2 -> 1 | L3: =RANK(K3,$K$3:$K$17,1)+COUNTIF(K3:$K$3,K3)-1 -> 1 | O3: required | P3: estimate | Q3: actual | R3: required | S3: estimate | T3: actual
A4: AW | B4: DA1669 | C4: 111 | D4: Average | E4: 2 | F4: 328 | G4: 83 | H4: =RANK(G4,$G$3:$G$17)+COUNTIF(G$3:$G4,G4)-1 -> 4 | I4: 87 | J4: =RANK(I4,$I$3:$I$17)+COUNTIF(I$3:$I4,I4)-1 -> 6 | K4: =(E4+J4)/2 -> 4 | L4: =RANK(K4,$K$3:$K$17,1)+COUNTIF(K$3:$K4,K4)-1 -> 3 | N4: total | O4: =SUM(O5:O9) -> 485 | P4: 507 | Q4: 488 | R4: =SUM(R5:R9) -> 180 | S4: 217 | T4: 174
B5: DA2470 | C5: 111 | D5: Average | E5: 3 | F5: 0 | G5: 0 | H5: =RANK(G5,$G$3:$G$17)+COUNTIF(G$3:$G5,G5)-1 -> 14 | I5: 0 | J5: =RANK(I5,$I$3:$I$17)+COUNTIF(I$3:$I5,I5)-1 -> 14 | K5: =(E5+J5)/2 -> 8.5 | L5: =RANK(K5,$K$3:$K$17,1)+COUNTIF(K$3:$K5,K5)-1 -> 8 | N5: grasmere | O5: 180 | R5: 60
A6: TA | B6: DA1130 | C6: 107 | D6: Average | E6: 4 | F6: 466 | G6: 95 | H6: =RANK(G6,$G$3:$G$17)+COUNTIF(G$3:$G6,G6)-1 -> 1 | I6: 87 | J6: =RANK(I6,$I$3:$I$17)+COUNTIF(I$3:$I6,I6)-1 -> 7 | K6: =(E6+J6)/2 -> 5.5 | L6: =RANK(K6,$K$3:$K$17,1)+COUNTIF(K$3:$K6,K6)-1 -> 5 | N6: richlands | O6: 85 | R6: 35
A7: CM | B7: DA1721 | C7: 107 | D7: Average | E7: 5 | F7: 238 | G7: 42 | H7: =RANK(G7,$G$3:$G$17)+COUNTIF(G$3:$G7,G7)-1 -> 9 | I7: 89 | J7: =RANK(I7,$I$3:$I$17)+COUNTIF(I$3:$I7,I7)-1 -> 2 | K7: =(E7+J7)/2 -> 3.5 | L7: =RANK(K7,$K$3:$K$17,1)+COUNTIF(K$3:$K7,K7)-1 -> 2 | N7: Villa | O7: 40 | R7: 10 | U7: Actual total | V7: estimated
A8: TA | B8: DA1627 | C8: 106 | D8: Average | E8: 6 | F8: 308 | G8: 45 | H8: =RANK(G8,$G$3:$G$17)+COUNTIF(G$3:$G8,G8)-1 -> 8 | I8: 88 | J8: =RANK(I8,$I$3:$I$17)+COUNTIF(I$3:$I8,I8)-1 -> 3 | K8: =(E8+J8)/2 -> 4.5 | L8: =RANK(K8,$K$3:$K$17,1)+COUNTIF(K$3:$K8,K8)-1 -> 4 | N8: Lions Head | O8: 95 | R8: 40 | U8: =Q4+T4 -> 662 | V8: =P4+S4 -> 724
B9: DA2477 | C9: 105 | D9: Average | E9: 7 | F9: 0 | G9: 0 | H9: =RANK(G9,$G$3:$G$17)+COUNTIF(G$3:$G9,G9)-1 -> 15 | I9: 0 | J9: =RANK(I9,$I$3:$I$17)+COUNTIF(I$3:$I9,I9)-1 -> 15 | K9: =(E9+J9)/2 -> 11 | L9: =RANK(K9,$K$3:$K$17,1)+COUNTIF(K$3:$K9,K9)-1 -> 12 | N9: Porta | O9: 85 | R9: 35 | V9: =U8-V8 -> -62
A10: CM | B10: DA2568 | C10: 104 | D10: Average | E10: 8 | F10: 252 | G10: 34 | H10: =RANK(G10,$G$3:$G$17)+COUNTIF(G$3:$G10,G10)-1 -> 13 | I10: 87 | J10: =RANK(I10,$I$3:$I$17)+COUNTIF(I$3:$I10,I10)-1 -> 8 | K10: =(E10+J10)/2 -> 8 | L10: =RANK(K10,$K$3:$K$17,1)+COUNTIF(K$3:$K10,K10)-1 -> 6
B11: CL7180 | C11: 102 | D11: Below average | E11: 9 | F11: 266 | G11: 55 | H11: =RANK(G11,$G$3:$G$17)+COUNTIF(G$3:$G11,G11)-1 -> 6 | I11: 86 | J11: =RANK(I11,$I$3:$I$17)+COUNTIF(I$3:$I11,I11)-1 -> 13 | K11: =(E11+J11)/2 -> 11 | L11: =RANK(K11,$K$3:$K$17,1)+COUNTIF(K$3:$K11,K11)-1 -> 13
A12: CM | B12: CJ0211 | C12: 101 | D12: Below average | E12: 10 | F12: 566 | G12: 87 | H12: =RANK(G12,$G$3:$G$17)+COUNTIF(G$3:$G12,G12)-1 -> 3 | I12: 87 | J12: =RANK(I12,$I$3:$I$17)+COUNTIF(I$3:$I12,I12)-1 -> 9 | K12: =(E12+J12)/2 -> 9.5 | L12: =RANK(K12,$K$3:$K$17,1)+COUNTIF(K$3:$K12,K12)-1 -> 10
A13: CM | B13: CL5312 | C13: 98 | D13: Low | E13: 11 | F13: 300 | G13: 56 | H13: =RANK(G13,$G$3:$G$17)+COUNTIF(G$3:$G13,G13)-1 -> 5 | I13: 87 | J13: =RANK(I13,$I$3:$I$17)+COUNTIF(I$3:$I13,I13)-1 -> 10 | K13: =(E13+J13)/2 -> 10.5 | L13: =RANK(K13,$K$3:$K$17,1)+COUNTIF(K$3:$K13,K13)-1 -> 11
A14: TA | B14: CL3033 | C14: 97 | D14: Low | E14: 12 | F14: 268 | G14: 93 | H14: =RANK(G14,$G$3:$G$17)+COUNTIF(G$3:$G14,G14)-1 -> 2 | I14: 88 | J14: =RANK(I14,$I$3:$I$17)+COUNTIF(I$3:$I14,I14)-1 -> 4 | K14: =(E14+J14)/2 -> 8 | L14: =RANK(K14,$K$3:$K$17,1)+COUNTIF(K$3:$K14,K14)-1 -> 7
A15: CM | B15: DA0379 | C15: 95 | D15: Low | E15: 13 | F15: 274 | G15: 49 | H15: =RANK(G15,$G$3:$G$17)+COUNTIF(G$3:$G15,G15)-1 -> 7 | I15: 88 | J15: =RANK(I15,$I$3:$I$17)+COUNTIF(I$3:$I15,I15)-1 -> 5 | K15: =(E15+J15)/2 -> 9 | L15: =RANK(K15,$K$3:$K$17,1)+COUNTIF(K$3:$K15,K15)-1 -> 9
B16: CJ2150 | C16: 91 | D16: Low | E16: 14 | F16: 240 | G16: 41 | H16: =RANK(G16,$G$3:$G$17)+COUNTIF(G$3:$G16,G16)-1 -> 10 | I16: 87 | J16: =RANK(I16,$I$3:$I$17)+COUNTIF(I$3:$I16,I16)-1 -> 11 | K16: =(E16+J16)/2 -> 12.5 | L16: =RANK(K16,$K$3:$K$17,1)+COUNTIF(K$3:$K16,K16)-1 -> 14
A17: CM | B17: CE6835 | C17: 90 | D17: Low | E17: 15 | F17: 220 | G17: 40 | H17: =RANK(G17,$G$3:$G$17)+COUNTIF(G$3:$G17,G17)-1 -> 11 | I17: 87 | J17: =RANK(I17,$I$3:$I$17)+COUNTIF(I$3:$I17,I17)-1 -> 12 | K17: =(E17+J17)/2 -> 13.5 | L17: =RANK(K17,$K$3:$K$17,1)+COUNTIF(K$3:$K17,K17)-1 -> 15
B20: Sunday | C20: Wednesday
B21: T1 | C21: T2
B24: COMMENT
B25: DA2477 and DA2470 are still not mounting the dummy and we are currently working on them
B26: CL80, CJ50,DA27 rested in week 03

Sheet week 05
A1: Collector ID | B1: Boar | C1: TSI | D1: Genetic level | E1: Genetic Rank | F1: Last recorded raw Semen collected (mls) | G1: Last recorded Doses | H1: Dose rank | I1: Last recorded Morphology | J1: Morphology Rank | K1: Overal Grading | L1: Overal Rank | Y1: 45677
O2: Sunday | P2: Sunday | Q2: Sunday | R2: Wed | S2: Wed | T2: Wed
B3: DA2338 | C3: 114 | D3: Average | E3: 1 | F3: 208 | G3: 38 | H3: =RANK(G3,$G$3:$G$17)+COUNTIF(G3:$G$3,G3)-1 -> 11 | I3: 89 | J3: =RANK(I3,$I$3:$I$17)+COUNTIF(I3:$I$3,I3)-1 -> 1 | K3: =(E3+J3)/2 -> 1 | L3: =RANK(K3,$K$3:$K$17,1)+COUNTIF(K3:$K$3,K3)-1 -> 1 | O3: required | P3: estimate | Q3: actual | R3: required | S3: estimate | T3: actual
A4: CM | B4: DA1669 | C4: 111 | D4: Average | E4: 2 | F4: 362 | G4: 70 | H4: =RANK(G4,$G$3:$G$17)+COUNTIF(G$3:$G4,G4)-1 -> 5 | I4: 88 | J4: =RANK(I4,$I$3:$I$17)+COUNTIF(I$3:$I4,I4)-1 -> 4 | K4: =(E4+J4)/2 -> 3 | L4: =RANK(K4,$K$3:$K$17,1)+COUNTIF(K$3:$K4,K4)-1 -> 2 | N4: total | O4: =SUM(O5:O9) -> 480 | P4: 488 | Q4: 525 | R4: =SUM(R5:R9) -> 180 | S4: 174 | T4: 185
B5: DA2470 | C5: 111 | D5: Average | E5: 3 | F5: 0 | G5: 0 | H5: =RANK(G5,$G$3:$G$17)+COUNTIF(G$3:$G5,G5)-1 -> 14 | I5: 0 | J5: =RANK(I5,$I$3:$I$17)+COUNTIF(I$3:$I5,I5)-1 -> 14 | K5: =(E5+J5)/2 -> 8.5 | L5: =RANK(K5,$K$3:$K$17,1)+COUNTIF(K$3:$K5,K5)-1 -> 8 | N5: grasmere | O5: 180 | R5: 60
A6: AW | B6: DA1130 | C6: 107 | D6: Average | E6: 4 | F6: 558 | G6: 102 | H6: =RANK(G6,$G$3:$G$17)+COUNTIF(G$3:$G6,G6)-1 -> 1 | I6: 87 | J6: =RANK(I6,$I$3:$I$17)+COUNTIF(I$3:$I6,I6)-1 -> 9 | K6: =(E6+J6)/2 -> 6.5 | L6: =RANK(K6,$K$3:$K$17,1)+COUNTIF(K$3:$K6,K6)-1 -> 6 | N6: richlands | O6: 85 | R6: 35
A7: AW | B7: DA1721 | C7: 107 | D7: Average | E7: 5 | F7: 146 | G7: 35 | H7: =RANK(G7,$G$3:$G$17)+COUNTIF(G$3:$G7,G7)-1 -> 13 | I7: 89 | J7: =RANK(I7,$I$3:$I$17)+COUNTIF(I$3:$I7,I7)-1 -> 2 | K7: =(E7+J7)/2 -> 3.5 | L7: =RANK(K7,$K$3:$K$17,1)+COUNTIF(K$3:$K7,K7)-1 -> 3 | N7: Villa | O7: 40 | R7: 10 | U7: Actual total | V7: estimated
A8: AW | B8: DA1627 | C8: 106 | D8: Average | E8: 6 | F8: 304 | G8: 68 | H8: =RANK(G8,$G$3:$G$17)+COUNTIF(G$3:$G8,G8)-1 -> 6 | I8: 88 | J8: =RANK(I8,$I$3:$I$17)+COUNTIF(I$3:$I8,I8)-1 -> 5 | K8: =(E8+J8)/2 -> 5.5 | L8: =RANK(K8,$K$3:$K$17,1)+COUNTIF(K$3:$K8,K8)-1 -> 4 | N8: Lions Head | O8: 95 | R8: 40 | U8: =Q4+T4 -> 710 | V8: =P4+S4 -> 662
B9: DA2477 | C9: 105 | D9: Average | E9: 7 | F9: 0 | G9: 0 | H9: =RANK(G9,$G$3:$G$17)+COUNTIF(G$3:$G9,G9)-1 -> 15 | I9: 0 | J9: =RANK(I9,$I$3:$I$17)+COUNTIF(I$3:$I9,I9)-1 -> 15 | K9: =(E9+J9)/2 -> 11 | L9: =RANK(K9,$K$3:$K$17,1)+COUNTIF(K$3:$K9,K9)-1 -> 12 | N9: Porta | O9: 80 | R9: 35 | V9: =U8-V8 -> 48
A10: CM | B10: DA2568 | C10: 104 | D10: Average | E10: 8 | F10: 206 | G10: 38 | H10: =RANK(G10,$G$3:$G$17)+COUNTIF(G$3:$G10,G10)-1 -> 12 | I10: 89 | J10: =RANK(I10,$I$3:$I$17)+COUNTIF(I$3:$I10,I10)-1 -> 3 | K10: =(E10+J10)/2 -> 5.5 | L10: =RANK(K10,$K$3:$K$17,1)+COUNTIF(K$3:$K10,K10)-1 -> 5
B11: CL7180 | C11: 102 | D11: Below average | E11: 9 | F11: 266 | G11: 55 | H11: =RANK(G11,$G$3:$G$17)+COUNTIF(G$3:$G11,G11)-1 -> 9 | I11: 86 | J11: =RANK(I11,$I$3:$I$17)+COUNTIF(I$3:$I11,I11)-1 -> 13 | K11: =(E11+J11)/2 -> 11 | L11: =RANK(K11,$K$3:$K$17,1)+COUNTIF(K$3:$K11,K11)-1 -> 13
A12: AW | B12: CJ0211 | C12: 101 | D12: Below average | E12: 10 | F12: 524 | G12: 93 | H12: =RANK(G12,$G$3:$G$17)+COUNTIF(G$3:$G12,G12)-1 -> 2 | I12: 88 | J12: =RANK(I12,$I$3:$I$17)+COUNTIF(I$3:$I12,I12)-1 -> 6 | K12: =(E12+J12)/2 -> 8 | L12: =RANK(K12,$K$3:$K$17,1)+COUNTIF(K$3:$K12,K12)-1 -> 7
A13: CM | B13: CL5312 | C13: 98 | D13: Low | E13: 11 | F13: 322 | G13: 68 | H13: =RANK(G13,$G$3:$G$17)+COUNTIF(G$3:$G13,G13)-1 -> 7 | I13: 87 | J13: =RANK(I13,$I$3:$I$17)+COUNTIF(I$3:$I13,I13)-1 -> 10 | K13: =(E13+J13)/2 -> 10.5 | L13: =RANK(K13,$K$3:$K$17,1)+COUNTIF(K$3:$K13,K13)-1 -> 10
A14: CM | B14: CL3033 | C14: 97 | D14: Low | E14: 12 | F14: 246 | G14: 65 | H14: =RANK(G14,$G$3:$G$17)+COUNTIF(G$3:$G14,G14)-1 -> 8 | I14: 88 | J14: =RANK(I14,$I$3:$I$17)+COUNTIF(I$3:$I14,I14)-1 -> 7 | K14: =(E14+J14)/2 -> 9.5 | L14: =RANK(K14,$K$3:$K$17,1)+COUNTIF(K$3:$K14,K14)-1 -> 9
A15: TA | B15: DA0379 | C15: 95 | D15: Low | E15: 13 | F15: 278 | G15: 80 | H15: =RANK(G15,$G$3:$G$17)+COUNTIF(G$3:$G15,G15)-1 -> 4 | I15: 88 | J15: =RANK(I15,$I$3:$I$17)+COUNTIF(I$3:$I15,I15)-1 -> 8 | K15: =(E15+J15)/2 -> 10.5 | L15: =RANK(K15,$K$3:$K$17,1)+COUNTIF(K$3:$K15,K15)-1 -> 11
A16: AW | B16: CJ2150 | C16: 91 | D16: Low | E16: 14 | F16: 214 | G16: 91 | H16: =RANK(G16,$G$3:$G$17)+COUNTIF(G$3:$G16,G16)-1 -> 3 | I16: 87 | J16: =RANK(I16,$I$3:$I$17)+COUNTIF(I$3:$I16,I16)-1 -> 11 | K16: =(E16+J16)/2 -> 12.5 | L16: =RANK(K16,$K$3:$K$17,1)+COUNTIF(K$3:$K16,K16)-1 -> 14
B17: CE6835 | C17: 90 | D17: Low | E17: 15 | F17: 220 | G17: 40 | H17: =RANK(G17,$G$3:$G$17)+COUNTIF(G$3:$G17,G17)-1 -> 10 | I17: 87 | J17: =RANK(I17,$I$3:$I$17)+COUNTIF(I$3:$I17,I17)-1 -> 12 | K17: =(E17+J17)/2 -> 13.5 | L17: =RANK(K17,$K$3:$K$17,1)+COUNTIF(K$3:$K17,K17)-1 -> 15
B20: Sunday | C20: Wednesday
B21: T1 | C21: T2
B24: COMMENT
B25: DA2477 and DA2470 are still not mounting the dummy and we are currently working on them
B26: CL80, CE35,DA38 rested in week 04

Sheet week 06
A1: Collector ID | B1: Boar | C1: TSI | D1: Genetic level | E1: Genetic Rank | F1: Last recorded raw Semen collected (mls) | G1: Last recorded Doses | H1: Dose rank | I1: Last recorded Morphology | J1: Morphology Rank | K1: Overal Grading | L1: Overal Rank | Y1: 45677
O2: Sunday | P2: Sunday | Q2: Sunday | R2: Wed | S2: Wed | T2: Wed
A3: AW | B3: DA2338 | C3: 114 | D3: Average | E3: 1 | F3: 226 | G3: 40 | H3: =RANK(G3,$G$3:$G$17)+COUNTIF(G3:$G$3,G3)-1 -> 10 | I3: 88 | J3: =RANK(I3,$I$3:$I$17)+COUNTIF(I3:$I$3,I3)-1 -> 4 | K3: =(E3+J3)/2 -> 2.5 | L3: =RANK(K3,$K$3:$K$17,1)+COUNTIF(K3:$K$3,K3)-1 -> 2 | O3: required | P3: estimate | Q3: actual | R3: required | S3: estimate | T3: actual
A4: CM | B4: DA1669 | C4: 111 | D4: Average | E4: 2 | F4: 230 | G4: 45 | H4: =RANK(G4,$G$3:$G$17)+COUNTIF(G$3:$G4,G4)-1 -> 9 | I4: 89 | J4: =RANK(I4,$I$3:$I$17)+COUNTIF(I$3:$I4,I4)-1 -> 1 | K4: =(E4+J4)/2 -> 1.5 | L4: =RANK(K4,$K$3:$K$17,1)+COUNTIF(K$3:$K4,K4)-1 -> 1 | N4: total | O4: =SUM(O5:O9) -> 480 | P4: 525 | Q4: 490 | R4: =SUM(R5:R9) -> 175 | S4: 185 | T4: 220
B5: DA2470 | C5: 111 | D5: Average | E5: 3 | F5: 0 | G5: 0 | H5: =RANK(G5,$G$3:$G$17)+COUNTIF(G$3:$G5,G5)-1 -> 14 | I5: 0 | J5: =RANK(I5,$I$3:$I$17)+COUNTIF(I$3:$I5,I5)-1 -> 14 | K5: =(E5+J5)/2 -> 8.5 | L5: =RANK(K5,$K$3:$K$17,1)+COUNTIF(K$3:$K5,K5)-1 -> 6 | N5: grasmere | O5: 180 | R5: 60
A6: CM | B6: DA1130 | C6: 107 | D6: Average | E6: 4 | F6: 548 | G6: 77 | H6: =RANK(G6,$G$3:$G$17)+COUNTIF(G$3:$G6,G6)-1 -> 3 | I6: 89 | J6: =RANK(I6,$I$3:$I$17)+COUNTIF(I$3:$I6,I6)-1 -> 2 | K6: =(E6+J6)/2 -> 3 | L6: =RANK(K6,$K$3:$K$17,1)+COUNTIF(K$3:$K6,K6)-1 -> 3 | N6: richlands | O6: 85 | R6: 35
A7: CM | B7: DA1721 | C7: 107 | D7: Average | E7: 5 | F7: 186 | G7: 40 | H7: =RANK(G7,$G$3:$G$17)+COUNTIF(G$3:$G7,G7)-1 -> 11 | I7: 88 | J7: =RANK(I7,$I$3:$I$17)+COUNTIF(I$3:$I7,I7)-1 -> 5 | K7: =(E7+J7)/2 -> 5 | L7: =RANK(K7,$K$3:$K$17,1)+COUNTIF(K$3:$K7,K7)-1 -> 5 | N7: Villa | O7: 40 | R7: 10 | U7: Actual total | V7: estimated
A8: AW | B8: DA1627 | C8: 106 | D8: Average | E8: 6 | F8: 294 | G8: 51 | H8: =RANK(G8,$G$3:$G$17)+COUNTIF(G$3:$G8,G8)-1 -> 8 | I8: 89 | J8: =RANK(I8,$I$3:$I$17)+COUNTIF(I$3:$I8,I8)-1 -> 3 | K8: =(E8+J8)/2 -> 4.5 | L8: =RANK(K8,$K$3:$K$17,1)+COUNTIF(K$3:$K8,K8)-1 -> 4 | N8: Lions Head | O8: 95 | R8: 40 | U8: =Q4+T4 -> 710 | V8: =P4+S4 -> 710
B9: DA2477 | C9: 105 | D9: Average | E9: 7 | F9: 0 | G9: 0 | H9: =RANK(G9,$G$3:$G$17)+COUNTIF(G$3:$G9,G9)-1 -> 15 | I9: 0 | J9: =RANK(I9,$I$3:$I$17)+COUNTIF(I$3:$I9,I9)-1 -> 15 | K9: =(E9+J9)/2 -> 11 | L9: =RANK(K9,$K$3:$K$17,1)+COUNTIF(K$3:$K9,K9)-1 -> 12 | N9: Porta | O9: 80 | R9: 30 | V9: =U8-V8 -> 0
A10: AW | B10: DA2568 | C10: 104 | D10: Average | E10: 8 | F10: 238 | G10: 52 | H10: =RANK(G10,$G$3:$G$17)+COUNTIF(G$3:$G10,G10)-1 -> 7 | I10: 87 | J10: =RANK(I10,$I$3:$I$17)+COUNTIF(I$3:$I10,I10)-1 -> 9 | K10: =(E10+J10)/2 -> 8.5 | L10: =RANK(K10,$K$3:$K$17,1)+COUNTIF(K$3:$K10,K10)-1 -> 7
A11: CM | B11: CL7180 | C11: 102 | D11: Below average | E11: 9 | F11: 201 | G11: 69 | H11: =RANK(G11,$G$3:$G$17)+COUNTIF(G$3:$G11,G11)-1 -> 4 | I11: 87 | J11: =RANK(I11,$I$3:$I$17)+COUNTIF(I$3:$I11,I11)-1 -> 10 | K11: =(E11+J11)/2 -> 9.5 | L11: =RANK(K11,$K$3:$K$17,1)+COUNTIF(K$3:$K11,K11)-1 -> 9
A12: AW | B12: CJ0211 | C12: 101 | D12: Below average | E12: 10 | F12: 594 | G12: 69 | H12: =RANK(G12,$G$3:$G$17)+COUNTIF(G$3:$G12,G12)-1 -> 5 | I12: 87 | J12: =RANK(I12,$I$3:$I$17)+COUNTIF(I$3:$I12,I12)-1 -> 11 | K12: =(E12+J12)/2 -> 10.5 | L12: =RANK(K12,$K$3:$K$17,1)+COUNTIF(K$3:$K12,K12)-1 -> 11
A13: AW | B13: CL5312 | C13: 98 | D13: Low | E13: 11 | F13: 354 | G13: 33 | H13: =RANK(G13,$G$3:$G$17)+COUNTIF(G$3:$G13,G13)-1 -> 13 | I13: 88 | J13: =RANK(I13,$I$3:$I$17)+COUNTIF(I$3:$I13,I13)-1 -> 6 | K13: =(E13+J13)/2 -> 8.5 | L13: =RANK(K13,$K$3:$K$17,1)+COUNTIF(K$3:$K13,K13)-1 -> 8
A14: CM | B14: CL3033 | C14: 97 | D14: Low | E14: 12 | F14: 360 | G14: 84 | H14: =RANK(G14,$G$3:$G$17)+COUNTIF(G$3:$G14,G14)-1 -> 1 | I14: 86 | J14: =RANK(I14,$I$3:$I$17)+COUNTIF(I$3:$I14,I14)-1 -> 13 | K14: =(E14+J14)/2 -> 12.5 | L14: =RANK(K14,$K$3:$K$17,1)+COUNTIF(K$3:$K14,K14)-1 -> 14
A15: TA | B15: DA0379 | C15: 95 | D15: Low | E15: 13 | F15: 288 | G15: 66 | H15: =RANK(G15,$G$3:$G$17)+COUNTIF(G$3:$G15,G15)-1 -> 6 | I15: 88 | J15: =RANK(I15,$I$3:$I$17)+COUNTIF(I$3:$I15,I15)-1 -> 7 | K15: =(E15+J15)/2 -> 10 | L15: =RANK(K15,$K$3:$K$17,1)+COUNTIF(K$3:$K15,K15)-1 -> 10
A16: CM | B16: CJ2150 | C16: 91 | D16: Low | E16: 14 | F16: 278 | G16: 84 | H16: =RANK(G16,$G$3:$G$17)+COUNTIF(G$3:$G16,G16)-1 -> 2 | I16: 87 | J16: =RANK(I16,$I$3:$I$17)+COUNTIF(I$3:$I16,I16)-1 -> 12 | K16: =(E16+J16)/2 -> 13 | L16: =RANK(K16,$K$3:$K$17,1)+COUNTIF(K$3:$K16,K16)-1 -> 15
B17: CE6835 | C17: 90 | D17: Low | E17: 15 | F17: 220 | G17: 40 | H17: =RANK(G17,$G$3:$G$17)+COUNTIF(G$3:$G17,G17)-1 -> 12 | I17: 88 | J17: =RANK(I17,$I$3:$I$17)+COUNTIF(I$3:$I17,I17)-1 -> 8 | K17: =(E17+J17)/2 -> 11.5 | L17: =RANK(K17,$K$3:$K$17,1)+COUNTIF(K$3:$K17,K17)-1 -> 13
B20: Sunday | C20: Wednesday
B21: T1 | C21: T2
B24: COMMENT
B25: DA2477 and DA2470 are still not mounting the dummy and we are currently working on them
B26: DA21 rested in week 05

Sheet week 07
A1: Collector ID | B1: Boar | C1: TSI | D1: Genetic level | E1: Genetic Rank | F1: Last recorded raw Semen collected (mls) | G1: Last recorded Doses | H1: Dose rank | I1: Last recorded Morphology | J1: Morphology Rank | K1: Overal Grading | L1: Overal Rank | Y1: 45677
O2: Sunday | P2: Sunday | Q2: Sunday | R2: Wed | S2: Wed | T2: Wed
A3: TA | B3: DA2338 | C3: 114 | D3: Average | E3: 1 | F3: 210 | G3: 50 | H3: =RANK(G3,$G$3:$G$17)+COUNTIF(G3:$G$3,G3)-1 -> 10 | I3: 88 | J3: =RANK(I3,$I$3:$I$17)+COUNTIF(I3:$I$3,I3)-1 -> 2 | K3: =(E3+J3)/2 -> 1.5 | L3: =RANK(K3,$K$3:$K$17,1)+COUNTIF(K3:$K$3,K3)-1 -> 1 | O3: required | P3: estimate | Q3: actual | R3: required | S3: estimate | T3: actual
A4: AW | B4: DA1669 | C4: 111 | D4: Average | E4: 2 | F4: 336 | G4: 79 | H4: =RANK(G4,$G$3:$G$17)+COUNTIF(G$3:$G4,G4)-1 -> 5 | I4: 87 | J4: =RANK(I4,$I$3:$I$17)+COUNTIF(I$3:$I4,I4)-1 -> 8 | K4: =(E4+J4)/2 -> 5 | L4: =RANK(K4,$K$3:$K$17,1)+COUNTIF(K$3:$K4,K4)-1 -> 5 | N4: total | O4: =SUM(O5:O9) -> 480 | P4: 490 | Q4: 534 | R4: =SUM(R5:R9) -> 175 | S4: 220
A5: AW | B5: DA2470 | C5: 111 | D5: Average | E5: 3 | F5: 156 | G5: 21 | H5: =RANK(G5,$G$3:$G$17)+COUNTIF(G$3:$G5,G5)-1 -> 14 | I5: 88 | J5: =RANK(I5,$I$3:$I$17)+COUNTIF(I$3:$I5,I5)-1 -> 3 | K5: =(E5+J5)/2 -> 3 | L5: =RANK(K5,$K$3:$K$17,1)+COUNTIF(K$3:$K5,K5)-1 -> 3 | N5: grasmere | O5: 180 | R5: 60
A6: CM | B6: DA1130 | C6: 107 | D6: Average | E6: 4 | F6: 420 | G6: 92 | H6: =RANK(G6,$G$3:$G$17)+COUNTIF(G$3:$G6,G6)-1 -> 1 | I6: 89 | J6: =RANK(I6,$I$3:$I$17)+COUNTIF(I$3:$I6,I6)-1 -> 1 | K6: =(E6+J6)/2 -> 2.5 | L6: =RANK(K6,$K$3:$K$17,1)+COUNTIF(K$3:$K6,K6)-1 -> 2 | N6: richlands | O6: 85 | R6: 35
A7: CM | B7: DA1721 | C7: 107 | D7: Average | E7: 5 | F7: 186 | G7: 40 | H7: =RANK(G7,$G$3:$G$17)+COUNTIF(G$3:$G7,G7)-1 -> 12 | I7: 88 | J7: =RANK(I7,$I$3:$I$17)+COUNTIF(I$3:$I7,I7)-1 -> 4 | K7: =(E7+J7)/2 -> 4.5 | L7: =RANK(K7,$K$3:$K$17,1)+COUNTIF(K$3:$K7,K7)-1 -> 4 | N7: Villa | O7: 40 | R7: 10 | U7: Actual total | V7: estimated
A8: TA | B8: DA1627 | C8: 106 | D8: Average | E8: 6 | F8: 288 | G8: 69 | H8: =RANK(G8,$G$3:$G$17)+COUNTIF(G$3:$G8,G8)-1 -> 7 | I8: 88 | J8: =RANK(I8,$I$3:$I$17)+COUNTIF(I$3:$I8,I8)-1 -> 5 | K8: =(E8+J8)/2 -> 5.5 | L8: =RANK(K8,$K$3:$K$17,1)+COUNTIF(K$3:$K8,K8)-1 -> 6 | N8: Lions Head | O8: 95 | R8: 40 | U8: =Q4+T4 -> 534 | V8: =P4+S4 -> 710
B9: DA2477 | C9: 105 | D9: Average | E9: 7 | F9: 0 | G9: 0 | H9: =RANK(G9,$G$3:$G$17)+COUNTIF(G$3:$G9,G9)-1 -> 15 | I9: 0 | J9: =RANK(I9,$I$3:$I$17)+COUNTIF(I$3:$I9,I9)-1 -> 15 | K9: =(E9+J9)/2 -> 11 | L9: =RANK(K9,$K$3:$K$17,1)+COUNTIF(K$3:$K9,K9)-1 -> 10 | N9: Porta | O9: 80 | R9: 30 | V9: =U8-V8 -> -176
A10: TA | B10: DA2568 | C10: 104 | D10: Average | E10: 8 | F10: 270 | G10: 79 | H10: =RANK(G10,$G$3:$G$17)+COUNTIF(G$3:$G10,G10)-1 -> 6 | I10: 87 | J10: =RANK(I10,$I$3:$I$17)+COUNTIF(I$3:$I10,I10)-1 -> 9 | K10: =(E10+J10)/2 -> 8.5 | L10: =RANK(K10,$K$3:$K$17,1)+COUNTIF(K$3:$K10,K10)-1 -> 8
A11: CM | B11: CL7180 | C11: 102 | D11: Below average | E11: 9 | F11: 296 | G11: 46 | H11: =RANK(G11,$G$3:$G$17)+COUNTIF(G$3:$G11,G11)-1 -> 11 | I11: 87 | J11: =RANK(I11,$I$3:$I$17)+COUNTIF(I$3:$I11,I11)-1 -> 10 | K11: =(E11+J11)/2 -> 9.5 | L11: =RANK(K11,$K$3:$K$17,1)+COUNTIF(K$3:$K11,K11)-1 -> 9
A12: TA | B12: CJ0211 | C12: 101 | D12: Below average | E12: 10 | F12: 458 | G12: 89 | H12: =RANK(G12,$G$3:$G$17)+COUNTIF(G$3:$G12,G12)-1 -> 2 | I12: 88 | J12: =RANK(I12,$I$3:$I$17)+COUNTIF(I$3:$I12,I12)-1 -> 6 | K12: =(E12+J12)/2 -> 8 | L12: =RANK(K12,$K$3:$K$17,1)+COUNTIF(K$3:$K12,K12)-1 -> 7
A13: CM | B13: CL5312 | C13: 98 | D13: Low | E13: 11 | F13: 330 | G13: 68 | H13: =RANK(G13,$G$3:$G$17)+COUNTIF(G$3:$G13,G13)-1 -> 8 | I13: 87 | J13: =RANK(I13,$I$3:$I$17)+COUNTIF(I$3:$I13,I13)-1 -> 11 | K13: =(E13+J13)/2 -> 11 | L13: =RANK(K13,$K$3:$K$17,1)+COUNTIF(K$3:$K13,K13)-1 -> 11
A14: CM | B14: CL3033 | C14: 97 | D14: Low | E14: 12 | F14: 416 | G14: 87 | H14: =RANK(G14,$G$3:$G$17)+COUNTIF(G$3:$G14,G14)-1 -> 3 | I14: 87 | J14: =RANK(I14,$I$3:$I$17)+COUNTIF(I$3:$I14,I14)-1 -> 12 | K14: =(E14+J14)/2 -> 12 | L14: =RANK(K14,$K$3:$K$17,1)+COUNTIF(K$3:$K14,K14)-1 -> 13
A15: AW | B15: DA0379 | C15: 95 | D15: Low | E15: 13 | F15: 268 | G15: 59 | H15: =RANK(G15,$G$3:$G$17)+COUNTIF(G$3:$G15,G15)-1 -> 9 | I15: 86 | J15: =RANK(I15,$I$3:$I$17)+COUNTIF(I$3:$I15,I15)-1 -> 14 | K15: =(E15+J15)/2 -> 13.5 | L15: =RANK(K15,$K$3:$K$17,1)+COUNTIF(K$3:$K15,K15)-1 -> 14
A16: CM | B16: CJ2150 | C16: 91 | D16: Low | E16: 14 | F16: 278 | G16: 84 | H16: =RANK(G16,$G$3:$G$17)+COUNTIF(G$3:$G16,G16)-1 -> 4 | I16: 87 | J16: =RANK(I16,$I$3:$I$17)+COUNTIF(I$3:$I16,I16)-1 -> 13 | K16: =(E16+J16)/2 -> 13.5 | L16: =RANK(K16,$K$3:$K$17,1)+COUNTIF(K$3:$K16,K16)-1 -> 15
B17: CE6835 | C17: 90 | D17: Low | E17: 15 | F17: 220 | G17: 40 | H17: =RANK(G17,$G$3:$G$17)+COUNTIF(G$3:$G17,G17)-1 -> 13 | I17: 88 | J17: =RANK(I17,$I$3:$I$17)+COUNTIF(I$3:$I17,I17)-1 -> 7 | K17: =(E17+J17)/2 -> 11 | L17: =RANK(K17,$K$3:$K$17,1)+COUNTIF(K$3:$K17,K17)-1 -> 12
B20: Sunday | C20: Wednesday
B21: T1 | C21: T2
B24: COMMENT

Sheet week 08
A1: Collector ID | B1: Boar | C1: TSI | D1: Genetic level | E1: Genetic Rank | F1: Last recorded raw Semen collected (mls) | G1: Last recorded Doses | H1: Dose rank | I1: Last recorded Morphology | J1: Morphology Rank | K1: Overal Grading | L1: Overal Rank | Y1: 45677
O2: Sunday | P2: Sunday | Q2: Sunday | R2: Wed | S2: Wed | T2: Wed
B3: DA2338 | C3: 114 | D3: Average | E3: 1 | H3: =RANK(G3,$G$3:$G$17)+COUNTIF(G3:$G$3,G3)-1 -> 13 | J3: =RANK(I3,$I$3:$I$17)+COUNTIF(I3:$I$3,I3)-1 -> 13 | K3: =(E3+J3)/2 -> 7 | L3: =RANK(K3,$K$3:$K$17,1)+COUNTIF(K3:$K$3,K3)-1 -> 6 | O3: required | P3: estimate | Q3: actual | R3: required | S3: estimate | T3: actual
A4: TA | B4: DA1669 | C4: 111 | D4: Average | E4: 2 | F4: 352 | G4: 84 | H4: =RANK(G4,$G$3:$G$17)+COUNTIF(G$3:$G4,G4)-1 -> 6 | I4: 89 | J4: =RANK(I4,$I$3:$I$17)+COUNTIF(I$3:$I4,I4)-1 -> 1 | K4: =(E4+J4)/2 -> 1.5 | L4: =RANK(K4,$K$3:$K$17,1)+COUNTIF(K$3:$K4,K4)-1 -> 1 | N4: total | O4: =SUM(O5:O9) -> 480 | P4: 534 | Q4: 619 | R4: =SUM(R5:R9) -> 175 | S4: 205 | T4: 210
A5: TA | B5: DA2470 | C5: 111 | D5: Average | E5: 3 | F5: 106 | G5: 12 | H5: =RANK(G5,$G$3:$G$17)+COUNTIF(G$3:$G5,G5)-1 -> 13 | I5: 88 | J5: =RANK(I5,$I$3:$I$17)+COUNTIF(I$3:$I5,I5)-1 -> 4 | K5: =(E5+J5)/2 -> 3.5 | L5: =RANK(K5,$K$3:$K$17,1)+COUNTIF(K$3:$K5,K5)-1 -> 2 | N5: grasmere | O5: 180 | R5: 60
A6: AW | B6: DA1130 | C6: 107 | D6: Average | E6: 4 | F6: 626 | G6: 125 | H6: =RANK(G6,$G$3:$G$17)+COUNTIF(G$3:$G6,G6)-1 -> 1 | I6: 88 | J6: =RANK(I6,$I$3:$I$17)+COUNTIF(I$3:$I6,I6)-1 -> 5 | K6: =(E6+J6)/2 -> 4.5 | L6: =RANK(K6,$K$3:$K$17,1)+COUNTIF(K$3:$K6,K6)-1 -> 3 | N6: richlands | O6: 85 | R6: 35
A7: TA | B7: DA1721 | C7: 107 | D7: Average | E7: 5 | F7: 362 | G7: 59 | H7: =RANK(G7,$G$3:$G$17)+COUNTIF(G$3:$G7,G7)-1 -> 9 | I7: 87 | J7: =RANK(I7,$I$3:$I$17)+COUNTIF(I$3:$I7,I7)-1 -> 10 | K7: =(E7+J7)/2 -> 7.5 | L7: =RANK(K7,$K$3:$K$17,1)+COUNTIF(K$3:$K7,K7)-1 -> 7 | N7: Villa | O7: 40 | R7: 10 | U7: Actual total | V7: estimated
A8: TA | B8: DA1627 | C8: 106 | D8: Average | E8: 6 | F8: 280 | G8: 95 | H8: =RANK(G8,$G$3:$G$17)+COUNTIF(G$3:$G8,G8)-1 -> 4 | I8: 88 | J8: =RANK(I8,$I$3:$I$17)+COUNTIF(I$3:$I8,I8)-1 -> 6 | K8: =(E8+J8)/2 -> 6 | L8: =RANK(K8,$K$3:$K$17,1)+COUNTIF(K$3:$K8,K8)-1 -> 5 | N8: Lions Head | O8: 95 | R8: 40 | U8: =Q4+T4 -> 829 | V8: =P4+S4 -> 739
B9: DA2477 | C9: 105 | D9: Average | E9: 7 | F9: 0 | G9: 0 | H9: =RANK(G9,$G$3:$G$17)+COUNTIF(G$3:$G9,G9)-1 -> 14 | I9: 0 | J9: =RANK(I9,$I$3:$I$17)+COUNTIF(I$3:$I9,I9)-1 -> 14 | K9: =(E9+J9)/2 -> 10.5 | L9: =RANK(K9,$K$3:$K$17,1)+COUNTIF(K$3:$K9,K9)-1 -> 11 | N9: Porta | O9: 80 | R9: 30 | V9: =U8-V8 -> 90
A10: TA | B10: DA2568 | C10: 104 | D10: Average | E10: 8 | F10: 238 | G10: 44 | H10: =RANK(G10,$G$3:$G$17)+COUNTIF(G$3:$G10,G10)-1 -> 12 | I10: 86 | J10: =RANK(I10,$I$3:$I$17)+COUNTIF(I$3:$I10,I10)-1 -> 13 | K10: =(E10+J10)/2 -> 10.5 | L10: =RANK(K10,$K$3:$K$17,1)+COUNTIF(K$3:$K10,K10)-1 -> 12
A11: CM | B11: CL7180 | C11: 102 | D11: Below average | E11: 9 | F11: 346 | G11: 67 | H11: =RANK(G11,$G$3:$G$17)+COUNTIF(G$3:$G11,G11)-1 -> 8 | I11: 89 | J11: =RANK(I11,$I$3:$I$17)+COUNTIF(I$3:$I11,I11)-1 -> 2 | K11: =(E11+J11)/2 -> 5.5 | L11: =RANK(K11,$K$3:$K$17,1)+COUNTIF(K$3:$K11,K11)-1 -> 4
A12: AW | B12: CJ0211 | C12: 101 | D12: Below average | E12: 10 | F12: 572 | G12: 95 | H12: =RANK(G12,$G$3:$G$17)+COUNTIF(G$3:$G12,G12)-1 -> 5 | I12: 87 | J12: =RANK(I12,$I$3:$I$17)+COUNTIF(I$3:$I12,I12)-1 -> 11 | K12: =(E12+J12)/2 -> 10.5 | L12: =RANK(K12,$K$3:$K$17,1)+COUNTIF(K$3:$K12,K12)-1 -> 13
A13: CM | B13: CL5312 | C13: 98 | D13: Low | E13: 11 | F13: 180 | G13: 47 | H13: =RANK(G13,$G$3:$G$17)+COUNTIF(G$3:$G13,G13)-1 -> 11 | I13: 88 | J13: =RANK(I13,$I$3:$I$17)+COUNTIF(I$3:$I13,I13)-1 -> 7 | K13: =(E13+J13)/2 -> 9 | L13: =RANK(K13,$K$3:$K$17,1)+COUNTIF(K$3:$K13,K13)-1 -> 8
A14: AW | B14: CL3033 | C14: 97 | D14: Low | E14: 12 | F14: 442 | G14: 102 | H14: =RANK(G14,$G$3:$G$17)+COUNTIF(G$3:$G14,G14)-1 -> 2 | I14: 88 | J14: =RANK(I14,$I$3:$I$17)+COUNTIF(I$3:$I14,I14)-1 -> 8 | K14: =(E14+J14)/2 -> 10 | L14: =RANK(K14,$K$3:$K$17,1)+COUNTIF(K$3:$K14,K14)-1 -> 10
A15: TA | B15: DA0379 | C15: 95 | D15: Low | E15: 13 | F15: 336 | G15: 99 | H15: =RANK(G15,$G$3:$G$17)+COUNTIF(G$3:$G15,G15)-1 -> 3 | I15: 87 | J15: =RANK(I15,$I$3:$I$17)+COUNTIF(I$3:$I15,I15)-1 -> 12 | K15: =(E15+J15)/2 -> 12.5 | L15: =RANK(K15,$K$3:$K$17,1)+COUNTIF(K$3:$K15,K15)-1 -> 15
A16: CM | B16: CJ2150 | C16: 91 | D16: Low | E16: 14 | F16: 278 | G16: 84 | H16: =RANK(G16,$G$3:$G$17)+COUNTIF(G$3:$G16,G16)-1 -> 7 | I16: 88 | J16: =RANK(I16,$I$3:$I$17)+COUNTIF(I$3:$I16,I16)-1 -> 9 | K16: =(E16+J16)/2 -> 11.5 | L16: =RANK(K16,$K$3:$K$17,1)+COUNTIF(K$3:$K16,K16)-1 -> 14
A17: AW | B17: CE6835 | C17: 90 | D17: Low | E17: 15 | F17: 201 | G17: 48 | H17: =RANK(G17,$G$3:$G$17)+COUNTIF(G$3:$G17,G17)-1 -> 10 | I17: 89 | J17: =RANK(I17,$I$3:$I$17)+COUNTIF(I$3:$I17,I17)-1 -> 3 | K17: =(E17+J17)/2 -> 9 | L17: =RANK(K17,$K$3:$K$17,1)+COUNTIF(K$3:$K17,K17)-1 -> 9
B20: Sunday | C20: Wednesday
B21: T1 | C21: T2
B24: COMMENT

Sheet week 09
A1: Collector ID | B1: Boar | C1: TSI | D1: Genetic level | E1: Genetic Rank | F1: Last recorded raw Semen collected (mls) | G1: Last recorded Doses | H1: Dose rank | I1: Last recorded Morphology | J1: Morphology Rank | K1: Overal Grading | L1: Overal Rank | Y1: 45677
O2: Sunday | P2: Sunday | Q2: Sunday | R2: Wed | S2: Wed | T2: Wed
O3: required | P3: estimate | Q3: actual | R3: required | S3: estimate | T3: actual
A4: AW | B4: DA1669 | C4: 111 | D4: Average | E4: 2 | F4: 388 | G4: 55 | H4: =RANK(G4,$G$3:$G$17)+COUNTIF(G$3:$G4,G4)-1 -> 8 | I4: 87 | J4: =RANK(I4,$I$3:$I$17)+COUNTIF(I$3:$I4,I4)-1 -> 9 | K4: =(E4+J4)/2 -> 5.5 | L4: =RANK(K4,$K$3:$K$17,1)+COUNTIF(K$3:$K4,K4)-1 -> 3 | N4: total | O4: =SUM(O5:O9) -> 480 | P4: 619 | Q4: 483 | R4: =SUM(R5:R9) -> 175 | S4: 210 | T4: 239
A5: TA | B5: DA2470 | C5: 111 | D5: Average | E5: 3 | F5: 265 | G5: 34 | H5: =RANK(G5,$G$3:$G$17)+COUNTIF(G$3:$G5,G5)-1 -> 12 | I5: 88 | J5: =RANK(I5,$I$3:$I$17)+COUNTIF(I$3:$I5,I5)-1 -> 5 | K5: =(E5+J5)/2 -> 4 | L5: =RANK(K5,$K$3:$K$17,1)+COUNTIF(K$3:$K5,K5)-1 -> 2 | N5: grasmere | O5: 180 | R5: 60
A6: CM | B6: DA1130 | C6: 107 | D6: Average | E6: 4 | F6: 706 | G6: 88 | H6: =RANK(G6,$G$3:$G$17)+COUNTIF(G$3:$G6,G6)-1 -> 3 | I6: 89 | J6: =RANK(I6,$I$3:$I$17)+COUNTIF(I$3:$I6,I6)-1 -> 2 | K6: =(E6+J6)/2 -> 3 | L6: =RANK(K6,$K$3:$K$17,1)+COUNTIF(K$3:$K6,K6)-1 -> 1 | N6: richlands | O6: 85 | R6: 35
A7: CM | B7: DA1721 | C7: 107 | D7: Average | E7: 5 | F7: 158 | G7: 36 | H7: =RANK(G7,$G$3:$G$17)+COUNTIF(G$3:$G7,G7)-1 -> 11 | I7: 88 | J7: =RANK(I7,$I$3:$I$17)+COUNTIF(I$3:$I7,I7)-1 -> 6 | K7: =(E7+J7)/2 -> 5.5 | L7: =RANK(K7,$K$3:$K$17,1)+COUNTIF(K$3:$K7,K7)-1 -> 4 | N7: Villa | O7: 40 | R7: 10 | U7: Actual total | V7: estimated
A8: TA | B8: DA1627 | C8: 106 | D8: Average | E8: 6 | F8: 270 | G8: 45 | H8: =RANK(G8,$G$3:$G$17)+COUNTIF(G$3:$G8,G8)-1 -> 9 | I8: 87 | J8: =RANK(I8,$I$3:$I$17)+COUNTIF(I$3:$I8,I8)-1 -> 10 | K8: =(E8+J8)/2 -> 8 | L8: =RANK(K8,$K$3:$K$17,1)+COUNTIF(K$3:$K8,K8)-1 -> 7 | N8: Lions Head | O8: 95 | R8: 40 | U8: =Q4+T4 -> 722 | V8: =P4+S4 -> 829
B9: DA2477 | C9: 105 | D9: Average | E9: 7 | F9: 0 | G9: 0 | H9: =RANK(G9,$G$3:$G$17)+COUNTIF(G$3:$G9,G9)-1 -> 14 | I9: 0 | J9: =RANK(I9,$I$3:$I$17)+COUNTIF(I$3:$I9,I9)-1 -> 14 | K9: =(E9+J9)/2 -> 10.5 | L9: =RANK(K9,$K$3:$K$17,1)+COUNTIF(K$3:$K9,K9)-1 -> 12 | N9: Porta | O9: 80 | R9: 30 | V9: =U8-V8 -> -107
A10: TA | B10: DA2568 | C10: 104 | D10: Average | E10: 8 | F10: 170 | G10: 34 | H10: =RANK(G10,$G$3:$G$17)+COUNTIF(G$3:$G10,G10)-1 -> 13 | I10: 86 | J10: =RANK(I10,$I$3:$I$17)+COUNTIF(I$3:$I10,I10)-1 -> 13 | K10: =(E10+J10)/2 -> 10.5 | L10: =RANK(K10,$K$3:$K$17,1)+COUNTIF(K$3:$K10,K10)-1 -> 13
A11: AW | B11: CL7180 | C11: 102 | D11: Below average | E11: 9 | F11: 344 | G11: 58 | H11: =RANK(G11,$G$3:$G$17)+COUNTIF(G$3:$G11,G11)-1 -> 7 | I11: 87 | J11: =RANK(I11,$I$3:$I$17)+COUNTIF(I$3:$I11,I11)-1 -> 11 | K11: =(E11+J11)/2 -> 10 | L11: =RANK(K11,$K$3:$K$17,1)+COUNTIF(K$3:$K11,K11)-1 -> 10
A12: TA | B12: CJ0211 | C12: 101 | D12: Below average | E12: 10 | F12: 552 | G12: 100 | H12: =RANK(G12,$G$3:$G$17)+COUNTIF(G$3:$G12,G12)-1 -> 2 | I12: 88 | J12: =RANK(I12,$I$3:$I$17)+COUNTIF(I$3:$I12,I12)-1 -> 7 | K12: =(E12+J12)/2 -> 8.5 | L12: =RANK(K12,$K$3:$K$17,1)+COUNTIF(K$3:$K12,K12)-1 -> 8
A13: AW | B13: CL5312 | C13: 98 | D13: Low | E13: 11 | F13: 362 | G13: 59 | H13: =RANK(G13,$G$3:$G$17)+COUNTIF(G$3:$G13,G13)-1 -> 6 | I13: 89 | J13: =RANK(I13,$I$3:$I$17)+COUNTIF(I$3:$I13,I13)-1 -> 3 | K13: =(E13+J13)/2 -> 7 | L13: =RANK(K13,$K$3:$K$17,1)+COUNTIF(K$3:$K13,K13)-1 -> 5
A14: CM | B14: CL3033 | C14: 97 | D14: Low | E14: 12 | F14: 434 | G14: 101 | H14: =RANK(G14,$G$3:$G$17)+COUNTIF(G$3:$G14,G14)-1 -> 1 | I14: 88 | J14: =RANK(I14,$I$3:$I$17)+COUNTIF(I$3:$I14,I14)-1 -> 8 | K14: =(E14+J14)/2 -> 10 | L14: =RANK(K14,$K$3:$K$17,1)+COUNTIF(K$3:$K14,K14)-1 -> 11
A15: TA | B15: DA0379 | C15: 95 | D15: Low | E15: 13 | F15: 270 | G15: 45 | H15: =RANK(G15,$G$3:$G$17)+COUNTIF(G$3:$G15,G15)-1 -> 10 | I15: 89 | J15: =RANK(I15,$I$3:$I$17)+COUNTIF(I$3:$I15,I15)-1 -> 4 | K15: =(E15+J15)/2 -> 8.5 | L15: =RANK(K15,$K$3:$K$17,1)+COUNTIF(K$3:$K15,K15)-1 -> 9
A16: CM | B16: CJ2150 | C16: 91 | D16: Low | E16: 14 | F16: 278 | G16: 84 | H16: =RANK(G16,$G$3:$G$17)+COUNTIF(G$3:$G16,G16)-1 -> 4 | I16: 90 | J16: =RANK(I16,$I$3:$I$17)+COUNTIF(I$3:$I16,I16)-1 -> 1 | K16: =(E16+J16)/2 -> 7.5 | L16: =RANK(K16,$K$3:$K$17,1)+COUNTIF(K$3:$K16,K16)-1 -> 6
A17: AW | B17: CE6835 | C17: 90 | D17: Low | E17: 15 | F17: 212 | G17: 67 | H17: =RANK(G17,$G$3:$G$17)+COUNTIF(G$3:$G17,G17)-1 -> 5 | I17: 87 | J17: =RANK(I17,$I$3:$I$17)+COUNTIF(I$3:$I17,I17)-1 -> 12 | K17: =(E17+J17)/2 -> 13.5 | L17: =RANK(K17,$K$3:$K$17,1)+COUNTIF(K$3:$K17,K17)-1 -> 14
B20: Sunday | C20: Wednesday
B21: T1 | C21: T2
B24: COMMENT

Sheet week 10
A1: Collector ID | B1: Boar | C1: TSI | D1: Genetic level | E1: Genetic Rank | F1: Last recorded raw Semen collected (mls) | G1: Last recorded Doses | H1: Dose rank | I1: Last recorded Morphology | J1: Morphology Rank | K1: Overal Grading | L1: Overal Rank | Y1: 45677
O2: Sunday | P2: Sunday | Q2: Sunday | R2: Wed | S2: Wed | T2: Wed
O3: required | P3: estimate | Q3: actual | R3: required | S3: estimate | T3: actual
A4: AW | B4: DA1669 | C4: 111 | D4: Average | E4: 2 | F4: 388 | G4: 55 | H4: =RANK(G4,$G$3:$G$17)+COUNTIF(G$3:$G4,G4)-1 -> 9 | I4: 88 | J4: =RANK(I4,$I$3:$I$17)+COUNTIF(I$3:$I4,I4)-1 -> 2 | K4: =(E4+J4)/2 -> 2 | L4: =RANK(K4,$K$3:$K$17,1)+COUNTIF(K$3:$K4,K4)-1 -> 1 | N4: total | O4: =SUM(O5:O9) -> 480 | P4: 483 | Q4: 497 | R4: =SUM(R5:R9) -> 175 | S4: 239
A5: AW | B5: DA2470 | C5: 111 | D5: Average | E5: 3 | F5: 164 | G5: 39 | H5: =RANK(G5,$G$3:$G$17)+COUNTIF(G$3:$G5,G5)-1 -> 11 | I5: 87 | J5: =RANK(I5,$I$3:$I$17)+COUNTIF(I$3:$I5,I5)-1 -> 7 | K5: =(E5+J5)/2 -> 5 | L5: =RANK(K5,$K$3:$K$17,1)+COUNTIF(K$3:$K5,K5)-1 -> 3 | N5: grasmere | O5: 180 | R5: 60
A6: AW | B6: DA1130 | C6: 107 | D6: Average | E6: 4 | F6: 574 | G6: 67 | H6: =RANK(G6,$G$3:$G$17)+COUNTIF(G$3:$G6,G6)-1 -> 6 | I6: 86 | J6: =RANK(I6,$I$3:$I$17)+COUNTIF(I$3:$I6,I6)-1 -> 12 | K6: =(E6+J6)/2 -> 8 | L6: =RANK(K6,$K$3:$K$17,1)+COUNTIF(K$3:$K6,K6)-1 -> 7 | N6: richlands | O6: 85 | R6: 35
A7: TA | B7: DA1721 | C7: 107 | D7: Average | E7: 5 | F7: 338 | G7: 83 | H7: =RANK(G7,$G$3:$G$17)+COUNTIF(G$3:$G7,G7)-1 -> 3 | I7: 87 | J7: =RANK(I7,$I$3:$I$17)+COUNTIF(I$3:$I7,I7)-1 -> 8 | K7: =(E7+J7)/2 -> 6.5 | L7: =RANK(K7,$K$3:$K$17,1)+COUNTIF(K$3:$K7,K7)-1 -> 4 | N7: Villa | O7: 40 | R7: 10 | U7: Actual total | V7: estimated
A8: AW | B8: DA1627 | C8: 106 | D8: Average | E8: 6 | F8: 150 | G8: 29 | H8: =RANK(G8,$G$3:$G$17)+COUNTIF(G$3:$G8,G8)-1 -> 13 | I8: 88 | J8: =RANK(I8,$I$3:$I$17)+COUNTIF(I$3:$I8,I8)-1 -> 3 | K8: =(E8+J8)/2 -> 4.5 | L8: =RANK(K8,$K$3:$K$17,1)+COUNTIF(K$3:$K8,K8)-1 -> 2 | N8: Lions Head | O8: 95 | R8: 40 | U8: =Q4+T4 -> 497 | V8: =P4+S4 -> 722
B9: DA2477 | C9: 105 | D9: Average | E9: 7 | F9: 0 | G9: 0 | H9: =RANK(G9,$G$3:$G$17)+COUNTIF(G$3:$G9,G9)-1 -> 14 | I9: 0 | J9: =RANK(I9,$I$3:$I$17)+COUNTIF(I$3:$I9,I9)-1 -> 14 | K9: =(E9+J9)/2 -> 10.5 | L9: =RANK(K9,$K$3:$K$17,1)+COUNTIF(K$3:$K9,K9)-1 -> 11 | N9: Porta | O9: 80 | R9: 30 | V9: =U8-V8 -> -225
A10: TA | B10: DA2568 | C10: 104 | D10: Average | E10: 8 | F10: 232 | G10: 64 | H10: =RANK(G10,$G$3:$G$17)+COUNTIF(G$3:$G10,G10)-1 -> 7 | I10: 87 | J10: =RANK(I10,$I$3:$I$17)+COUNTIF(I$3:$I10,I10)-1 -> 9 | K10: =(E10+J10)/2 -> 8.5 | L10: =RANK(K10,$K$3:$K$17,1)+COUNTIF(K$3:$K10,K10)-1 -> 8
A11: AW | B11: CL7180 | C11: 102 | D11: Below average | E11: 9 | F11: 326 | G11: 42 | H11: =RANK(G11,$G$3:$G$17)+COUNTIF(G$3:$G11,G11)-1 -> 10 | I11: 86 | J11: =RANK(I11,$I$3:$I$17)+COUNTIF(I$3:$I11,I11)-1 -> 13 | K11: =(E11+J11)/2 -> 11 | L11: =RANK(K11,$K$3:$K$17,1)+COUNTIF(K$3:$K11,K11)-1 -> 13
A12: AW | B12: CJ0211 | C12: 101 | D12: Below average | E12: 10 | F12: 568 | G12: 79 | H12: =RANK(G12,$G$3:$G$17)+COUNTIF(G$3:$G12,G12)-1 -> 5 | I12: 87 | J12: =RANK(I12,$I$3:$I$17)+COUNTIF(I$3:$I12,I12)-1 -> 10 | K12: =(E12+J12)/2 -> 10 | L12: =RANK(K12,$K$3:$K$17,1)+COUNTIF(K$3:$K12,K12)-1 -> 10
A13: TA | B13: CL5312 | C13: 98 | D13: Low | E13: 11 | F13: 298 | G13: 56 | H13: =RANK(G13,$G$3:$G$17)+COUNTIF(G$3:$G13,G13)-1 -> 8 | I13: 88 | J13: =RANK(I13,$I$3:$I$17)+COUNTIF(I$3:$I13,I13)-1 -> 4 | K13: =(E13+J13)/2 -> 7.5 | L13: =RANK(K13,$K$3:$K$17,1)+COUNTIF(K$3:$K13,K13)-1 -> 6
A14: TA | B14: CL3033 | C14: 97 | D14: Low | E14: 12 | F14: 408 | G14: 82 | H14: =RANK(G14,$G$3:$G$17)+COUNTIF(G$3:$G14,G14)-1 -> 4 | I14: 89 | J14: =RANK(I14,$I$3:$I$17)+COUNTIF(I$3:$I14,I14)-1 -> 1 | K14: =(E14+J14)/2 -> 6.5 | L14: =RANK(K14,$K$3:$K$17,1)+COUNTIF(K$3:$K14,K14)-1 -> 5
A15: TA | B15: DA0379 | C15: 95 | D15: Low | E15: 13 | F15: 244 | G15: 93 | H15: =RANK(G15,$G$3:$G$17)+COUNTIF(G$3:$G15,G15)-1 -> 1 | I15: 88 | J15: =RANK(I15,$I$3:$I$17)+COUNTIF(I$3:$I15,I15)-1 -> 5 | K15: =(E15+J15)/2 -> 9 | L15: =RANK(K15,$K$3:$K$17,1)+COUNTIF(K$3:$K15,K15)-1 -> 9
A16: CM | B16: CJ2150 | C16: 91 | D16: Low | E16: 14 | F16: 278 | G16: 84 | H16: =RANK(G16,$G$3:$G$17)+COUNTIF(G$3:$G16,G16)-1 -> 2 | I16: 87 | J16: =RANK(I16,$I$3:$I$17)+COUNTIF(I$3:$I16,I16)-1 -> 11 | K16: =(E16+J16)/2 -> 12.5 | L16: =RANK(K16,$K$3:$K$17,1)+COUNTIF(K$3:$K16,K16)-1 -> 14
A17: TA | B17: CE6835 | C17: 90 | D17: Low | E17: 15 | F17: 128 | G17: 38 | H17: =RANK(G17,$G$3:$G$17)+COUNTIF(G$3:$G17,G17)-1 -> 12 | I17: 88 | J17: =RANK(I17,$I$3:$I$17)+COUNTIF(I$3:$I17,I17)-1 -> 6 | K17: =(E17+J17)/2 -> 10.5 | L17: =RANK(K17,$K$3:$K$17,1)+COUNTIF(K$3:$K17,K17)-1 -> 12
B20: Sunday | C20: Wednesday
B21: T1 | C21: T2
B24: COMMENT

Sheet week 11
B1: Collector ID | C1: Boar | D1: TSI | E1: Genetic level | F1: Genetic Rank | G1: Last recorded raw Semen collected (mls) | H1: Last recorded Doses | I1: Dose rank | J1: Last recorded Morphology | K1: Morphology Rank | L1: Overal Grading | M1: Overal Rank | Z1: 45677
P2: Sunday | Q2: Sunday | R2: Sunday | S2: Wed | T2: Wed | U2: Wed
C3: DA3337 | D3: 119 | E3: Above average | F3: 1 | P3: required | Q3: estimate | R3: actual | S3: required | T3: estimate | U3: actual
C4: DA3132 | D4: 118 | E4: Above average | F4: 2 | O4: total | P4: =SUM(P5:P9) -> 480 | Q4: 497 | R4: 534 | S4: =SUM(S5:S9) -> 175 | T4: =#REF! -> #REF! | U4: 184
C5: DA3300 | D5: 117 | E5: Above average | F5: 3 | O5: grasmere | P5: 180 | S5: 60
B6: AW | C6: DA1721 | D6: 108 | E6: Average | F6: 4 | G6: 172 | H6: 40 | I6: =RANK(H6,$H$3:$H$17)+COUNTIF(H$3:$H6,H6)-1 -> 11 | J6: 88 | K6: =RANK(J6,$J$3:$J$17)+COUNTIF(J$3:$J6,J6)-1 -> 1 | L6: =(F6+K6)/2 -> 2.5 | M6: =RANK(L6,$L$3:$L$17,1)+COUNTIF(L$3:$L6,L6)-1 -> 1 | O6: richlands | P6: 85 | S6: 35
B7: TA | C7: DA1669 | D7: 107 | E7: Average | F7: 5 | G7: 236 | H7: 82 | I7: =RANK(H7,$H$3:$H$17)+COUNTIF(H$3:$H7,H7)-1 -> 4 | J7: 87 | K7: =RANK(J7,$J$3:$J$17)+COUNTIF(J$3:$J7,J7)-1 -> 6 | L7: =(F7+K7)/2 -> 5.5 | M7: =RANK(L7,$L$3:$L$17,1)+COUNTIF(L$3:$L7,L7)-1 -> 3 | O7: Villa | P7: 40 | S7: 10 | V7: Actual total | W7: estimated
B8: TA | C8: DA2470 | D8: 106 | E8: Average | F8: 6 | G8: 112 | H8: 30 | I8: =RANK(H8,$H$3:$H$17)+COUNTIF(H$3:$H8,H8)-1 -> 12 | J8: 86 | K8: =RANK(J8,$J$3:$J$17)+COUNTIF(J$3:$J8,J8)-1 -> 10 | L8: =(F8+K8)/2 -> 8 | M8: =RANK(L8,$L$3:$L$17,1)+COUNTIF(L$3:$L8,L8)-1 -> 6 | O8: Lions Head | P8: 95 | S8: 40 | V8: =R4+U4 -> 718 | W8: =Q4+T4 -> #REF!
B9: AW | C9: DA1627 | D9: 102 | E9: Below average | F9: 7 | G9: 302 | H9: 78 | I9: =RANK(H9,$H$3:$H$17)+COUNTIF(H$3:$H9,H9)-1 -> 6 | J9: 87 | K9: =RANK(J9,$J$3:$J$17)+COUNTIF(J$3:$J9,J9)-1 -> 7 | L9: =(F9+K9)/2 -> 7 | M9: =RANK(L9,$L$3:$L$17,1)+COUNTIF(L$3:$L9,L9)-1 -> 4 | O9: Porta | P9: 80 | S9: 30 | W9: =V8-W8 -> #REF!
B10: CM | C10: DA1130 | D10: 100 | E10: Low | F10: 8 | G10: 556 | H10: 128 | I10: =RANK(H10,$H$3:$H$17)+COUNTIF(H$3:$H10,H10)-1 -> 1 | J10: 88 | K10: =RANK(J10,$J$3:$J$17)+COUNTIF(J$3:$J10,J10)-1 -> 2 | L10: =(F10+K10)/2 -> 5 | M10: =RANK(L10,$L$3:$L$17,1)+COUNTIF(L$3:$L10,L10)-1 -> 2
B11: TA | C11: CL7180 | D11: 99 | E11: Low | F11: 9 | G11: 344 | H11: 67 | I11: =RANK(H11,$H$3:$H$17)+COUNTIF(H$3:$H11,H11)-1 -> 7 | J11: 87 | K11: =RANK(J11,$J$3:$J$17)+COUNTIF(J$3:$J11,J11)-1 -> 8 | L11: =(F11+K11)/2 -> 8.5 | M11: =RANK(L11,$L$3:$L$17,1)+COUNTIF(L$3:$L11,L11)-1 -> 7
B12: AW | C12: DA2568 | D12: 99 | E12: Low | F12: 11 | G12: 226 | H12: 53 | I12: =RANK(H12,$H$3:$H$17)+COUNTIF(H$3:$H12,H12)-1 -> 9 | J12: 88 | K12: =RANK(J12,$J$3:$J$17)+COUNTIF(J$3:$J12,J12)-1 -> 3 | L12: =(F12+K12)/2 -> 7 | M12: =RANK(L12,$L$3:$L$17,1)+COUNTIF(L$3:$L12,L12)-1 -> 5
B13: CM | C13: CL3033 | D13: 98 | E13: Low | F13: 12 | G13: 396 | H13: 82 | I13: =RANK(H13,$H$3:$H$17)+COUNTIF(H$3:$H13,H13)-1 -> 5 | J13: 86 | K13: =RANK(J13,$J$3:$J$17)+COUNTIF(J$3:$J13,J13)-1 -> 11 | L13: =(F13+K13)/2 -> 11.5 | M13: =RANK(L13,$L$3:$L$17,1)+COUNTIF(L$3:$L13,L13)-1 -> 10
B14: CM | C14: CJ0211 | D14: 98 | E14: Low | F14: 13 | G14: 540 | H14: 66 | I14: =RANK(H14,$H$3:$H$17)+COUNTIF(H$3:$H14,H14)-1 -> 8 | J14: 88 | K14: =RANK(J14,$J$3:$J$17)+COUNTIF(J$3:$J14,J14)-1 -> 4 | L14: =(F14+K14)/2 -> 8.5 | M14: =RANK(L14,$L$3:$L$17,1)+COUNTIF(L$3:$L14,L14)-1 -> 8
B15: AW | C15: DA0379 | D15: 97 | E15: Low | F15: 14 | G15: 316 | H15: 87 | I15: =RANK(H15,$H$3:$H$17)+COUNTIF(H$3:$H15,H15)-1 -> 2 | J15: 87 | K15: =RANK(J15,$J$3:$J$17)+COUNTIF(J$3:$J15,J15)-1 -> 9 | L15: =(F15+K15)/2 -> 11.5 | M15: =RANK(L15,$L$3:$L$17,1)+COUNTIF(L$3:$L15,L15)-1 -> 11
B16: CM | C16: CL5312 | D16: 96 | E16: Low | F16: 15 | G16: 394 | H16: 44 | I16: =RANK(H16,$H$3:$H$17)+COUNTIF(H$3:$H16,H16)-1 -> 10 | J16: 86 | K16: =RANK(J16,$J$3:$J$17)+COUNTIF(J$3:$J16,J16)-1 -> 12 | L16: =(F16+K16)/2 -> 13.5 | M16: =RANK(L16,$L$3:$L$17,1)+COUNTIF(L$3:$L16,L16)-1 -> 12
A17: CULL | B17: TA | C17: CJ2150 | D17: 90 | E17: Very low | F17: 16 | G17: 278 | H17: 84 | I17: =RANK(H17,$H$3:$H$17)+COUNTIF(H$3:$H17,H17)-1 -> 3 | J17: 88 | K17: =RANK(J17,$J$3:$J$17)+COUNTIF(J$3:$J17,J17)-1 -> 5 | L17: =(F17+K17)/2 -> 10.5 | M17: =RANK(L17,$L$3:$L$17,1)+COUNTIF(L$3:$L17,L17)-1 -> 9
A18: CULL | C18: da77
A19: CULL | C19: ce35
C21: Sunday | D21: Wednesday
C22: T1 | D22: T2
C25: COMMENT
D26: Not yet in use

Sheet week 12
A1: Collector ID | B1: Boar | C1: TSI | D1: Genetic level | E1: Genetic Rank | F1: Last recorded raw Semen collected (mls) | G1: Last recorded Doses | H1: Dose rank | I1: Last recorded Morphology | J1: Morphology Rank | K1: Overal Grading | L1: Overal Rank | Y1: 45677
O2: Sunday | P2: Sunday | Q2: Sunday | R2: Wed | S2: Wed | T2: Wed
B3: DA3337 | C3: 119 | D3: Above average | E3: 1 | O3: required | P3: estimate | Q3: actual | R3: required | S3: estimate | T3: actual
B4: DA3132 | C4: 118 | D4: Above average | E4: 2 | N4: total | O4: =SUM(O5:O9) -> 480 | P4: 534 | Q4: 572 | R4: =SUM(R5:R9) -> 175 | S4: =#REF! -> #REF!
B5: DA3300 | C5: 117 | D5: Above average | E5: 3 | N5: grasmere | O5: 180 | R5: 60
A6: CM | B6: DA1721 | C6: 108 | D6: Average | E6: 4 | F6: 344 | G6: 93 | H6: =RANK(G6,$G$3:$G$16)+COUNTIF(G$3:$G6,G6)-1 -> 2 | I6: 87 | J6: =RANK(I6,$I$3:$I$16)+COUNTIF(I$3:$I6,I6)-1 -> 9 | K6: =(E6+J6)/2 -> 6.5 | L6: =RANK(K6,$K$3:$K$16,1)+COUNTIF(K$3:$K6,K6)-1 -> 5 | N6: richlands | O6: 85 | R6: 35
A7: TA | B7: DA1669 | C7: 107 | D7: Average | E7: 5 | F7: 236 | G7: 68 | H7: =RANK(G7,$G$3:$G$16)+COUNTIF(G$3:$G7,G7)-1 -> 7 | I7: 88 | J7: =RANK(I7,$I$3:$I$16)+COUNTIF(I$3:$I7,I7)-1 -> 2 | K7: =(E7+J7)/2 -> 3.5 | L7: =RANK(K7,$K$3:$K$16,1)+COUNTIF(K$3:$K7,K7)-1 -> 1 | N7: Villa | O7: 40 | R7: 10 | U7: Actual total | V7: estimated
A8: CM | B8: DA2470 | C8: 106 | D8: Average | E8: 6 | F8: 136 | G8: 22 | H8: =RANK(G8,$G$3:$G$16)+COUNTIF(G$3:$G8,G8)-1 -> 11 | I8: 89 | J8: =RANK(I8,$I$3:$I$16)+COUNTIF(I$3:$I8,I8)-1 -> 1 | K8: =(E8+J8)/2 -> 3.5 | L8: =RANK(K8,$K$3:$K$16,1)+COUNTIF(K$3:$K8,K8)-1 -> 2 | N8: Lions Head | O8: 95 | R8: 40 | U8: =Q4+T4 -> 572 | V8: =P4+S4 -> #REF!
A9: CM | B9: DA1627 | C9: 102 | D9: Below average | E9: 7 | F9: 294 | G9: 71 | H9: =RANK(G9,$G$3:$G$16)+COUNTIF(G$3:$G9,G9)-1 -> 6 | I9: 88 | J9: =RANK(I9,$I$3:$I$16)+COUNTIF(I$3:$I9,I9)-1 -> 3 | K9: =(E9+J9)/2 -> 5 | L9: =RANK(K9,$K$3:$K$16,1)+COUNTIF(K$3:$K9,K9)-1 -> 3 | N9: Porta | O9: 80 | R9: 30 | V9: =U8-V8 -> #REF!
A10: TA | B10: DA1130 | C10: 100 | D10: Low | E10: 8 | F10: 506 | G10: 103 | H10: =RANK(G10,$G$3:$G$16)+COUNTIF(G$3:$G10,G10)-1 -> 1 | I10: 88 | J10: =RANK(I10,$I$3:$I$16)+COUNTIF(I$3:$I10,I10)-1 -> 4 | K10: =(E10+J10)/2 -> 6 | L10: =RANK(K10,$K$3:$K$16,1)+COUNTIF(K$3:$K10,K10)-1 -> 4
A11: CM | B11: CL7180 | C11: 99 | D11: Low | E11: 9 | F11: 376 | G11: 33 | H11: =RANK(G11,$G$3:$G$16)+COUNTIF(G$3:$G11,G11)-1 -> 10 | I11: 88 | J11: =RANK(I11,$I$3:$I$16)+COUNTIF(I$3:$I11,I11)-1 -> 5 | K11: =(E11+J11)/2 -> 7 | L11: =RANK(K11,$K$3:$K$16,1)+COUNTIF(K$3:$K11,K11)-1 -> 6
A12: CM | B12: DA2568 | C12: 99 | D12: Low | E12: 11 | F12: 250 | G12: 73 | H12: =RANK(G12,$G$3:$G$16)+COUNTIF(G$3:$G12,G12)-1 -> 5 | I12: 86 | J12: =RANK(I12,$I$3:$I$16)+COUNTIF(I$3:$I12,I12)-1 -> 11 | K12: =(E12+J12)/2 -> 11 | L12: =RANK(K12,$K$3:$K$16,1)+COUNTIF(K$3:$K12,K12)-1 -> 9
A13: TA | B13: CL3033 | C13: 98 | D13: Low | E13: 12 | F13: 396 | G13: 86 | H13: =RANK(G13,$G$3:$G$16)+COUNTIF(G$3:$G13,G13)-1 -> 4 | I13: 88 | J13: =RANK(I13,$I$3:$I$16)+COUNTIF(I$3:$I13,I13)-1 -> 6 | K13: =(E13+J13)/2 -> 9 | L13: =RANK(K13,$K$3:$K$16,1)+COUNTIF(K$3:$K13,K13)-1 -> 7
A14: TA | B14: CJ0211 | C14: 98 | D14: Low | E14: 13 | F14: 516 | G14: 92 | H14: =RANK(G14,$G$3:$G$16)+COUNTIF(G$3:$G14,G14)-1 -> 3 | I14: 87 | J14: =RANK(I14,$I$3:$I$16)+COUNTIF(I$3:$I14,I14)-1 -> 10 | K14: =(E14+J14)/2 -> 11.5 | L14: =RANK(K14,$K$3:$K$16,1)+COUNTIF(K$3:$K14,K14)-1 -> 10
A15: CM | B15: DA0379 | C15: 97 | D15: Low | E15: 14 | F15: 256 | G15: 54 | H15: =RANK(G15,$G$3:$G$16)+COUNTIF(G$3:$G15,G15)-1 -> 8 | I15: 88 | J15: =RANK(I15,$I$3:$I$16)+COUNTIF(I$3:$I15,I15)-1 -> 7 | K15: =(E15+J15)/2 -> 10.5 | L15: =RANK(K15,$K$3:$K$16,1)+COUNTIF(K$3:$K15,K15)-1 -> 8
A16: TA | B16: CL5312 | C16: 96 | D16: Low | E16: 15 | F16: 374 | G16: 45 | H16: =RANK(G16,$G$3:$G$16)+COUNTIF(G$3:$G16,G16)-1 -> 9 | I16: 88 | J16: =RANK(I16,$I$3:$I$16)+COUNTIF(I$3:$I16,I16)-1 -> 8 | K16: =(E16+J16)/2 -> 11.5 | L16: =RANK(K16,$K$3:$K$16,1)+COUNTIF(K$3:$K16,K16)-1 -> 11
B19: Sunday | C19: Wednesday
B20: T1 | C20: T2
B23: COMMENT
C24: Not yet in use

Sheet week 13
A1: Collector ID | B1: Boar | C1: TSI | D1: Genetic level | E1: Genetic Rank | F1: Last recorded raw Semen collected (mls) | G1: Last recorded Doses | H1: Dose rank | I1: Last recorded Morphology | J1: Morphology Rank | K1: Overal Grading | L1: Overal Rank | Y1: 45677
O2: Sunday | P2: Sunday | Q2: Sunday | R2: Wed | S2: Wed | T2: Wed
B3: DA3337 | C3: 119 | D3: Above average | E3: 1 | O3: required | P3: estimate | Q3: actual | R3: required | S3: estimate | T3: actual
B4: DA3132 | C4: 118 | D4: Above average | E4: 2 | N4: total | O4: =SUM(O5:O9) -> 480 | P4: 572 | Q4: 489 | R4: =SUM(R5:R9) -> 175 | S4: =#REF! -> #REF! | T4: 185
B5: DA3300 | C5: 117 | D5: Above average | E5: 3 | N5: grasmere | O5: 180 | R5: 60
